Workbook
Name Ccy: MAIN!$C$6
Name circ: MAIN!$C$9
Name CoName: MAIN!$C$4
Name g: #REF!
Name IQ_CH: 110000
Name IQ_CQ: 5000
Name IQ_CY: 10000
Name IQ_DAILY: 500000
Name IQ_FH: 100000
Name IQ_FQ: 500
Name IQ_FY: 1000
Name IQ_LTM: 2000
Name IQ_MONTH: 15000
Name IQ_NTM: 6000
Name IQ_WEEK: 50000
Name IQ_YTD: 3000
Name OpCase: [1]DCF!$E$98
Name ScenarioREV: Assumptions!$D$4
Name TTS: #REF!
Name Units: MAIN!$C$7

Sheet MAIN
A1: =CoName -> Advanced Micro Devices Inc.
A2: Model Details
B4: Company name | C4: Advanced Micro Devices Inc. | E4: Current Stock Price | F4: 254.77 | H4: Operating Case One | I4: Terminal Mult | J4: Perpetuity | K4: Average
B5: Latest BS date | C5: 247.43 | E5: S/O | F5: 1628.0415 | H5: Implied Price | I5: ='DCF Model'!G18 -> 300.82362 | J5: ='DCF Model'!C18 -> 193.96932 | K5: =AVERAGE(I5:J5) -> 247.39647
B6: Currency | C6: USD | E6: Mkt Cap | F6: =F5*F4 -> 414776.14 | H6: Difference | I6: =I5/$F$4-1 -> 0.18076548 | J6: =J5/$F$4-1 -> -0.2386493 | K6: =K5/$F$4-1 -> -0.028941912
B7: Units | C7: m | E7: Cash | F7: =13182.9+5.6 -> 13188.5
B8: Analyst name | C8: Alan Chen | E8: Debt | F8: =1045.1+3806.4 -> 4851.5
B9: Circular switch | C9: 0 | E9: EV | F9: =F6-F7+F8 -> 406439.14

Sheet Revenue
A1: =CoName -> Advanced Micro Devices Inc.
A2: Revenues | C2: Q122 | D2: Q222 | E2: Q322 | F2: Q422 | G2: 2022 | H2: Q123 | I2: Q223 | J2: Q323 | K2: Q423 | L2: 2023 | M2: Q124 | N2: Q224 | O2: Q324 | P2: Q424 | Q2: 2024 | R2: Q125 | S2: Q225 | T2: Q325 | U2: Q425 | V2: 2025 | W2: Q126 | X2: Q226 | Y2: Q326 | Z2: Q426 | AA2: 2026 | AB2: =AA2+1 -> 2027 | AC2: =AB2+1 -> 2028 | AD2: =AC2+1 -> 2029 | AE2: =AD2+1 -> 2030 | AF2: =AE2+1 -> 2031 | AG2: =AF2+1 -> 2032 | AH2: =AG2+1 -> 2033 | AI2: =AH2+1 -> 2034
A3: * | B3: Data Centers | C3: 1293 | D3: 1486 | E3: 1609 | F3: 1655 | G3: =SUM(C3:F3) -> 6043 | H3: 1295 | I3: 1321 | J3: 1598 | K3: 3549 | L3: =SUM(H3:K3) -> 7763 | M3: 2337 | N3: 2834 | O3: 3549 | P3: 3859 | Q3: =SUM(M3:P3) -> 12579 | R3: 3674 | S3: 3240 | T3: 4341 | U3: =P3*(1+U9) -> 4630.8 | V3: =SUM(R3:U3) -> 15885.8 | W3: =R3*(1+W9) -> 4408.8 | X3: =S3*(1+X9) -> 4091.7396 | Y3: =T3*(1+Y9) -> 5209.2 | Z3: =U3*(1+Z9) -> 5848.1567 | AA3: =SUM(W3:Z3) -> 19557.896 | AB3: =AA3*(1+AB9) -> 27381.055 | AC3: =AB3*(1+AC9) -> 38881.098 | AD3: =AC3*(1+AD9) -> 53655.915 | AE3: =AD3*(1+AE9) -> 71898.926 | AF3: =AE3*(1+AF9) -> 93468.604 | AG3: =AF3*(1+AG9) -> 117770.44 | AH3: =AG3*(1+AH9) -> 143679.94 | AI3: =AH3*(1+AI9) -> 169542.33
B4: Client | C4: 2124 | D4: 2152 | E4: 1022 | F4: 903 | G4: =SUM(C4:F4) -> 6201 | H4: 739 | I4: 998 | J4: 1453 | K4: 1881 | L4: =SUM(H4:K4) -> 5071 | M4: 1368 | N4: 1492 | O4: 1881 | P4: 2313 | Q4: =SUM(M4:P4) -> 7054 | R4: 2294 | S4: 2499 | T4: 2750 | U4: =P4*(1+U10) -> 3469.5 | V4: =SUM(R4:U4) -> 11012.5 | W4: =R4*(1+W10) -> 3441 | X4: =S4*(1+X10) -> 3901.3662 | Y4: =T4*(1+Y10) -> 4125 | Z4: =U4*(1+Z10) -> 5416.4827 | AA4: =SUM(W4:Z4) -> 16883.849 | AB4: =AA4*(1+AB10) -> 23637.388 | AC4: =AB4*(1+AC10) -> 33565.092 | AD4: =AC4*(1+AD10) -> 46319.826 | AE4: =AD4*(1+AE10) -> 62068.567 | AF4: =AE4*(1+AF10) -> 80689.138 | AG4: =AF4*(1+AG10) -> 101668.31 | AH4: =AG4*(1+AH10) -> 124035.34 | AI4: =AH4*(1+AI10) -> 146361.7
B5: Gaming | C5: 1875 | D5: 1655 | E5: 1631 | F5: 1644 | G5: =SUM(C5:F5) -> 6805 | H5: 1575 | I5: 1581 | J5: 1506 | K5: 462 | L5: =SUM(H5:K5) -> 5124 | M5: 922 | N5: 648 | O5: 462 | P5: 563 | Q5: =SUM(M5:P5) -> 2595 | R5: 647 | S5: 1122 | T5: 1298 | U5: =P5*(1+U11) -> 844.5 | V5: =SUM(R5:U5) -> 3911.5 | W5: =R5*(1+W11) -> 970.5 | X5: =S5*(1+X11) -> 1691.215 | Y5: =T5*(1+Y11) -> 1947 | Z5: =U5*(1+Z11) -> 1272.9332 | AA5: =SUM(W5:Z5) -> 5881.6483 | AB5: =AA5*(1+AB11) -> 8234.3076 | AC5: =AB5*(1+AC11) -> 11692.717 | AD5: =AC5*(1+AD11) -> 16135.949 | AE5: =AD5*(1+AE11) -> 21622.172 | AF5: =AE5*(1+AF11) -> 28108.823 | AG5: =AF5*(1+AG11) -> 35417.117 | AH5: =AG5*(1+AH11) -> 43208.883 | AI5: =AH5*(1+AI11) -> 50986.482
B6: Embedded | C6: 595 | D6: 1257 | E6: 1303 | F6: 1397 | G6: =SUM(C6:F6) -> 4552 | H6: 1562 | I6: 1459 | J6: 1242 | K6: 927 | L6: =SUM(H6:K6) -> 5190 | M6: 846 | N6: 861 | O6: 927 | P6: 923 | Q6: =SUM(M6:P6) -> 3557 | R6: 823 | S6: 824 | T6: 857 | U6: =P6*(1+U12) -> 932.23 | V6: =SUM(R6:U6) -> 3436.23 | W6: =R6*(1+W12) -> 831.23 | X6: =S6*(1+X12) -> 796.02292 | Y6: =T6*(1+Y12) -> 865.57 | Z6: =U6*(1+Z12) -> 900.57821 | AA6: =SUM(W6:Z6) -> 3393.4011 | AB6: =AA6*(1+AB12) -> 4750.7616 | AC6: =AB6*(1+AC12) -> 6746.0814 | AD6: =AC6*(1+AD12) -> 9309.5924 | AE6: =AD6*(1+AE12) -> 12474.854 | AF6: =AE6*(1+AF12) -> 16217.31 | AG6: =AF6*(1+AG12) -> 20433.811 | AH6: =AG6*(1+AH12) -> 24929.249 | AI6: =AH6*(1+AI12) -> 29416.514
B7: TOTAL REVENUES | C7: =SUM(C3:C6) -> 5887 | D7: =SUM(D3:D6) -> 6550 | E7: =SUM(E3:E6) -> 5565 | F7: =SUM(F3:F6) -> 5599 | G7: =SUM(G3:G6) -> 23601 | H7: =SUM(H3:H6) -> 5171 | I7: =SUM(I3:I6) -> 5359 | J7: =SUM(J3:J6) -> 5799 | ... AI7: =SUM(AI3:AI6) -> 396307.03
B8: y/y | H8: =H7/C7-1 -> -0.12162392 | I8: =I7/D7-1 -> -0.18183206 | J8: =J7/E7-1 -> 0.042048518 | K8: =K7/F7-1 -> 0.21789605 | L8: =L7/G7-1 -> -0.019194102 | M8: =M7/H7-1 -> 0.05840263 | N8: =N7/I7-1 -> 0.088822542 | O8: =O7/J7-1 -> 0.1758924 | ... AA8: =AA7/V7-1 -> 0.33495166 | AB8: =AB7/AA7-1 -> 0.4 | AC8: =AC7/AB7-1 -> 0.42 | AD8: =AD7/AC7-1 -> 0.38 | AE8: =AE7/AD7-1 -> 0.34 | AF8: =AF7/AE7-1 -> 0.3 | AG8: =AG7/AF7-1 -> 0.26 | AH8: =AH7/AG7-1 -> 0.22 | AI8: =AI7/AH7-1 -> 0.18
A9: % | B9: Data Centers | H9: =H3/C3-1 -> 0.0015467904 | I9: =I3/D3-1 -> -0.11103634 | J9: =J3/E3-1 -> -0.0068365444 | K9: =K3/F3-1 -> 1.1444109 | L9: =L3/G3-1 -> 0.28462684 | M9: =M3/H3-1 -> 0.8046332 | N9: =N3/I3-1 -> 1.1453444 | O9: =O3/J3-1 -> 1.2209011 | ... T9: =T3/O3-1 -> 0.22316145 | U9: 0.2 | V9: =V3/Q3-1 -> 0.26288258 | W9: =U9 -> 0.2 | X9: =V9 -> 0.26288258 | Y9: 0.2 | Z9: =X9 -> 0.26288258 | AA9: =AA3/V3-1 -> 0.23115589 | AB9: 0.4 | AC9: 0.42 | AD9: =AC9-0.04 -> 0.38 | AE9: =AD9-0.04 -> 0.34 | AF9: =AE9-0.04 -> 0.3 | AG9: =AF9-0.04 -> 0.26 | AH9: =AG9-0.04 -> 0.22 | AI9: =AH9-0.04 -> 0.18
A10: % | B10: Client | H10: =H4/C4-1 -> -0.65207156 | I10: =I4/D4-1 -> -0.53624535 | J10: =J4/E4-1 -> 0.42172211 | K10: =K4/F4-1 -> 1.0830565 | L10: =L4/G4-1 -> -0.18222867 | M10: =M4/H4-1 -> 0.8511502 | N10: =N4/I4-1 -> 0.49498998 | O10: =O4/J4-1 -> 0.29456297 | ... T10: =T4/O4-1 -> 0.4619883 | U10: 0.5 | V10: =V4/Q4-1 -> 0.56117097 | W10: =U10 -> 0.5 | X10: =V10 -> 0.56117097 | Y10: =W10 -> 0.5 | Z10: =X10 -> 0.56117097 | AA10: =AA4/V4-1 -> 0.53315314 | AB10: 0.4 | AC10: 0.42 | AD10: =AC10-0.04 -> 0.38 | AE10: =AD10-0.04 -> 0.34 | AF10: =AE10-0.04 -> 0.3 | AG10: =AF10-0.04 -> 0.26 | AH10: =AG10-0.04 -> 0.22 | AI10: =AH10-0.04 -> 0.18
A11: % | B11: Gaming | H11: =H5/C5-1 -> -0.16 | I11: =I5/D5-1 -> -0.044712991 | J11: =J5/E5-1 -> -0.076640098 | K11: =K5/F5-1 -> -0.7189781 | L11: =L5/G5-1 -> -0.24702425 | M11: =M5/H5-1 -> -0.41460317 | N11: =N5/I5-1 -> -0.59013283 | O11: =O5/J5-1 -> -0.69322709 | ... T11: =T5/O5-1 -> 1.8095238 | U11: 0.5 | V11: =V5/Q5-1 -> 0.50732177 | W11: =U11 -> 0.5 | X11: =V11 -> 0.50732177 | Y11: =W11 -> 0.5 | Z11: =X11 -> 0.50732177 | AA11: =AA5/V5-1 -> 0.50368101 | AB11: 0.4 | AC11: 0.42 | AD11: =AC11-0.04 -> 0.38 | AE11: =AD11-0.04 -> 0.34 | AF11: =AE11-0.04 -> 0.3 | AG11: =AF11-0.04 -> 0.26 | AH11: =AG11-0.04 -> 0.22 | AI11: =AH11-0.04 -> 0.18
A12: % | B12: Embedded | H12: =H6/C6-1 -> 1.6252101 | I12: =I6/D6-1 -> 0.16070008 | J12: =J6/E6-1 -> -0.046815042 | K12: =K6/F6-1 -> -0.33643522 | L12: =L6/G6-1 -> 0.14015817 | M12: =M6/H6-1 -> -0.45838668 | N12: =N6/I6-1 -> -0.40986977 | O12: =O6/J6-1 -> -0.25362319 | ... T12: =T6/O6-1 -> -0.075512406 | U12: 0.01 | V12: =V6/Q6-1 -> -0.033952769 | W12: =U12 -> 0.01 | X12: =V12 -> -0.033952769 | Y12: =W12 -> 0.01 | Z12: =X12 -> -0.033952769 | AA12: =AA6/V6-1 -> -0.012463913 | AB12: 0.4 | AC12: 0.42 | AD12: =AC12-0.04 -> 0.38 | AE12: =AD12-0.04 -> 0.34 | AF12: =AE12-0.04 -> 0.3 | AG12: =AF12-0.04 -> 0.26 | AH12: =AG12-0.04 -> 0.22 | AI12: =AH12-0.04 -> 0.18

Sheet Assumptions
A1: =CoName -> Advanced Micro Devices Inc. | C1: Hist. | D1: Hist. | E1: Hist. | F1: Proj. | G1: Proj. | H1: Proj. | I1: Proj. | J1: Proj. | K1: Proj. | L1: Proj. | M1: Proj. | N1: Proj. | O1: Proj.
A2: * | B2: Income Statement | C2: 44926 | D2: 45291 | E2: 45657 | F2: 46022 | G2: 46387 | H2: 46752 | I2: 47118 | J2: 47483 | K2: 47848 | L2: 48213 | M2: 48579 | N2: =M2+1 -> 48580 | O2: =N2+1 -> 48581
B4: Operating Case | D4: 1
D5: Variance
B6: Street Case | D6: 0 | F6: =Revenue!V8 -> 0.32813768 | G6: =Revenue!AA8 -> 0.33495166 | H6: =Revenue!AB8 -> 0.4 | I6: =Revenue!AC8 -> 0.42 | J6: =Revenue!AD8 -> 0.38 | K6: =Revenue!AE8 -> 0.34 | L6: =Revenue!AF8 -> 0.3 | M6: =Revenue!AG8 -> 0.26 | N6: =Revenue!AH8 -> 0.22 | O6: =Revenue!AI8 -> 0.18
B7: Optimistic Case | D7: 0.025 | F7: =F6+$D$7 -> 0.35313768 | G7: =G6+$D$7 -> 0.35995166 | H7: =H6+$D$7 -> 0.425 | I7: =I6+$D$7 -> 0.445 | J7: =J6+$D$7 -> 0.405 | K7: =K6+$D$7 -> 0.365 | L7: =L6+$D$7 -> 0.325 | M7: =M6+$D$7 -> 0.285 | ... O7: =O6+$D$7 -> 0.205
B8: Pessimistic Case | D8: -0.025 | F8: =F6+$D$8 -> 0.30313768 | G8: =G6+$D$8 -> 0.30995166 | H8: =H6+$D$8 -> 0.375 | I8: =I6+$D$8 -> 0.395 | J8: =J6+$D$8 -> 0.355 | K8: =K6+$D$8 -> 0.315 | L8: =L6+$D$8 -> 0.275 | M8: =M6+$D$8 -> 0.235 | ... O8: =O6+$D$8 -> 0.155
B10: Revenue Growth | F10: =CHOOSE(ScenarioREV,F6,F7,F8) -> 0.32813768 | G10: =CHOOSE(ScenarioREV,G6,G7,G8) -> 0.33495166 | H10: =CHOOSE(ScenarioREV,H6,H7,H8) -> 0.4 | I10: =CHOOSE(ScenarioREV,I6,I7,I8) -> 0.42 | J10: =CHOOSE(ScenarioREV,J6,J7,J8) -> 0.38 | K10: =CHOOSE(ScenarioREV,K6,K7,K8) -> 0.34 | L10: =CHOOSE(ScenarioREV,L6,L7,L8) -> 0.3 | M10: =CHOOSE(ScenarioREV,M6,M7,M8) -> 0.26 | ... O10: =CHOOSE(ScenarioREV,O6,O7,O8) -> 0.18
B11: COGS % of sales | C11: =IncState!C17/IncState!C16 -> 0.55073938 | D11: =IncState!D17/IncState!D16 -> 0.53880071 | E11: =IncState!E17/IncState!E16 -> 0.50649602 | F11: =E11-0.0075 -> 0.49899602 | G11: =F11-0.0075 -> 0.49149602 | H11: =G11-0.0075 -> 0.48399602 | I11: =H11-0.0075 -> 0.47649602 | J11: =I11-0.0075 -> 0.46899602 | K11: =J11-0.0075 -> 0.46149602 | L11: =K11-0.0075 -> 0.45399602 | M11: =L11-0.0075 -> 0.44649602 | ... O11: =N11-0.0075 -> 0.43149602
B12: R&D % of sales | C12: =IncState!C18/IncState!C16 -> 0.21206729 | D12: =IncState!D18/IncState!D16 -> 0.25890653 | E12: =IncState!E18/IncState!E16 -> 0.25037813 | F12: =E12-0.005 -> 0.24537813 | G12: =F12-0.005 -> 0.24037813 | H12: =G12-0.005 -> 0.23537813 | I12: =H12-0.005 -> 0.23037813 | J12: =I12-0.005 -> 0.22537813 | K12: =J12-0.005 -> 0.22037813 | L12: =K12-0.005 -> 0.21537813 | M12: =L12-0.005 -> 0.21037813 | ... O12: =N12-0.005 -> 0.20037813
B13: SG&A % of sales | C13: =IncState!C19/IncState!C16 -> 0.18795814 | D13: =IncState!D19/IncState!D16 -> 0.18611111 | E13: =IncState!E19/IncState!E16 -> 0.16408765 | F13: =E13-0.005 -> 0.15908765 | G13: =F13-0.005 -> 0.15408765 | H13: =G13-0.005 -> 0.14908765 | I13: =H13-0.005 -> 0.14408765 | J13: =I13-0.005 -> 0.13908765 | K13: =J13-0.005 -> 0.13408765 | L13: =K13-0.005 -> 0.12908765 | M13: =L13-0.005 -> 0.12408765 | ... O13: =N13-0.005 -> 0.11408765
B14: Amortization $ Amt | C14: =IncState!C23 -> 3548 | D14: =IncState!D23 -> 2811 | E14: =IncState!E23 -> 2394 | F14: 2000 | G14: =F14 -> 2000 | H14: =G14 -> 2000 | I14: =H14 -> 2000 | J14: =I14 -> 2000 | K14: =J14 -> 2000 | L14: =K14 -> 2000 | M14: =L14 -> 2000 | N14: =M14 -> 2000 | O14: =N14 -> 2000
B15: Non recurring income / (expense) | C15: =IncState!C26 -> 0 | D15: =IncState!D26 -> 0 | E15: =IncState!E26 -> -186 | F15: 0 | G15: 0 | H15: 0 | I15: 0 | J15: 0 | K15: 0 | L15: 0 | M15: 0 | N15: 0 | O15: 0
B16: Other Income / (expense) | C16: =IncState!C27 -> 102 | D16: =IncState!D27 -> 34 | E16: =IncState!E27 -> 48 | F16: 0 | G16: 0 | H16: 0 | I16: 0 | J16: 0 | K16: 0 | L16: 0 | M16: 0 | N16: 0 | O16: 0
B17: Effective tax rate | C17: =IncState!C34/IncState!C32 -> -0.097972973 | D17: =IncState!D34/IncState!D32 -> -0.73577236 | E17: =IncState!E34/IncState!E32 -> 0.17496229 | F17: =E17 -> 0.17496229 | G17: =F17 -> 0.17496229 | H17: =G17 -> 0.17496229 | I17: =H17 -> 0.17496229 | J17: =I17 -> 0.17496229 | K17: =J17 -> 0.17496229 | L17: =K17 -> 0.17496229 | M17: =L17 -> 0.17496229 | ... O17: =N17 -> 0.17496229
B18: Basic WASO | C18: =IncState!C38 -> 1561 | D18: =IncState!D38 -> 1614 | E18: =IncState!E38 -> 1620 | F18: =E18 -> 1620 | G18: =F18 -> 1620 | H18: =G18 -> 1620 | I18: =H18 -> 1620 | J18: =I18 -> 1620 | K18: =J18 -> 1620 | L18: =K18 -> 1620 | M18: =L18 -> 1620 | ... O18: =N18 -> 1620
B19: Diluted WASO | C19: =IncState!C39 -> 1571 | D19: =IncState!D39 -> 1625 | E19: =IncState!E39 -> 1637 | F19: =E19 -> 1637 | G19: =F19 -> 1637 | H19: =G19 -> 1637 | I19: =H19 -> 1637 | J19: =I19 -> 1637 | K19: =J19 -> 1637 | L19: =K19 -> 1637 | M19: =L19 -> 1637 | ... O19: =N19 -> 1637
A21: * | B21: Debt | C21: 44926 | D21: 45291 | E21: 45657 | F21: 46022 | G21: 46387 | H21: 46752 | I21: 47118 | J21: 47483 | K21: =K2 -> 47848 | L21: =L2 -> 48213 | M21: =M2 -> 48579 | N21: =N2 -> 48580 | O21: =O2 -> 48581
B23: Interest rate on Revolver | F23: =E23 -> 0 | G23: =F23 -> 0 | H23: =G23 -> 0 | I23: =H23 -> 0 | J23: =I23 -> 0 | K23: =J23 -> 0 | L23: =K23 -> 0 | M23: =L23 -> 0 | ... O23: =N23 -> 0
B24: Interest rate on long-term debt | E24: 0.0324 | F24: =E24 -> 0.0324 | G24: =F24 -> 0.0324 | H24: =G24 -> 0.0324 | I24: =H24 -> 0.0324 | J24: =I24 -> 0.0324 | K24: =J24 -> 0.0324 | L24: =K24 -> 0.0324 | M24: =L24 -> 0.0324 | ... O24: =N24 -> 0.0324
B25: Interest rate on cash | C25: =IncState!C29/BalSheet!C18 -> 0.0017853218 | D25: =IncState!D29/BalSheet!D18 -> 0.054831886 | E25: =IncState!E29/BalSheet!E18 -> 0.053231771 | F25: =E25 -> 0.053231771 | G25: =F25 -> 0.053231771 | H25: =G25 -> 0.053231771 | I25: =H25 -> 0.053231771 | J25: =I25 -> 0.053231771 | K25: =J25 -> 0.053231771 | L25: =K25 -> 0.053231771 | M25: =L25 -> 0.053231771 | ... O25: =N25 -> 0.053231771
B27: Issuance of long-term debt | F27: 0 | G27: 0 | H27: 0 | I27: 0 | J27: 0 | K27: 0 | L27: 0 | M27: 0 | N27: 0 | O27: 0
B28: Repayment of long-term debt | F28: 0 | G28: 0 | H28: 0 | I28: 0 | J28: 0 | K28: 0 | L28: 0 | M28: 0 | N28: 0 | O28: 0
A30: * | B30: Calcs | C30: 44926 | D30: 45291 | E30: 45657 | F30: 46022 | G30: 46387 | H30: 46752 | I30: 47118 | J30: 47483 | K30: 2030 | L30: =K30+1 -> 2031 | M30: =L30+1 -> 2032 | N30: =M30+1 -> 2033 | O30: =N30+1 -> 2034
B32: CapEx % of Sales | C32: =450/IncState!C16 -> 0.019066989 | D32: =546/IncState!D16 -> 0.024074074 | E32: =636/IncState!E16 -> 0.024665503 | F32: =E32 -> 0.024665503 | G32: =F32 -> 0.024665503 | H32: =G32 -> 0.024665503 | I32: =H32 -> 0.024665503 | J32: =I32 -> 0.024665503 | K32: =J32 -> 0.024665503 | L32: =K32 -> 0.024665503 | M32: =L32 -> 0.024665503 | ... O32: =N32 -> 0.024665503
B33: Depreciation % of beginning PP&E | D33: =IncState!D22/BalSheet!C24 -> 0.3253928 | E33: =IncState!E22/BalSheet!D24 -> 0.3019802 | F33: =E33 -> 0.3019802 | G33: =F33 -> 0.3019802 | H33: =G33 -> 0.3019802 | I33: =H33 -> 0.3019802 | J33: =I33 -> 0.3019802 | K33: =J33 -> 0.3019802 | L33: =K33 -> 0.3019802 | M33: =L33 -> 0.3019802 | ... O33: =N33 -> 0.3019802
B34: Share issuance / (repurchases) | F34: 0 | G34: 0 | H34: 0 | I34: 0 | J34: 0 | K34: 0 | L34: 0 | M34: 0 | N34: 0 | O34: 0
A36: * | B36: Balance Sheet - Assets | C36: 44926 | D36: 45291 | E36: 45657 | F36: 46022 | G36: 46387 | H36: 46752 | I36: 47118 | J36: 47483 | K36: 2030 | L36: =K36+1 -> 2031 | M36: =L36+1 -> 2032 | N36: =M36+1 -> 2033 | O36: =N36+1 -> 2034
B38: Operating Cash % of sales | C38: =BalSheet!C17/IncState!C16 -> 0.015 | D38: =BalSheet!D17/IncState!D16 -> 0.015 | E38: =BalSheet!E17/IncState!E16 -> 0.015 | F38: =E38 -> 0.015 | G38: =F38 -> 0.015 | H38: =G38 -> 0.015 | I38: =H38 -> 0.015 | J38: =I38 -> 0.015 | K38: =J38 -> 0.015 | L38: =K38 -> 0.015 | M38: =L38 -> 0.015 | ... O38: =N38 -> 0.015
B39: Accounts receivable % of sales | C39: =BalSheet!C19/IncState!C16 -> 0.17490784 | D39: =BalSheet!D19/IncState!D16 -> 0.19100529 | E39: =BalSheet!E19/IncState!E16 -> 0.24452201 | F39: =AVERAGE(C39:E39) -> 0.20347838 | G39: =F39 -> 0.20347838 | H39: =G39 -> 0.20347838 | I39: =H39 -> 0.20347838 | J39: =I39 -> 0.20347838 | K39: =J39 -> 0.20347838 | L39: =K39 -> 0.20347838 | M39: =L39 -> 0.20347838 | N39: =M39 -> 0.20347838 | O39: =N39 -> 0.20347838
B40: Inventories % of COGS | C40: =BalSheet!C20/IncState!C17 -> 0.29012156 | D40: =BalSheet!D20/IncState!D17 -> 0.35605565 | E40: =BalSheet!E20/IncState!E17 -> 0.43905054 | F40: =AVERAGE(C40:E40) -> 0.36174258 | G40: =F40 -> 0.36174258 | H40: =G40 -> 0.36174258 | I40: =H40 -> 0.36174258 | J40: =I40 -> 0.36174258 | K40: =J40 -> 0.36174258 | L40: =K40 -> 0.36174258 | M40: =L40 -> 0.36174258 | N40: =M40 -> 0.36174258 | O40: =N40 -> 0.36174258
B41: Other current assets % of sales | C41: =BalSheet!C21/IncState!C16 -> 0.096817931 | D41: =BalSheet!D21/IncState!D16 -> 0.18306878 | E41: =BalSheet!E21/IncState!E16 -> 0.12499515 | F41: =AVERAGE(C41:E41) -> 0.13496062 | G41: =F41 -> 0.13496062 | H41: =G41 -> 0.13496062 | I41: =H41 -> 0.13496062 | J41: =I41 -> 0.13496062 | K41: =J41 -> 0.13496062 | L41: =K41 -> 0.13496062 | M41: =L41 -> 0.13496062 | N41: =M41 -> 0.13496062 | O41: =N41 -> 0.13496062
B42: Investments in unconsolidated entities | C42: =BalSheet!C26 -> 83 | D42: =BalSheet!D26 -> 99 | E42: =BalSheet!E26 -> 149 | F42: =E42 -> 149 | G42: =F42 -> 149 | H42: =G42 -> 149 | I42: =H42 -> 149 | J42: =I42 -> 149 | K42: =J42 -> 149 | L42: =K42 -> 149 | M42: =L42 -> 149 | ... O42: =N42 -> 149
B43: Other long-term assets % of sales | C43: =BalSheet!C27/IncState!C16 -> 0.0936401 | D43: =BalSheet!D27/IncState!D16 -> 0.13981481 | E43: =BalSheet!E27/IncState!E16 -> 0.1486911 | F43: =AVERAGE(C43:E43) -> 0.127382 | G43: =F43 -> 0.127382 | H43: =G43 -> 0.127382 | I43: =H43 -> 0.127382 | J43: =I43 -> 0.127382 | K43: =J43 -> 0.127382 | L43: =K43 -> 0.127382 | M43: =L43 -> 0.127382 | N43: =M43 -> 0.127382 | O43: =N43 -> 0.127382
A45: * | B45: Balance Sheet - Liabilities | C45: 44926 | D45: 45291 | E45: 45657 | F45: 46022 | G45: 46387 | H45: 46752 | I45: 47118 | J45: 47483 | K45: 2030 | L45: =K45+1 -> 2031 | M45: =L45+1 -> 2032 | N45: =M45+1 -> 2033 | O45: =N45+1 -> 2034
B47: Accounts payable % of COGS | C47: =BalSheet!C33/IncState!C17 -> 0.2274196 | D47: =BalSheet!D33/IncState!D17 -> 0.19787234 | E47: =BalSheet!E33/IncState!E17 -> 0.18882083 | F47: =E47 -> 0.18882083 | G47: =F47 -> 0.18882083 | H47: =G47 -> 0.18882083 | I47: =H47 -> 0.18882083 | J47: =I47 -> 0.18882083 | K47: =J47 -> 0.18882083 | L47: =K47 -> 0.18882083 | M47: =L47 -> 0.18882083 | ... O47: =N47 -> 0.18882083
B48: Other current liabilities % of sales | C48: =BalSheet!C34/IncState!C16 -> 0.14461252 | D48: =BalSheet!D34/IncState!D16 -> 0.15520282 | E48: =BalSheet!E34/IncState!E16 -> 0.18673647 | F48: =E48 -> 0.18673647 | G48: =F48 -> 0.18673647 | H48: =G48 -> 0.18673647 | I48: =H48 -> 0.18673647 | J48: =I48 -> 0.18673647 | K48: =J48 -> 0.18673647 | L48: =K48 -> 0.18673647 | M48: =L48 -> 0.18673647 | ... O48: =N48 -> 0.18673647
B49: Other long-term liabilities % of sales | C49: =BalSheet!C38/IncState!C16 -> 0.16923012 | D49: =BalSheet!D38/IncState!D16 -> 0.15815697 | E49: =BalSheet!E38/IncState!E16 -> 0.10300562 | F49: =E49 -> 0.10300562 | G49: =F49 -> 0.10300562 | H49: =G49 -> 0.10300562 | I49: =H49 -> 0.10300562 | J49: =I49 -> 0.10300562 | K49: =J49 -> 0.10300562 | L49: =K49 -> 0.10300562 | M49: =L49 -> 0.10300562 | ... O49: =N49 -> 0.10300562

Sheet Calcs
A1: =CoName -> Advanced Micro Devices Inc. | C1: Hist. | D1: Hist. | E1: Hist. | F1: Proj. | G1: Proj. | H1: Proj. | I1: Proj. | J1: Proj. | K1: Proj. | L1: Proj. | M1: Proj. | N1: Proj. | O1: Proj.
A2: Net PP&E | C2: 2022 | D2: =C2+1 -> 2023 | E2: =D2+1 -> 2024 | F2: =E2+1 -> 2025 | G2: =F2+1 -> 2026 | H2: =G2+1 -> 2027 | I2: =H2+1 -> 2028 | J2: =I2+1 -> 2029 | K2: =J2+1 -> 2030 | ... O2: =N2+1 -> 2034
B3: Capital expenditure % of sales | F3: =Assumptions!F32 -> 0.024665503 | G3: =Assumptions!G32 -> 0.024665503 | H3: =Assumptions!H32 -> 0.024665503 | I3: =Assumptions!I32 -> 0.024665503 | J3: =Assumptions!J32 -> 0.024665503 | K3: =Assumptions!K32 -> 0.024665503 | L3: =Assumptions!L32 -> 0.024665503 | M3: =Assumptions!M32 -> 0.024665503 | ... O3: =Assumptions!O32 -> 0.024665503
B4: Depreciation % of PP&E | F4: =Assumptions!F33 -> 0.3019802 | G4: =F4 -> 0.3019802 | H4: =G4 -> 0.3019802 | I4: =H4 -> 0.3019802 | J4: =I4 -> 0.3019802 | K4: =J4 -> 0.3019802 | L4: =K4 -> 0.3019802 | M4: =L4 -> 0.3019802 | N4: =M4 -> 0.3019802 | O4: =N4 -> 0.3019802
B6: Beginning PP&E | F6: =E9 -> 2425 | G6: =F9 -> 2537.3936 | H6: =G9 -> 2898.7787 | I6: =H9 -> 3602.0838 | J6: =I9 -> 4756.0498 | K6: =J9 -> 6413.396 | L6: =K9 -> 8622.0733 | M6: =L9 -> 11407.393 | ... O6: =N9 -> 18581.701
B7: Capex | F7: =F3*IncState!F16 -> 844.69556 | G7: =G3*IncState!G16 -> 1127.6277 | H7: =H3*IncState!H16 -> 1578.6788 | I7: =I3*IncState!I16 -> 2241.724 | J7: =J3*IncState!J16 -> 3093.5791 | K7: =K3*IncState!K16 -> 4145.3959 | L7: =L3*IncState!L16 -> 5389.0147 | M7: =M3*IncState!M16 -> 6790.1585 | ... O7: =O3*IncState!O16 -> 9775.1122
B8: Depreciation | F8: =F6*F4 -> 732.30198 | G8: =G6*G4 -> 766.24262 | H8: =H6*H4 -> 875.37377 | I8: =I6*I4 -> 1087.758 | J8: =J6*J4 -> 1436.2328 | K8: =K6*K4 -> 1936.7186 | L8: =L6*L4 -> 2603.6954 | M8: =M6*M4 -> 3444.8067 | ... O8: =O6*O4 -> 5611.3058
B9: Ending PP&E | E9: =BalSheet!E24 -> 2425 | F9: =F6+F7-F8 -> 2537.3936 | G9: =G6+G7-G8 -> 2898.7787 | H9: =H6+H7-H8 -> 3602.0838 | I9: =I6+I7-I8 -> 4756.0498 | J9: =J6+J7-J8 -> 6413.396 | K9: =K6+K7-K8 -> 8622.0733 | L9: =L6+L7-L8 -> 11407.393 | M9: =M6+M7-M8 -> 14752.744 | ... O9: =O6+O7-O8 -> 22745.508
A10: Equity | C10: =C2 -> 2022 | D10: =D2 -> 2023 | E10: =E2 -> 2024 | F10: =F2 -> 2025 | G10: =G2 -> 2026 | H10: =H2 -> 2027 | I10: =I2 -> 2028 | J10: =J2 -> 2029 | ... O10: =O2 -> 2034
B11: Share issuance/(repurchases) | F11: =Assumptions!F34 -> 0 | G11: =Assumptions!G34 -> 0 | H11: =Assumptions!H34 -> 0 | I11: =Assumptions!I34 -> 0 | J11: =Assumptions!J34 -> 0 | K11: =Assumptions!K34 -> 0 | L11: =Assumptions!L34 -> 0 | M11: =Assumptions!M34 -> 0 | ... O11: =Assumptions!O34 -> 0
B13: Beginning balance | F13: =E16 -> 57568 | G13: =F16 -> 60295.616 | H13: =G16 -> 64596.918 | I13: =H16 -> 71542.833 | J13: =I16 -> 82718.246 | K13: =J16 -> 99951.167 | L13: =K16 -> 125469.82 | M13: =L16 -> 161798.58 | ... O13: =N16 -> 277090.27
B14: Net income | F14: =IncState!F35 -> 2727.616 | G14: =IncState!G35 -> 4301.3019 | H14: =IncState!H35 -> 6945.9156 | I14: =IncState!I35 -> 11175.412 | J14: =IncState!J35 -> 17232.921 | K14: =IncState!K35 -> 25518.657 | L14: =IncState!L35 -> 36328.759 | M14: =IncState!M35 -> 49748.913 | ... O14: =IncState!O35 -> 83062.423
B15: Share issuance / (repurchase) | F15: =F11 -> 0 | G15: =G11 -> 0 | H15: =H11 -> 0 | I15: =I11 -> 0 | J15: =J11 -> 0 | K15: =K11 -> 0 | L15: =L11 -> 0 | M15: =M11 -> 0 | ... O15: =O11 -> 0
B16: Ending balance | E16: =BalSheet!E41 -> 57568 | F16: =SUM(F13:F15) -> 60295.616 | G16: =SUM(G13:G15) -> 64596.918 | H16: =SUM(H13:H15) -> 71542.833 | I16: =SUM(I13:I15) -> 82718.246 | J16: =SUM(J13:J15) -> 99951.167 | K16: =SUM(K13:K15) -> 125469.82 | L16: =SUM(L13:L15) -> 161798.58 | M16: =SUM(M13:M15) -> 211547.5 | ... O16: =SUM(O13:O15) -> 360152.7
A17: OWC | C17: =C10 -> 2022 | D17: =D10 -> 2023 | E17: =E10 -> 2024 | F17: =F10 -> 2025 | G17: =G10 -> 2026 | H17: =H10 -> 2027 | I17: =I10 -> 2028 | J17: =J10 -> 2029 | ... O17: =O10 -> 2034
B18: Operating Cash | E18: =BalSheet!E17 -> 386.775 | F18: =BalSheet!F17 -> 513.69045 | G18: =BalSheet!G17 -> 685.75192 | H18: =BalSheet!H17 -> 960.05269 | I18: =BalSheet!I17 -> 1363.2748 | J18: =BalSheet!J17 -> 1881.3192 | K18: =BalSheet!K17 -> 2520.9678 | L18: =BalSheet!L17 -> 3277.2581 | ... O18: =BalSheet!O17 -> 5944.6054
B19: =BalSheet!B20 -> Inventories | E19: =BalSheet!E20 -> 5734 | F19: =BalSheet!F20 -> 6181.6861 | G19: =BalSheet!G20 -> 8128.2193 | H19: =BalSheet!H20 -> 11205.861 | I19: =BalSheet!I20 -> 15665.745 | J19: =BalSheet!J20 -> 21278.452 | K19: =BalSheet!K20 -> 28057.155 | L19: =BalSheet!L20 -> 35881.54 | ... O19: =BalSheet!O20 -> 61859.756
B20: =BalSheet!B19 -> Accounts receivable | E20: =BalSheet!E19 -> 6305 | F20: =BalSheet!F19 -> 6968.3267 | G20: =BalSheet!G19 -> 9302.3793 | H20: =BalSheet!H19 -> 13023.331 | I20: =BalSheet!I19 -> 18493.13 | J20: =BalSheet!J19 -> 25520.52 | K20: =BalSheet!K19 -> 34197.496 | L20: =BalSheet!L19 -> 44456.745 | ... O20: =BalSheet!O19 -> 80639.912
B21: Other current assets | E21: =BalSheet!E21 -> 3223 | F21: =BalSheet!F21 -> 4621.8655 | G21: =BalSheet!G21 -> 6169.967 | H21: =BalSheet!H21 -> 8637.9539 | I21: =BalSheet!I21 -> 12265.894 | J21: =BalSheet!J21 -> 16926.934 | K21: =BalSheet!K21 -> 22682.092 | L21: =BalSheet!L21 -> 29486.72 | ... O21: =BalSheet!O21 -> 53485.843
B22: Accounts payables | E22: =BalSheet!E33 -> 2466 | F22: =BalSheet!F33 -> 3226.6898 | G22: =BalSheet!G33 -> 4242.7328 | H22: =BalSheet!H33 -> 5849.1869 | I22: =BalSheet!I33 -> 8177.138 | J22: =BalSheet!J33 -> 11106.834 | K22: =BalSheet!K33 -> 14645.152 | L22: =BalSheet!L33 -> 18729.291 | ... O22: =BalSheet!O33 -> 32289.288
B23: Other current liabilities | E23: =BalSheet!E34 -> 4815 | F23: =BalSheet!F34 -> 6394.9829 | G23: =BalSheet!G34 -> 8536.993 | H23: =BalSheet!H34 -> 11951.79 | I23: =BalSheet!I34 -> 16971.542 | J23: =BalSheet!J34 -> 23420.728 | K23: =BalSheet!K34 -> 31383.776 | L23: =BalSheet!L34 -> 40798.909 | ... O23: =BalSheet!O34 -> 74004.977
A24: * | B24: OWC | E24: =SUM(E18:E21)-SUM(E22:E23) -> 8367.775 | F24: =SUM(F18:F21)-SUM(F22:F23) -> 8663.8961 | G24: =SUM(G18:G21)-SUM(G22:G23) -> 11506.592 | H24: =SUM(H18:H21)-SUM(H22:H23) -> 16026.222 | I24: =SUM(I18:I21)-SUM(I22:I23) -> 22639.365 | J24: =SUM(J18:J21)-SUM(J22:J23) -> 31079.663 | K24: =SUM(K18:K21)-SUM(K22:K23) -> 41428.783 | L24: =SUM(L18:L21)-SUM(L22:L23) -> 53574.063 | ... O24: =SUM(O18:O21)-SUM(O22:O23) -> 95635.852
B25: Change in OWC | F25: =E24-F24 -> -296.12114 | G25: =F24-G24 -> -2842.6957 | H25: =G24-H24 -> -4519.6297 | I25: =H24-I24 -> -6613.1431 | J25: =I24-J24 -> -8440.2981 | K25: =J24-K24 -> -10349.12 | L25: =K24-L24 -> -12145.28 | M25: =L24-M24 -> -13572.23 | ... O25: =N24-O24 -> -14152.947

Sheet Debt
A1: =CoName -> Advanced Micro Devices Inc. | C1: Hist. | D1: Hist. | E1: Hist. | F1: Proj. | G1: Proj. | H1: Proj. | I1: Proj. | J1: Proj. | K1: Proj. | L1: Proj. | M1: Proj. | N1: Proj. | O1: Proj.
A2: Assumptions | C2: 44926 | D2: 45291 | E2: 45657 | F2: 46022 | G2: 46387 | H2: 46752 | I2: 47118 | J2: 47483 | K2: =2030 -> 2030 | L2: =K2+1 -> 2031 | M2: =L2+1 -> 2032 | N2: =M2+1 -> 2033 | O2: =N2+1 -> 2034
B4: Interest rate on revolver | F4: =Assumptions!F23 -> 0 | G4: =Assumptions!G23 -> 0 | H4: =Assumptions!H23 -> 0 | I4: =Assumptions!I23 -> 0 | J4: =Assumptions!J23 -> 0 | K4: =Assumptions!K23 -> 0 | L4: =Assumptions!L23 -> 0 | M4: =Assumptions!M23 -> 0 | ... O4: =Assumptions!O23 -> 0
B5: Interest rate on long-term debt | F5: =Assumptions!F24 -> 0.0324 | G5: =Assumptions!G24 -> 0.0324 | H5: =Assumptions!H24 -> 0.0324 | I5: =Assumptions!I24 -> 0.0324 | J5: =Assumptions!J24 -> 0.0324 | K5: =Assumptions!K24 -> 0.0324 | L5: =Assumptions!L24 -> 0.0324 | M5: =Assumptions!M24 -> 0.0324 | ... O5: =Assumptions!O24 -> 0.0324
B6: Interest rate on cash | F6: =Assumptions!F25 -> 0.053231771 | G6: =Assumptions!G25 -> 0.053231771 | H6: =Assumptions!H25 -> 0.053231771 | I6: =Assumptions!I25 -> 0.053231771 | J6: =Assumptions!J25 -> 0.053231771 | K6: =Assumptions!K25 -> 0.053231771 | L6: =Assumptions!L25 -> 0.053231771 | M6: =Assumptions!M25 -> 0.053231771 | ... O6: =Assumptions!O25 -> 0.053231771
B8: Issuance of long-term debt | F8: =Assumptions!F27 -> 0 | G8: =Assumptions!G27 -> 0 | H8: =Assumptions!H27 -> 0 | I8: =Assumptions!I27 -> 0 | J8: =Assumptions!J27 -> 0 | K8: =Assumptions!K27 -> 0 | L8: =Assumptions!L27 -> 0 | M8: =Assumptions!M27 -> 0 | ... O8: =Assumptions!O27 -> 0
B9: Repayment of long-term debt | F9: =Assumptions!F28 -> 0 | G9: =Assumptions!G28 -> 0 | H9: =Assumptions!H28 -> 0 | I9: =Assumptions!I28 -> 0 | J9: =Assumptions!J28 -> 0 | K9: =Assumptions!K28 -> 0 | L9: =Assumptions!L28 -> 0 | M9: =Assumptions!M28 -> 0 | ... O9: =Assumptions!O28 -> 0
A11: Revolver | C11: =C2 -> 44926 | D11: =D2 -> 45291 | E11: =E2 -> 45657 | F11: =F2 -> 46022 | G11: =G2 -> 46387 | H11: =H2 -> 46752 | I11: =I2 -> 47118 | J11: =J2 -> 47483 | ... O11: =O2 -> 2034
B12: Balance | F12: NO REVOLVER
B13: Interest rate
B14: Interest expense
A16: Long term debt | C16: =C11 -> 44926 | D16: =D11 -> 45291 | E16: =E11 -> 45657 | F16: =F11 -> 46022 | G16: =G11 -> 46387 | H16: =H11 -> 46752 | I16: =I11 -> 47118 | J16: =J11 -> 47483 | ... O16: =O11 -> 2034
B17: Beginning balance | F17: =E20 -> 1721 | G17: =F20 -> 1721 | H17: =G20 -> 1721 | I17: =H20 -> 1721 | J17: =I20 -> 1721 | K17: =J20 -> 1721 | L17: =K20 -> 1721 | M17: =L20 -> 1721 | ... O17: =N20 -> 1721
B18: Issuance | F18: =F8 -> 0 | G18: =G8 -> 0 | H18: =H8 -> 0 | I18: =I8 -> 0 | J18: =J8 -> 0 | K18: =K8 -> 0 | L18: =L8 -> 0 | M18: =M8 -> 0 | ... O18: =O8 -> 0
B19: Repayment | F19: =F9 -> 0 | G19: =G9 -> 0 | H19: =H9 -> 0 | I19: =I9 -> 0 | J19: =J9 -> 0 | K19: =K9 -> 0 | L19: =L9 -> 0 | M19: =M9 -> 0 | ... O19: =O9 -> 0
B20: Ending balance | E20: =BalSheet!E37 -> 1721 | F20: =SUM(F17:F19) -> 1721 | G20: =SUM(G17:G19) -> 1721 | H20: =SUM(H17:H19) -> 1721 | I20: =SUM(I17:I19) -> 1721 | J20: =SUM(J17:J19) -> 1721 | K20: =SUM(K17:K19) -> 1721 | L20: =SUM(L17:L19) -> 1721 | M20: =SUM(M17:M19) -> 1721 | ... O20: =SUM(O17:O19) -> 1721
B21: Interest rate | F21: =F5 -> 0.0324 | G21: =G5 -> 0.0324 | H21: =H5 -> 0.0324 | I21: =I5 -> 0.0324 | J21: =J5 -> 0.0324 | K21: =K5 -> 0.0324 | L21: =L5 -> 0.0324 | M21: =M5 -> 0.0324 | ... O21: =O5 -> 0.0324
B22: Interest expense | F22: =F20*F21 -> 55.7604 | G22: =G20*G21 -> 55.7604 | H22: =H20*H21 -> 55.7604 | I22: =I20*I21 -> 55.7604 | J22: =J20*J21 -> 55.7604 | K22: =K20*K21 -> 55.7604 | L22: =L20*L21 -> 55.7604 | M22: =M20*M21 -> 55.7604 | ... O22: =O20*O21 -> 55.7604
A24: Debt summary | C24: =C16 -> 44926 | D24: =D16 -> 45291 | E24: =E16 -> 45657 | F24: =F16 -> 46022 | G24: =G16 -> 46387 | H24: =H16 -> 46752 | I24: =I16 -> 47118 | J24: =J16 -> 47483 | ... O24: =O16 -> 2034
B25: Revolver | F25: =F12 -> NO REVOLVER | G25: =G12 -> 0 | H25: =H12 -> 0 | I25: =I12 -> 0 | J25: =J12 -> 0 | K25: =K12 -> 0 | L25: =L12 -> 0 | M25: =M12 -> 0 | ... O25: =O12 -> 0
B26: Total long term debt | F26: =F20 -> 1721 | G26: =G20 -> 1721 | H26: =H20 -> 1721 | I26: =I20 -> 1721 | J26: =J20 -> 1721 | K26: =K20 -> 1721 | L26: =L20 -> 1721 | M26: =M20 -> 1721 | ... O26: =O20 -> 1721
B27: Total debt | F27: =F20 -> 1721 | G27: =G20 -> 1721 | H27: =H20 -> 1721 | I27: =I20 -> 1721 | J27: =J20 -> 1721 | K27: =K20 -> 1721 | L27: =L20 -> 1721 | M27: =M20 -> 1721 | ... O27: =O20 -> 1721
B28: Total interest expense | F28: =F22 -> 55.7604 | G28: =G22 -> 55.7604 | H28: =H22 -> 55.7604 | I28: =I22 -> 55.7604 | J28: =J22 -> 55.7604 | K28: =K22 -> 55.7604 | L28: =L22 -> 55.7604 | M28: =M22 -> 55.7604 | ... O28: =O22 -> 55.7604
A30: Interest income | C30: =C11 -> 44926 | D30: =D11 -> 45291 | E30: =E11 -> 45657 | F30: =F11 -> 46022 | G30: =G11 -> 46387 | H30: =H11 -> 46752 | I30: =I11 -> 47118 | J30: =J11 -> 47483 | ... O30: =O11 -> 2034
B31: Excess Cash | F31: =BalSheet!F18 -> 7802.9944 | G31: =BalSheet!G18 -> 10533.667 | H31: =BalSheet!H18 -> 13672.296 | I31: =BalSheet!I18 -> 18221.602 | J31: =BalSheet!J18 -> 26253.271 | K31: =BalSheet!K18 -> 39851.466 | L31: =BalSheet!L18 -> 61638.475 | M31: =BalSheet!M18 -> 94654.577 | ... O31: =BalSheet!O18 -> 206910.35
B32: Interest rate | F32: =F6 -> 0.053231771 | G32: =G6 -> 0.053231771 | H32: =H6 -> 0.053231771 | I32: =I6 -> 0.053231771 | J32: =J6 -> 0.053231771 | K32: =K6 -> 0.053231771 | L32: =L6 -> 0.053231771 | M32: =M6 -> 0.053231771 | ... O32: =O6 -> 0.053231771
B33: Interest income | F33: =F31*F32 -> 415.36722 | G33: =G31*G32 -> 560.72577 | H33: =H31*H32 -> 727.80054 | I33: =I31*I32 -> 969.96813 | J33: =J31*J32 -> 1397.5081 | K33: =K31*K32 -> 2121.3641 | L33: =L31*L32 -> 3281.1252 | M33: =M31*M32 -> 5038.6308 | ... O33: =O31*O32 -> 11014.204

Sheet IncState
A1: =CoName -> Advanced Micro Devices Inc. | C1: Hist. | D1: Hist. | E1: Hist. | F1: Proj. | G1: Proj. | H1: Proj. | I1: Proj. | J1: Proj. | K1: Proj. | L1: Proj. | M1: Proj. | N1: Proj. | O1: Proj.
A2: Assumptions | C2: 44926 | D2: 45291 | E2: 45657 | F2: 46022 | G2: 46387 | H2: 46752 | I2: 47118 | J2: 47483 | K2: 2030 | L2: 2031 | M2: 2032 | N2: =M2+1 -> 2033 | O2: =N2+1 -> 2034
B4: Revenue growth | F4: =Assumptions!F10 -> 0.32813768 | G4: =Assumptions!G10 -> 0.33495166 | H4: =Assumptions!H10 -> 0.4 | I4: =Assumptions!I10 -> 0.42 | J4: =Assumptions!J10 -> 0.38 | K4: =Assumptions!K10 -> 0.34 | L4: =Assumptions!L10 -> 0.3 | M4: =Assumptions!M10 -> 0.26 | ... O4: =Assumptions!O10 -> 0.18
B5: Cost of goods sold as % of sales | F5: =Assumptions!F11 -> 0.49899602 | G5: =Assumptions!G11 -> 0.49149602 | H5: =Assumptions!H11 -> 0.48399602 | I5: =Assumptions!I11 -> 0.47649602 | J5: =Assumptions!J11 -> 0.46899602 | K5: =Assumptions!K11 -> 0.46149602 | L5: =Assumptions!L11 -> 0.45399602 | M5: =Assumptions!M11 -> 0.44649602 | ... O5: =Assumptions!O11 -> 0.43149602
B6: R&D % of sales | F6: =Assumptions!F12 -> 0.24537813 | G6: =Assumptions!G12 -> 0.24037813 | H6: =Assumptions!H12 -> 0.23537813 | I6: =Assumptions!I12 -> 0.23037813 | J6: =Assumptions!J12 -> 0.22537813 | K6: =Assumptions!K12 -> 0.22037813 | L6: =Assumptions!L12 -> 0.21537813 | M6: =Assumptions!M12 -> 0.21037813 | ... O6: =Assumptions!O12 -> 0.20037813
B7: SG&A % of sales | F7: =Assumptions!F13 -> 0.15908765 | G7: =Assumptions!G13 -> 0.15408765 | H7: =Assumptions!H13 -> 0.14908765 | I7: =Assumptions!I13 -> 0.14408765 | J7: =Assumptions!J13 -> 0.13908765 | K7: =Assumptions!K13 -> 0.13408765 | L7: =Assumptions!L13 -> 0.12908765 | M7: =Assumptions!M13 -> 0.12408765 | ... O7: =Assumptions!O13 -> 0.11408765
B8: Amortization amount | F8: =Assumptions!F14 -> 2000 | G8: =Assumptions!G14 -> 2000 | H8: =Assumptions!H14 -> 2000 | I8: =Assumptions!I14 -> 2000 | J8: =Assumptions!J14 -> 2000 | K8: =Assumptions!K14 -> 2000 | L8: =Assumptions!L14 -> 2000 | M8: =Assumptions!M14 -> 2000 | ... O8: =Assumptions!O14 -> 2000
B9: Non recurring items, amount | F9: =Assumptions!F15 -> 0 | G9: =Assumptions!G15 -> 0 | H9: =Assumptions!H15 -> 0 | I9: =Assumptions!I15 -> 0 | J9: =Assumptions!J15 -> 0 | K9: =Assumptions!K15 -> 0 | L9: =Assumptions!L15 -> 0 | M9: =Assumptions!M15 -> 0 | ... O9: =Assumptions!O15 -> 0
B10: Other income (expense), amt | F10: =Assumptions!F16 -> 0 | G10: =Assumptions!G16 -> 0 | H10: =Assumptions!H16 -> 0 | I10: =Assumptions!I16 -> 0 | J10: =Assumptions!J16 -> 0 | K10: =Assumptions!K16 -> 0 | L10: =Assumptions!L16 -> 0 | M10: =Assumptions!M16 -> 0 | ... O10: =Assumptions!O16 -> 0
B11: Effective tax rate | F11: =Assumptions!F17 -> 0.17496229 | G11: =Assumptions!G17 -> 0.17496229 | H11: =Assumptions!H17 -> 0.17496229 | I11: =Assumptions!I17 -> 0.17496229 | J11: =Assumptions!J17 -> 0.17496229 | K11: =Assumptions!K17 -> 0.17496229 | L11: =Assumptions!L17 -> 0.17496229 | M11: =Assumptions!M17 -> 0.17496229 | ... O11: =Assumptions!O17 -> 0.17496229
B12: Basic WASO | F12: =Assumptions!F18 -> 1620 | G12: =Assumptions!G18 -> 1620 | H12: =Assumptions!H18 -> 1620 | I12: =Assumptions!I18 -> 1620 | J12: =Assumptions!J18 -> 1620 | K12: =Assumptions!K18 -> 1620 | L12: =Assumptions!L18 -> 1620 | M12: =Assumptions!M18 -> 1620 | ... O12: =Assumptions!O18 -> 1620
B13: Diluted WASO | F13: =Assumptions!F19 -> 1637 | G13: =Assumptions!G19 -> 1637 | H13: =Assumptions!H19 -> 1637 | I13: =Assumptions!I19 -> 1637 | J13: =Assumptions!J19 -> 1637 | K13: =Assumptions!K19 -> 1637 | L13: =Assumptions!L19 -> 1637 | M13: =Assumptions!M19 -> 1637 | ... O13: =Assumptions!O19 -> 1637
A15: Income statement | C15: =C37 -> 44926 | D15: =D37 -> 45291 | E15: =E37 -> 45657 | F15: =F37 -> 46022 | G15: =G37 -> 46022 | H15: =H37 -> 46022 | I15: =I37 -> 46022 | J15: =J37 -> 46022 | ... O15: =O37 -> 46022
B16: Revenue | C16: 23601 | D16: 22680 | E16: 25785 | F16: =E16*(1+F4) -> 34246.03 | G16: =F16*(1+G4) -> 45716.795 | H16: =G16*(1+H4) -> 64003.512 | I16: =H16*(1+I4) -> 90884.988 | J16: =I16*(1+J4) -> 125421.28 | K16: =J16*(1+K4) -> 168064.52 | L16: =K16*(1+L4) -> 218483.87 | M16: =L16*(1+M4) -> 275289.68 | ... O16: =N16*(1+O4) -> 396307.03
B17: COGS | C17: 12998 | D17: 12220 | E17: 13060 | F17: =F16*F5 -> 17088.633 | G17: =G16*G5 -> 22469.623 | H17: =H16*H5 -> 30977.446 | I17: =I16*I5 -> 43306.335 | J17: =J16*J5 -> 58822.083 | K17: =K16*K5 -> 77561.107 | L17: =L16*L5 -> 99190.811 | M17: =M16*M5 -> 122915.75 | ... O17: =O16*O5 -> 171004.91
B18: R&D | C18: 5005 | D18: 5872 | E18: 6456 | F18: =F16*F6 -> 8403.2267 | G18: =G16*G6 -> 10989.317 | H18: =H16*H6 -> 15065.027 | I18: =I16*I6 -> 20937.913 | J18: =J16*J6 -> 28267.214 | K18: =K16*K6 -> 37037.744 | L18: =L16*L6 -> 47056.648 | M18: =M16*M6 -> 57914.928 | ... O18: =O16*O6 -> 79411.26
B19: SG&A | C19: =2336+2100 -> 4436 | D19: =2352+1869 -> 4221 | E19: =2783+1448 -> 4231 | F19: =F16*F7 -> 5448.1204 | G19: =G16*G7 -> 7044.3933 | H19: =H16*H7 -> 9542.1331 | I19: =I16*I7 -> 13095.404 | J19: =J16*J7 -> 17444.551 | K19: =K16*K7 -> 22535.376 | L19: =L16*L7 -> 28203.569 | M19: =M16*M7 -> 34160.049 | ... O19: =O16*O7 -> 45213.736
A20: * | B20: EBIT | C20: =C16-SUM(C17:C19) -> 1162 | D20: =D16-SUM(D17:D19) -> 367 | E20: =E16-SUM(E17:E19) -> 2038 | F20: =F16-SUM(F17:F19) -> 3306.0501 | G20: =G16-SUM(G17:G19) -> 5213.461 | H20: =H16-SUM(H17:H19) -> 8418.9068 | I20: =I16-SUM(I17:I19) -> 13545.335 | J20: =J16-SUM(J17:J19) -> 20887.435 | ... O20: =O16-SUM(O17:O19) -> 100677.12
B22: Depreciation | C22: 626 | D22: 642 | E22: 671 | F22: =Calcs!F8 -> 732.30198 | G22: =Calcs!G8 -> 766.24262 | H22: =Calcs!H8 -> 875.37377 | I22: =Calcs!I8 -> 1087.758 | J22: =Calcs!J8 -> 1436.2328 | K22: =Calcs!K8 -> 1936.7186 | L22: =Calcs!L8 -> 2603.6954 | M22: =Calcs!M8 -> 3444.8067 | ... O22: =Calcs!O8 -> 5611.3058
B23: Amortization | C23: =1448+2100 -> 3548 | D23: =942+1869 -> 2811 | E23: =946+1448 -> 2394 | F23: =F8 -> 2000 | G23: =G8 -> 2000 | H23: =H8 -> 2000 | I23: =I8 -> 2000 | J23: =J8 -> 2000 | K23: =K8 -> 2000 | L23: =L8 -> 2000 | M23: =M8 -> 2000 | ... O23: =O8 -> 2000
A24: * | B24: EBITDA | C24: =C20+C22 -> 1788 | D24: =D20+D22 -> 1009 | E24: =E20+E22 -> 2709 | F24: =F20+F22 -> 4038.3521 | G24: =G20+G22 -> 5979.7036 | H24: =H20+H22 -> 9294.2806 | I24: =I20+I22 -> 14633.093 | J24: =J20+J22 -> 22323.668 | ... O24: =O20+O22 -> 106288.43
B26: Non-recurring items | E26: -186 | F26: =F9 -> 0 | G26: =G9 -> 0 | H26: =H9 -> 0 | I26: =I9 -> 0 | J26: =J9 -> 0 | K26: =K9 -> 0 | L26: =L9 -> 0 | M26: =M9 -> 0 | ... O26: =O9 -> 0
B27: Other income (expense) | C27: 102 | D27: 34 | E27: 48 | F27: =F10 -> 0 | G27: =G10 -> 0 | H27: =H10 -> 0 | I27: =I10 -> 0 | J27: =J10 -> 0 | K27: =K10 -> 0 | L27: =L10 -> 0 | M27: =M10 -> 0 | ... O27: =O10 -> 0
B29: Interest income | C29: 8 | D29: 197 | E29: 181 | F29: =IF(circ=1,Debt!F33,0) -> 0 | G29: =IF(circ=1,Debt!G33,0) -> 0 | H29: =IF(circ=1,Debt!H33,0) -> 0 | I29: =IF(circ=1,Debt!I33,0) -> 0 | J29: =IF(circ=1,Debt!J33,0) -> 0 | K29: =IF(circ=1,Debt!K33,0) -> 0 | L29: =IF(circ=1,Debt!L33,0) -> 0 | M29: =IF(circ=1,Debt!M33,0) -> 0 | ... O29: =IF(circ=1,Debt!O33,0) -> 0
B30: Interest expense | C30: -88 | D30: -106 | E30: -92 | F30: =IF(circ=1,Debt!F22,0) -> 0 | G30: =IF(circ=1,Debt!G22,0) -> 0 | H30: =IF(circ=1,Debt!H22,0) -> 0 | I30: =IF(circ=1,Debt!I22,0) -> 0 | J30: =IF(circ=1,Debt!J22,0) -> 0 | K30: =IF(circ=1,Debt!K22,0) -> 0 | L30: =IF(circ=1,Debt!L22,0) -> 0 | M30: =IF(circ=1,Debt!M22,0) -> 0 | ... O30: =IF(circ=1,Debt!O22,0) -> 0
A32: * | B32: Pretax Income | C32: =C20+SUM(C27:C30) -> 1184 | D32: =D20+SUM(D27:D30) -> 492 | E32: =E20+SUM(E26:E30) -> 1989 | F32: =F20+SUM(F26:F30) -> 3306.0501 | G32: =G20+SUM(G26:G30) -> 5213.461 | H32: =H20+SUM(H26:H30) -> 8418.9068 | I32: =I20+SUM(I26:I30) -> 13545.335 | J32: =J20+SUM(J26:J30) -> 20887.435 | K32: =K20+SUM(K26:K30) -> 30930.292 | L32: =L20+SUM(L26:L30) -> 44032.847 | ... O32: =O20+SUM(O26:O30) -> 100677.12
B34: Tax expense | C34: -116 | D34: -362 | E34: =348 -> 348 | F34: =F11*F32 -> 578.43411 | G34: =G11*G32 -> 912.15909 | H34: =H11*H32 -> 1472.9912 | I34: =I11*I32 -> 2369.9229 | J34: =J11*J32 -> 3654.5135 | K34: =K11*K32 -> 5411.6347 | L34: =L11*L32 -> 7704.0878 | M34: =M11*M32 -> 10550.044 | ... O34: =O11*O32 -> 17614.7
A35: * | B35: Net income | C35: =C32-C34 -> 1300 | D35: =D32-D34 -> 854 | E35: =E32-E34 -> 1641 | F35: =F32-F34 -> 2727.616 | G35: =G32-G34 -> 4301.3019 | H35: =H32-H34 -> 6945.9156 | I35: =I32-I34 -> 11175.412 | J35: =J32-J34 -> 17232.921 | ... O35: =O32-O34 -> 83062.423
A37: Shareholder information | C37: 44926 | D37: 45291 | E37: 45657 | F37: 46022 | G37: 46022 | H37: 46022 | I37: 46022 | J37: 46022 | K37: 46022 | L37: 46022 | M37: 46022 | N37: 46022 | O37: 46022
B38: Basic WASO | C38: 1561 | D38: 1614 | E38: 1620 | F38: =F12 -> 1620 | G38: =G12 -> 1620 | H38: =H12 -> 1620 | I38: =I12 -> 1620 | J38: =J12 -> 1620 | K38: =K12 -> 1620 | L38: =L12 -> 1620 | M38: =M12 -> 1620 | ... O38: =O12 -> 1620
B39: Diluted WASO | C39: 1571 | D39: 1625 | E39: 1637 | F39: =F13 -> 1637 | G39: =G13 -> 1637 | H39: =H13 -> 1637 | I39: =I13 -> 1637 | J39: =J13 -> 1637 | K39: =K13 -> 1637 | L39: =L13 -> 1637 | M39: =M13 -> 1637 | ... O39: =O13 -> 1637
B40: Basic earnings per share | C40: =C35/C38 -> 0.83279949 | D40: =D35/D38 -> 0.5291202 | E40: =E35/E38 -> 1.012963 | F40: =F35/F38 -> 1.6837136 | G40: =G35/G38 -> 2.6551246 | H40: =H35/H38 -> 4.2876022 | I40: =I35/I38 -> 6.8984025 | J40: =J35/J38 -> 10.637606 | ... O40: =O35/O38 -> 51.273101
A41: * | B41: Diluted earnings per share | C41: =C35/C39 -> 0.82749841 | D41: =D35/D39 -> 0.52553846 | E41: =E35/E39 -> 1.0024435 | F41: =F35/F39 -> 1.6662285 | G41: =G35/G39 -> 2.6275516 | H41: =H35/H39 -> 4.2430761 | I41: =I35/I39 -> 6.8267637 | J41: =J35/J39 -> 10.527136 | ... O41: =O35/O39 -> 50.740637

Sheet BalSheet
A1: =CoName -> Advanced Micro Devices Inc. | C1: Hist. | D1: Hist. | E1: Hist. | F1: Proj. | G1: Proj. | H1: Proj. | I1: Proj. | J1: Proj. | K1: Proj. | L1: Proj. | M1: Proj. | N1: Proj. | O1: Proj.
A2: Assumptions | C2: 44926 | D2: 45291 | E2: 45657 | F2: 46022 | G2: 46387 | H2: 46752 | I2: 47118 | J2: 47483 | K2: =2030 -> 2030 | L2: =K2+1 -> 2031 | M2: =L2+1 -> 2032 | N2: =M2+1 -> 2033 | O2: =N2+1 -> 2034
B4: Operating Cash % of sales | F4: =Assumptions!F38 -> 0.015 | G4: =F4 -> 0.015 | H4: =G4 -> 0.015 | I4: =H4 -> 0.015 | J4: =I4 -> 0.015 | K4: =J4 -> 0.015 | L4: =K4 -> 0.015 | M4: =L4 -> 0.015 | N4: =M4 -> 0.015 | O4: =N4 -> 0.015
B5: Accounts receivable % of sales | F5: =Assumptions!F39 -> 0.20347838 | G5: =Assumptions!G39 -> 0.20347838 | H5: =Assumptions!H39 -> 0.20347838 | I5: =Assumptions!I39 -> 0.20347838 | J5: =Assumptions!J39 -> 0.20347838 | K5: =Assumptions!K39 -> 0.20347838 | L5: =Assumptions!L39 -> 0.20347838 | M5: =Assumptions!M39 -> 0.20347838 | ... O5: =Assumptions!O39 -> 0.20347838
B6: Inventories % of COGS | F6: =Assumptions!F40 -> 0.36174258 | G6: =Assumptions!G40 -> 0.36174258 | H6: =Assumptions!H40 -> 0.36174258 | I6: =Assumptions!I40 -> 0.36174258 | J6: =Assumptions!J40 -> 0.36174258 | K6: =Assumptions!K40 -> 0.36174258 | L6: =Assumptions!L40 -> 0.36174258 | M6: =Assumptions!M40 -> 0.36174258 | ... O6: =Assumptions!O40 -> 0.36174258
B7: Other current assets % of sales | F7: =Assumptions!F41 -> 0.13496062 | G7: =Assumptions!G41 -> 0.13496062 | H7: =Assumptions!H41 -> 0.13496062 | I7: =Assumptions!I41 -> 0.13496062 | J7: =Assumptions!J41 -> 0.13496062 | K7: =Assumptions!K41 -> 0.13496062 | L7: =Assumptions!L41 -> 0.13496062 | M7: =Assumptions!M41 -> 0.13496062 | ... O7: =Assumptions!O41 -> 0.13496062
B9: Other long-term assets % of sales | F9: =Assumptions!F43 -> 0.127382 | G9: =Assumptions!G43 -> 0.127382 | H9: =Assumptions!H43 -> 0.127382 | I9: =Assumptions!I43 -> 0.127382 | J9: =Assumptions!J43 -> 0.127382 | K9: =Assumptions!K43 -> 0.127382 | L9: =Assumptions!L43 -> 0.127382 | M9: =Assumptions!M43 -> 0.127382 | ... O9: =Assumptions!O43 -> 0.127382
B10: Investment in unconsolidated entities $ balance | F10: =Assumptions!F42 -> 149 | G10: =Assumptions!G42 -> 149 | H10: =Assumptions!H42 -> 149 | I10: =Assumptions!I42 -> 149 | J10: =Assumptions!J42 -> 149 | K10: =Assumptions!K42 -> 149 | L10: =Assumptions!L42 -> 149 | M10: =Assumptions!M42 -> 149 | ... O10: =Assumptions!O42 -> 149
B12: Accounts payable/Accural % of COGS | F12: =Assumptions!F47 -> 0.18882083 | G12: =Assumptions!G47 -> 0.18882083 | H12: =Assumptions!H47 -> 0.18882083 | I12: =Assumptions!I47 -> 0.18882083 | J12: =Assumptions!J47 -> 0.18882083 | K12: =Assumptions!K47 -> 0.18882083 | L12: =Assumptions!L47 -> 0.18882083 | M12: =Assumptions!M47 -> 0.18882083 | ... O12: =Assumptions!O47 -> 0.18882083
B13: Other current liabilities % of sales | F13: =Assumptions!F48 -> 0.18673647 | G13: =Assumptions!G48 -> 0.18673647 | H13: =Assumptions!H48 -> 0.18673647 | I13: =Assumptions!I48 -> 0.18673647 | J13: =Assumptions!J48 -> 0.18673647 | K13: =Assumptions!K48 -> 0.18673647 | L13: =Assumptions!L48 -> 0.18673647 | M13: =Assumptions!M48 -> 0.18673647 | ... O13: =Assumptions!O48 -> 0.18673647
B14: Other long-term liabilities % of sales | F14: =Assumptions!F49 -> 0.10300562 | G14: =Assumptions!G49 -> 0.10300562 | H14: =Assumptions!H49 -> 0.10300562 | I14: =Assumptions!I49 -> 0.10300562 | J14: =Assumptions!J49 -> 0.10300562 | K14: =Assumptions!K49 -> 0.10300562 | L14: =Assumptions!L49 -> 0.10300562 | M14: =Assumptions!M49 -> 0.10300562 | ... O14: =Assumptions!O49 -> 0.10300562
A16: Balance sheet | C16: =C2 -> 44926 | D16: =D2 -> 45291 | E16: =E2 -> 45657 | F16: =F2 -> 46022 | G16: =G2 -> 46387 | H16: =H2 -> 46752 | I16: =I2 -> 47118 | J16: =J2 -> 47483 | ... O16: =O2 -> 2034
B17: Operating Cash | C17: =1.5%*IncState!C16 -> 354.015 | D17: =1.5%*IncState!D16 -> 340.2 | E17: =1.5%*IncState!E16 -> 386.775 | F17: =F4*IncState!F16 -> 513.69045 | G17: =G4*IncState!G16 -> 685.75192 | H17: =H4*IncState!H16 -> 960.05269 | I17: =I4*IncState!I16 -> 1363.2748 | J17: =J4*IncState!J16 -> 1881.3192 | K17: =K4*IncState!K16 -> 2520.9678 | L17: =L4*IncState!L16 -> 3277.2581 | M17: =M4*IncState!M16 -> 4129.3452 | ... O17: =O4*IncState!O16 -> 5944.6054
B18: Excess cash | C18: =4835-C17 -> 4480.985 | D18: =3933-D17 -> 3592.8 | E18: =3787-E17 -> 3400.225 | F18: =MAX(CashFlow!F22,0) -> 7802.9944 | G18: =MAX(CashFlow!G22,0) -> 10533.667 | H18: =MAX(CashFlow!H22,0) -> 13672.296 | I18: =MAX(CashFlow!I22,0) -> 18221.602 | J18: =MAX(CashFlow!J22,0) -> 26253.271 | K18: =MAX(CashFlow!K22,0) -> 39851.466 | L18: =MAX(CashFlow!L22,0) -> 61638.475 | M18: =MAX(CashFlow!M22,0) -> 94654.577 | ... O18: =MAX(CashFlow!O22,0) -> 206910.35
B19: Accounts receivable | C19: =4126+2 -> 4128 | D19: =4323+9 -> 4332 | E19: =6192+113 -> 6305 | F19: =F5*IncState!F16 -> 6968.3267 | G19: =G5*IncState!G16 -> 9302.3793 | H19: =H5*IncState!H16 -> 13023.331 | I19: =I5*IncState!I16 -> 18493.13 | J19: =J5*IncState!J16 -> 25520.52 | K19: =K5*IncState!K16 -> 34197.496 | L19: =L5*IncState!L16 -> 44456.745 | M19: =M5*IncState!M16 -> 56015.499 | ... O19: =O5*IncState!O16 -> 80639.912
B20: Inventories | C20: 3771 | D20: 4351 | E20: 5734 | F20: =F6*IncState!F17 -> 6181.6861 | G20: =G6*IncState!G17 -> 8128.2193 | H20: =H6*IncState!H17 -> 11205.861 | I20: =I6*IncState!I17 -> 15665.745 | J20: =J6*IncState!J17 -> 21278.452 | K20: =K6*IncState!K17 -> 28057.155 | L20: =L6*IncState!L17 -> 35881.54 | M20: =M6*IncState!M17 -> 44463.86 | ... O20: =O6*IncState!O17 -> 61859.756
B21: Other current assets | C21: =1265+1020 -> 2285 | D21: =2312+1840 -> 4152 | E21: =1345+1878 -> 3223 | F21: =BalSheet!F7*IncState!F16 -> 4621.8655 | G21: =BalSheet!G7*IncState!G16 -> 6169.967 | H21: =BalSheet!H7*IncState!H16 -> 8637.9539 | I21: =BalSheet!I7*IncState!I16 -> 12265.894 | J21: =BalSheet!J7*IncState!J16 -> 16926.934 | K21: =BalSheet!K7*IncState!K16 -> 22682.092 | L21: =BalSheet!L7*IncState!L16 -> 29486.72 | M21: =BalSheet!M7*IncState!M16 -> 37153.267 | ... O21: =BalSheet!O7*IncState!O16 -> 53485.843
B22: Total current assets | C22: =SUM(C17:C21) -> 15019 | D22: =SUM(D17:D21) -> 16768 | E22: =SUM(E17:E21) -> 19049 | F22: =SUM(F17:F21) -> 26088.563 | G22: =SUM(G17:G21) -> 34819.985 | H22: =SUM(H17:H21) -> 47499.495 | I22: =SUM(I17:I21) -> 66009.646 | J22: =SUM(J17:J21) -> 91860.497 | ... O22: =SUM(O17:O21) -> 408840.46
B24: Property, plant & equipment, net | C24: =1513+460 -> 1973 | D24: =1589+633 -> 2222 | E24: =1802+623 -> 2425 | F24: =Calcs!F9 -> 2537.3936 | G24: =Calcs!G9 -> 2898.7787 | H24: =Calcs!H9 -> 3602.0838 | I24: =Calcs!I9 -> 4756.0498 | J24: =Calcs!J9 -> 6413.396 | K24: =Calcs!K9 -> 8622.0733 | L24: =Calcs!L9 -> 11407.393 | M24: =Calcs!M9 -> 14752.744 | ... O24: =Calcs!O9 -> 22745.508
B25: Intangible assets | C25: =24177+24118 -> 48295 | D25: =24262+21363 -> 45625 | E25: =24839+18930 -> 43769 | F25: =E25-IncState!F23 -> 41769 | G25: =F25-IncState!G23 -> 39769 | H25: =G25-IncState!H23 -> 37769 | I25: =H25-IncState!I23 -> 35769 | J25: =I25-IncState!J23 -> 33769 | K25: =J25-IncState!K23 -> 31769 | L25: =K25-IncState!L23 -> 29769 | M25: =L25-IncState!M23 -> 27769 | ... O25: =N25-IncState!O23 -> 23769
B26: Investment in unconsolidated entities | C26: 83 | D26: =99 -> 99 | E26: 149 | F26: =F10 -> 149 | G26: =G10 -> 149 | H26: =H10 -> 149 | I26: =I10 -> 149 | J26: =J10 -> 149 | K26: =K10 -> 149 | L26: =L10 -> 149 | M26: =M10 -> 149 | ... O26: =O10 -> 149
B27: Other assets | C27: =58+2152 -> 2210 | D27: =2805+366 -> 3171 | E27: =688+3146 -> 3834 | F27: =F7*IncState!F16 -> 4621.8655 | G27: =G7*IncState!G16 -> 6169.967 | H27: =H7*IncState!H16 -> 8637.9539 | I27: =I7*IncState!I16 -> 12265.894 | J27: =J7*IncState!J16 -> 16926.934 | K27: =K7*IncState!K16 -> 22682.092 | L27: =L7*IncState!L16 -> 29486.72 | M27: =M7*IncState!M16 -> 37153.267 | ... O27: =O7*IncState!O16 -> 53485.843
B28: Total non-current assets | C28: =SUM(C24:C27) -> 52561 | D28: =SUM(D24:D27) -> 51117 | E28: =SUM(E24:E27) -> 50177 | F28: =SUM(F24:F27) -> 49077.259 | G28: =SUM(G24:G27) -> 48986.746 | H28: =SUM(H24:H27) -> 50158.038 | I28: =SUM(I24:I27) -> 52939.944 | J28: =SUM(J24:J27) -> 57258.33 | ... O28: =SUM(O24:O27) -> 100149.35
A30: * | B30: TOTAL ASSETS | C30: =SUM(C28,C22) -> 67580 | D30: =SUM(D28,D22) -> 67885 | E30: =SUM(E28,E22) -> 69226 | F30: =SUM(F28,F22) -> 75165.822 | G30: =SUM(G28,G22) -> 83806.731 | H30: =SUM(H28,H22) -> 97657.532 | I30: =SUM(I28,I22) -> 118949.59 | J30: =SUM(J28,J22) -> 149118.83 | ... O30: =SUM(O28,O22) -> 508989.82
B32: Revolver/Short term debt | C32: 0 | D32: 751 | E32: 0 | F32: =MIN(CashFlow!F22,0) -> 0 | G32: =MIN(CashFlow!G22,0) -> 0 | H32: =MIN(CashFlow!H22,0) -> 0 | I32: =MIN(CashFlow!I22,0) -> 0 | J32: =MIN(CashFlow!J22,0) -> 0 | K32: =MIN(CashFlow!K22,0) -> 0 | L32: =MIN(CashFlow!L22,0) -> 0 | M32: =MIN(CashFlow!M22,0) -> 0 | ... O32: =MIN(CashFlow!O22,0) -> 0
B33: Accounts payable/Accurals | C33: =2493+463 -> 2956 | D33: =2055+363 -> 2418 | E33: =1990+476 -> 2466 | F33: =F12*IncState!F17 -> 3226.6898 | G33: =G12*IncState!G17 -> 4242.7328 | H33: =H12*IncState!H17 -> 5849.1869 | I33: =I12*IncState!I17 -> 8177.138 | J33: =J12*IncState!J17 -> 11106.834 | K33: =K12*IncState!K17 -> 14645.152 | L33: =L12*IncState!L17 -> 18729.291 | M33: =M12*IncState!M17 -> 23209.053 | ... O33: =O12*IncState!O17 -> 32289.288
B34: Other current liabilities | C34: =336+3077 -> 3413 | D34: =438+3082 -> 3520 | E34: =4260+555 -> 4815 | F34: =F13*IncState!F16 -> 6394.9829 | G34: =G13*IncState!G16 -> 8536.993 | H34: =H13*IncState!H16 -> 11951.79 | I34: =I13*IncState!I16 -> 16971.542 | J34: =J13*IncState!J16 -> 23420.728 | K34: =K13*IncState!K16 -> 31383.776 | L34: =L13*IncState!L16 -> 40798.909 | M34: =M13*IncState!M16 -> 51406.625 | ... O34: =O13*IncState!O16 -> 74004.977
B35: Total current liabilities | C35: =SUM(C32:C34) -> 6369 | D35: =SUM(D32:D34) -> 6689 | E35: =SUM(E32:E34) -> 7281 | F35: =SUM(F32:F34) -> 9621.6727 | G35: =SUM(G32:G34) -> 12779.726 | H35: =SUM(H32:H34) -> 17800.977 | I35: =SUM(I32:I34) -> 25148.68 | J35: =SUM(J32:J34) -> 34527.563 | ... O35: =SUM(O32:O34) -> 106294.26
B37: Long-term debt, including current maturities | C37: 2467 | D37: 1717 | E37: =1721 -> 1721 | F37: =Debt!F26 -> 1721 | G37: =Debt!G26 -> 1721 | H37: =Debt!H26 -> 1721 | I37: =Debt!I26 -> 1721 | J37: =Debt!J26 -> 1721 | K37: =Debt!K26 -> 1721 | L37: =Debt!L26 -> 1721 | M37: =Debt!M26 -> 1721 | ... O37: =Debt!O26 -> 1721
B38: Other long-term liabilities | C38: =396+1934+1664 -> 3994 | D38: =1850+1202+535 -> 3587 | E38: =491+349+1816 -> 2656 | F38: =F14*IncState!F16 -> 3527.5337 | G38: =G14*IncState!G16 -> 4709.0869 | H38: =H14*IncState!H16 -> 6592.7217 | I38: =I14*IncState!I16 -> 9361.6648 | J38: =J14*IncState!J16 -> 12919.097 | K38: =K14*IncState!K16 -> 17311.591 | L38: =L14*IncState!L16 -> 22505.068 | M38: =M14*IncState!M16 -> 28356.385 | ... O38: =O14*IncState!O16 -> 40821.852
B39: Total non-current liabilities | C39: =SUM(C37:C38) -> 6461 | D39: =SUM(D37:D38) -> 5304 | E39: =SUM(E37:E38) -> 4377 | F39: =SUM(F37:F38) -> 5248.5337 | G39: =SUM(G37:G38) -> 6430.0869 | H39: =SUM(H37:H38) -> 8313.7217 | I39: =SUM(I37:I38) -> 11082.665 | J39: =SUM(J37:J38) -> 14640.097 | ... O39: =SUM(O37:O38) -> 42542.852
B41: Equity | C41: 54750 | D41: 55892 | E41: 57568 | F41: =Calcs!F16 -> 60295.616 | G41: =Calcs!G16 -> 64596.918 | H41: =Calcs!H16 -> 71542.833 | I41: =Calcs!I16 -> 82718.246 | J41: =Calcs!J16 -> 99951.167 | K41: =Calcs!K16 -> 125469.82 | L41: =Calcs!L16 -> 161798.58 | M41: =Calcs!M16 -> 211547.5 | ... O41: =Calcs!O16 -> 360152.7
A42: * | B42: TOTAL LIABILITIES & EQUITY | C42: =SUM(C41,C39,C35) -> 67580 | D42: =SUM(D41,D39,D35) -> 67885 | E42: =SUM(E41,E39,E35) -> 69226 | F42: =SUM(F41,F39,F35) -> 75165.822 | G42: =SUM(G41,G39,G35) -> 83806.731 | H42: =SUM(H41,H39,H35) -> 97657.532 | I42: =SUM(I41,I39,I35) -> 118949.59 | J42: =SUM(J41,J39,J35) -> 149118.83 | ... O42: =SUM(O41,O39,O35) -> 508989.82
A44: * | B44: Balance check | C44: =C42-C30 -> 0 | D44: =D42-D30 -> 0 | E44: =E42-E30 -> 0 | F44: =F42-F30 -> 0 | G44: =G42-G30 -> 0 | H44: =H42-H30 -> 0 | I44: =I42-I30 -> 0 | J44: =J42-J30 -> 0 | ... O44: =O42-O30 -> 0

Sheet CashFlow
A1: =CoName -> Advanced Micro Devices Inc. | C1: Hist. | D1: Hist. | E1: Hist. | F1: Proj. | G1: Proj. | H1: Proj. | I1: Proj. | J1: Proj. | K1: Proj. | L1: Proj. | M1: Proj. | N1: Proj. | O1: Proj.
A2: Cash flow statement | C2: 2022 | D2: =C2+1 -> 2023 | E2: =D2+1 -> 2024 | F2: =E2+1 -> 2025 | G2: =F2+1 -> 2026 | H2: =G2+1 -> 2027 | I2: =H2+1 -> 2028 | J2: =I2+1 -> 2029 | K2: =J2+1 -> 2030 | ... O2: =N2+1 -> 2034
B3: Net Income | F3: =IncState!F35 -> 2727.616 | G3: =IncState!G35 -> 4301.3019 | H3: =IncState!H35 -> 6945.9156 | I3: =IncState!I35 -> 11175.412 | J3: =IncState!J35 -> 17232.921 | K3: =IncState!K35 -> 25518.657 | L3: =IncState!L35 -> 36328.759 | M3: =IncState!M35 -> 49748.913 | ... O3: =IncState!O35 -> 83062.423
B4: Depreciation | F4: =IncState!F22 -> 732.30198 | G4: =IncState!G22 -> 766.24262 | H4: =IncState!H22 -> 875.37377 | I4: =IncState!I22 -> 1087.758 | J4: =IncState!J22 -> 1436.2328 | K4: =IncState!K22 -> 1936.7186 | L4: =IncState!L22 -> 2603.6954 | M4: =IncState!M22 -> 3444.8067 | ... O4: =IncState!O22 -> 5611.3058
B5: Amortization | F5: =IncState!F23 -> 2000 | G5: =IncState!G23 -> 2000 | H5: =IncState!H23 -> 2000 | I5: =IncState!I23 -> 2000 | J5: =IncState!J23 -> 2000 | K5: =IncState!K23 -> 2000 | L5: =IncState!L23 -> 2000 | M5: =IncState!M23 -> 2000 | ... O5: =IncState!O23 -> 2000
B6: (inc) / dec In OWC | F6: =Calcs!F25 -> -296.12114 | G6: =Calcs!G25 -> -2842.6957 | H6: =Calcs!H25 -> -4519.6297 | I6: =Calcs!I25 -> -6613.1431 | J6: =Calcs!J25 -> -8440.2981 | K6: =Calcs!K25 -> -10349.12 | L6: =Calcs!L25 -> -12145.28 | M6: =Calcs!M25 -> -13572.23 | ... O6: =Calcs!O25 -> -14152.947
B7: (inc) / dec In LT assets | F7: =BalSheet!E27-BalSheet!F27 -> -787.86552 | G7: =BalSheet!F27-BalSheet!G27 -> -1548.1015 | H7: =BalSheet!G27-BalSheet!H27 -> -2467.9868 | I7: =BalSheet!H27-BalSheet!I27 -> -3627.9406 | J7: =BalSheet!I27-BalSheet!J27 -> -4661.0399 | K7: =BalSheet!J27-BalSheet!K27 -> -5755.1577 | L7: =BalSheet!K27-BalSheet!L27 -> -6804.6276 | M7: =BalSheet!L27-BalSheet!M27 -> -7666.5471 | ... O7: =BalSheet!N27-BalSheet!O27 -> -8158.8574
B8: inc / (dec) in LT liabilities | F8: =BalSheet!F38-BalSheet!E38 -> 871.53367 | G8: =BalSheet!G38-BalSheet!F38 -> 1181.5533 | H8: =BalSheet!H38-BalSheet!G38 -> 1883.6348 | I8: =BalSheet!I38-BalSheet!H38 -> 2768.9431 | J8: =BalSheet!J38-BalSheet!I38 -> 3557.4326 | K8: =BalSheet!K38-BalSheet!J38 -> 4392.4931 | L8: =BalSheet!L38-BalSheet!K38 -> 5193.4772 | M8: =BalSheet!M38-BalSheet!L38 -> 5851.3176 | ... O8: =BalSheet!O38-BalSheet!N38 -> 6227.0622
B9: Cash Flow From Operations | F9: =SUM(F3:F8) -> 5247.465 | G9: =SUM(G3:G8) -> 3858.3006 | H9: =SUM(H3:H8) -> 4717.3076 | I9: =SUM(I3:I8) -> 6791.0295 | J9: =SUM(J3:J8) -> 11125.249 | K9: =SUM(K3:K8) -> 17743.591 | L9: =SUM(L3:L8) -> 27176.024 | M9: =SUM(M3:M8) -> 39806.26 | ... O9: =SUM(O3:O8) -> 74588.987
B11: Capex | F11: =Calcs!F7 -> 844.69556 | G11: =Calcs!G7 -> 1127.6277 | H11: =Calcs!H7 -> 1578.6788 | I11: =Calcs!I7 -> 2241.724 | J11: =Calcs!J7 -> 3093.5791 | K11: =Calcs!K7 -> 4145.3959 | L11: =Calcs!L7 -> 5389.0147 | M11: =Calcs!M7 -> 6790.1585 | ... O11: =Calcs!O7 -> 9775.1122
B12: Cash Flow From Investing | F12: =-F11 -> -844.69556 | G12: =-G11 -> -1127.6277 | H12: =-H11 -> -1578.6788 | I12: =-I11 -> -2241.724 | J12: =-J11 -> -3093.5791 | K12: =-K11 -> -4145.3959 | L12: =-L11 -> -5389.0147 | M12: =-M11 -> -6790.1585 | ... O12: =-O11 -> -9775.1122
B14: Share Issuance / (repayment) | F14: =Calcs!F11 -> 0 | G14: =Calcs!G11 -> 0 | H14: =Calcs!H11 -> 0 | I14: =Calcs!I11 -> 0 | J14: =Calcs!J11 -> 0 | K14: =Calcs!K11 -> 0 | L14: =Calcs!L11 -> 0 | M14: =Calcs!M11 -> 0 | ... O14: =Calcs!O11 -> 0
B15: Debt Issuance / (repayment) | F15: =SUM(Debt!F8:F9) -> 0 | G15: =SUM(Debt!G8:G9) -> 0 | H15: =SUM(Debt!H8:H9) -> 0 | I15: =SUM(Debt!I8:I9) -> 0 | J15: =SUM(Debt!J8:J9) -> 0 | K15: =SUM(Debt!K8:K9) -> 0 | L15: =SUM(Debt!L8:L9) -> 0 | M15: =SUM(Debt!M8:M9) -> 0 | ... O15: =SUM(Debt!O8:O9) -> 0
B16: Cash Flow From Financing | F16: =SUM(F14:F15) -> 0 | G16: =SUM(G14:G15) -> 0 | H16: =SUM(H14:H15) -> 0 | I16: =SUM(I14:I15) -> 0 | J16: =SUM(J14:J15) -> 0 | K16: =SUM(K14:K15) -> 0 | L16: =SUM(L14:L15) -> 0 | M16: =SUM(M14:M15) -> 0 | ... O16: =SUM(O14:O15) -> 0
B18: Net changes in Cash | F18: =SUM(F16,F12,F9) -> 4402.7694 | G18: =SUM(G16,G12,G9) -> 2730.6728 | H18: =SUM(H16,H12,H9) -> 3138.6288 | I18: =SUM(I16,I12,I9) -> 4549.3055 | J18: =SUM(J16,J12,J9) -> 8031.6697 | K18: =SUM(K16,K12,K9) -> 13598.195 | L18: =SUM(L16,L12,L9) -> 21787.009 | M18: =SUM(M16,M12,M9) -> 33016.102 | ... O18: =SUM(O16,O12,O9) -> 64813.875
B20: Beginning Cash | F20: =BalSheet!E18 -> 3400.225 | G20: =BalSheet!F18 -> 7802.9944 | H20: =BalSheet!G18 -> 10533.667 | I20: =BalSheet!H18 -> 13672.296 | J20: =BalSheet!I18 -> 18221.602 | K20: =BalSheet!J18 -> 26253.271 | L20: =BalSheet!K18 -> 39851.466 | M20: =BalSheet!L18 -> 61638.475 | ... O20: =BalSheet!N18 -> 142096.47
B21: =B18 -> Net changes in Cash | F21: =F18 -> 4402.7694 | G21: =G18 -> 2730.6728 | H21: =H18 -> 3138.6288 | I21: =I18 -> 4549.3055 | J21: =J18 -> 8031.6697 | K21: =K18 -> 13598.195 | L21: =L18 -> 21787.009 | M21: =M18 -> 33016.102 | ... O21: =O18 -> 64813.875
B22: Ending Cash | F22: =SUM(F20:F21) -> 7802.9944 | G22: =SUM(G20:G21) -> 10533.667 | H22: =SUM(H20:H21) -> 13672.296 | I22: =SUM(I20:I21) -> 18221.602 | J22: =SUM(J20:J21) -> 26253.271 | K22: =SUM(K20:K21) -> 39851.466 | L22: =SUM(L20:L21) -> 61638.475 | M22: =SUM(M20:M21) -> 94654.577 | ... O22: =SUM(O20:O21) -> 206910.35

Sheet Free Cash Flow
A1: =CoName -> Advanced Micro Devices Inc. | C1: Hist. | D1: Hist. | E1: Hist. | F1: Proj. | G1: Proj. | H1: Proj. | I1: Proj. | J1: Proj. | K1: Proj. | L1: Proj. | M1: Proj. | N1: Proj. | O1: Proj.
