Workbook
Name Ccy: MAIN!$C$6
Name circ: MAIN!$C$9
Name CoName: MAIN!$C$4
Name g: #REF!
Name IQ_CH: 110000
Name IQ_CQ: 5000
Name IQ_CY: 10000
Name IQ_DAILY: 500000
Name IQ_FH: 100000
Name IQ_FQ: 500
Name IQ_FY: 1000
Name IQ_LTM: 2000
Name IQ_MONTH: 15000
Name IQ_NTM: 6000
Name IQ_WEEK: 50000
Name IQ_YTD: 3000
Name OpCase: [1]DCF!$E$98
Name ScenarioREV: Assumptions!$D$4
Name TTS: #REF!
Name Units: MAIN!$C$7

Sheet MAIN
A1: =CoName -> Broadcom Inc.
A2: Model Details
B4: Company name | C4: Broadcom Inc. | E4: Current Stock Price | F4: 354.19 | H4: Operating Case One | I4: Terminal Mult | J4: Perpetuity | K4: Average
B5: Latest BS date | C5: 247.43 | E5: Diluted s/o | F5: 4722.365 | H5: Implied Price | I5: ='DCF Model'!G18 -> 305.86788 | J5: ='DCF Model'!C18 -> 286.8967 | K5: =AVERAGE(I5:J5) -> 296.38229
B6: Currency | C6: USD | E6: Mkt Cap | F6: =F5*F4 -> 1672614.5 | H6: Difference | I6: =I5/$F$4-1 -> -0.13642995 | J6: =J5/$F$4-1 -> -0.18999211 | K6: =K5/$F$4-1 -> -0.16321103
B7: Units | C7: m | E7: Cash | F7: =10718 -> 10718
B8: Analyst name | C8: Alan Chen | E8: Debt | F8: =1399+82830 -> 84229
B9: Circular switch | C9: 0 | E9: EV | F9: =F6-F7+F8 -> 1746125.5

Sheet Quarterly Projections
A1: =CoName -> Broadcom Inc.
A2: Revenues | C2: Q122 | D2: Q222 | E2: Q322 | F2: Q422 | G2: 2022 | H2: Q123 | I2: Q223 | J2: Q323 | K2: Q423 | L2: 2023 | M2: Q124 | N2: Q224 | O2: Q324 | P2: Q424 | Q2: 2024 | R2: Q125 | S2: Q225 | T2: Q325 | U2: Q425 | V2: 2025 | W2: Q126 | X2: Q226 | Y2: Q326 | Z2: Q426 | AA2: 2026 | AB2: =AA2+1 -> 2027 | AC2: =AB2+1 -> 2028 | AD2: =AC2+1 -> 2029 | AE2: =AD2+1 -> 2030 | AF2: =AE2+1 -> 2031 | AG2: =AF2+1 -> 2032 | AH2: =AG2+1 -> 2033 | AI2: =AH2+1 -> 2034
B3: Semiconductor solutions | C3: 5873 | D3: 6229 | E3: 6624 | F3: 7092 | G3: =SUM(C3:F3) -> 25818 | H3: 7107 | I3: 6808 | J3: 6941 | K3: 7326 | L3: =SUM(H3:K3) -> 28182 | M3: 7390 | N3: 7202 | O3: 7274 | P3: 8230 | Q3: =SUM(M3:P3) -> 30096 | R3: 8212 | S3: 8408 | T3: 9166 | U3: =P3*(1+U4) -> 9876 | V3: =SUM(R3:U3) -> 35662 | W3: =R3*(1+W4) -> 9854.4 | X3: =S3*(1+X4) -> 10089.6 | Y3: =T3*(1+Y4) -> 13474.02 | Z3: =U3*(1+Z4) -> 14715.24 | AA3: =SUM(W3:Z3) -> 48133.26 | AB3: =AA3*(1+AB4) -> 62573.238 | AC3: =AB3*(1+AC4) -> 81032.343 | AD3: =AC3*(1+AD4) -> 104531.72 | AE3: =AD3*(1+AE4) -> 134323.26 | AF3: =AE3*(1+AF4) -> 171933.78 | AG3: =AF3*(1+AG4) -> 219215.57 | AH3: =AG3*(1+AH4) -> 278403.77 | AI3: =AH3*(1+AI4) -> 352180.77
B4: y/y | H4: =H3/C3-1 -> 0.21011408 | I4: =I3/D3-1 -> 0.09295232 | J4: =J3/E3-1 -> 0.04785628 | K4: =K3/F3-1 -> 0.032994924 | L4: =L3/G3-1 -> 0.091564025 | M4: =M3/H3-1 -> 0.039819896 | N4: =N3/I3-1 -> 0.05787309 | O4: =O3/J3-1 -> 0.047975796 | ... T4: =T3/O3-1 -> 0.26010448 | U4: 0.2 | V4: =V3/Q3-1 -> 0.18494152 | W4: =U4 -> 0.2 | X4: =W4 -> 0.2 | Y4: 0.47 | Z4: 0.49 | AA4: =AA3/V3-1 -> 0.34970725 | AB4: 0.3 | AC4: =AB4-0.005 -> 0.295 | AD4: =AC4-0.005 -> 0.29 | AE4: =AD4-0.005 -> 0.285 | AF4: =AE4-0.005 -> 0.28 | AG4: =AF4-0.005 -> 0.275 | AH4: =AG4-0.005 -> 0.27 | AI4: =AH4-0.005 -> 0.265
B5: Infrastructure software | C5: 1833 | D5: 1874 | E5: 1840 | F5: 1838 | G5: =SUM(C5:F5) -> 7385 | H5: 1808 | I5: 1925 | J5: 1935 | K5: 1969 | L5: =SUM(H5:K5) -> 7637 | M5: 4571 | N5: 5285 | O5: 5798 | P5: 5824 | Q5: =SUM(M5:P5) -> 21478 | R5: 6704 | S5: 6596 | T5: 6786 | U5: =P5*(1+U6) -> 7542.2773 | V5: =SUM(R5:U5) -> 27628.277 | W5: =R5*(1+W6) -> 8681.9071 | X5: =S5*(1+X6) -> 8542.0435 | Y5: =T5*(1+Y6) -> 9975.42 | Z5: =U5*(1+Z6) -> 11313.416 | AA5: =SUM(W5:Z5) -> 38512.787 | AB5: =AA5*(1+AB6) -> 50066.622 | AC5: =AB5*(1+AC6) -> 64836.276 | AD5: =AC5*(1+AD6) -> 83638.796 | AE5: =AD5*(1+AE6) -> 107475.85 | AF5: =AE5*(1+AF6) -> 137569.09 | AG5: =AF5*(1+AG6) -> 175400.59 | AH5: =AG5*(1+AH6) -> 222758.75 | AI5: =AH5*(1+AI6) -> 281789.82
B6: y/y | H6: =H5/C5-1 -> -0.013638843 | I6: =I5/D5-1 -> 0.027214514 | J6: =J5/E5-1 -> 0.051630435 | K6: =K5/F5-1 -> 0.071273123 | L6: =L5/G5-1 -> 0.034123223 | M6: =M5/H5-1 -> 1.528208 | N6: =N5/I5-1 -> 1.7454545 | O6: =O5/J5-1 -> 1.9963824 | ... T6: =T5/O5-1 -> 0.17040359 | U6: =AVERAGE(R6:T6) -> 0.29503388 | V6: =V5/Q5-1 -> 0.28635242 | W6: =U6 -> 0.29503388 | X6: =W6 -> 0.29503388 | Y6: 0.47 | Z6: 0.5 | AA6: =AA5/V5-1 -> 0.39396265 | AB6: 0.3 | AC6: =AB6-0.005 -> 0.295 | AD6: =AC6-0.005 -> 0.29 | AE6: =AD6-0.005 -> 0.285 | AF6: =AE6-0.005 -> 0.28 | AG6: =AF6-0.005 -> 0.275 | AH6: =AG6-0.005 -> 0.27 | AI6: =AH6-0.005 -> 0.265
A7: * | B7: TOTAL REVENUES | C7: =SUM(C5,C3) -> 7706 | D7: =SUM(D5,D3) -> 8103 | E7: =SUM(E5,E3) -> 8464 | F7: =SUM(F5,F3) -> 8930 | G7: =SUM(G5,G3) -> 33203 | H7: =SUM(H5,H3) -> 8915 | I7: =SUM(I5,I3) -> 8733 | J7: =SUM(J5,J3) -> 8876 | ... AI7: =SUM(AI5,AI3) -> 633970.59
B8: y/y | H8: =H7/C7-1 -> 0.15689073 | I8: =I7/D7-1 -> 0.077748982 | J8: =J7/E7-1 -> 0.048676749 | K8: =K7/F7-1 -> 0.04087346 | L8: =L7/G7-1 -> 0.078788061 | M8: =M7/H7-1 -> 0.34167134 | N8: =N7/I7-1 -> 0.42986374 | O8: =O7/J7-1 -> 0.47273547 | ... AA8: =AA7/V7-1 -> 0.36902618 | AB8: =AB7/AA7-1 -> 0.3 | AC8: =AC7/AB7-1 -> 0.295 | AD8: =AD7/AC7-1 -> 0.29 | AE8: =AE7/AD7-1 -> 0.285 | AF8: =AF7/AE7-1 -> 0.28 | AG8: =AG7/AF7-1 -> 0.275 | AH8: =AH7/AG7-1 -> 0.27 | AI8: =AI7/AH7-1 -> 0.265

Sheet Assumptions
A1: =CoName -> Broadcom Inc. | C1: Hist. | D1: Hist. | E1: Hist. | F1: Proj. | G1: Proj. | H1: Proj. | I1: Proj. | J1: Proj. | K1: Proj. | L1: Proj. | M1: Proj. | N1: Proj. | O1: Proj.
A2: * | B2: Income Statement | C2: 2022 | D2: =C2+1 -> 2023 | E2: =D2+1 -> 2024 | F2: =E2+1 -> 2025 | G2: =F2+1 -> 2026 | H2: =G2+1 -> 2027 | I2: =H2+1 -> 2028 | J2: =I2+1 -> 2029 | K2: =J2+1 -> 2030 | ... O2: =N2+1 -> 2034
B4: Operating Case | D4: 1
D5: Variance
B6: Street Case | D6: 0 | F6: ='Quarterly Projections'!V6 -> 0.28635242 | G6: ='Quarterly Projections'!AA6 -> 0.39396265 | H6: ='Quarterly Projections'!AB6 -> 0.3 | I6: ='Quarterly Projections'!AC6 -> 0.295 | J6: ='Quarterly Projections'!AD6 -> 0.29 | K6: ='Quarterly Projections'!AE6 -> 0.285 | L6: ='Quarterly Projections'!AF6 -> 0.28 | M6: ='Quarterly Projections'!AG6 -> 0.275 | N6: ='Quarterly Projections'!AH6 -> 0.27 | O6: ='Quarterly Projections'!AI6 -> 0.265
B7: Optimistic Case | D7: 0.025 | F7: =F6+$D$7 -> 0.31135242 | G7: =G6+$D$7 -> 0.41896265 | H7: =H6+$D$7 -> 0.325 | I7: =I6+$D$7 -> 0.32 | J7: =J6+$D$7 -> 0.315 | K7: =K6+$D$7 -> 0.31 | L7: =L6+$D$7 -> 0.305 | M7: =M6+$D$7 -> 0.3 | ... O7: =O6+$D$7 -> 0.29
B8: Pessimistic Case | D8: -0.025 | F8: =F6+$D$8 -> 0.26135242 | G8: =G6+$D$8 -> 0.36896265 | H8: =H6+$D$8 -> 0.275 | I8: =I6+$D$8 -> 0.27 | J8: =J6+$D$8 -> 0.265 | K8: =K6+$D$8 -> 0.26 | L8: =L6+$D$8 -> 0.255 | M8: =M6+$D$8 -> 0.25 | ... O8: =O6+$D$8 -> 0.24
B10: Revenue Growth | D10: =IncState!D17/IncState!C17-1 -> 0.078788061 | E10: =IncState!E17/IncState!D17-1 -> 0.43985036 | F10: =CHOOSE(ScenarioREV,F6,F7,F8) -> 0.28635242 | G10: =CHOOSE(ScenarioREV,G6,G7,G8) -> 0.39396265 | H10: =CHOOSE(ScenarioREV,H6,H7,H8) -> 0.3 | I10: =CHOOSE(ScenarioREV,I6,I7,I8) -> 0.295 | J10: =CHOOSE(ScenarioREV,J6,J7,J8) -> 0.29 | K10: =CHOOSE(ScenarioREV,K6,K7,K8) -> 0.285 | L10: =CHOOSE(ScenarioREV,L6,L7,L8) -> 0.28 | M10: =CHOOSE(ScenarioREV,M6,M7,M8) -> 0.275 | ... O10: =CHOOSE(ScenarioREV,O6,O7,O8) -> 0.265
B11: COGS % of sales | C11: =IncState!C18/IncState!C17 -> 0.33454808 | D11: =IncState!D18/IncState!D17 -> 0.31058935 | E11: =IncState!E18/IncState!E17 -> 0.36473805 | F11: =E11 -> 0.36473805 | G11: =F11 -> 0.36473805 | H11: =G11 -> 0.36473805 | I11: =H11 -> 0.36473805 | J11: =I11 -> 0.36473805 | K11: =J11 -> 0.36473805 | L11: =K11 -> 0.36473805 | M11: =L11 -> 0.36473805 | ... O11: =N11 -> 0.36473805
B12: R&D % of sales | C12: =IncState!C19/IncState!C17 -> 0.14814926 | D12: =IncState!D19/IncState!D17 -> 0.14665401 | E12: =IncState!E19/IncState!E17 -> 0.18051731 | F12: =E12 -> 0.18051731 | G12: =F12 -> 0.18051731 | H12: =G12 -> 0.18051731 | I12: =H12 -> 0.18051731 | J12: =I12 -> 0.18051731 | K12: =J12 -> 0.18051731 | L12: =K12 -> 0.18051731 | M12: =L12 -> 0.18051731 | ... O12: =N12 -> 0.18051731
B13: SG&A % of sales | C13: =IncState!C20/IncState!C17 -> 0.088877511 | D13: =IncState!D20/IncState!D17 -> 0.083363578 | E13: =IncState!E20/IncState!E17 -> 0.15905301 | F13: =E13 -> 0.15905301 | G13: =F13 -> 0.15905301 | H13: =G13 -> 0.15905301 | I13: =H13 -> 0.15905301 | J13: =I13 -> 0.15905301 | K13: =J13 -> 0.15905301 | L13: =K13 -> 0.15905301 | M13: =L13 -> 0.15905301 | ... O13: =N13 -> 0.15905301
B14: Amortization $ Amt | C14: =IncState!C24 -> 4455 | D14: =IncState!D24 -> 3333 | E14: =IncState!E24 -> 9417 | F14: =(24156+15239)/8 -> 4924.375 | G14: =F14 -> 4924.375 | H14: =G14 -> 4924.375 | I14: =H14 -> 4924.375 | J14: =I14 -> 4924.375 | K14: =J14 -> 4924.375 | L14: =K14 -> 4924.375 | M14: =L14 -> 4924.375 | N14: 0 | O14: =N14 -> 0
B15: Non recurring income / (expense) | C15: =IncState!C27 -> -62 | D15: =IncState!D27 -> -248 | E15: =IncState!E27 -> -1787 | F15: 0 | G15: 0 | H15: 0 | I15: 0 | J15: 0 | K15: 0 | L15: 0 | M15: 0 | N15: 0 | O15: 0
B16: Other Income / (expense) | C16: =IncState!C28 -> -54 | D16: =IncState!D28 -> 512 | E16: =IncState!E28 -> 406 | F16: 0 | G16: 0 | H16: 0 | I16: 0 | J16: 0 | K16: 0 | L16: 0 | M16: 0 | N16: 0 | O16: 0
B17: Effective tax rate | C17: =IncState!C35/IncState!C33 -> 0.075518739 | D17: =IncState!D35/IncState!D33 -> 0.066145324 | E17: =IncState!E35/IncState!E33 -> 0.37797499 | F17: 0.21 | G17: =F17 -> 0.21 | H17: =G17 -> 0.21 | I17: =H17 -> 0.21 | J17: =I17 -> 0.21 | K17: =J17 -> 0.21 | L17: =K17 -> 0.21 | M17: =L17 -> 0.21 | N17: =M17 -> 0.21 | O17: =N17 -> 0.21
B18: Dividend Payout Rate | C18: =IncState!C37 -> 1.7197359 | D18: =IncState!D37 -> 1.8426127 | E18: =IncState!E37 -> 2.1224048 | F18: =E18+(E18-D18) -> 2.402197 | G18: =F18+(F18-E18) -> 2.6819892 | H18: =G18+(G18-F18) -> 2.9617813 | I18: =H18+(H18-G18) -> 3.2415735 | J18: =I18+(I18-H18) -> 3.5213657 | K18: =J18+(J18-I18) -> 3.8011578 | L18: =K18+(K18-J18) -> 4.08095 | M18: =L18+(L18-K18) -> 4.3607422 | ... O18: =N18+(N18-M18) -> 4.9203265
B19: Basic WASO | C19: =IncState!C40 -> 4089 | D19: =IncState!D40 -> 4149 | E19: =IncState!E40 -> 4624 | F19: =E19 -> 4624 | G19: =F19 -> 4624 | H19: =G19 -> 4624 | I19: =H19 -> 4624 | J19: =I19 -> 4624 | K19: =J19 -> 4624 | L19: =K19 -> 4624 | M19: =L19 -> 4624 | ... O19: =N19 -> 4624
B20: Diluted WASO | C20: =IncState!C41 -> 4232 | D20: =IncState!D41 -> 4272 | E20: =IncState!E41 -> 4778 | F20: =E20 -> 4778 | G20: =F20 -> 4778 | H20: =G20 -> 4778 | I20: =H20 -> 4778 | J20: =I20 -> 4778 | K20: =J20 -> 4778 | L20: =K20 -> 4778 | M20: =L20 -> 4778 | ... O20: =N20 -> 4778
A22: * | B22: Debt | C22: =C2 -> 2022 | D22: =D2 -> 2023 | E22: =E2 -> 2024 | F22: =F2 -> 2025 | G22: =G2 -> 2026 | H22: =H2 -> 2027 | I22: =I2 -> 2028 | J22: =J2 -> 2029 | ... O22: =O2 -> 2034
B24: Interest rate on Revolver | F24: =E24 -> 0 | G24: =F24 -> 0 | H24: =G24 -> 0 | I24: =H24 -> 0 | J24: =I24 -> 0 | K24: =J24 -> 0 | L24: =K24 -> 0 | M24: =L24 -> 0 | ... O24: =N24 -> 0
B25: Interest rate on long-term debt | E25: 0.04474 | F25: =E25 -> 0.04474 | G25: =F25 -> 0.04474 | H25: =G25 -> 0.04474 | I25: =H25 -> 0.04474 | J25: =I25 -> 0.04474 | K25: =J25 -> 0.04474 | L25: =K25 -> 0.04474 | M25: =L25 -> 0.04474 | ... O25: =N25 -> 0.04474
B26: Interest rate on cash | E26: 0.05 | F26: =E26 -> 0.05 | G26: =F26 -> 0.05 | H26: =G26 -> 0.05 | I26: =H26 -> 0.05 | J26: =I26 -> 0.05 | K26: =J26 -> 0.05 | L26: =K26 -> 0.05 | M26: =L26 -> 0.05 | ... O26: =N26 -> 0.05
B28: Issuance of long-term debt | F28: 0 | G28: 0 | H28: 0 | I28: 0 | J28: 0 | K28: 0 | L28: 0 | M28: 0 | N28: 0 | O28: 0
B29: Repayment of long-term debt | F29: 0 | G29: 0 | H29: 0 | I29: 0 | J29: 0 | K29: 0 | L29: 0 | M29: 0 | N29: 0 | O29: 0
A31: * | B31: Calcs | C31: =C22 -> 2022 | D31: =D22 -> 2023 | E31: =E22 -> 2024 | F31: =F22 -> 2025 | G31: =G22 -> 2026 | H31: =H22 -> 2027 | I31: =I22 -> 2028 | J31: =J22 -> 2029 | ... O31: =O22 -> 2034
B33: CapEx % of Sales | C33: =424/IncState!C17 -> 0.01276993 | D33: =452/IncState!D17 -> 0.012619001 | E33: =548/IncState!E17 -> 0.010625509 | F33: =E33 -> 0.010625509 | G33: =F33 -> 0.010625509 | H33: =G33 -> 0.010625509 | I33: =H33 -> 0.010625509 | J33: =I33 -> 0.010625509 | K33: =J33 -> 0.010625509 | L33: =K33 -> 0.010625509 | M33: =L33 -> 0.010625509 | ... O33: =N33 -> 0.010625509
B34: Depreciation % of beginning PP&E | D34: =IncState!D23/BalSheet!C22 -> 0.22582096 | E34: =IncState!E23/BalSheet!D22 -> 0.27530176 | F34: =E34 -> 0.27530176 | G34: =F34 -> 0.27530176 | H34: =G34 -> 0.27530176 | I34: =H34 -> 0.27530176 | J34: =I34 -> 0.27530176 | K34: =J34 -> 0.27530176 | L34: =K34 -> 0.27530176 | M34: =L34 -> 0.27530176 | ... O34: =N34 -> 0.27530176
B35: Share issuance / (repurchases) | F35: 0 | G35: 0 | H35: 0 | I35: 0 | J35: 0 | K35: 0 | L35: 0 | M35: 0 | N35: 0 | O35: 0
A37: * | B37: Shareholder information | C37: =C31 -> 2022 | D37: =D31 -> 2023 | E37: =E31 -> 2024 | F37: =F31 -> 2025 | G37: =G31 -> 2026 | H37: =H31 -> 2027 | I37: =I31 -> 2028 | J37: =J31 -> 2029 | ... O37: =O31 -> 2034
B39: =B18 -> Dividend Payout Rate | C39: =C18 -> 1.7197359 | D39: =D18 -> 1.8426127 | E39: =E18 -> 2.1224048 | F39: =F18 -> 2.402197 | G39: =G18 -> 2.6819892 | H39: =H18 -> 2.9617813 | I39: =I18 -> 3.2415735 | ... O39: =O18 -> 4.9203265
B40: Basic WASO | C40: =C19 -> 4089 | D40: =D19 -> 4149 | E40: =E19 -> 4624 | F40: =F19 -> 4624 | G40: =G19 -> 4624 | H40: =H19 -> 4624 | I40: =I19 -> 4624 | J40: =J19 -> 4624 | ... O40: =O19 -> 4624
B41: Diluted WASO | C41: =C20 -> 4232 | D41: =D20 -> 4272 | E41: =E20 -> 4778 | F41: =F20 -> 4778 | G41: =G20 -> 4778 | H41: =H20 -> 4778 | I41: =I20 -> 4778 | J41: =J20 -> 4778 | ... O41: =O20 -> 4778
A43: * | B43: Balance Sheet - Assets | C43: =C37 -> 2022 | D43: =D37 -> 2023 | E43: =E37 -> 2024 | F43: =F37 -> 2025 | G43: =G37 -> 2026 | H43: =H37 -> 2027 | I43: =I37 -> 2028 | J43: =J37 -> 2029 | ... O43: =O37 -> 2034
B45: Operating Cash % of sales | C45: =BalSheet!C15/IncState!C17 -> 0.015 | D45: =BalSheet!D15/IncState!D17 -> 0.015 | E45: =BalSheet!E15/IncState!E17 -> 0.015 | F45: =E45 -> 0.015 | G45: =F45 -> 0.015 | H45: =G45 -> 0.015 | I45: =H45 -> 0.015 | J45: =I45 -> 0.015 | K45: =J45 -> 0.015 | L45: =K45 -> 0.015 | M45: =L45 -> 0.015 | ... O45: =N45 -> 0.015
B46: Accounts receivable % of sales | C46: =BalSheet!C17/IncState!C17 -> 0.089088335 | D46: =BalSheet!D17/IncState!D17 -> 0.088053826 | E46: =BalSheet!E17/IncState!E17 -> 0.085624539 | F46: =E46 -> 0.085624539 | G46: =F46 -> 0.085624539 | H46: =G46 -> 0.085624539 | I46: =H46 -> 0.085624539 | J46: =I46 -> 0.085624539 | K46: =J46 -> 0.085624539 | L46: =K46 -> 0.085624539 | M46: =L46 -> 0.085624539 | ... O46: =N46 -> 0.085624539
B47: Inventories % of COGS | C47: =BalSheet!C18/IncState!C18 -> 0.17329852 | D47: =BalSheet!D18/IncState!D18 -> 0.17060674 | E47: =BalSheet!E18/IncState!E18 -> 0.093562277 | F47: =E47 -> 0.093562277 | G47: =F47 -> 0.093562277 | H47: =G47 -> 0.093562277 | I47: =H47 -> 0.093562277 | J47: =I47 -> 0.093562277 | K47: =J47 -> 0.093562277 | L47: =K47 -> 0.093562277 | M47: =L47 -> 0.093562277 | ... O47: =N47 -> 0.093562277
B48: Other current assets % of sales | C48: =BalSheet!C19/IncState!C17 -> 0.036291901 | D48: =BalSheet!D19/IncState!D17 -> 0.044836539 | E48: =BalSheet!E19/IncState!E17 -> 0.078935122 | F48: =E48 -> 0.078935122 | G48: =F48 -> 0.078935122 | H48: =G48 -> 0.078935122 | I48: =H48 -> 0.078935122 | J48: =I48 -> 0.078935122 | K48: =J48 -> 0.078935122 | L48: =K48 -> 0.078935122 | M48: =L48 -> 0.078935122 | ... O48: =N48 -> 0.078935122
B49: Other long-term assets % of sales | C49: =BalSheet!C24/IncState!C17 -> 0.054121616 | D49: =BalSheet!D24/IncState!D17 -> 0.065328457 | E49: =BalSheet!E24/IncState!E17 -> 0.098363517 | F49: =E49 -> 0.098363517 | G49: =F49 -> 0.098363517 | H49: =G49 -> 0.098363517 | I49: =H49 -> 0.098363517 | J49: =I49 -> 0.098363517 | K49: =J49 -> 0.098363517 | L49: =K49 -> 0.098363517 | M49: =L49 -> 0.098363517 | ... O49: =N49 -> 0.098363517
A51: * | B51: Balance Sheet - Liabilities | C51: =C43 -> 2022 | D51: =D43 -> 2023 | E51: =E43 -> 2024 | F51: =F43 -> 2025 | G51: =G43 -> 2026 | H51: =H43 -> 2027 | I51: =I43 -> 2028 | J51: =J43 -> 2029 | ... O51: =O43 -> 2034
B53: Accounts payable % of COGS | C53: =BalSheet!C30/IncState!C18 -> 0.089845157 | D53: =BalSheet!D30/IncState!D18 -> 0.10876404 | E53: =BalSheet!E30/IncState!E18 -> 0.08835256 | F53: =E53 -> 0.08835256 | G53: =F53 -> 0.08835256 | H53: =G53 -> 0.08835256 | I53: =H53 -> 0.08835256 | J53: =I53 -> 0.08835256 | K53: =J53 -> 0.08835256 | L53: =K53 -> 0.08835256 | M53: =L53 -> 0.08835256 | ... O53: =N53 -> 0.08835256
...

Sheet Calcs
A1: =CoName -> Broadcom Inc. | C1: Hist. | D1: Hist. | E1: Hist. | F1: Proj. | G1: Proj. | H1: Proj. | I1: Proj. | J1: Proj. | K1: Proj. | L1: Proj. | M1: Proj. | N1: Proj. | O1: Proj.
A2: Net PP&E | C2: 2022 | D2: =C2+1 -> 2023 | E2: =D2+1 -> 2024 | F2: =E2+1 -> 2025 | G2: =F2+1 -> 2026 | H2: =G2+1 -> 2027 | I2: =H2+1 -> 2028 | J2: =I2+1 -> 2029 | K2: =J2+1 -> 2030 | ... O2: =N2+1 -> 2034
B3: Capital expenditure % of sales | F3: =Assumptions!F33 -> 0.010625509 | G3: =Assumptions!G33 -> 0.010625509 | H3: =Assumptions!H33 -> 0.010625509 | I3: =Assumptions!I33 -> 0.010625509 | J3: =Assumptions!J33 -> 0.010625509 | K3: =Assumptions!K33 -> 0.010625509 | L3: =Assumptions!L33 -> 0.010625509 | M3: =Assumptions!M33 -> 0.010625509 | ... O3: =Assumptions!O33 -> 0.010625509
B4: Depreciation % of PP&E | F4: =Assumptions!F34 -> 0.27530176 | G4: =F4 -> 0.27530176 | H4: =G4 -> 0.27530176 | I4: =H4 -> 0.27530176 | J4: =I4 -> 0.27530176 | K4: =J4 -> 0.27530176 | L4: =K4 -> 0.27530176 | M4: =L4 -> 0.27530176 | N4: =M4 -> 0.27530176 | O4: =N4 -> 0.27530176
B6: Beginning PP&E | F6: =E9 -> 2521 | G6: =F9 -> 2531.8854 | H6: =G9 -> 2817.4866 | I6: =H9 -> 3319.2514 | J6: =I9 -> 4059.7195 | K6: =J9 -> 5076.0719 | L6: =K9 -> 6420.8109 | M6: =L9 -> 8163.1542 | ... O6: =N9 -> 13213.97
B7: Capex | F7: =F3*IncState!F17 -> 704.92113 | G7: =G3*IncState!G17 -> 982.63372 | H7: =H3*IncState!H17 -> 1277.4238 | I7: =I3*IncState!I17 -> 1654.2639 | J7: =J3*IncState!J17 -> 2134.0004 | K7: =K3*IncState!K17 -> 2742.1905 | L7: =L3*IncState!L17 -> 3510.0038 | M7: =M3*IncState!M17 -> 4475.2549 | ... O7: =O3*IncState!O17 -> 7189.7207
B8: Depreciation | F8: =F6*F4 -> 694.03575 | G8: =G6*G4 -> 697.03251 | H8: =H6*H4 -> 775.65903 | I8: =I6*I4 -> 913.79576 | J8: =J6*J4 -> 1117.6479 | K8: =K6*K4 -> 1397.4516 | L8: =L6*L4 -> 1767.6606 | M8: =M6*M4 -> 2247.3307 | ... O8: =O6*O4 -> 3637.8292
B9: Ending PP&E | E9: =BalSheet!E22 -> 2521 | F9: =F6+F7-F8 -> 2531.8854 | G9: =G6+G7-G8 -> 2817.4866 | H9: =H6+H7-H8 -> 3319.2514 | I9: =I6+I7-I8 -> 4059.7195 | J9: =J6+J7-J8 -> 5076.0719 | K9: =K6+K7-K8 -> 6420.8109 | L9: =L6+L7-L8 -> 8163.1542 | M9: =M6+M7-M8 -> 10391.078 | ... O9: =O6+O7-O8 -> 16765.861
A10: Equity | C10: =C2 -> 2022 | D10: =D2 -> 2023 | E10: =E2 -> 2024 | F10: =F2 -> 2025 | G10: =G2 -> 2026 | H10: =H2 -> 2027 | I10: =I2 -> 2028 | J10: =J2 -> 2029 | ... O10: =O2 -> 2034
B11: Share issuance/(repurchases) | F11: =Assumptions!F35 -> 0 | G11: =Assumptions!G35 -> 0 | H11: =Assumptions!H35 -> 0 | I11: =Assumptions!I35 -> 0 | J11: =Assumptions!J35 -> 0 | K11: =Assumptions!K35 -> 0 | L11: =Assumptions!L35 -> 0 | M11: =Assumptions!M35 -> 0 | ... O11: =Assumptions!O35 -> 0
B13: Beginning balance | F13: =E17 -> 67678 | G13: =F17 -> 72067.572 | H13: =G17 -> 81268.754 | I13: =H17 -> 95656.987 | J13: =I17 -> 117036.1 | K13: =J17 -> 147668.21 | L13: =K17 -> 190377.31 | M13: =L17 -> 248672.64 | ... O13: =N17 -> 430387.4
B14: Net income | F14: =IncState!F36 -> 15497.331 | G14: =IncState!G36 -> 21602.7 | H14: =IncState!H36 -> 28083.51 | I14: =IncState!I36 -> 36368.146 | J14: =IncState!J36 -> 46914.908 | K14: =IncState!K36 -> 60285.657 | L14: =IncState!L36 -> 77165.641 | M14: =IncState!M36 -> 98386.192 | ... O14: =IncState!O36 -> 158062.34
B15: Dividends paid | F15: =-IncState!F38 -> -11107.759 | G15: =-IncState!G38 -> -12401.518 | H15: =-IncState!H38 -> -13695.277 | I15: =-IncState!I38 -> -14989.036 | J15: =-IncState!J38 -> -16282.795 | K15: =-IncState!K38 -> -17576.554 | L15: =-IncState!L38 -> -18870.313 | M15: =-IncState!M38 -> -20164.072 | ... O15: =-IncState!O38 -> -22751.59
B16: Share issuance / (repurchase) | F16: =F11 -> 0 | G16: =G11 -> 0 | H16: =H11 -> 0 | I16: =I11 -> 0 | J16: =J11 -> 0 | K16: =K11 -> 0 | L16: =L11 -> 0 | M16: =M11 -> 0 | ... O16: =O11 -> 0
B17: Ending balance | E17: =BalSheet!E38 -> 67678 | F17: =SUM(F13:F16) -> 72067.572 | G17: =SUM(G13:G16) -> 81268.754 | H17: =SUM(H13:H16) -> 95656.987 | I17: =SUM(I13:I16) -> 117036.1 | J17: =SUM(J13:J16) -> 147668.21 | K17: =SUM(K13:K16) -> 190377.31 | L17: =SUM(L13:L16) -> 248672.64 | M17: =SUM(M13:M16) -> 326894.76 | ... O17: =SUM(O13:O16) -> 565698.14
A18: OWC | C18: =C10 -> 2022 | D18: =D10 -> 2023 | E18: =E10 -> 2024 | F18: =F10 -> 2025 | G18: =G10 -> 2026 | H18: =H10 -> 2027 | I18: =I10 -> 2028 | J18: =J10 -> 2029 | ... O18: =O10 -> 2034
B19: Operating Cash | E19: =BalSheet!E15 -> 773.61 | F19: =BalSheet!F15 -> 995.1351 | G19: =BalSheet!G15 -> 1387.1812 | H19: =BalSheet!H15 -> 1803.3355 | I19: =BalSheet!I15 -> 2335.3195 | J19: =BalSheet!J15 -> 3012.5621 | K19: =BalSheet!K15 -> 3871.1423 | L19: =BalSheet!L15 -> 4955.0622 | ... O19: =BalSheet!O15 -> 10149.708
B20: =BalSheet!B18 -> Inventories | E20: =BalSheet!E18 -> 1760 | F20: =BalSheet!F18 -> 2263.9803 | G20: =BalSheet!G18 -> 3155.9039 | H20: =BalSheet!H18 -> 4102.6751 | I20: =BalSheet!I18 -> 5312.9642 | J20: =BalSheet!J18 -> 6853.7239 | K20: =BalSheet!K18 -> 8807.0352 | L20: =BalSheet!L18 -> 11273.005 | ... O20: =BalSheet!O18 -> 23091.074
B21: =BalSheet!B17 -> Accounts receivable | E21: =BalSheet!E17 -> 4416 | F21: =BalSheet!F17 -> 5680.5323 | G21: =BalSheet!G17 -> 7918.4498 | H21: =BalSheet!H17 -> 10293.985 | I21: =BalSheet!I17 -> 13330.71 | J21: =BalSheet!J17 -> 17196.616 | K21: =BalSheet!K17 -> 22097.652 | L21: =BalSheet!L17 -> 28284.994 | ... O21: =BalSheet!O17 -> 57937.604
B22: Other current assets | E22: =BalSheet!E19 -> 4071 | F22: =BalSheet!F19 -> 5236.7407 | G22: =BalSheet!G19 -> 7299.8209 | H22: =BalSheet!H19 -> 9489.7672 | I22: =BalSheet!I19 -> 12289.249 | J22: =BalSheet!J19 -> 15853.131 | K22: =BalSheet!K19 -> 20371.273 | L22: =BalSheet!L19 -> 26075.229 | ... O22: =BalSheet!O19 -> 53411.228
B23: Accounts payables | E23: =BalSheet!E30 -> 1662 | F23: =BalSheet!F30 -> 2137.9177 | G23: =BalSheet!G30 -> 2980.1774 | H23: =BalSheet!H30 -> 3874.2307 | I23: =BalSheet!I30 -> 5017.1287 | J23: =BalSheet!J30 -> 6472.0961 | K23: =BalSheet!K30 -> 8316.6434 | L23: =BalSheet!L30 -> 10645.304 | ... O23: =BalSheet!O30 -> 21805.321
B24: Other current liabilities | E24: =BalSheet!E31 -> 13764 | F24: =BalSheet!F31 -> 17705.355 | G24: =BalSheet!G31 -> 24680.603 | H24: =BalSheet!H31 -> 32084.784 | I24: =BalSheet!I31 -> 41549.795 | J24: =BalSheet!J31 -> 53599.236 | K24: =BalSheet!K31 -> 68875.018 | L24: =BalSheet!L31 -> 88160.023 | ... O24: =BalSheet!O31 -> 180582.69
A25: * | B25: OWC | E25: =SUM(E19:E22)-SUM(E23:E24) -> -4405.39 | F25: =SUM(F19:F22)-SUM(F23:F24) -> -5666.8841 | G25: =SUM(G19:G22)-SUM(G23:G24) -> -7899.4247 | H25: =SUM(H19:H22)-SUM(H23:H24) -> -10269.252 | I25: =SUM(I19:I22)-SUM(I23:I24) -> -13298.682 | J25: =SUM(J19:J22)-SUM(J23:J24) -> -17155.299 | K25: =SUM(K19:K22)-SUM(K23:K24) -> -22044.559 | L25: =SUM(L19:L22)-SUM(L23:L24) -> -28217.036 | ... O25: =SUM(O19:O22)-SUM(O23:O24) -> -57798.401
B26: Change in OWC | F26: =E25-F25 -> 1261.4941 | G26: =F25-G25 -> 2232.5407 | H26: =G25-H25 -> 2369.8274 | I26: =H25-I25 -> 3029.4294 | J26: =I25-J25 -> 3856.6177 | K26: =J25-K25 -> 4889.2603 | L26: =K25-L25 -> 6172.4767 | M26: =L25-M25 -> 7759.6849 | ... O26: =N25-O25 -> 12107.965

Sheet Debt
A1: =CoName -> Broadcom Inc. | C1: Hist. | D1: Hist. | E1: Hist. | F1: Proj. | G1: Proj. | H1: Proj. | I1: Proj. | J1: Proj. | K1: Proj. | L1: Proj. | M1: Proj. | N1: Proj. | O1: Proj.
A2: Assumptions | C2: 2022 | D2: =C2 -> 2022 | E2: =D2 -> 2022 | F2: =E2 -> 2022 | G2: =F2 -> 2022 | H2: =G2 -> 2022 | I2: =H2 -> 2022 | J2: =I2 -> 2022 | K2: =J2 -> 2022 | ... O2: =N2 -> 2022
B4: Interest rate on revolver | F4: =Assumptions!F24 -> 0 | G4: =Assumptions!G24 -> 0 | H4: =Assumptions!H24 -> 0 | I4: =Assumptions!I24 -> 0 | J4: =Assumptions!J24 -> 0 | K4: =Assumptions!K24 -> 0 | L4: =Assumptions!L24 -> 0 | M4: =Assumptions!M24 -> 0 | ... O4: =Assumptions!O24 -> 0
B5: Interest rate on long-term debt | F5: =Assumptions!F25 -> 0.04474 | G5: =Assumptions!G25 -> 0.04474 | H5: =Assumptions!H25 -> 0.04474 | I5: =Assumptions!I25 -> 0.04474 | J5: =Assumptions!J25 -> 0.04474 | K5: =Assumptions!K25 -> 0.04474 | L5: =Assumptions!L25 -> 0.04474 | M5: =Assumptions!M25 -> 0.04474 | ... O5: =Assumptions!O25 -> 0.04474
B6: Interest rate on cash | F6: =Assumptions!F26 -> 0.05 | G6: =Assumptions!G26 -> 0.05 | H6: =Assumptions!H26 -> 0.05 | I6: =Assumptions!I26 -> 0.05 | J6: =Assumptions!J26 -> 0.05 | K6: =Assumptions!K26 -> 0.05 | L6: =Assumptions!L26 -> 0.05 | M6: =Assumptions!M26 -> 0.05 | ... O6: =Assumptions!O26 -> 0.05
B8: Issuance of long-term debt | F8: =Assumptions!F28 -> 0 | G8: =Assumptions!G28 -> 0 | H8: =Assumptions!H28 -> 0 | I8: =Assumptions!I28 -> 0 | J8: =Assumptions!J28 -> 0 | K8: =Assumptions!K28 -> 0 | L8: =Assumptions!L28 -> 0 | M8: =Assumptions!M28 -> 0 | ... O8: =Assumptions!O28 -> 0
B9: Repayment of long-term debt | F9: -1271 | G9: =Assumptions!G29 -> 0 | H9: =Assumptions!H29 -> 0 | I9: =Assumptions!I29 -> 0 | J9: =Assumptions!J29 -> 0 | K9: =Assumptions!K29 -> 0 | L9: =Assumptions!L29 -> 0 | M9: =Assumptions!M29 -> 0 | N9: =Assumptions!N29 -> 0 | O9: =Assumptions!O29 -> 0
A11: Revolver | C11: =C2 -> 2022 | D11: =D2 -> 2022 | E11: =E2 -> 2022 | F11: =F2 -> 2022 | G11: =G2 -> 2022 | H11: =H2 -> 2022 | I11: =I2 -> 2022 | J11: =J2 -> 2022 | ... O11: =O2 -> 2022
B12: Balance | F12: NO REVOLVER | G12: NO REVOLVER | H12: NO REVOLVER | I12: NO REVOLVER | J12: NO REVOLVER | K12: NO REVOLVER | L12: NO REVOLVER | M12: NO REVOLVER | N12: NO REVOLVER | O12: NO REVOLVER
B13: Interest rate
B14: Interest expense
A16: Long term debt | C16: =C11 -> 2022 | D16: =D11 -> 2022 | E16: =E11 -> 2022 | F16: =F11 -> 2022 | G16: =G11 -> 2022 | H16: =H11 -> 2022 | I16: =I11 -> 2022 | J16: =J11 -> 2022 | ... O16: =O11 -> 2022
B17: Beginning balance | F17: =E20 -> 67566 | G17: =F20 -> 66295 | H17: =G20 -> 66295 | I17: =H20 -> 66295 | J17: =I20 -> 66295 | K17: =J20 -> 66295 | L17: =K20 -> 66295 | M17: =L20 -> 66295 | ... O17: =N20 -> 66295
B18: Issuance | F18: =F8 -> 0 | G18: =G8 -> 0 | H18: =H8 -> 0 | I18: =I8 -> 0 | J18: =J8 -> 0 | K18: =K8 -> 0 | L18: =L8 -> 0 | M18: =M8 -> 0 | ... O18: =O8 -> 0
B19: Repayment | F19: =F9 -> -1271 | G19: =G9 -> 0 | H19: =H9 -> 0 | I19: =I9 -> 0 | J19: =J9 -> 0 | K19: =K9 -> 0 | L19: =L9 -> 0 | M19: =M9 -> 0 | ... O19: =O9 -> 0
B20: Ending balance | E20: =BalSheet!E34 -> 67566 | F20: =SUM(F17:F19) -> 66295 | G20: =SUM(G17:G19) -> 66295 | H20: =SUM(H17:H19) -> 66295 | I20: =SUM(I17:I19) -> 66295 | J20: =SUM(J17:J19) -> 66295 | K20: =SUM(K17:K19) -> 66295 | L20: =SUM(L17:L19) -> 66295 | M20: =SUM(M17:M19) -> 66295 | ... O20: =SUM(O17:O19) -> 66295
B21: Interest rate | F21: =F5 -> 0.04474 | G21: =G5 -> 0.04474 | H21: =H5 -> 0.04474 | I21: =I5 -> 0.04474 | J21: =J5 -> 0.04474 | K21: =K5 -> 0.04474 | L21: =L5 -> 0.04474 | M21: =M5 -> 0.04474 | ... O21: =O5 -> 0.04474
B22: Interest expense | F22: =F20*F21 -> 2966.0383 | G22: =G20*G21 -> 2966.0383 | H22: =H20*H21 -> 2966.0383 | I22: =I20*I21 -> 2966.0383 | J22: =J20*J21 -> 2966.0383 | K22: =K20*K21 -> 2966.0383 | L22: =L20*L21 -> 2966.0383 | M22: =M20*M21 -> 2966.0383 | ... O22: =O20*O21 -> 2966.0383
A24: Debt summary | C24: =C16 -> 2022 | D24: =D16 -> 2022 | E24: =E16 -> 2022 | F24: =F16 -> 2022 | G24: =G16 -> 2022 | H24: =H16 -> 2022 | I24: =I16 -> 2022 | J24: =J16 -> 2022 | ... O24: =O16 -> 2022
B25: Revolver | F25: =F12 -> NO REVOLVER | G25: =G12 -> NO REVOLVER | H25: =H12 -> NO REVOLVER | I25: =I12 -> NO REVOLVER | J25: =J12 -> NO REVOLVER | K25: =K12 -> NO REVOLVER | L25: =L12 -> NO REVOLVER | M25: =M12 -> NO REVOLVER | ... O25: =O12 -> NO REVOLVER
B26: Total long term debt | F26: =F20 -> 66295 | G26: =G20 -> 66295 | H26: =H20 -> 66295 | I26: =I20 -> 66295 | J26: =J20 -> 66295 | K26: =K20 -> 66295 | L26: =L20 -> 66295 | M26: =M20 -> 66295 | ... O26: =O20 -> 66295
B27: Total debt | F27: =SUM(F25:F26) -> 66295 | G27: =SUM(G25:G26) -> 66295 | H27: =SUM(H25:H26) -> 66295 | I27: =SUM(I25:I26) -> 66295 | J27: =SUM(J25:J26) -> 66295 | K27: =SUM(K25:K26) -> 66295 | L27: =SUM(L25:L26) -> 66295 | M27: =SUM(M25:M26) -> 66295 | ... O27: =SUM(O25:O26) -> 66295
B28: Total interest expense | F28: =F22 -> 2966.0383 | G28: =G22 -> 2966.0383 | H28: =H22 -> 2966.0383 | I28: =I22 -> 2966.0383 | J28: =J22 -> 2966.0383 | K28: =K22 -> 2966.0383 | L28: =L22 -> 2966.0383 | M28: =M22 -> 2966.0383 | ... O28: =O22 -> 2966.0383
A30: Interest income | C30: =C11 -> 2022 | D30: =D11 -> 2022 | E30: =E11 -> 2022 | F30: =F11 -> 2022 | G30: =G11 -> 2022 | H30: =H11 -> 2022 | I30: =I11 -> 2022 | J30: =J11 -> 2022 | ... O30: =O11 -> 2022
B31: Excess Cash | F31: =BalSheet!F16 -> 20703.407 | G31: =BalSheet!G16 -> 41793.988 | H31: =BalSheet!H16 -> 68301.323 | I31: =BalSheet!I16 -> 103703.02 | J31: =BalSheet!J16 -> 150768.3 | K31: =BalSheet!K16 -> 212935.89 | L31: =BalSheet!L16 -> 294459.61 | M31: =BalSheet!M16 -> 400579.32 | ... O31: =BalSheet!O16 -> 703878.21
B32: Interest rate | F32: =F6 -> 0.05 | G32: =G6 -> 0.05 | H32: =H6 -> 0.05 | I32: =I6 -> 0.05 | J32: =J6 -> 0.05 | K32: =K6 -> 0.05 | L32: =L6 -> 0.05 | M32: =M6 -> 0.05 | ... O32: =O6 -> 0.05
B33: Interest income | F33: =F31*F32 -> 1035.1704 | G33: =G31*G32 -> 2089.6994 | H33: =H31*H32 -> 3415.0661 | I33: =I31*I32 -> 5185.151 | J33: =J31*J32 -> 7538.4149 | K33: =K31*K32 -> 10646.795 | L33: =L31*L32 -> 14722.981 | M33: =M31*M32 -> 20028.966 | ... O33: =O31*O32 -> 35193.911

Sheet IncState
A1: =CoName -> Broadcom Inc. | C1: Hist. | D1: Hist. | E1: Hist. | F1: Proj. | G1: Proj. | H1: Proj. | I1: Proj. | J1: Proj. | K1: Proj. | L1: Proj. | M1: Proj. | N1: Proj. | O1: Proj.
A2: Assumptions | C2: 2022 | D2: =C2+1 -> 2023 | E2: =D2+1 -> 2024 | F2: =E2+1 -> 2025 | G2: =F2+1 -> 2026 | H2: =G2+1 -> 2027 | I2: =H2+1 -> 2028 | J2: =I2+1 -> 2029 | K2: =J2+1 -> 2030 | ... O2: =N2+1 -> 2034
B4: Revenue growth | F4: =Assumptions!F10 -> 0.28635242 | G4: =Assumptions!G10 -> 0.39396265 | H4: =Assumptions!H10 -> 0.3 | I4: =Assumptions!I10 -> 0.295 | J4: =Assumptions!J10 -> 0.29 | K4: =Assumptions!K10 -> 0.285 | L4: =Assumptions!L10 -> 0.28 | M4: =Assumptions!M10 -> 0.275 | ... O4: =Assumptions!O10 -> 0.265
B5: Cost of goods sold as % of sales | F5: =Assumptions!F11 -> 0.36473805 | G5: =Assumptions!G11 -> 0.36473805 | H5: =Assumptions!H11 -> 0.36473805 | I5: =Assumptions!I11 -> 0.36473805 | J5: =Assumptions!J11 -> 0.36473805 | K5: =Assumptions!K11 -> 0.36473805 | L5: =Assumptions!L11 -> 0.36473805 | M5: =Assumptions!M11 -> 0.36473805 | ... O5: =Assumptions!O11 -> 0.36473805
B6: R&D % of sales | F6: =Assumptions!F12 -> 0.18051731 | G6: =Assumptions!G12 -> 0.18051731 | H6: =Assumptions!H12 -> 0.18051731 | I6: =Assumptions!I12 -> 0.18051731 | J6: =Assumptions!J12 -> 0.18051731 | K6: =Assumptions!K12 -> 0.18051731 | L6: =Assumptions!L12 -> 0.18051731 | M6: =Assumptions!M12 -> 0.18051731 | ... O6: =Assumptions!O12 -> 0.18051731
B7: SG&A % of sales | F7: =Assumptions!F13 -> 0.15905301 | G7: =Assumptions!G13 -> 0.15905301 | H7: =Assumptions!H13 -> 0.15905301 | I7: =Assumptions!I13 -> 0.15905301 | J7: =Assumptions!J13 -> 0.15905301 | K7: =Assumptions!K13 -> 0.15905301 | L7: =Assumptions!L13 -> 0.15905301 | M7: =Assumptions!M13 -> 0.15905301 | ... O7: =Assumptions!O13 -> 0.15905301
B8: Amortization amount | F8: =Assumptions!F14 -> 4924.375 | G8: =Assumptions!G14 -> 4924.375 | H8: =Assumptions!H14 -> 4924.375 | I8: =Assumptions!I14 -> 4924.375 | J8: =Assumptions!J14 -> 4924.375 | K8: =Assumptions!K14 -> 4924.375 | L8: =Assumptions!L14 -> 4924.375 | M8: =Assumptions!M14 -> 4924.375 | ... O8: =Assumptions!O14 -> 0
B9: Non recurring items, amount | F9: =Assumptions!F15 -> 0 | G9: =Assumptions!G15 -> 0 | H9: =Assumptions!H15 -> 0 | I9: =Assumptions!I15 -> 0 | J9: =Assumptions!J15 -> 0 | K9: =Assumptions!K15 -> 0 | L9: =Assumptions!L15 -> 0 | M9: =Assumptions!M15 -> 0 | ... O9: =Assumptions!O15 -> 0
B10: Other income (expense), amt | F10: =Assumptions!F16 -> 0 | G10: =Assumptions!G16 -> 0 | H10: =Assumptions!H16 -> 0 | I10: =Assumptions!I16 -> 0 | J10: =Assumptions!J16 -> 0 | K10: =Assumptions!K16 -> 0 | L10: =Assumptions!L16 -> 0 | M10: =Assumptions!M16 -> 0 | ... O10: =Assumptions!O16 -> 0
B11: Effective tax rate | F11: =Assumptions!F17 -> 0.21 | G11: =Assumptions!G17 -> 0.21 | H11: =Assumptions!H17 -> 0.21 | I11: =Assumptions!I17 -> 0.21 | J11: =Assumptions!J17 -> 0.21 | K11: =Assumptions!K17 -> 0.21 | L11: =Assumptions!L17 -> 0.21 | M11: =Assumptions!M17 -> 0.21 | ... O11: =Assumptions!O17 -> 0.21
B12: Dividend Payout Rate | F12: =Assumptions!F18 -> 2.402197 | G12: =Assumptions!G18 -> 2.6819892 | H12: =Assumptions!H18 -> 2.9617813 | I12: =Assumptions!I18 -> 3.2415735 | J12: =Assumptions!J18 -> 3.5213657 | K12: =Assumptions!K18 -> 3.8011578 | L12: =Assumptions!L18 -> 4.08095 | M12: =Assumptions!M18 -> 4.3607422 | ... O12: =Assumptions!O18 -> 4.9203265
B13: Basic WASO | F13: =Assumptions!F19 -> 4624 | G13: =Assumptions!G19 -> 4624 | H13: =Assumptions!H19 -> 4624 | I13: =Assumptions!I19 -> 4624 | J13: =Assumptions!J19 -> 4624 | K13: =Assumptions!K19 -> 4624 | L13: =Assumptions!L19 -> 4624 | M13: =Assumptions!M19 -> 4624 | ... O13: =Assumptions!O19 -> 4624
B14: Diluted WASO | F14: =Assumptions!F20 -> 4778 | G14: =Assumptions!G20 -> 4778 | H14: =Assumptions!H20 -> 4778 | I14: =Assumptions!I20 -> 4778 | J14: =Assumptions!J20 -> 4778 | K14: =Assumptions!K20 -> 4778 | L14: =Assumptions!L20 -> 4778 | M14: =Assumptions!M20 -> 4778 | ... O14: =Assumptions!O20 -> 4778
A16: Income statement | C16: =C39 -> 44926 | D16: =D39 -> 45291 | E16: =E39 -> 45657 | F16: =F39 -> 2025 | G16: =G2 -> 2026 | H16: =H2 -> 2027 | I16: =I2 -> 2028 | J16: =J2 -> 2029 | K16: =K2 -> 2030 | L16: =L2 -> 2031 | M16: =M2 -> 2032 | N16: =N2 -> 2033 | O16: =O2 -> 2034
B17: Revenue | C17: 33203 | D17: 35819 | E17: 51574 | F17: =E17*(1+F4) -> 66342.34 | G17: =F17*(1+G4) -> 92478.743 | H17: =G17*(1+H4) -> 120222.37 | I17: =H17*(1+I4) -> 155687.96 | J17: =I17*(1+J4) -> 200837.47 | K17: =J17*(1+K4) -> 258076.15 | L17: =K17*(1+L4) -> 330337.48 | M17: =L17*(1+M4) -> 421180.28 | ... O17: =N17*(1+O4) -> 676647.19
B18: COGS | C18: 11108 | D18: =11129-4 -> 11125 | E18: =19065-254 -> 18811 | F18: =F17*F5 -> 24197.575 | G18: =G17*G5 -> 33730.516 | H18: =H17*H5 -> 43849.671 | I18: =I17*I5 -> 56785.324 | J18: =J17*J5 -> 73253.068 | K18: =K17*K5 -> 94130.192 | L18: =L17*L5 -> 120486.65 | M18: =M17*M5 -> 153620.47 | ... O18: =O17*O5 -> 246798.97
B19: R&D | C19: 4919 | D19: 5253 | E19: 9310 | F19: =F6*F17 -> 11975.941 | G19: =G6*G17 -> 16694.014 | H19: =H6*H17 -> 21702.219 | I19: =I6*I17 -> 28104.373 | J19: =J6*J17 -> 36254.642 | K19: =K6*K17 -> 46587.214 | L19: =L6*L17 -> 59631.635 | M19: =M6*M17 -> 76030.334 | ... O19: =O6*O17 -> 122146.53
B20: SG&A | C20: =1382+1512+57 -> 2951 | D20: =1592+1394 -> 2986 | E20: =4959+3244 -> 8203 | F20: =F17*F7 -> 10551.949 | G20: =G17*G7 -> 14709.023 | H20: =H17*H7 -> 19121.729 | I20: =I17*I7 -> 24762.64 | J20: =J17*J7 -> 31943.805 | K20: =K17*K7 -> 41047.79 | L20: =L17*L7 -> 52541.171 | M20: =M17*M7 -> 66989.992 | ... O20: =O17*O7 -> 107622.77
A21: * | B21: EBIT | C21: =C17-SUM(C18:C20) -> 14225 | D21: =D17-SUM(D18:D20) -> 16455 | E21: =E17-SUM(E18:E20) -> 15250 | F21: =F17-SUM(F18:F20) -> 19616.874 | G21: =G17-SUM(G18:G20) -> 27345.19 | H21: =H17-SUM(H18:H20) -> 35548.747 | I21: =I17-SUM(I18:I20) -> 46035.628 | J21: =J17-SUM(J18:J20) -> 59385.96 | ... O21: =O17-SUM(O18:O20) -> 200078.91
B23: Depreciation | C23: 529 | D23: 502 | E23: 593 | F23: =Calcs!F8 -> 694.03575 | G23: =Calcs!G8 -> 697.03251 | H23: =Calcs!H8 -> 775.65903 | I23: =Calcs!I8 -> 913.79576 | J23: =Calcs!J8 -> 1117.6479 | K23: =Calcs!K8 -> 1397.4516 | L23: =Calcs!L8 -> 1767.6606 | M23: =Calcs!M8 -> 2247.3307 | ... O23: =Calcs!O8 -> 3637.8292
B24: Amortization | C24: 4455 | D24: 3333 | E24: 9417 | F24: =F8 -> 4924.375 | G24: =G8 -> 4924.375 | H24: =H8 -> 4924.375 | I24: =I8 -> 4924.375 | J24: =J8 -> 4924.375 | K24: =K8 -> 4924.375 | L24: =L8 -> 4924.375 | M24: =M8 -> 4924.375 | ... O24: =O8 -> 0
A25: * | B25: EBITDA | C25: =SUM(C21,C23:C24) -> 19209 | D25: =SUM(D21,D23:D24) -> 20290 | E25: =SUM(E21,E23:E24) -> 25260 | F25: =SUM(F21,F23:F24) -> 25235.285 | G25: =SUM(G21,G23:G24) -> 32966.598 | H25: =SUM(H21,H23:H24) -> 41248.781 | I25: =SUM(I21,I23:I24) -> 51873.798 | J25: =SUM(J21,J23:J24) -> 65427.983 | ... O25: =SUM(O21,O23:O24) -> 203716.74
B27: Non-recurring items | C27: =-5-57 -> -62 | D27: =-244-4 -> -248 | E27: =-254-1533 -> -1787 | F27: =F9 -> 0 | G27: =G9 -> 0 | H27: =H9 -> 0 | I27: =I9 -> 0 | J27: =J9 -> 0 | K27: =K9 -> 0 | L27: =L9 -> 0 | M27: =M9 -> 0 | ... O27: =O9 -> 0
B28: Other income (expense) | C28: -54 | D28: 512 | E28: 406 | F28: =F10 -> 0 | G28: =G10 -> 0 | H28: =H10 -> 0 | I28: =I10 -> 0 | J28: =J10 -> 0 | K28: =K10 -> 0 | L28: =L10 -> 0 | M28: =M10 -> 0 | ... O28: =O10 -> 0
B30: Interest income | F30: =IF(circ=1,Debt!F33,0) -> 0 | G30: =IF(circ=1,Debt!G33,0) -> 0 | H30: =IF(circ=1,Debt!H33,0) -> 0 | I30: =IF(circ=1,Debt!I33,0) -> 0 | J30: =IF(circ=1,Debt!J33,0) -> 0 | K30: =IF(circ=1,Debt!K33,0) -> 0 | L30: =IF(circ=1,Debt!L33,0) -> 0 | M30: =IF(circ=1,Debt!M33,0) -> 0 | ... O30: =IF(circ=1,Debt!O33,0) -> 0
B31: Interest expense | C31: -1737 | D31: -1622 | E31: -3953 | F31: =IF(circ=1,Debt!F22,0) -> 0 | G31: =IF(circ=1,Debt!G22,0) -> 0 | H31: =IF(circ=1,Debt!H22,0) -> 0 | I31: =IF(circ=1,Debt!I22,0) -> 0 | J31: =IF(circ=1,Debt!J22,0) -> 0 | K31: =IF(circ=1,Debt!K22,0) -> 0 | L31: =IF(circ=1,Debt!L22,0) -> 0 | M31: =IF(circ=1,Debt!M22,0) -> 0 | ... O31: =IF(circ=1,Debt!O22,0) -> 0
A33: * | B33: Pretax Income | C33: =C21+SUM(C28:C31) -> 12434 | D33: =D21+SUM(D28:D31) -> 15345 | E33: =E21+SUM(E27:E31) -> 9916 | F33: =F21+SUM(F27:F31) -> 19616.874 | G33: =G21+SUM(G27:G31) -> 27345.19 | H33: =H21+SUM(H27:H31) -> 35548.747 | I33: =I21+SUM(I27:I31) -> 46035.628 | J33: =J21+SUM(J27:J31) -> 59385.96 | K33: =K21+SUM(K27:K31) -> 76310.958 | L33: =L21+SUM(L27:L31) -> 97678.026 | ... O33: =O21+SUM(O27:O31) -> 200078.91
B35: Tax expense | C35: 939 | D35: 1015 | E35: 3748 | F35: =F11*F33 -> 4119.5436 | G35: =G11*G33 -> 5742.4899 | H35: =H11*H33 -> 7465.2369 | I35: =I11*I33 -> 9667.4818 | J35: =J11*J33 -> 12471.052 | K35: =K11*K33 -> 16025.301 | L35: =L11*L33 -> 20512.386 | M35: =M11*M33 -> 26153.292 | ... O35: =O11*O33 -> 42016.571
A36: * | B36: Net income | C36: =C33-C35 -> 11495 | D36: =D33-D35 -> 14330 | E36: =E33-E35 -> 6168 | F36: =F33-F35 -> 15497.331 | G36: =G33-G35 -> 21602.7 | H36: =H33-H35 -> 28083.51 | I36: =I33-I35 -> 36368.146 | J36: =J33-J35 -> 46914.908 | ... O36: =O33-O35 -> 158062.34
B37: Dividend payout rate | C37: =C38/C40 -> 1.7197359 | D37: =D38/D40 -> 1.8426127 | E37: =E38/E40 -> 2.1224048 | F37: =F12 -> 2.402197 | G37: =G12 -> 2.6819892 | H37: =H12 -> 2.9617813 | I37: =I12 -> 3.2415735 | J37: =J12 -> 3.5213657 | K37: =K12 -> 3.8011578 | L37: =L12 -> 4.08095 | M37: =M12 -> 4.3607422 | ... O37: =O12 -> 4.9203265
B38: Dividends | C38: 7032 | D38: 7645 | E38: 9814 | F38: =F37*F40 -> 11107.759 | G38: =G37*G40 -> 12401.518 | H38: =H37*H40 -> 13695.277 | I38: =I37*I40 -> 14989.036 | J38: =J37*J40 -> 16282.795 | K38: =K37*K40 -> 17576.554 | L38: =L37*L40 -> 18870.313 | M38: =M37*M40 -> 20164.072 | ... O38: =O37*O40 -> 22751.59
A39: Shareholder information | C39: 44926 | D39: 45291 | E39: 45657 | F39: 2025 | G39: 2026 | H39: 2027 | I39: 2028 | J39: 2029 | K39: 2030 | L39: 2031 | M39: 2032 | N39: 2033 | O39: 2034
B40: Basic WASO | C40: 4089 | D40: 4149 | E40: 4624 | F40: =F13 -> 4624 | G40: =G13 -> 4624 | H40: =H13 -> 4624 | I40: =I13 -> 4624 | J40: =J13 -> 4624 | K40: =K13 -> 4624 | L40: =L13 -> 4624 | M40: =M13 -> 4624 | ... O40: =O13 -> 4624
B41: Diluted WASO | C41: 4232 | D41: 4272 | E41: 4778 | F41: =F14 -> 4778 | G41: =G14 -> 4778 | H41: =H14 -> 4778 | I41: =I14 -> 4778 | J41: =J14 -> 4778 | K41: =K14 -> 4778 | L41: =L14 -> 4778 | M41: =M14 -> 4778 | ... O41: =O14 -> 4778
B42: Basic earnings per share | C42: =C36/C40 -> 2.8112008 | D42: =D36/D40 -> 3.4538443 | E42: =E36/E40 -> 1.33391 | F42: =F36/F40 -> 3.3514989 | G42: =G36/G40 -> 4.6718642 | H42: =H36/H40 -> 6.0734235 | I42: =I36/I40 -> 7.8650834 | J42: =J36/J40 -> 10.145958 | ... O42: =O36/O40 -> 34.183031
A43: * | B43: Diluted earnings per share | C43: =C36/C41 -> 2.7162098 | D43: =D36/D41 -> 3.3544007 | E43: =E36/E41 -> 1.2909167 | F43: =F36/F41 -> 3.2434765 | G43: =G36/G41 -> 4.5212851 | H43: =H36/H41 -> 5.8776706 | I43: =I36/I41 -> 7.6115835 | J43: =J36/J41 -> 9.8189427 | ... O43: =O36/O41 -> 33.081276

Sheet BalSheet
A1: =CoName -> Broadcom Inc. | C1: Hist. | D1: Hist. | E1: Hist. | F1: Proj. | G1: Proj. | H1: Proj. | I1: Proj. | J1: Proj. | K1: Proj. | L1: Proj. | M1: Proj. | N1: Proj. | O1: Proj.
A2: Assumptions | C2: 2022 | D2: =C2+1 -> 2023 | E2: =D2+1 -> 2024 | F2: =E2+1 -> 2025 | G2: =F2+1 -> 2026 | H2: =G2+1 -> 2027 | I2: =H2+1 -> 2028 | J2: =I2+1 -> 2029 | K2: =J2+1 -> 2030 | ... O2: =N2+1 -> 2034
B4: Operating Cash % of sales | F4: =Assumptions!F45 -> 0.015 | G4: =F4 -> 0.015 | H4: =G4 -> 0.015 | I4: =H4 -> 0.015 | J4: =I4 -> 0.015 | K4: =J4 -> 0.015 | L4: =K4 -> 0.015 | M4: =L4 -> 0.015 | N4: =M4 -> 0.015 | O4: =N4 -> 0.015
B5: Accounts receivable % of sales | F5: =Assumptions!F46 -> 0.085624539 | G5: =Assumptions!G46 -> 0.085624539 | H5: =Assumptions!H46 -> 0.085624539 | I5: =Assumptions!I46 -> 0.085624539 | J5: =Assumptions!J46 -> 0.085624539 | K5: =Assumptions!K46 -> 0.085624539 | L5: =Assumptions!L46 -> 0.085624539 | M5: =Assumptions!M46 -> 0.085624539 | ... O5: =Assumptions!O46 -> 0.085624539
B6: Inventories % of COGS | F6: =Assumptions!F47 -> 0.093562277 | G6: =Assumptions!G47 -> 0.093562277 | H6: =Assumptions!H47 -> 0.093562277 | I6: =Assumptions!I47 -> 0.093562277 | J6: =Assumptions!J47 -> 0.093562277 | K6: =Assumptions!K47 -> 0.093562277 | L6: =Assumptions!L47 -> 0.093562277 | M6: =Assumptions!M47 -> 0.093562277 | ... O6: =Assumptions!O47 -> 0.093562277
B7: Other current assets % of sales | F7: =Assumptions!F48 -> 0.078935122 | G7: =Assumptions!G48 -> 0.078935122 | H7: =Assumptions!H48 -> 0.078935122 | I7: =Assumptions!I48 -> 0.078935122 | J7: =Assumptions!J48 -> 0.078935122 | K7: =Assumptions!K48 -> 0.078935122 | L7: =Assumptions!L48 -> 0.078935122 | M7: =Assumptions!M48 -> 0.078935122 | ... O7: =Assumptions!O48 -> 0.078935122
B8: Other long-term assets % of sales | F8: =Assumptions!F49 -> 0.098363517 | G8: =Assumptions!G49 -> 0.098363517 | H8: =Assumptions!H49 -> 0.098363517 | I8: =Assumptions!I49 -> 0.098363517 | J8: =Assumptions!J49 -> 0.098363517 | K8: =Assumptions!K49 -> 0.098363517 | L8: =Assumptions!L49 -> 0.098363517 | M8: =Assumptions!M49 -> 0.098363517 | ... O8: =Assumptions!O49 -> 0.098363517
B10: Accounts payable/Accural % of COGS | F10: =Assumptions!F53 -> 0.08835256 | G10: =Assumptions!G53 -> 0.08835256 | H10: =Assumptions!H53 -> 0.08835256 | I10: =Assumptions!I53 -> 0.08835256 | J10: =Assumptions!J53 -> 0.08835256 | K10: =Assumptions!K53 -> 0.08835256 | L10: =Assumptions!L53 -> 0.08835256 | M10: =Assumptions!M53 -> 0.08835256 | ... O10: =Assumptions!O53 -> 0.08835256
B11: Other current liabilities % of sales | F11: =Assumptions!F54 -> 0.26687866 | G11: =Assumptions!G54 -> 0.26687866 | H11: =Assumptions!H54 -> 0.26687866 | I11: =Assumptions!I54 -> 0.26687866 | J11: =Assumptions!J54 -> 0.26687866 | K11: =Assumptions!K54 -> 0.26687866 | L11: =Assumptions!L54 -> 0.26687866 | M11: =Assumptions!M54 -> 0.26687866 | ... O11: =Assumptions!O54 -> 0.26687866
B12: Other long-term liabilities % of sales | F12: =Assumptions!F55 -> 0.29035948 | G12: =Assumptions!G55 -> 0.29035948 | H12: =Assumptions!H55 -> 0.29035948 | I12: =Assumptions!I55 -> 0.29035948 | J12: =Assumptions!J55 -> 0.29035948 | K12: =Assumptions!K55 -> 0.29035948 | L12: =Assumptions!L55 -> 0.29035948 | M12: =Assumptions!M55 -> 0.29035948 | ... O12: =Assumptions!O55 -> 0.29035948
A14: Balance sheet | C14: =C2 -> 2022 | D14: =D2 -> 2023 | E14: =E2 -> 2024 | F14: =F2 -> 2025 | G14: =G2 -> 2026 | H14: =H2 -> 2027 | I14: =I2 -> 2028 | J14: =J2 -> 2029 | ... O14: =O2 -> 2034
B15: Operating Cash | C15: =1.5%*IncState!C17 -> 498.045 | D15: =1.5%*IncState!D17 -> 537.285 | E15: =1.5%*IncState!E17 -> 773.61 | F15: =F4*IncState!F17 -> 995.1351 | G15: =G4*IncState!G17 -> 1387.1812 | H15: =H4*IncState!H17 -> 1803.3355 | I15: =I4*IncState!I17 -> 2335.3195 | J15: =J4*IncState!J17 -> 3012.5621 | K15: =K4*IncState!K17 -> 3871.1423 | L15: =L4*IncState!L17 -> 4955.0622 | M15: =M4*IncState!M17 -> 6317.7043 | ... O15: =O4*IncState!O17 -> 10149.708
B16: Excess cash | C16: =12416-C15 -> 11917.955 | D16: =14189-D15 -> 13651.715 | E16: =9348-E15 -> 8574.39 | F16: =MAX(CashFlow!F23,0) -> 20703.407 | G16: =MAX(CashFlow!G23,0) -> 41793.988 | H16: =MAX(CashFlow!H23,0) -> 68301.323 | I16: =MAX(CashFlow!I23,0) -> 103703.02 | J16: =MAX(CashFlow!J23,0) -> 150768.3 | K16: =MAX(CashFlow!K23,0) -> 212935.89 | L16: =MAX(CashFlow!L23,0) -> 294459.61 | M16: =MAX(CashFlow!M23,0) -> 400579.32 | ... O16: =MAX(CashFlow!O23,0) -> 703878.21
B17: Accounts receivable | C17: 2958 | D17: 3154 | E17: 4416 | F17: =F5*IncState!F17 -> 5680.5323 | G17: =G5*IncState!G17 -> 7918.4498 | H17: =H5*IncState!H17 -> 10293.985 | I17: =I5*IncState!I17 -> 13330.71 | J17: =J5*IncState!J17 -> 17196.616 | K17: =K5*IncState!K17 -> 22097.652 | L17: =L5*IncState!L17 -> 28284.994 | M17: =M5*IncState!M17 -> 36063.368 | ... O17: =O5*IncState!O17 -> 57937.604
B18: Inventories | C18: 1925 | D18: 1898 | E18: 1760 | F18: =F6*IncState!F18 -> 2263.9803 | G18: =G6*IncState!G18 -> 3155.9039 | H18: =H6*IncState!H18 -> 4102.6751 | I18: =I6*IncState!I18 -> 5312.9642 | J18: =J6*IncState!J18 -> 6853.7239 | K18: =K6*IncState!K18 -> 8807.0352 | L18: =L6*IncState!L18 -> 11273.005 | M18: =M6*IncState!M18 -> 14373.081 | ... O18: =O6*IncState!O18 -> 23091.074
B19: Other current assets | C19: 1205 | D19: 1606 | E19: 4071 | F19: =F7*IncState!F17 -> 5236.7407 | G19: =G7*IncState!G17 -> 7299.8209 | H19: =H7*IncState!H17 -> 9489.7672 | I19: =I7*IncState!I17 -> 12289.249 | J19: =J7*IncState!J17 -> 15853.131 | K19: =K7*IncState!K17 -> 20371.273 | L19: =L7*IncState!L17 -> 26075.229 | M19: =M7*IncState!M17 -> 33245.917 | ... O19: =O7*IncState!O17 -> 53411.228
B20: Total current assets | C20: =SUM(C15:C19) -> 18504 | D20: =SUM(D15:D19) -> 20847 | E20: =SUM(E15:E19) -> 19595 | F20: =SUM(F15:F19) -> 34879.796 | G20: =SUM(G15:G19) -> 61555.344 | H20: =SUM(H15:H19) -> 93991.085 | I20: =SUM(I15:I19) -> 136971.26 | J20: =SUM(J15:J19) -> 193684.33 | ... O20: =SUM(O15:O19) -> 848467.83
B22: Property, plant & equipment, net | C22: 2223 | D22: 2154 | E22: 2521 | F22: =Calcs!F9 -> 2531.8854 | G22: =Calcs!G9 -> 2817.4866 | H22: =Calcs!H9 -> 3319.2514 | I22: =Calcs!I9 -> 4059.7195 | J22: =Calcs!J9 -> 5076.0719 | K22: =Calcs!K9 -> 6420.8109 | L22: =Calcs!L9 -> 8163.1542 | M22: =Calcs!M9 -> 10391.078 | ... O22: =Calcs!O9 -> 16765.861
B23: Intangible assets | C23: =43614+7111 -> 50725 | D23: =43653+3867 -> 47520 | E23: =97873+40583 -> 138456 | F23: =E23-IncState!F24 -> 133531.62 | G23: =F23-IncState!G24 -> 128607.25 | H23: =G23-IncState!H24 -> 123682.88 | I23: =H23-IncState!I24 -> 118758.5 | J23: =I23-IncState!J24 -> 113834.12 | K23: =J23-IncState!K24 -> 108909.75 | L23: =K23-IncState!L24 -> 103985.38 | M23: =L23-IncState!M24 -> 99061 | ... O23: =N23-IncState!O24 -> 99061
B24: Other assets | C24: 1797 | D24: 2340 | E24: 5073 | F24: =F8*IncState!F17 -> 6525.6658 | G24: =G8*IncState!G17 -> 9096.5344 | H24: =H8*IncState!H17 -> 11825.495 | I24: =I8*IncState!I17 -> 15314.016 | J24: =J8*IncState!J17 -> 19755.08 | K24: =K8*IncState!K17 -> 25385.278 | L24: =L8*IncState!L17 -> 32493.156 | M24: =M8*IncState!M17 -> 41428.774 | ... O24: =O8*IncState!O17 -> 66557.397
B25: Total non-current assets | C25: =SUM(C22:C24) -> 54745 | D25: =SUM(D22:D24) -> 52014 | E25: =SUM(E22:E24) -> 146050 | F25: =SUM(F22:F24) -> 142589.18 | G25: =SUM(G22:G24) -> 140521.27 | H25: =SUM(H22:H24) -> 138827.62 | I25: =SUM(I22:I24) -> 138132.24 | J25: =SUM(J22:J24) -> 138665.28 | ... O25: =SUM(O22:O24) -> 182384.26
A27: * | B27: TOTAL ASSETS | C27: =SUM(C25,C20) -> 73249 | D27: =SUM(D25,D20) -> 72861 | E27: =SUM(E25,E20) -> 165645 | F27: =SUM(F25,F20) -> 177468.97 | G27: =SUM(G25,G20) -> 202076.61 | H27: =SUM(H25,H20) -> 232818.71 | I27: =SUM(I25,I20) -> 275103.5 | J27: =SUM(J25,J20) -> 332349.61 | ... O27: =SUM(O25,O20) -> 1030852.1
B29: Revolver/Short term debt | C29: 440 | D29: 1608 | E29: 0 | F29: =MIN(CashFlow!F23,0) -> 0 | G29: =MIN(CashFlow!G23,0) -> 0 | H29: =MIN(CashFlow!H23,0) -> 0 | I29: =MIN(CashFlow!I23,0) -> 0 | J29: =MIN(CashFlow!J23,0) -> 0 | K29: =MIN(CashFlow!K23,0) -> 0 | L29: =MIN(CashFlow!L23,0) -> 0 | M29: =MIN(CashFlow!M23,0) -> 0 | ... O29: =MIN(CashFlow!O23,0) -> 0
B30: Accounts payable/Accurals | C30: 998 | D30: 1210 | E30: 1662 | F30: =F10*IncState!F18 -> 2137.9177 | G30: =G10*IncState!G18 -> 2980.1774 | H30: =H10*IncState!H18 -> 3874.2307 | I30: =I10*IncState!I18 -> 5017.1287 | J30: =J10*IncState!J18 -> 6472.0961 | K30: =K10*IncState!K18 -> 8316.6434 | L30: =L10*IncState!L18 -> 10645.304 | M30: =M10*IncState!M18 -> 13572.762 | ... O30: =O10*IncState!O18 -> 21805.321
B31: Other current liabilities | C31: =1202+4412 -> 5614 | D31: =3652+935 -> 4587 | E31: =1971+11793 -> 13764 | F31: =F11*IncState!F17 -> 17705.355 | G31: =G11*IncState!G17 -> 24680.603 | H31: =H11*IncState!H17 -> 32084.784 | I31: =I11*IncState!I17 -> 41549.795 | J31: =J11*IncState!J17 -> 53599.236 | K31: =K11*IncState!K17 -> 68875.018 | L31: =L11*IncState!L17 -> 88160.023 | M31: =M11*IncState!M17 -> 112404.03 | ... O31: =O11*IncState!O17 -> 180582.69
B32: Total current liabilities | C32: =SUM(C29:C31) -> 7052 | D32: =SUM(D29:D31) -> 7405 | E32: =SUM(E29:E31) -> 15426 | F32: =SUM(F29:F31) -> 19843.272 | G32: =SUM(G29:G31) -> 27660.781 | H32: =SUM(H29:H31) -> 35959.015 | I32: =SUM(I29:I31) -> 46566.924 | J32: =SUM(J29:J31) -> 60071.332 | ... O32: =SUM(O29:O31) -> 202388.02
B34: Long-term debt, including current maturities | C34: 39075 | D34: 37621 | E34: =66295+1271 -> 67566 | F34: =Debt!F20 -> 66295 | G34: =Debt!G20 -> 66295 | H34: =Debt!H20 -> 66295 | I34: =Debt!I20 -> 66295 | J34: =Debt!J20 -> 66295 | K34: =Debt!K20 -> 66295 | L34: =Debt!L20 -> 66295 | M34: =Debt!M20 -> 66295 | ... O34: =Debt!O20 -> 66295
B35: Other long-term liabilities | C35: 4413 | D35: 3847 | E35: 14975 | F35: =F12*IncState!F17 -> 19263.128 | G35: =G12*IncState!G17 -> 26852.08 | H35: =H12*IncState!H17 -> 34907.704 | I35: =I12*IncState!I17 -> 45205.477 | J35: =J12*IncState!J17 -> 58315.065 | K35: =K12*IncState!K17 -> 74934.859 | L35: =L12*IncState!L17 -> 95916.619 | M35: =M12*IncState!M17 -> 122293.69 | ... O35: =O12*IncState!O17 -> 196470.93
B36: Total non-current liabilities | C36: =SUM(C34:C35) -> 43488 | D36: =SUM(D34:D35) -> 41468 | E36: =SUM(E34:E35) -> 82541 | F36: =SUM(F34:F35) -> 85558.128 | G36: =SUM(G34:G35) -> 93147.08 | H36: =SUM(H34:H35) -> 101202.7 | I36: =SUM(I34:I35) -> 111500.48 | J36: =SUM(J34:J35) -> 124610.07 | ... O36: =SUM(O34:O35) -> 262765.93
B38: Equity | C38: 22709 | D38: 23988 | E38: 67678 | F38: =Calcs!F17 -> 72067.572 | G38: =Calcs!G17 -> 81268.754 | H38: =Calcs!H17 -> 95656.987 | I38: =Calcs!I17 -> 117036.1 | J38: =Calcs!J17 -> 147668.21 | K38: =Calcs!K17 -> 190377.31 | L38: =Calcs!L17 -> 248672.64 | M38: =Calcs!M17 -> 326894.76 | ... O38: =Calcs!O17 -> 565698.14
A39: * | B39: TOTAL LIABILITIES & EQUITY | C39: =SUM(C38,C36,C32) -> 73249 | D39: =SUM(D38,D36,D32) -> 72861 | E39: =SUM(E38,E36,E32) -> 165645 | F39: =SUM(F38,F36,F32) -> 177468.97 | G39: =SUM(G38,G36,G32) -> 202076.61 | H39: =SUM(H38,H36,H32) -> 232818.71 | I39: =SUM(I38,I36,I32) -> 275103.5 | J39: =SUM(J38,J36,J32) -> 332349.61 | ... O39: =SUM(O38,O36,O32) -> 1030852.1
A41: * | B41: Balance check | C41: =C39-C27 -> 0 | D41: =D39-D27 -> 0 | E41: =E39-E27 -> 0 | F41: =F39-F27 -> 0 | G41: =G39-G27 -> 0 | H41: =H39-H27 -> 0 | I41: =I39-I27 -> 0 | J41: =J39-J27 -> 0 | ... O41: =O39-O27 -> 0

Sheet CashFlow
A1: =CoName -> Broadcom Inc. | C1: Hist. | D1: Hist. | E1: Hist. | F1: Proj. | G1: Proj. | H1: Proj. | I1: Proj. | J1: Proj. | K1: Proj. | L1: Proj. | M1: Proj. | N1: Proj. | O1: Proj.
A2: Cash flow statement | C2: 2022 | D2: =C2+1 -> 2023 | E2: =D2+1 -> 2024 | F2: =E2+1 -> 2025 | G2: =F2+1 -> 2026 | H2: =G2+1 -> 2027 | I2: =H2+1 -> 2028 | J2: =I2+1 -> 2029 | K2: =J2+1 -> 2030 | ... O2: =N2+1 -> 2034
B3: Net Income | F3: =IncState!F36 -> 15497.331 | G3: =IncState!G36 -> 21602.7 | H3: =IncState!H36 -> 28083.51 | I3: =IncState!I36 -> 36368.146 | J3: =IncState!J36 -> 46914.908 | K3: =IncState!K36 -> 60285.657 | L3: =IncState!L36 -> 77165.641 | M3: =IncState!M36 -> 98386.192 | ... O3: =IncState!O36 -> 158062.34
B4: Depreciation | F4: =IncState!F23 -> 694.03575 | G4: =IncState!G23 -> 697.03251 | H4: =IncState!H23 -> 775.65903 | I4: =IncState!I23 -> 913.79576 | J4: =IncState!J23 -> 1117.6479 | K4: =IncState!K23 -> 1397.4516 | L4: =IncState!L23 -> 1767.6606 | M4: =IncState!M23 -> 2247.3307 | ... O4: =IncState!O23 -> 3637.8292
B5: Amortization | F5: =IncState!F24 -> 4924.375 | G5: =IncState!G24 -> 4924.375 | H5: =IncState!H24 -> 4924.375 | I5: =IncState!I24 -> 4924.375 | J5: =IncState!J24 -> 4924.375 | K5: =IncState!K24 -> 4924.375 | L5: =IncState!L24 -> 4924.375 | M5: =IncState!M24 -> 4924.375 | ... O5: =IncState!O24 -> 0
B6: (inc) / dec In OWC | F6: =Calcs!F26 -> 1261.4941 | G6: =Calcs!G26 -> 2232.5407 | H6: =Calcs!H26 -> 2369.8274 | I6: =Calcs!I26 -> 3029.4294 | J6: =Calcs!J26 -> 3856.6177 | K6: =Calcs!K26 -> 4889.2603 | L6: =Calcs!L26 -> 6172.4767 | M6: =Calcs!M26 -> 7759.6849 | ... O6: =Calcs!O26 -> 12107.965
B7: (inc) / dec In LT assets | F7: =BalSheet!E24-BalSheet!F24 -> -1452.6658 | G7: =BalSheet!F24-BalSheet!G24 -> -2570.8686 | H7: =BalSheet!G24-BalSheet!H24 -> -2728.9603 | I7: =BalSheet!H24-BalSheet!I24 -> -3488.5209 | J7: =BalSheet!I24-BalSheet!J24 -> -4441.0645 | K7: =BalSheet!J24-BalSheet!K24 -> -5630.1979 | L7: =BalSheet!K24-BalSheet!L24 -> -7107.8779 | M7: =BalSheet!L24-BalSheet!M24 -> -8935.6179 | ... O7: =BalSheet!N24-BalSheet!O24 -> -13942.854
B8: inc / (dec) In LT liabilities | F8: =BalSheet!F35-BalSheet!E35 -> 4288.1275 | G8: =BalSheet!G35-BalSheet!F35 -> 7588.9527 | H8: =BalSheet!H35-BalSheet!G35 -> 8055.6241 | I8: =BalSheet!I35-BalSheet!H35 -> 10297.773 | J8: =BalSheet!J35-BalSheet!I35 -> 13109.588 | K8: =BalSheet!K35-BalSheet!J35 -> 16619.794 | L8: =BalSheet!L35-BalSheet!K35 -> 20981.761 | M8: =BalSheet!M35-BalSheet!L35 -> 26377.07 | ... O8: =BalSheet!O35-BalSheet!N35 -> 41157.941
B9: Cash Flow From Operations | F9: =SUM(F3:F8) -> 25212.697 | G9: =SUM(G3:G8) -> 34474.733 | H9: =SUM(H3:H8) -> 41480.035 | I9: =SUM(I3:I8) -> 52044.998 | J9: =SUM(J3:J8) -> 65482.073 | K9: =SUM(K3:K8) -> 82486.34 | L9: =SUM(L3:L8) -> 103904.04 | M9: =SUM(M3:M8) -> 130759.04 | ... O9: =SUM(O3:O8) -> 201023.22
B11: Capex | F11: =Calcs!F7 -> 704.92113 | G11: =Calcs!G7 -> 982.63372 | H11: =Calcs!H7 -> 1277.4238 | I11: =Calcs!I7 -> 1654.2639 | J11: =Calcs!J7 -> 2134.0004 | K11: =Calcs!K7 -> 2742.1905 | L11: =Calcs!L7 -> 3510.0038 | M11: =Calcs!M7 -> 4475.2549 | ... O11: =Calcs!O7 -> 7189.7207
B12: Cash Flow From Investing | F12: =-F11 -> -704.92113 | G12: =-G11 -> -982.63372 | H12: =-H11 -> -1277.4238 | I12: =-I11 -> -1654.2639 | J12: =-J11 -> -2134.0004 | K12: =-K11 -> -2742.1905 | L12: =-L11 -> -3510.0038 | M12: =-M11 -> -4475.2549 | ... O12: =-O11 -> -7189.7207
B14: Dividends Paid | F14: =Calcs!F15 -> -11107.759 | G14: =Calcs!G15 -> -12401.518 | H14: =Calcs!H15 -> -13695.277 | I14: =Calcs!I15 -> -14989.036 | J14: =Calcs!J15 -> -16282.795 | K14: =Calcs!K15 -> -17576.554 | L14: =Calcs!L15 -> -18870.313 | M14: =Calcs!M15 -> -20164.072 | ... O14: =Calcs!O15 -> -22751.59
B15: Share issuance / (repurchase) | F15: =SUM(Calcs!F11) -> 0 | G15: =SUM(Calcs!G11) -> 0 | H15: =SUM(Calcs!H11) -> 0 | I15: =SUM(Calcs!I11) -> 0 | J15: =SUM(Calcs!J11) -> 0 | K15: =SUM(Calcs!K11) -> 0 | L15: =SUM(Calcs!L11) -> 0 | M15: =SUM(Calcs!M11) -> 0 | ... O15: =SUM(Calcs!O11) -> 0
B16: Debt issuance / (repayment) | F16: =SUM(Debt!F8:F9) -> -1271 | G16: =SUM(Debt!G8:G9) -> 0 | H16: =SUM(Debt!H8:H9) -> 0 | I16: =SUM(Debt!I8:I9) -> 0 | J16: =SUM(Debt!J8:J9) -> 0 | K16: =SUM(Debt!K8:K9) -> 0 | L16: =SUM(Debt!L8:L9) -> 0 | M16: =SUM(Debt!M8:M9) -> 0 | ... O16: =SUM(Debt!O8:O9) -> 0
B17: Cash Flow From Financing | F17: =SUM(F14:F16) -> -12378.759 | G17: =SUM(G14:G16) -> -12401.518 | H17: =SUM(H14:H16) -> -13695.277 | I17: =SUM(I14:I16) -> -14989.036 | J17: =SUM(J14:J16) -> -16282.795 | K17: =SUM(K14:K16) -> -17576.554 | L17: =SUM(L14:L16) -> -18870.313 | M17: =SUM(M14:M16) -> -20164.072 | ... O17: =SUM(O14:O16) -> -22751.59
B19: Net Changes in Cash | F19: =SUM(F17,F12,F9) -> 12129.017 | G19: =SUM(G17,G12,G9) -> 21090.581 | H19: =SUM(H17,H12,H9) -> 26507.335 | I19: =SUM(I17,I12,I9) -> 35401.698 | J19: =SUM(J17,J12,J9) -> 47065.277 | K19: =SUM(K17,K12,K9) -> 62167.595 | L19: =SUM(L17,L12,L9) -> 81523.719 | M19: =SUM(M17,M12,M9) -> 106119.71 | ... O19: =SUM(O17,O12,O9) -> 171081.91
B21: Beginning cash | F21: =BalSheet!E16 -> 8574.39 | G21: =BalSheet!F16 -> 20703.407 | H21: =BalSheet!G16 -> 41793.988 | I21: =BalSheet!H16 -> 68301.323 | J21: =BalSheet!I16 -> 103703.02 | K21: =BalSheet!J16 -> 150768.3 | L21: =BalSheet!K16 -> 212935.89 | M21: =BalSheet!L16 -> 294459.61 | ... O21: =BalSheet!N16 -> 532796.3
B22: =B19 -> Net Changes in Cash | F22: =F19 -> 12129.017 | G22: =G19 -> 21090.581 | H22: =H19 -> 26507.335 | I22: =I19 -> 35401.698 | J22: =J19 -> 47065.277 | K22: =K19 -> 62167.595 | L22: =L19 -> 81523.719 | M22: =M19 -> 106119.71 | ... O22: =O19 -> 171081.91
B23: Ending Cash | F23: =SUM(F21:F22) -> 20703.407 | G23: =SUM(G21:G22) -> 41793.988 | H23: =SUM(H21:H22) -> 68301.323 | I23: =SUM(I21:I22) -> 103703.02 | J23: =SUM(J21:J22) -> 150768.3 | K23: =SUM(K21:K22) -> 212935.89 | L23: =SUM(L21:L22) -> 294459.61 | M23: =SUM(M21:M22) -> 400579.32 | ... O23: =SUM(O21:O22) -> 703878.21

Sheet Free Cash Flow
A1: =CoName -> Broadcom Inc. | C1: Hist. | D1: Hist. | E1: Hist. | F1: Proj. | G1: Proj. | H1: Proj. | I1: Proj. | J1: Proj. | K1: Proj. | L1: Proj. | M1: Proj. | N1: Proj. | O1: Proj.
A2: Free Cash Flows | C2: 2022 | D2: =C2+1 -> 2023 | E2: =D2+1 -> 2024 | F2: =E2+1 -> 2025 | G2: =F2+1 -> 2026 | H2: =G2+1 -> 2027 | I2: =H2+1 -> 2028 | J2: =I2+1 -> 2029 | K2: =J2+1 -> 2030 | ... O2: =N2+1 -> 2034
A3: * | B3: Sales | F3: =IncState!F17 -> 66342.34 | G3: =IncState!G17 -> 92478.743 | H3: =IncState!H17 -> 120222.37 | I3: =IncState!I17 -> 155687.96 | J3: =IncState!J17 -> 200837.47 | K3: =IncState!K17 -> 258076.15 | L3: =IncState!L17 -> 330337.48 | M3: =IncState!M17 -> 421180.28 | ... O3: =IncState!O17 -> 676647.19
B4: EBIT | F4: =IncState!F21 -> 19616.874 | G4: =IncState!G21 -> 27345.19 | H4: =IncState!H21 -> 35548.747 | I4: =IncState!I21 -> 46035.628 | J4: =IncState!J21 -> 59385.96 | K4: =IncState!K21 -> 76310.958 | L4: =IncState!L21 -> 97678.026 | M4: =IncState!M21 -> 124539.48 | ... O4: =IncState!O21 -> 200078.91
B5: Effective Tax Rate | F5: =Assumptions!F17 -> 0.21 | G5: =Assumptions!G17 -> 0.21 | H5: =Assumptions!H17 -> 0.21 | I5: =Assumptions!I17 -> 0.21 | J5: =Assumptions!J17 -> 0.21 | K5: =Assumptions!K17 -> 0.21 | L5: =Assumptions!L17 -> 0.21 | M5: =Assumptions!M17 -> 0.21 | ... O5: =Assumptions!O17 -> 0.21
A7: * | B7: NOPAT | F7: =F4*(1-F5) -> 15497.331 | G7: =G4*(1-G5) -> 21602.7 | H7: =H4*(1-H5) -> 28083.51 | I7: =I4*(1-I5) -> 36368.146 | J7: =J4*(1-J5) -> 46914.908 | K7: =K4*(1-K5) -> 60285.657 | L7: =L4*(1-L5) -> 77165.641 | M7: =M4*(1-M5) -> 98386.192 | ... O7: =O4*(1-O5) -> 158062.34
