Workbook
Name Ccy: MAIN!$C$6
Name circ: MAIN!$C$9
Name CoName: MAIN!$C$4
Name g: #REF!
Name IQ_CH: 110000
Name IQ_CQ: 5000
Name IQ_CY: 10000
Name IQ_DAILY: 500000
Name IQ_FH: 100000
Name IQ_FQ: 500
Name IQ_FY: 1000
Name IQ_LTM: 2000
Name IQ_MONTH: 15000
Name IQ_NTM: 6000
Name IQ_WEEK: 50000
Name IQ_YTD: 3000
Name OpCase: [1]DCF!$E$98
Name ScenarioREV: Assumptions!$D$4
Name TTS: #REF!
Name Units: MAIN!$C$7

Sheet MAIN
A1: =CoName -> Salesforce Inc.
A2: Model Details
B4: Company name | C4: Salesforce Inc. | E4: Current Stock Price | F4: 243.62 | H4: Operating Case One | I4: Terminal Mult | J4: Perpetuity | K4: Average
B5: Latest BS date | C5: 247.43 | E5: S/O | F5: 952 | H5: Implied Price | I5: ='DCF Model'!T17 -> 252.88476 | J5: ='DCF Model'!N17 -> 236.34151 | K5: =AVERAGE(I5:J5) -> 244.61314
B6: Currency | C6: USD | E6: Mkt Cap | F6: =F5*F4 -> 231926.24 | H6: Difference | I6: =I5/$F$4-1 -> 0.038029563 | J6: =J5/$F$4-1 -> -0.029876408 | K6: =AVERAGE(I6:J6) -> 0.0040765777
B7: Units | C7: m | E7: Cash | F7: =10365+5007 -> 15372
B8: Analyst name | C8: Alan Chen | E8: Debt | F8: 8436
B9: Circular switch | C9: 0 | E9: EV | F9: =F6-F7+F8 -> 224990.24

Sheet Quarters
A1: =CoName -> Salesforce Inc.
A2: Quarterly Data | C2: Q123 | D2: Q223 | E2: Q323 | F2: Q423 | G2: 2023 | H2: Q124 | I2: Q224 | J2: Q324 | K2: Q424 | L2: 2024 | M2: Q125 | N2: Q225 | O2: Q325 | P2: Q425 | Q2: 2025 | R2: Q126 | S2: Q226 | T2: Q326 | U2: Q426 | V2: 2026 | W2: =V2+1 -> 2027 | X2: =W2+1 -> 2028 | Y2: =X2+1 -> 2029 | Z2: =Y2+1 -> 2030 | AA2: =Z2+1 -> 2031 | AB2: =AA2+1 -> 2032 | AC2: =AB2+1 -> 2033
B3: Subscription and support | C3: 6856 | D3: 7143 | E3: 7233 | F3: 7789 | G3: =SUM(C3:F3) -> 29021 | H3: 7642 | I3: 8006 | J3: 8141 | K3: 8748 | L3: =SUM(H3:K3) -> 32537 | M3: 8585 | N3: 8764 | O3: 8879 | P3: 9451 | Q3: =SUM(M3:P3) -> 35679 | R3: 9297 | S3: 9690 | V3: =SUM(R3:U3) -> 18987
B4: Professional Services and other | C4: 555 | D4: 577 | E4: 604 | F4: 595 | G4: =SUM(C4:F4) -> 2331 | H4: 605 | I4: 597 | J4: 579 | K4: 539 | L4: =SUM(H4:K4) -> 2320 | M4: 548 | N4: 561 | O4: 565 | P4: 542 | Q4: =SUM(M4:P4) -> 2216 | R4: 532 | S4: 546 | V4: =SUM(R4:U4) -> 1078
A5: * | B5: Revenues | C5: =SUM(C3:C4) -> 7411 | D5: =SUM(D3:D4) -> 7720 | E5: =SUM(E3:E4) -> 7837 | F5: =SUM(F3:F4) -> 8384 | G5: =SUM(C5:F5) -> 31352 | H5: =SUM(H3:H4) -> 8247 | I5: =SUM(I3:I4) -> 8603 | J5: =SUM(J3:J4) -> 8720 | K5: =SUM(K3:K4) -> 9287 | L5: =SUM(H5:K5) -> 34857 | M5: =SUM(M3:M4) -> 9133 | N5: =SUM(N3:N4) -> 9325 | O5: =SUM(O3:O4) -> 9444 | P5: =SUM(P3:P4) -> 9993 | Q5: =SUM(M5:P5) -> 37895 | R5: =SUM(R3:R4) -> 9829 | S5: =SUM(S3:S4) -> 10236 | T5: 10250 | U5: 12000 | V5: =SUM(R5:U5) -> 42315 | W5: =V5*(1+W21) -> 47250.54 | X5: =W5*(1+X21) -> 52761.753 | Y5: =X5*(1+Y21) -> 58915.782 | Z5: =Y5*(1+Z21) -> 65787.606 | AA5: =Z5*(1+AA21) -> 73460.946 | AB5: =AA5*(1+AB21) -> 82029.289 | AC5: =AB5*(1+AC21) -> 91597.028
B6: COGS | C6: 2045 | D6: 2127 | E6: 2088 | F6: 2100 | G6: =SUM(C6:F6) -> 8360 | H6: 2125 | I6: 2113 | J6: 2155 | K6: 2148 | L6: =SUM(H6:K6) -> 8541 | M6: 2162 | N6: 2159 | O6: 2105 | P6: 2217 | Q6: =SUM(M6:P6) -> 8643 | R6: 2265 | S6: 2242 | V6: =SUM(R6:U6) -> 4507
B7: R&D | C7: 1318 | D7: 1329 | E7: 1280 | F7: 1128 | G7: =SUM(C7:F7) -> 5055 | H7: 1207 | I7: 1220 | J7: 1204 | K7: 1275 | L7: =SUM(H7:K7) -> 4906 | M7: 1368 | N7: 1349 | O7: 1356 | P7: 1420 | Q7: =SUM(M7:P7) -> 5493 | R7: 1460 | S7: 1481 | V7: =SUM(R7:U7) -> 2941
B8: SG&A | C8: =3372+656 -> 4028 | D8: =3424+647 -> 4071 | E8: =3345+664 -> 4009 | F8: =3385+586 -> 3971 | G8: =SUM(C8:F8) -> 16079 | H8: =3154+638 -> 3792 | I8: =3113+632 -> 3745 | J8: =3173+632 -> 3805 | K8: =3437+632 -> 4069 | L8: =SUM(H8:K8) -> 15411 | M8: =3239+647 -> 3886 | N8: =3224+711 -> 3935 | O8: =3323+711 -> 4034 | P8: =3471+767 -> 4238 | Q8: =SUM(M8:P8) -> 16093 | R8: =3429+697 -> 4126 | S8: =3443+734 -> 4177 | V8: =SUM(R8:U8) -> 8303
B9: Restructuring (non-recurring) | C9: 0 | D9: 0 | E9: 0 | F9: 828 | G9: =SUM(C9:F9) -> 828 | H9: 711 | I9: 49 | J9: 55 | K9: 173 | L9: =SUM(H9:K9) -> 988 | M9: 8 | N9: 99 | O9: 56 | P9: 298 | Q9: =SUM(M9:P9) -> 461 | R9: 36 | S9: 4 | V9: =SUM(R9:U9) -> 40
A10: * | B10: EBIT | C10: =C5-SUM(C6:C9) -> 20 | D10: =D5-SUM(D6:D9) -> 193 | E10: =E5-SUM(E6:E9) -> 460 | F10: =F5-SUM(F6:F9) -> 357 | G10: =SUM(C10:F10) -> 1030 | H10: =H5-SUM(H6:H9) -> 412 | I10: =I5-SUM(I6:I9) -> 1476 | J10: =J5-SUM(J6:J9) -> 1501 | K10: =K5-SUM(K6:K9) -> 1622 | L10: =SUM(H10:K10) -> 5011 | M10: =M5-SUM(M6:M9) -> 1709 | N10: =N5-SUM(N6:N9) -> 1783 | O10: =O5-SUM(O6:O9) -> 1893 | P10: =P5-SUM(P6:P9) -> 1820 | Q10: =SUM(M10:P10) -> 7205 | R10: =R5-SUM(R6:R9) -> 1942 | S10: =S5-SUM(S6:S9) -> 2332 | T10: =T5*T22 -> 2334.2773 | U10: =U5*U22 -> 2732.8125 | V10: =SUM(R10:U10) -> 9341.0898 | W10: =W5*W22 -> 10420.766 | X10: =X5*X22 -> 11636.224 | Y10: =Y5*Y22 -> 12993.451 | Z10: =Z5*Z22 -> 14508.982 | AA10: =AA5*AA22 -> 16201.282 | AB10: =AB5*AB22 -> 18090.968 | AC10: =AC5*AC22 -> 20201.064
B11: Other income (expenses) | C11: =7-56 -> -49 | D11: =45-57 -> -12 | E11: =23-8 -> 15 | F11: -324 | G11: =SUM(C11:F11) -> -370 | H11: =55-141 -> -86 | I11: =45-29 -> 16 | J11: =58-72 -> -14 | K11: =58-35 -> 23 | L11: =SUM(H11:K11) -> -61 | M11: =37+121 -> 158 | N11: =91-37 -> 54 | O11: =70-217 -> -147 | P11: =96+72 -> 168 | Q11: =SUM(M11:P11) -> 233 | R11: =95-63 -> 32 | S11: =6+68 -> 74 | V11: =SUM(R11:U11) -> 106
B12: Pretax income | C12: =SUM(C10:C11) -> -29 | D12: =SUM(D10:D11) -> 181 | E12: =SUM(E10:E11) -> 475 | F12: =SUM(F10:F11) -> 33 | G12: =SUM(C12:F12) -> 660 | H12: =SUM(H10:H11) -> 326 | I12: =SUM(I10:I11) -> 1492 | J12: =SUM(J10:J11) -> 1487 | K12: =SUM(K10:K11) -> 1645 | L12: =SUM(H12:K12) -> 4950 | M12: =SUM(M10:M11) -> 1867 | N12: =SUM(N10:N11) -> 1837 | O12: =SUM(O10:O11) -> 1746 | P12: =SUM(P10:P11) -> 1988 | Q12: =SUM(M12:P12) -> 7438 | R12: =SUM(R10:R11) -> 1974 | S12: =SUM(S10:S11) -> 2406 | T12: =T10 -> 2334.2773 | U12: =U10 -> 2732.8125 | V12: =SUM(R12:U12) -> 9447.0898
B13: Taxes | C13: 57 | D13: -113 | E13: -265 | F13: -131 | G13: =SUM(C13:F13) -> -452 | H13: -127 | I13: -225 | J13: -263 | K13: -199 | L13: =SUM(H13:K13) -> -814 | M13: -334 | N13: -408 | O13: -219 | P13: -280 | Q13: =SUM(M13:P13) -> -1241 | R13: -433 | S13: -519 | T13: =T10*T23*-1 -> -503.52865 | U13: =U10*U23*-1 -> -589.49696 | V13: =SUM(R13:U13) -> -2045.0256 | W13: =W10*W23 -> 2255.7987 | X13: =X10*X23 -> 2518.9108 | Y13: =Y10*Y23 -> 2812.7117 | Z13: =Z10*Z23 -> 3140.781 | AA13: =AA10*AA23 -> 3507.1156 | AB13: =AB10*AB23 -> 3916.1789 | AC13: =AC10*AC23 -> 4372.9544
A14: * | B14: Net income | C14: =SUM(C12:C13) -> 28 | D14: =SUM(D12:D13) -> 68 | E14: =SUM(E12:E13) -> 210 | F14: =SUM(F12:F13) -> -98 | G14: =SUM(C14:F14) -> 208 | H14: =SUM(H12:H13) -> 199 | I14: =SUM(I12:I13) -> 1267 | J14: =SUM(J12:J13) -> 1224 | K14: =SUM(K12:K13) -> 1446 | L14: =SUM(H14:K14) -> 4136 | M14: =SUM(M12:M13) -> 1533 | N14: =SUM(N12:N13) -> 1429 | O14: =SUM(O12:O13) -> 1527 | P14: =SUM(P12:P13) -> 1708 | Q14: =SUM(M14:P14) -> 6197 | R14: =SUM(R12:R13) -> 1541 | S14: =SUM(S12:S13) -> 1887 | T14: =SUM(T13,T10) -> 1830.7487 | U14: =SUM(U13,U10) -> 2143.3155 | V14: =SUM(R14:U14) -> 7402.0642 | W14: =W10-W13 -> 8164.9672 | X14: =X10-X13 -> 9117.3133 | Y14: =Y10-Y13 -> 10180.739 | Z14: =Z10-Z13 -> 11368.201 | AA14: =AA10-AA13 -> 12694.166 | AB14: =AB10-AB13 -> 14174.789 | AC14: =AC10-AC13 -> 15828.11
B15: WASO | C15: 991 | D15: 997 | E15: 997 | F15: 984 | G15: 984 | H15: 980 | I15: 975 | J15: 972 | K15: 970 | L15: 970 | M15: 970 | N15: 956 | O15: 956 | P15: 959 | R15: 960 | S15: 956
B16: Diluted WASO | C16: 1001 | D16: 1001 | E16: 1000 | F16: 984 | G16: 984 | H16: 988 | I16: 986 | J16: 981 | K16: 983 | L16: 983 | M16: 985 | N16: 962 | O16: 965 | P16: 974 | R16: 970 | S16: 962
B17: EPS | C17: =C14/C15 -> 0.028254289 | D17: =D14/D15 -> 0.068204614 | E17: =E14/E15 -> 0.2106319 | F17: =F14/F15 -> -0.099593496 | G17: =G14/G15 -> 0.21138211 | H17: =H14/H15 -> 0.20306122 | I17: =I14/I15 -> 1.2994872 | J17: =J14/J15 -> 1.2592593 | ... P17: =P14/P15 -> 1.7810219 | R17: =R14/R15 -> 1.6052083 | S17: =S14/S15 -> 1.9738494
B18: Diluted EPS | C18: =C14/C16 -> 0.027972028 | D18: =D14/D16 -> 0.067932068 | E18: =E14/E16 -> 0.21 | F18: =F14/F16 -> -0.099593496 | G18: =G14/G16 -> 0.21138211 | H18: =H14/H16 -> 0.201417 | I18: =I14/I16 -> 1.2849899 | J18: =J14/J16 -> 1.2477064 | ... P18: =P14/P16 -> 1.7535934 | R18: =R14/R16 -> 1.5886598 | S18: =S14/S16 -> 1.9615385
B19: Subscription y/y | H19: =H3/C3-1 -> 0.11464411 | I19: =I3/D3-1 -> 0.12081758 | J19: =J3/E3-1 -> 0.12553574 | K19: =K3/F3-1 -> 0.12312235 | L19: =L3/G3-1 -> 0.12115365 | M19: =M3/H3-1 -> 0.12339702 | N19: =N3/I3-1 -> 0.094678991 | O19: =O3/J3-1 -> 0.090652254 | ... S19: =S3/N3-1 -> 0.10565952
B20: Other y/y | H20: =H4/C4-1 -> 0.09009009 | I20: =I4/D4-1 -> 0.034662045 | J20: =J4/E4-1 -> -0.041390728 | K20: =K4/F4-1 -> -0.094117647 | L20: =L4/G4-1 -> -0.0047190047 | M20: =M4/H4-1 -> -0.094214876 | N20: =N4/I4-1 -> -0.060301508 | O20: =O4/J4-1 -> -0.02417962 | ... S20: =S4/N4-1 -> -0.026737968
A21: * | B21: Revenue y/y | G21: =G5/26492-1 -> 0.18345161 | H21: =H3/C3-1 -> 0.11464411 | I21: =I3/D3-1 -> 0.12081758 | J21: =J3/E3-1 -> 0.12553574 | K21: =K3/F3-1 -> 0.12312235 | L21: =L5/G5-1 -> 0.1117951 | M21: =M3/H3-1 -> 0.12339702 | N21: =N3/I3-1 -> 0.094678991 | O21: =O3/J3-1 -> 0.090652254 | P21: =P3/K3-1 -> 0.080361225 | Q21: =Q5/L5-1 -> 0.087156095 | R21: =R3/M3-1 -> 0.082935352 | S21: =S3/N3-1 -> 0.10565952 | T21: =T5/O5-1 -> 0.085345193 | U21: =U5/P5-1 -> 0.20084059 | V21: =V5/Q5-1 -> 0.11663808 | W21: =V21 -> 0.11663808 | X21: =W21 -> 0.11663808 | Y21: =X21 -> 0.11663808 | Z21: =Y21 -> 0.11663808 | AA21: =Z21 -> 0.11663808 | AB21: =AA21 -> 0.11663808 | AC21: =AB21 -> 0.11663808
B22: Operating Margin no restructuring | C22: =C10/(C5+C9) -> 0.0026986911 | D22: =D10/(D5+D9) -> 0.025 | E22: =E10/(E5+E9) -> 0.05869593 | F22: =F10/(F5+F9) -> 0.038753799 | G22: =G10/(G5+G9) -> 0.032007458 | H22: =H10/(H5+H9) -> 0.045992409 | I22: =I10/(I5+I9) -> 0.17059639 | J22: =J10/(J5+J9) -> 0.17105413 | ... S22: =S10/(S5+S9) -> 0.22773437 | T22: =S22 -> 0.22773437 | U22: =T22 -> 0.22773437 | V22: =V10/(V5+V9) -> 0.22054279 | W22: =V22 -> 0.22054279 | X22: =W22 -> 0.22054279 | Y22: =X22 -> 0.22054279 | Z22: =Y22 -> 0.22054279 | AA22: =Z22 -> 0.22054279 | AB22: =AA22 -> 0.22054279 | AC22: =AB22 -> 0.22054279
B23: Tax rate | C23: =C13/C12*-1 -> 1.9655172 | D23: =D13/D12*-1 -> 0.62430939 | E23: =E13/E12*-1 -> 0.55789474 | F23: =F13/F12*-1 -> 3.969697 | G23: =G13/G12*-1 -> 0.68484848 | H23: =H13/H12*-1 -> 0.38957055 | I23: =I13/I12*-1 -> 0.15080429 | J23: =J13/J12*-1 -> 0.17686617 | ... S23: =S13/S12*-1 -> 0.21571072 | T23: =S23 -> 0.21571072 | U23: =T23 -> 0.21571072 | V23: =V13/V12*-1 -> 0.21647149 | W23: =V23 -> 0.21647149 | X23: =W23 -> 0.21647149 | Y23: =X23 -> 0.21647149 | Z23: =Y23 -> 0.21647149 | AA23: =Z23 -> 0.21647149 | AB23: =AA23 -> 0.21647149 | AC23: =AB23 -> 0.21647149

Sheet Assumptions
A1: =CoName -> Salesforce Inc. | C1: Hist. | D1: Hist. | E1: Hist. | F1: Proj. | G1: Proj. | H1: Proj. | I1: Proj. | J1: Proj. | K1: Proj. | L1: Proj. | M1: Proj.
A2: * | B2: Income Statement | C2: 2023 | D2: =C2+1 -> 2024 | E2: =D2+1 -> 2025 | F2: =E2+1 -> 2026 | G2: =F2+1 -> 2027 | H2: =G2+1 -> 2028 | I2: =H2+1 -> 2029 | J2: =I2+1 -> 2030 | K2: =J2+1 -> 2031 | ... M2: =L2+1 -> 2033
B4: Operating Case | D4: 1
D5: Variance
B6: Street Case | D6: 0 | F6: =Quarters!V21 -> 0.11663808 | G6: =Quarters!W21 -> 0.11663808 | H6: =Quarters!X21 -> 0.11663808 | I6: =Quarters!Y21 -> 0.11663808 | J6: =Quarters!Z21 -> 0.11663808 | K6: =Quarters!AA21 -> 0.11663808 | L6: =Quarters!AB21 -> 0.11663808 | M6: =Quarters!AC21 -> 0.11663808
B7: Optimistic Case | D7: 0.025 | F7: =F10+$D$7 -> 0.14163808 | G7: =G10+$D$7 -> 0.14163808 | H7: =H10+$D$7 -> 0.14163808 | I7: =I10+$D$7 -> 0.14163808 | J7: =J10+$D$7 -> 0.14163808 | K7: =K10+$D$7 -> 0.14163808 | L7: =L10+$D$7 -> 0.14163808 | M7: =M10+$D$7 -> 0.14163808
B8: Pessimistic Case | D8: -0.025 | F8: =F10+$D$8 -> 0.091638079 | G8: =G10+$D$8 -> 0.091638079 | H8: =H10+$D$8 -> 0.091638079 | I8: =I10+$D$8 -> 0.091638079 | J8: =J10+$D$8 -> 0.091638079 | K8: =K10+$D$8 -> 0.091638079 | L8: =L10+$D$8 -> 0.091638079 | M8: =M10+$D$8 -> 0.091638079
B10: Revenue Growth | C10: =Quarters!G21 -> 0.18345161 | D10: =Quarters!L21 -> 0.1117951 | E10: =Quarters!Q21 -> 0.087156095 | F10: =CHOOSE(ScenarioREV,F6,F7,F8) -> 0.11663808 | G10: =CHOOSE(ScenarioREV,G6,G7,G8) -> 0.11663808 | H10: =CHOOSE(ScenarioREV,H6,H7,H8) -> 0.11663808 | I10: =CHOOSE(ScenarioREV,I6,I7,I8) -> 0.11663808 | J10: =CHOOSE(ScenarioREV,J6,J7,J8) -> 0.11663808 | K10: =CHOOSE(ScenarioREV,K6,K7,K8) -> 0.11663808 | L10: =CHOOSE(ScenarioREV,L6,L7,L8) -> 0.11663808 | M10: =CHOOSE(ScenarioREV,M6,M7,M8) -> 0.11663808
B11: COGS % of sales | C11: =IncState!C18/IncState!C17 -> 0.26664966 | D11: =IncState!D18/IncState!D17 -> 0.24502969 | E11: =IncState!E18/IncState!E17 -> 0.22807758 | F11: =E11 -> 0.22807758 | G11: =F11 -> 0.22807758 | H11: =G11 -> 0.22807758 | I11: =H11 -> 0.22807758 | J11: =I11 -> 0.22807758 | K11: =J11 -> 0.22807758 | L11: =K11 -> 0.22807758 | M11: =L11 -> 0.22807758
B12: R&D % of sales | C12: =IncState!C19/IncState!C17 -> 0.16123373 | D12: =IncState!D19/IncState!D17 -> 0.14074648 | E12: =IncState!E19/IncState!E17 -> 0.14495316 | F12: =E12 -> 0.14495316 | G12: =F12 -> 0.14495316 | H12: =G12 -> 0.14495316 | I12: =H12 -> 0.14495316 | J12: =I12 -> 0.14495316 | K12: =J12 -> 0.14495316 | L12: =K12 -> 0.14495316 | M12: =L12 -> 0.14495316
B13: SG&A % of sales | C13: =IncState!C20/IncState!C17 -> 0.51285404 | D13: =IncState!D20/IncState!D17 -> 0.44212066 | E13: =IncState!E20/IncState!E17 -> 0.42467344 | F13: =E13-0.01 -> 0.41467344 | G13: =F13-0.01 -> 0.40467344 | H13: =G13-0.01 -> 0.39467344 | I13: =H13-0.01 -> 0.38467344 | J13: =I13-0.01 -> 0.37467344 | K13: =J13-0.01 -> 0.36467344 | L13: =K13-0.01 -> 0.35467344 | M13: =L13-0.01 -> 0.34467344
B14: Amortization $ Amt | F14: 1522 | G14: 1147 | H14: 745 | I14: 578 | J14: 294 | K14: 142 | L14: 0 | M14: =L14 -> 0
B15: Non recurring income / (expense) | F15: 0 | G15: 0 | H15: 0 | I15: 0 | J15: 0 | K15: 0 | L15: 0 | M15: 0
B16: Other Income / (expense) | F16: 0 | G16: 0 | H16: 0 | I16: 0 | J16: 0 | K16: 0 | L16: 0 | M16: 0
B17: Effective tax rate | C17: =IncState!C35/IncState!C33 -> 0.30376344 | D17: =IncState!D35/IncState!D33 -> 0.13708319 | E17: =IncState!E35/IncState!E33 -> 0.14844498 | F17: 0.17 | G17: =F17 -> 0.17 | H17: =G17 -> 0.17 | I17: =H17 -> 0.17 | J17: =I17 -> 0.17 | K17: =J17 -> 0.17 | L17: =K17 -> 0.17 | M17: =L17 -> 0.17
B18: Dividend Payout Rate | C18: =IncState!C37 -> 0 | D18: =IncState!D37 -> 0 | E18: =IncState!E37 -> 1.5977131 | F18: =E18 -> 1.5977131 | G18: =F18 -> 1.5977131 | H18: =G18 -> 1.5977131 | I18: =H18 -> 1.5977131 | J18: =I18 -> 1.5977131 | K18: =J18 -> 1.5977131 | L18: =K18 -> 1.5977131 | M18: =L18 -> 1.5977131
B19: Basic WASO | C19: =IncState!C40 -> 992 | D19: =IncState!D40 -> 974 | E19: =IncState!E40 -> 962 | F19: =E19 -> 962 | G19: =F19 -> 962 | H19: =G19 -> 962 | I19: =H19 -> 962 | J19: =I19 -> 962 | K19: =J19 -> 962 | L19: =K19 -> 962 | M19: =L19 -> 962
B20: Diluted WASO | C20: =IncState!C41 -> 997 | D20: =IncState!D41 -> 984 | E20: =IncState!E41 -> 974 | F20: =E20 -> 974 | G20: =F20 -> 974 | H20: =G20 -> 974 | I20: =H20 -> 974 | J20: =I20 -> 974 | K20: =J20 -> 974 | L20: =K20 -> 974 | M20: =L20 -> 974
A22: * | B22: Debt | C22: 2023 | D22: =C22+1 -> 2024 | E22: =D22+1 -> 2025 | F22: =E22+1 -> 2026 | G22: =F22+1 -> 2027 | H22: =G22+1 -> 2028 | I22: =H22+1 -> 2029 | J22: =I22+1 -> 2030 | K22: =J22+1 -> 2031 | ... M22: =L22+1 -> 2033
B24: Interest rate on Revolver | F24: =E24 -> 0 | G24: =F24 -> 0 | H24: =G24 -> 0 | I24: =H24 -> 0 | J24: =I24 -> 0 | K24: =J24 -> 0 | L24: =K24 -> 0 | M24: =L24 -> 0
B25: Interest rate on long-term debt | E25: 0.03 | F25: =E25 -> 0.03 | G25: =F25 -> 0.03 | H25: =G25 -> 0.03 | I25: =H25 -> 0.03 | J25: =I25 -> 0.03 | K25: =J25 -> 0.03 | L25: =K25 -> 0.03 | M25: =L25 -> 0.03
B26: Interest rate on cash | E26: 0.05 | F26: =E26 -> 0.05 | G26: =F26 -> 0.05 | H26: =G26 -> 0.05 | I26: =H26 -> 0.05 | J26: =I26 -> 0.05 | K26: =J26 -> 0.05 | L26: =K26 -> 0.05 | M26: =L26 -> 0.05
B28: Issuance of long-term debt | F28: 0 | G28: 0 | H28: 0 | I28: 0 | J28: 0 | K28: 0 | L28: 0 | M28: 0
B29: Repayment of long-term debt | F29: 0 | G29: 0 | H29: -2500 | I29: 0 | J29: -6000 | K29: 0 | L29: 0 | M29: 0
A31: * | B31: Calcs | C31: 2023 | D31: =C31+1 -> 2024 | E31: =D31+1 -> 2025 | F31: =E31+1 -> 2026 | G31: =F31+1 -> 2027 | H31: =G31+1 -> 2028 | I31: =H31+1 -> 2029 | J31: =I31+1 -> 2030 | K31: =J31+1 -> 2031 | ... M31: =L31+1 -> 2033
B33: CapEx % of Sales | C33: =658/IncState!C17 -> 0.020987497 | D33: =736/IncState!D17 -> 0.021114841 | E33: =798/IncState!E17 -> 0.021058187 | F33: =E33 -> 0.021058187 | G33: =F33 -> 0.021058187 | H33: =G33 -> 0.021058187 | I33: =H33 -> 0.021058187 | J33: =I33 -> 0.021058187 | K33: =J33 -> 0.021058187 | L33: =K33 -> 0.021058187 | M33: =L33 -> 0.021058187
B34: Depreciation % of beginning PP&E | D34: =IncState!D23/BalSheet!C21 -> 0.36969053 | E34: =IncState!E23/BalSheet!D21 -> 0.32287366 | F34: =E34 -> 0.32287366 | G34: =F34 -> 0.32287366 | H34: =G34 -> 0.32287366 | I34: =H34 -> 0.32287366 | J34: =I34 -> 0.32287366 | K34: =J34 -> 0.32287366 | L34: =K34 -> 0.32287366 | M34: =L34 -> 0.32287366
B35: Share issuance / (repurchases) | F35: -3400 | G35: 0 | H35: 0 | I35: 0 | J35: 0 | K35: 0 | L35: 0 | M35: 0
A37: * | B37: Shareholder information | C37: 2023 | D37: =C37+1 -> 2024 | E37: =D37+1 -> 2025 | F37: =E37+1 -> 2026 | G37: =F37+1 -> 2027 | H37: =G37+1 -> 2028 | I37: =H37+1 -> 2029 | J37: =I37+1 -> 2030 | K37: =J37+1 -> 2031 | ... M37: =L37+1 -> 2033
B39: Dividend payout ratio | E39: =E18 -> 1.5977131 | F39: =E39 -> 1.5977131 | G39: =F39 -> 1.5977131 | H39: =G39 -> 1.5977131 | I39: =H39 -> 1.5977131 | J39: =I39 -> 1.5977131 | K39: =J39 -> 1.5977131 | L39: =K39 -> 1.5977131 | M39: =L39 -> 1.5977131
B40: Basic WASO | C40: =C19 -> 992 | D40: =D19 -> 974 | E40: =E19 -> 962 | F40: =F19 -> 962 | G40: =G19 -> 962 | H40: =H19 -> 962 | I40: =I19 -> 962 | J40: =J19 -> 962 | ... M40: =M19 -> 962
B41: Diluted WASO | C41: =C20 -> 997 | D41: =D20 -> 984 | E41: =E20 -> 974 | F41: =F20 -> 974 | G41: =G20 -> 974 | H41: =H20 -> 974 | I41: =I20 -> 974 | J41: =J20 -> 974 | ... M41: =M20 -> 974
A43: * | B43: Balance Sheet - Assets | C43: 2023 | D43: =C43+1 -> 2024 | E43: =D43+1 -> 2025 | F43: =E43+1 -> 2026 | G43: =F43+1 -> 2027 | H43: =G43+1 -> 2028 | I43: =H43+1 -> 2029 | J43: =I43+1 -> 2030 | K43: =J43+1 -> 2031 | ... M43: =L43+1 -> 2033
B45: Operating Cash % of sales | C45: =BalSheet!C15/IncState!C17 -> 0.05 | D45: =BalSheet!D15/IncState!D17 -> 0.05 | E45: =BalSheet!E15/IncState!E17 -> 0.05 | F45: =E45 -> 0.05 | G45: =F45 -> 0.05 | H45: =G45 -> 0.05 | I45: =H45 -> 0.05 | J45: =I45 -> 0.05 | K45: =J45 -> 0.05 | L45: =K45 -> 0.05 | M45: =L45 -> 0.05
B46: Accounts receivable % of sales | C46: =BalSheet!C17/IncState!C17 -> 0.34304032 | D46: =BalSheet!D17/IncState!D17 -> 0.32745216 | E46: =BalSheet!E17/IncState!E17 -> 0.31521309 | F46: =E46 -> 0.31521309 | G46: =F46 -> 0.31521309 | H46: =G46 -> 0.31521309 | I46: =H46 -> 0.31521309 | J46: =I46 -> 0.31521309 | K46: =J46 -> 0.31521309 | L46: =K46 -> 0.31521309 | M46: =L46 -> 0.31521309
B47: Other current assets % of sales | C47: =BalSheet!C18/IncState!C17 -> 0.27507017 | D47: =BalSheet!D18/IncState!D17 -> 0.26359124 | E47: =BalSheet!E18/IncState!E17 -> 0.2357567 | F47: =E47 -> 0.2357567 | G47: =F47 -> 0.2357567 | H47: =G47 -> 0.2357567 | I47: =H47 -> 0.2357567 | J47: =I47 -> 0.2357567 | K47: =J47 -> 0.2357567 | L47: =K47 -> 0.2357567 | M47: =L47 -> 0.2357567
B48: Investments in unconsolidated entities | C48: =BalSheet!C23 -> 4672 | D48: =BalSheet!D23 -> 4848 | E48: =BalSheet!E23 -> 4852 | F48: =E48 -> 4852 | G48: =F48 -> 4852 | H48: =G48 -> 4852 | I48: =H48 -> 4852 | J48: =I48 -> 4852 | K48: =J48 -> 4852 | L48: =K48 -> 4852 | M48: =L48 -> 4852
B49: Other long-term assets % of sales | C49: =BalSheet!C24/IncState!C17 -> 0.17533172 | D49: =BalSheet!D24/IncState!D17 -> 0.17064004 | E49: =BalSheet!E24/IncState!E17 -> 0.19118617 | F49: =E49 -> 0.19118617 | G49: =F49 -> 0.19118617 | H49: =G49 -> 0.19118617 | I49: =H49 -> 0.19118617 | J49: =I49 -> 0.19118617 | K49: =J49 -> 0.19118617 | L49: =K49 -> 0.19118617 | M49: =L49 -> 0.19118617
A51: * | B51: Balance Sheet - Liabilities | C51: 2023 | D51: =C51+1 -> 2024 | E51: =D51+1 -> 2025 | F51: =E51+1 -> 2026 | G51: =F51+1 -> 2027 | H51: =G51+1 -> 2028 | I51: =H51+1 -> 2029 | J51: =I51+1 -> 2030 | K51: =J51+1 -> 2031 | ... M51: =L51+1 -> 2033
B53: Accounts payable % of COGS | C53: =BalSheet!C30/IncState!C18 -> 0.80657895 | D53: =BalSheet!D30/IncState!D18 -> 0.71548999 | E53: =BalSheet!E30/IncState!E18 -> 0.77033437 | F53: =E53 -> 0.77033437 | G53: =F53 -> 0.77033437 | H53: =G53 -> 0.77033437 | I53: =H53 -> 0.77033437 | J53: =I53 -> 0.77033437 | K53: =J53 -> 0.77033437 | L53: =K53 -> 0.77033437 | M53: =L53 -> 0.77033437
...

Sheet Calcs
A1: =CoName -> Salesforce Inc. | C1: Hist. | D1: Hist. | E1: Hist. | F1: Proj. | G1: Proj. | H1: Proj. | I1: Proj. | J1: Proj. | K1: Proj. | L1: Proj. | M1: Proj.
A2: Net PP&E | C2: 2023 | D2: =C2+1 -> 2024 | E2: =D2+1 -> 2025 | F2: =E2+1 -> 2026 | G2: =F2+1 -> 2027 | H2: =G2+1 -> 2028 | I2: =H2+1 -> 2029 | J2: =I2+1 -> 2030 | K2: =J2+1 -> 2031 | ... M2: =L2+1 -> 2033
B3: Capital expenditure % of sales | F3: =Assumptions!F33 -> 0.021058187 | G3: =Assumptions!G33 -> 0.021058187 | H3: =Assumptions!H33 -> 0.021058187 | I3: =Assumptions!I33 -> 0.021058187 | J3: =Assumptions!J33 -> 0.021058187 | K3: =Assumptions!K33 -> 0.021058187 | L3: =Assumptions!L33 -> 0.021058187 | M3: =Assumptions!M33 -> 0.021058187
B4: Depreciation % of PP&E | F4: =Assumptions!F34 -> 0.32287366 | G4: =F4 -> 0.32287366 | H4: =G4 -> 0.32287366 | I4: =H4 -> 0.32287366 | J4: =I4 -> 0.32287366 | K4: =J4 -> 0.32287366 | L4: =K4 -> 0.32287366 | M4: =L4 -> 0.32287366
B6: Beginning PP&E | F6: =E9 -> 5393 | G6: =F9 -> 4542.8195 | H6: =G9 -> 4071.0735 | I6: =H9 -> 3867.698 | J6: =I9 -> 3859.5797 | K6: =J9 -> 3998.7908 | L6: =K9 -> 4254.6409 | M6: =L9 -> 4608.3176
B7: Capex | F7: =F3*IncState!F17 -> 891.07719 | G7: =G3*IncState!G17 -> 995.01072 | H7: =H3*IncState!H17 -> 1111.0669 | I7: =I3*IncState!I17 -> 1240.6596 | J7: =J3*IncState!J17 -> 1385.3677 | K7: =K3*IncState!K17 -> 1546.9543 | L7: =L3*IncState!L17 -> 1727.3881 | M7: =M3*IncState!M17 -> 1928.8673
B8: Depreciation | F8: =F4*F6 -> 1741.2576 | G8: =G4*G6 -> 1466.7568 | H8: =H4*H6 -> 1314.4424 | I8: =I4*I6 -> 1248.7778 | J8: =J4*J6 -> 1246.1566 | K8: =K4*K6 -> 1291.1042 | L8: =L4*L6 -> 1373.7115 | M8: =M4*M6 -> 1487.9044
B9: Ending PP&E | E9: =BalSheet!E21 -> 5393 | F9: =F6+F7-F8 -> 4542.8195 | G9: =G6+G7-G8 -> 4071.0735 | H9: =H6+H7-H8 -> 3867.698 | I9: =I6+I7-I8 -> 3859.5797 | J9: =J6+J7-J8 -> 3998.7908 | K9: =K6+K7-K8 -> 4254.6409 | L9: =L6+L7-L8 -> 4608.3176 | M9: =M6+M7-M8 -> 5049.2806
A10: Equity | C10: =C2 -> 2023 | D10: =D2 -> 2024 | E10: =E2 -> 2025 | F10: =F2 -> 2026 | G10: =G2 -> 2027 | H10: =H2 -> 2028 | I10: =I2 -> 2029 | J10: =J2 -> 2030 | ... M10: =M2 -> 2033
B11: Share issuance/(repurchases) | F11: =Assumptions!F35 -> -3400 | G11: =Assumptions!G35 -> 0 | H11: =Assumptions!H35 -> 0 | I11: =Assumptions!I35 -> 0 | J11: =Assumptions!J35 -> 0 | K11: =Assumptions!K35 -> 0 | L11: =Assumptions!L35 -> 0 | M11: =Assumptions!M35 -> 0
B13: Beginning balance | F13: =E17 -> 61173 | G13: =F17 -> 63692.137 | H13: =G17 -> 70873.123 | I13: =H17 -> 79508.88 | J13: =I17 -> 89820.17 | K13: =J17 -> 102059.46 | L13: =K17 -> 116515.31 | M13: =L17 -> 133517.39
B14: Net income | F14: =IncState!F36 -> 7456.1369 | G14: =IncState!G36 -> 8717.9859 | H14: =IncState!H36 -> 10172.758 | I14: =IncState!I36 -> 11848.289 | J14: =IncState!J36 -> 13776.288 | K14: =IncState!K36 -> 15992.854 | L14: =IncState!L36 -> 18539.073 | M14: =IncState!M36 -> 21461.69
B15: Dividends paid | F15: =-IncState!F38 -> -1537 | G15: =-IncState!G38 -> -1537 | H15: =-IncState!H38 -> -1537 | I15: =-IncState!I38 -> -1537 | J15: =-IncState!J38 -> -1537 | K15: =-IncState!K38 -> -1537 | L15: =-IncState!L38 -> -1537 | M15: =-IncState!M38 -> -1537
B16: Share issuance / (repurchase) | F16: =F11 -> -3400 | G16: =G11 -> 0 | H16: =H11 -> 0 | I16: =I11 -> 0 | J16: =J11 -> 0 | K16: =K11 -> 0 | L16: =L11 -> 0 | M16: =M11 -> 0
B17: Ending balance | E17: =BalSheet!E38 -> 61173 | F17: =SUM(F13:F16) -> 63692.137 | G17: =SUM(G13:G16) -> 70873.123 | H17: =SUM(H13:H16) -> 79508.88 | I17: =SUM(I13:I16) -> 89820.17 | J17: =SUM(J13:J16) -> 102059.46 | K17: =SUM(K13:K16) -> 116515.31 | L17: =SUM(L13:L16) -> 133517.39 | M17: =SUM(M13:M16) -> 153442.08
A18: OWC | C18: =C10 -> 2023 | D18: =D10 -> 2024 | E18: =E10 -> 2025 | F18: =F10 -> 2026 | G18: =G10 -> 2027 | H18: =H10 -> 2028 | I18: =I10 -> 2029 | J18: =J10 -> 2030 | ... M18: =M10 -> 2033
B19: Operating Cash | E19: =BalSheet!E15 -> 1894.75 | F19: =BalSheet!F15 -> 2115.75 | G19: =BalSheet!G15 -> 2362.527 | H19: =BalSheet!H15 -> 2638.0876 | I19: =BalSheet!I15 -> 2945.7891 | J19: =BalSheet!J15 -> 3289.3803 | K19: =BalSheet!K15 -> 3673.0473 | L19: =BalSheet!L15 -> 4101.4645 | M19: =BalSheet!M15 -> 4579.8514
B20: =BalSheet!B17 -> Accounts receivable | E20: =BalSheet!E17 -> 11945 | F20: =BalSheet!F17 -> 13338.242 | G20: =BalSheet!G17 -> 14893.989 | H20: =BalSheet!H17 -> 16631.195 | I20: =BalSheet!I17 -> 18571.026 | J20: =BalSheet!J17 -> 20737.114 | K20: =BalSheet!K17 -> 23155.852 | L20: =BalSheet!L17 -> 25856.706 | M20: =BalSheet!M17 -> 28872.582
B21: Other current assets | E21: =BalSheet!E18 -> 8934 | F21: =BalSheet!F18 -> 9976.0446 | G21: =BalSheet!G18 -> 11139.631 | H21: =BalSheet!H18 -> 12438.936 | I21: =BalSheet!I18 -> 13889.79 | J21: =BalSheet!J18 -> 15509.869 | K21: =BalSheet!K18 -> 17318.91 | L21: =BalSheet!L18 -> 19338.954 | M21: =BalSheet!M18 -> 21594.613
B22: Accounts payables | E22: =BalSheet!E30 -> 6658 | F22: =BalSheet!F30 -> 7434.5763 | G22: =BalSheet!G30 -> 8301.731 | H22: =BalSheet!H30 -> 9270.029 | I22: =BalSheet!I30 -> 10351.267 | J22: =BalSheet!J30 -> 11558.619 | K22: =BalSheet!K30 -> 12906.794 | L22: =BalSheet!L30 -> 14412.218 | M22: =BalSheet!M30 -> 16093.232
B23: Other current liabilities | E23: =BalSheet!E31 -> 21322 | F23: =BalSheet!F31 -> 23808.957 | G23: =BalSheet!G31 -> 26585.988 | H23: =BalSheet!H31 -> 29686.927 | I23: =BalSheet!I31 -> 33149.553 | J23: =BalSheet!J31 -> 37016.053 | K23: =BalSheet!K31 -> 41333.534 | L23: =BalSheet!L31 -> 46154.598 | M23: =BalSheet!M31 -> 51537.982
A24: * | B24: OWC | E24: =SUM(E19:E21)-SUM(E22:E23) -> -5206.25 | F24: =SUM(F19:F21)-SUM(F22:F23) -> -5813.497 | G24: =SUM(G19:G21)-SUM(G22:G23) -> -6491.5721 | H24: =SUM(H19:H21)-SUM(H22:H23) -> -7248.7366 | I24: =SUM(I19:I21)-SUM(I22:I23) -> -8094.2153 | J24: =SUM(J19:J21)-SUM(J22:J23) -> -9038.3091 | K24: =SUM(K19:K21)-SUM(K22:K23) -> -10092.52 | L24: =SUM(L19:L21)-SUM(L22:L23) -> -11269.692 | M24: =SUM(M19:M21)-SUM(M22:M23) -> -12584.167
B25: Change in OWC | F25: =E24-F24 -> 607.247 | G25: =F24-G24 -> 678.07512 | H25: =G24-H24 -> 757.1645 | I25: =H24-I24 -> 845.47871 | J25: =I24-J24 -> 944.09373 | K25: =J24-K24 -> 1054.211 | L25: =K24-L24 -> 1177.1722 | M25: =L24-M24 -> 1314.4753

Sheet Debt
A1: =CoName -> Salesforce Inc. | C1: Hist. | D1: Hist. | E1: Hist. | F1: Proj. | G1: Proj. | H1: Proj. | I1: Proj. | J1: Proj. | K1: Proj. | L1: Proj. | M1: Proj.
A2: Assumptions | C2: 2023 | D2: =C2+1 -> 2024 | E2: =D2+1 -> 2025 | F2: =E2+1 -> 2026 | G2: =F2+1 -> 2027 | H2: =G2+1 -> 2028 | I2: =H2+1 -> 2029 | J2: =I2+1 -> 2030 | K2: =J2+1 -> 2031 | ... M2: =L2+1 -> 2033
B4: Interest rate on revolver | F4: =Assumptions!F24 -> 0 | G4: =Assumptions!G24 -> 0 | H4: =Assumptions!H24 -> 0 | I4: =Assumptions!I24 -> 0 | J4: =Assumptions!J24 -> 0 | K4: =Assumptions!K24 -> 0 | L4: =Assumptions!L24 -> 0 | M4: =Assumptions!M24 -> 0
B5: Interest rate on long-term debt | F5: =Assumptions!F25 -> 0.03 | G5: =Assumptions!G25 -> 0.03 | H5: =Assumptions!H25 -> 0.03 | I5: =Assumptions!I25 -> 0.03 | J5: =Assumptions!J25 -> 0.03 | K5: =Assumptions!K25 -> 0.03 | L5: =Assumptions!L25 -> 0.03 | M5: =Assumptions!M25 -> 0.03
B6: Interest rate on cash | F6: =Assumptions!F26 -> 0.05 | G6: =Assumptions!G26 -> 0.05 | H6: =Assumptions!H26 -> 0.05 | I6: =Assumptions!I26 -> 0.05 | J6: =Assumptions!J26 -> 0.05 | K6: =Assumptions!K26 -> 0.05 | L6: =Assumptions!L26 -> 0.05 | M6: =Assumptions!M26 -> 0.05
B8: Issuance of long-term debt | F8: =Assumptions!F28 -> 0 | G8: =Assumptions!G28 -> 0 | H8: =Assumptions!H28 -> 0 | I8: =Assumptions!I28 -> 0 | J8: =Assumptions!J28 -> 0 | K8: =Assumptions!K28 -> 0 | L8: =Assumptions!L28 -> 0 | M8: =Assumptions!M28 -> 0
B9: Repayment of long-term debt | F9: =Assumptions!F29 -> 0 | G9: =Assumptions!G29 -> 0 | H9: =Assumptions!H29 -> -2500 | I9: 67 | J9: =Assumptions!J29 -> -6000 | K9: =Assumptions!K29 -> 0 | L9: =Assumptions!L29 -> 0 | M9: =Assumptions!M29 -> 0
A11: Revolver | C11: 2023 | D11: =C11+1 -> 2024 | E11: =D11+1 -> 2025 | F11: =E11+1 -> 2026 | G11: =F11+1 -> 2027 | H11: =G11+1 -> 2028 | I11: =H11+1 -> 2029 | J11: =I11+1 -> 2030 | K11: =J11+1 -> 2031 | ... M11: =L11+1 -> 2033
B12: Balance | F12: NO REVOLVER | G12: NO REVOLVER | H12: NO REVOLVER | I12: NO REVOLVER | J12: NO REVOLVER | K12: NO REVOLVER | L12: NO REVOLVER | M12: NO REVOLVER
B13: Interest rate
B14: Interest expense
A16: Long term debt | C16: 2023 | D16: =C16+1 -> 2024 | E16: =D16+1 -> 2025 | F16: =E16+1 -> 2026 | G16: =F16+1 -> 2027 | H16: =G16+1 -> 2028 | I16: =H16+1 -> 2029 | J16: =I16+1 -> 2030 | K16: =J16+1 -> 2031 | ... M16: =L16+1 -> 2033
B17: Beginning balance | F17: =E20 -> 8433 | G17: =F20 -> 8433 | H17: =G20 -> 8433 | I17: =H20 -> 5933 | J17: =I20 -> 6000 | K17: =J20 -> 0 | L17: =K20 -> 0 | M17: =L20 -> 0
B18: Issuance | F18: =F8 -> 0 | G18: =G8 -> 0 | H18: =H8 -> 0 | I18: =I8 -> 0 | J18: =J8 -> 0 | K18: =K8 -> 0 | L18: =L8 -> 0 | M18: =M8 -> 0
B19: Repayment | F19: =F9 -> 0 | G19: =G9 -> 0 | H19: =H9 -> -2500 | I19: =I9 -> 67 | J19: =J9 -> -6000 | K19: =K9 -> 0 | L19: =L9 -> 0 | M19: =M9 -> 0
B20: Ending balance | E20: =BalSheet!E34 -> 8433 | F20: =SUM(F17:F19) -> 8433 | G20: =SUM(G17:G19) -> 8433 | H20: =SUM(H17:H19) -> 5933 | I20: =SUM(I17:I19) -> 6000 | J20: =SUM(J17:J19) -> 0 | K20: =SUM(K17:K19) -> 0 | L20: =SUM(L17:L19) -> 0 | M20: =SUM(M17:M19) -> 0
B21: Interest rate | F21: =F5 -> 0.03 | G21: =G5 -> 0.03 | H21: =H5 -> 0.03 | I21: =I5 -> 0.03 | J21: =J5 -> 0.03 | K21: =K5 -> 0.03 | L21: =L5 -> 0.03 | M21: =M5 -> 0.03
B22: Interest expense | F22: =F20*F21 -> 252.99 | G22: =G20*G21 -> 252.99 | H22: =H20*H21 -> 177.99 | I22: =I20*I21 -> 180 | J22: =J20*J21 -> 0 | K22: =K20*K21 -> 0 | L22: =L20*L21 -> 0 | M22: =M20*M21 -> 0
A24: Debt summary | C24: 2023 | D24: =C24+1 -> 2024 | E24: =D24+1 -> 2025 | F24: =E24+1 -> 2026 | G24: =F24+1 -> 2027 | H24: =G24+1 -> 2028 | I24: =H24+1 -> 2029 | J24: =I24+1 -> 2030 | K24: =J24+1 -> 2031 | ... M24: =L24+1 -> 2033
B25: Revolver | F25: NO REVOLVER | G25: NO REVOLVER | H25: NO REVOLVER | I25: NO REVOLVER | J25: NO REVOLVER | K25: NO REVOLVER | L25: NO REVOLVER | M25: NO REVOLVER
B26: Total long term debt | F26: =F20 -> 8433 | G26: =G20 -> 8433 | H26: =H20 -> 5933 | I26: =I20 -> 6000 | J26: =J20 -> 0 | K26: =K20 -> 0 | L26: =L20 -> 0 | M26: =M20 -> 0
B27: Total debt | F27: =SUM(F25:F26) -> 8433 | G27: =SUM(G25:G26) -> 8433 | H27: =SUM(H25:H26) -> 5933 | I27: =SUM(I25:I26) -> 6000 | J27: =SUM(J25:J26) -> 0 | K27: =SUM(K25:K26) -> 0 | L27: =SUM(L25:L26) -> 0 | M27: =SUM(M25:M26) -> 0
B28: Total interest expense | F28: =F22 -> 252.99 | G28: =G22 -> 252.99 | H28: =H22 -> 177.99 | I28: =I22 -> 180 | J28: =J22 -> 0 | K28: =K22 -> 0 | L28: =L22 -> 0 | M28: =M22 -> 0
A30: Interest income | C30: 2023 | D30: =C30+1 -> 2024 | E30: =D30+1 -> 2025 | F30: =E30+1 -> 2026 | G30: =F30+1 -> 2027 | H30: =G30+1 -> 2028 | I30: =H30+1 -> 2029 | J30: =I30+1 -> 2030 | K30: =J30+1 -> 2031 | ... M30: =L30+1 -> 2033
B31: Excess Cash | F31: =BalSheet!F16 -> 12229.852 | G31: =BalSheet!G16 -> 21459.808 | H31: =BalSheet!H16 -> 29024.345 | I31: =BalSheet!I16 -> 40525.19 | J31: =BalSheet!J16 -> 47518.274 | K31: =BalSheet!K16 -> 62529.151 | L31: =BalSheet!L16 -> 79924.437 | M31: =BalSheet!M16 -> 100242.17
B32: Interest rate | F32: =F6 -> 0.05 | G32: =G6 -> 0.05 | H32: =H6 -> 0.05 | I32: =I6 -> 0.05 | J32: =J6 -> 0.05 | K32: =K6 -> 0.05 | L32: =L6 -> 0.05 | M32: =M6 -> 0.05
B33: Interest income | F33: =F31*F32 -> 611.49261 | G33: =G31*G32 -> 1072.9904 | H33: =H31*H32 -> 1451.2172 | I33: =I31*I32 -> 2026.2595 | J33: =J31*J32 -> 2375.9137 | K33: =K31*K32 -> 3126.4576 | L33: =L31*L32 -> 3996.2218 | M33: =M31*M32 -> 5012.1085

Sheet IncState
A1: =CoName -> Salesforce Inc. | C1: Hist. | D1: Hist. | E1: Hist. | F1: Proj. | G1: Proj. | H1: Proj. | I1: Proj. | J1: Proj. | K1: Proj. | L1: Proj. | M1: Proj.
A2: Assumptions | C2: 2023 | D2: =C2+1 -> 2024 | E2: =D2+1 -> 2025 | F2: =E2+1 -> 2026 | G2: =F2+1 -> 2027 | H2: =G2+1 -> 2028 | I2: =H2+1 -> 2029 | J2: =I2+1 -> 2030 | K2: =J2+1 -> 2031 | ... M2: =L2+1 -> 2033
B4: Revenue growth | F4: =Assumptions!F10 -> 0.11663808 | G4: =Assumptions!G10 -> 0.11663808 | H4: =Assumptions!H10 -> 0.11663808 | I4: =Assumptions!I10 -> 0.11663808 | J4: =Assumptions!J10 -> 0.11663808 | K4: =Assumptions!K10 -> 0.11663808 | L4: =Assumptions!L10 -> 0.11663808 | M4: =Assumptions!M10 -> 0.11663808
B5: Cost of goods sold as % of sales | F5: =Assumptions!F11 -> 0.22807758 | G5: =Assumptions!G11 -> 0.22807758 | H5: =Assumptions!H11 -> 0.22807758 | I5: =Assumptions!I11 -> 0.22807758 | J5: =Assumptions!J11 -> 0.22807758 | K5: =Assumptions!K11 -> 0.22807758 | L5: =Assumptions!L11 -> 0.22807758 | M5: =Assumptions!M11 -> 0.22807758
B6: R&D % of sales | F6: =Assumptions!F12 -> 0.14495316 | G6: =Assumptions!G12 -> 0.14495316 | H6: =Assumptions!H12 -> 0.14495316 | I6: =Assumptions!I12 -> 0.14495316 | J6: =Assumptions!J12 -> 0.14495316 | K6: =Assumptions!K12 -> 0.14495316 | L6: =Assumptions!L12 -> 0.14495316 | M6: =Assumptions!M12 -> 0.14495316
B7: SG&A % of sales | F7: =Assumptions!F13 -> 0.41467344 | G7: =Assumptions!G13 -> 0.40467344 | H7: =Assumptions!H13 -> 0.39467344 | I7: =Assumptions!I13 -> 0.38467344 | J7: =Assumptions!J13 -> 0.37467344 | K7: =Assumptions!K13 -> 0.36467344 | L7: =Assumptions!L13 -> 0.35467344 | M7: =Assumptions!M13 -> 0.34467344
B8: Amortization amount | F8: =Assumptions!F14 -> 1522 | G8: =Assumptions!G14 -> 1147 | H8: =Assumptions!H14 -> 745 | I8: =Assumptions!I14 -> 578 | J8: =Assumptions!J14 -> 294 | K8: =Assumptions!K14 -> 142 | L8: =Assumptions!L14 -> 0 | M8: =Assumptions!M14 -> 0
B9: Non recurring items, amount | F9: =Assumptions!F15 -> 0 | G9: =Assumptions!G15 -> 0 | H9: =Assumptions!H15 -> 0 | I9: =Assumptions!I15 -> 0 | J9: =Assumptions!J15 -> 0 | K9: =Assumptions!K15 -> 0 | L9: =Assumptions!L15 -> 0 | M9: =Assumptions!M15 -> 0
B10: Other income (expense), amt | F10: =Assumptions!F16 -> 0 | G10: =Assumptions!G16 -> 0 | H10: =Assumptions!H16 -> 0 | I10: =Assumptions!I16 -> 0 | J10: =Assumptions!J16 -> 0 | K10: =Assumptions!K16 -> 0 | L10: =Assumptions!L16 -> 0 | M10: =Assumptions!M16 -> 0
B11: Effective tax rate | F11: =Assumptions!F17 -> 0.17 | G11: =Assumptions!G17 -> 0.17 | H11: =Assumptions!H17 -> 0.17 | I11: =Assumptions!I17 -> 0.17 | J11: =Assumptions!J17 -> 0.17 | K11: =Assumptions!K17 -> 0.17 | L11: =Assumptions!L17 -> 0.17 | M11: =Assumptions!M17 -> 0.17
B12: Dividend payout ratio | F12: =Assumptions!F18 -> 1.5977131 | G12: =Assumptions!G18 -> 1.5977131 | H12: =Assumptions!H18 -> 1.5977131 | I12: =Assumptions!I18 -> 1.5977131 | J12: =Assumptions!J18 -> 1.5977131 | K12: =Assumptions!K18 -> 1.5977131 | L12: =Assumptions!L18 -> 1.5977131 | M12: =Assumptions!M18 -> 1.5977131
B13: Basic WASO | F13: =Assumptions!F19 -> 962 | G13: =Assumptions!G19 -> 962 | H13: =Assumptions!H19 -> 962 | I13: =Assumptions!I19 -> 962 | J13: =Assumptions!J19 -> 962 | K13: =Assumptions!K19 -> 962 | L13: =Assumptions!L19 -> 962 | M13: =Assumptions!M19 -> 962
B14: Diluted WASO | F14: =Assumptions!F20 -> 974 | G14: =Assumptions!G20 -> 974 | H14: =Assumptions!H20 -> 974 | I14: =Assumptions!I20 -> 974 | J14: =Assumptions!J20 -> 974 | K14: =Assumptions!K20 -> 974 | L14: =Assumptions!L20 -> 974 | M14: =Assumptions!M20 -> 974
A16: Income statement | C16: 2023 | D16: =C16+1 -> 2024 | E16: =D16+1 -> 2025 | F16: =E16+1 -> 2026 | G16: =F16+1 -> 2027 | H16: =G16+1 -> 2028 | I16: =H16+1 -> 2029 | J16: =I16+1 -> 2030 | K16: =J16+1 -> 2031 | ... M16: =L16+1 -> 2033
B17: Revenue | C17: =Quarters!G5 -> 31352 | D17: =Quarters!L5 -> 34857 | E17: =Quarters!Q5 -> 37895 | F17: =E17*(1+F4) -> 42315 | G17: =F17*(1+G4) -> 47250.54 | H17: =G17*(1+H4) -> 52761.753 | I17: =H17*(1+I4) -> 58915.782 | J17: =I17*(1+J4) -> 65787.606 | K17: =J17*(1+K4) -> 73460.946 | L17: =K17*(1+L4) -> 82029.289 | M17: =L17*(1+M4) -> 91597.028
B18: COGS | C18: =Quarters!G6 -> 8360 | D18: =Quarters!L6 -> 8541 | E18: =Quarters!Q6 -> 8643 | F18: =F17*F5 -> 9651.1029 | G18: =G17*G5 -> 10776.789 | H18: =H17*H5 -> 12033.773 | I18: =I17*I5 -> 13437.369 | J18: =J17*J5 -> 15004.678 | K18: =K17*K5 -> 16754.795 | L18: =L17*L5 -> 18709.042 | M18: =M17*M5 -> 20891.229
B19: R&D | C19: =Quarters!G7 -> 5055 | D19: =Quarters!L7 -> 4906 | E19: =Quarters!Q7 -> 5493 | F19: =F17*F6 -> 6133.693 | G19: =G17*G6 -> 6849.1151 | H19: =H17*H6 -> 7647.9828 | I19: =I17*I6 -> 8540.0288 | J19: =J17*J6 -> 9536.1213 | K19: =K17*K6 -> 10648.396 | L19: =L17*L6 -> 11890.405 | M19: =M17*M6 -> 13277.279
B20: SG&A | C20: =Quarters!G8 -> 16079 | D20: =Quarters!L8 -> 15411 | E20: =Quarters!Q8 -> 16093 | F20: =F17*F7 -> 17546.907 | G20: =G17*G7 -> 19121.039 | H20: =H17*H7 -> 20823.662 | I20: =I17*I7 -> 22663.337 | J20: =J17*J7 -> 24648.869 | K20: =K17*K7 -> 26789.256 | L20: =L17*L7 -> 29093.61 | M20: =M17*M7 -> 31571.063
A21: * | B21: EBIT | C21: =C17-SUM(C18:C20) -> 1858 | D21: =D17-SUM(D18:D20) -> 5999 | E21: =E17-SUM(E18:E20) -> 7666 | F21: =F17-SUM(F18:F20) -> 8983.2975 | G21: =G17-SUM(G18:G20) -> 10503.597 | H21: =H17-SUM(H18:H20) -> 12256.334 | I21: =I17-SUM(I18:I20) -> 14275.048 | J21: =J17-SUM(J18:J20) -> 16597.938 | ... M21: =M17-SUM(M18:M20) -> 25857.458
B23: Depreciation | C23: =3786-C24 -> 2264 | D23: =3959-D24 -> 2437 | E23: =3477-E24 -> 1955 | F23: =Calcs!F8 -> 1741.2576 | G23: =Calcs!G8 -> 1466.7568 | H23: =Calcs!H8 -> 1314.4424 | I23: =Calcs!I8 -> 1248.7778 | J23: =Calcs!J8 -> 1246.1566 | K23: =Calcs!K8 -> 1291.1042 | L23: =Calcs!L8 -> 1373.7115 | M23: =Calcs!M8 -> 1487.9044
B24: Amortization | C24: 1522 | D24: 1522 | E24: 1522 | F24: =F8 -> 1522 | G24: =G8 -> 1147 | H24: =H8 -> 745 | I24: =I8 -> 578 | J24: =J8 -> 294 | K24: =K8 -> 142 | L24: =L8 -> 0 | M24: =M8 -> 0
A25: * | B25: EBITDA | C25: =C21+C23 -> 4122 | D25: =D21+D23 -> 8436 | E25: =E21+E23 -> 9621 | F25: =F21+F23 -> 10724.555 | G25: =G21+G23 -> 11970.354 | H25: =H21+H23 -> 13570.777 | I25: =I21+I23 -> 15523.825 | J25: =J21+J23 -> 17844.094 | ... M25: =M21+M23 -> 27345.362
B27: Non-recurring items | C27: =Quarters!G9 -> 828 | D27: =Quarters!L9 -> 988 | E27: =Quarters!Q9 -> 461 | F27: =F9 -> 0 | G27: =G9 -> 0 | H27: =H9 -> 0 | I27: =I9 -> 0 | J27: =J9 -> 0 | K27: =K9 -> 0 | L27: =L9 -> 0 | M27: =M9 -> 0
B28: Other income (expense) | C28: =Quarters!G11 -> -370 | D28: =Quarters!L11 -> -61 | E28: =Quarters!Q11 -> 233 | F28: =F10 -> 0 | G28: =G10 -> 0 | H28: =H10 -> 0 | I28: =I10 -> 0 | J28: =J10 -> 0 | K28: =K10 -> 0 | L28: =L10 -> 0 | M28: =M10 -> 0
B30: Interest income | C30: 0 | D30: 0 | E30: 0 | F30: =IF(circ=1,Debt!F33,0) -> 0 | G30: =IF(circ=1,Debt!G33,0) -> 0 | H30: =IF(circ=1,Debt!H33,0) -> 0 | I30: =IF(circ=1,Debt!I33,0) -> 0 | J30: =IF(circ=1,Debt!J33,0) -> 0 | K30: =IF(circ=1,Debt!K33,0) -> 0 | L30: =IF(circ=1,Debt!L33,0) -> 0 | M30: =IF(circ=1,Debt!M33,0) -> 0
B31: Interest expense | C31: 0 | D31: 0 | E31: 0 | F31: =IF(circ=1,-Debt!F28,0) -> 0 | G31: =IF(circ=1,-Debt!G28,0) -> 0 | H31: =IF(circ=1,-Debt!H28,0) -> 0 | I31: =IF(circ=1,-Debt!I28,0) -> 0 | J31: =IF(circ=1,-Debt!J28,0) -> 0 | K31: =IF(circ=1,-Debt!K28,0) -> 0 | L31: =IF(circ=1,-Debt!L28,0) -> 0 | M31: =IF(circ=1,-Debt!M28,0) -> 0
A33: * | B33: Pretax Income | C33: =C21+SUM(C28:C31) -> 1488 | D33: =D21+SUM(D28:D31) -> 5938 | E33: =E21+SUM(E27:E31) -> 8360 | F33: =F21+SUM(F27:F31) -> 8983.2975 | G33: =G21+SUM(G27:G31) -> 10503.597 | H33: =H21+SUM(H27:H31) -> 12256.334 | I33: =I21+SUM(I27:I31) -> 14275.048 | J33: =J21+SUM(J27:J31) -> 16597.938 | K33: =K21+SUM(K27:K31) -> 19268.499 | L33: =L21+SUM(L27:L31) -> 22336.232 | M33: =M21+SUM(M27:M31) -> 25857.458
B35: Tax expense | C35: 452 | D35: 814 | E35: 1241 | F35: =F33*F11 -> 1527.1606 | G35: =G33*G11 -> 1785.6116 | H35: =H33*H11 -> 2083.5769 | I35: =I33*I11 -> 2426.7581 | J35: =J33*J11 -> 2821.6494 | K35: =K33*K11 -> 3275.6448 | L35: =L33*L11 -> 3797.1595 | M35: =M33*M11 -> 4395.7678
A36: * | B36: Net income | C36: =C33-C35 -> 1036 | D36: =D33-D35 -> 5124 | E36: =E33-E35 -> 7119 | F36: =F33-F35 -> 7456.1369 | G36: =G33-G35 -> 8717.9859 | H36: =H33-H35 -> 10172.758 | I36: =I33-I35 -> 11848.289 | J36: =J33-J35 -> 13776.288 | ... M36: =M33-M35 -> 21461.69
B37: Dividend payout rate | C37: =C38/C40 -> 0 | D37: =D38/D40 -> 0 | E37: =E38/E40 -> 1.5977131 | F37: =F12 -> 1.5977131 | G37: =G12 -> 1.5977131 | H37: =H12 -> 1.5977131 | I37: =I12 -> 1.5977131 | J37: =J12 -> 1.5977131 | K37: =K12 -> 1.5977131 | L37: =L12 -> 1.5977131 | M37: =M12 -> 1.5977131
B38: Diviends | C38: 0 | D38: 0 | E38: 1537 | F38: =F37*F40 -> 1537 | G38: =G37*G40 -> 1537 | H38: =H37*H40 -> 1537 | I38: =I37*I40 -> 1537 | J38: =J37*J40 -> 1537 | K38: =K37*K40 -> 1537 | L38: =L37*L40 -> 1537 | M38: =M37*M40 -> 1537
A39: Shareholder information | C39: 2023 | D39: =C39+1 -> 2024 | E39: =D39+1 -> 2025 | F39: =E39+1 -> 2026 | G39: =F39+1 -> 2027 | H39: =G39+1 -> 2028 | I39: =H39+1 -> 2029 | J39: =I39+1 -> 2030 | K39: =J39+1 -> 2031 | ... M39: =L39+1 -> 2033
B40: Basic WASO | C40: 992 | D40: 974 | E40: 962 | F40: 962 | G40: 962 | H40: 962 | I40: 962 | J40: 962 | K40: 962 | L40: 962 | M40: 962
B41: Diluted WASO | C41: 997 | D41: 984 | E41: 974 | F41: 974 | G41: 974 | H41: 974 | I41: 974 | J41: 974 | K41: 974 | L41: 974 | M41: 974
B42: Basic earnings per share | C42: =C36/C40 -> 1.0443548 | D42: =D36/D40 -> 5.2607803 | E42: =E36/E40 -> 7.4002079 | F42: =F36/F40 -> 7.7506621 | G42: =G36/G40 -> 9.0623554 | H42: =H36/H40 -> 10.574592 | I42: =I36/I40 -> 12.316309 | J42: =J36/J40 -> 14.320466 | ... M42: =M36/M40 -> 22.309449
A43: * | B43: Diluted earnings per share | C43: =C36/C41 -> 1.0391174 | D43: =D36/D41 -> 5.2073171 | E43: =E36/E41 -> 7.3090349 | F43: =F36/F41 -> 7.6551714 | G43: =G36/G41 -> 8.9507042 | H43: =H36/H41 -> 10.44431 | I43: =I36/I41 -> 12.164568 | J43: =J36/J41 -> 14.144033 | ... M43: =M36/M41 -> 22.034589

Sheet BalSheet
A1: =CoName -> Salesforce Inc. | C1: Hist. | D1: Hist. | E1: Hist. | F1: Proj. | G1: Proj. | H1: Proj. | I1: Proj. | J1: Proj. | K1: Proj. | L1: Proj. | M1: Proj.
A2: Assumptions | C2: 2023 | D2: =C2+1 -> 2024 | E2: =D2+1 -> 2025 | F2: =E2+1 -> 2026 | G2: =F2+1 -> 2027 | H2: =G2+1 -> 2028 | I2: =H2+1 -> 2029 | J2: =I2+1 -> 2030 | K2: =J2+1 -> 2031 | ... M2: =L2+1 -> 2033
B4: Operating Cash % of sales | F4: =Assumptions!F45 -> 0.05 | G4: =F4 -> 0.05 | H4: =G4 -> 0.05 | I4: =H4 -> 0.05 | J4: =I4 -> 0.05 | K4: =J4 -> 0.05 | L4: =K4 -> 0.05 | M4: =L4 -> 0.05
B5: Accounts receivable % of sales | F5: =Assumptions!F46 -> 0.31521309 | G5: =Assumptions!G46 -> 0.31521309 | H5: =Assumptions!H46 -> 0.31521309 | I5: =Assumptions!I46 -> 0.31521309 | J5: =Assumptions!J46 -> 0.31521309 | K5: =Assumptions!K46 -> 0.31521309 | L5: =Assumptions!L46 -> 0.31521309 | M5: =Assumptions!M46 -> 0.31521309
B6: Other current assets % of sales | F6: =Assumptions!F47 -> 0.2357567 | G6: =Assumptions!G47 -> 0.2357567 | H6: =Assumptions!H47 -> 0.2357567 | I6: =Assumptions!I47 -> 0.2357567 | J6: =Assumptions!J47 -> 0.2357567 | K6: =Assumptions!K47 -> 0.2357567 | L6: =Assumptions!L47 -> 0.2357567 | M6: =Assumptions!M47 -> 0.2357567
B7: Other long-term assets % of sales | F7: =Assumptions!F49 -> 0.19118617 | G7: =Assumptions!G49 -> 0.19118617 | H7: =Assumptions!H49 -> 0.19118617 | I7: =Assumptions!I49 -> 0.19118617 | J7: =Assumptions!J49 -> 0.19118617 | K7: =Assumptions!K49 -> 0.19118617 | L7: =Assumptions!L49 -> 0.19118617 | M7: =Assumptions!M49 -> 0.19118617
B8: Investment in unconsolidated entities $ balance | F8: =Assumptions!F48 -> 4852 | G8: =Assumptions!G48 -> 4852 | H8: =Assumptions!H48 -> 4852 | I8: =Assumptions!I48 -> 4852 | J8: =Assumptions!J48 -> 4852 | K8: =Assumptions!K48 -> 4852 | L8: =Assumptions!L48 -> 4852 | M8: =Assumptions!M48 -> 4852
B10: Accounts payable/Accural % of COGS | F10: =Assumptions!F53 -> 0.77033437 | G10: =Assumptions!G53 -> 0.77033437 | H10: =Assumptions!H53 -> 0.77033437 | I10: =Assumptions!I53 -> 0.77033437 | J10: =Assumptions!J53 -> 0.77033437 | K10: =Assumptions!K53 -> 0.77033437 | L10: =Assumptions!L53 -> 0.77033437 | M10: =Assumptions!M53 -> 0.77033437
B11: Other current liabilities % of sales | F11: =Assumptions!F54 -> 0.56265998 | G11: =Assumptions!G54 -> 0.56265998 | H11: =Assumptions!H54 -> 0.56265998 | I11: =Assumptions!I54 -> 0.56265998 | J11: =Assumptions!J54 -> 0.56265998 | K11: =Assumptions!K54 -> 0.56265998 | L11: =Assumptions!L54 -> 0.56265998 | M11: =Assumptions!M54 -> 0.56265998
B12: Other long-term liabilities % of sales | F12: =Assumptions!F55 -> 0.14096847 | G12: =Assumptions!G55 -> 0.14096847 | H12: =Assumptions!H55 -> 0.14096847 | I12: =Assumptions!I55 -> 0.14096847 | J12: =Assumptions!J55 -> 0.14096847 | K12: =Assumptions!K55 -> 0.14096847 | L12: =Assumptions!L55 -> 0.14096847 | M12: =Assumptions!M55 -> 0.14096847
A14: Balance sheet | C14: 2023 | D14: =C14+1 -> 2024 | E14: =D14+1 -> 2025 | F14: =E14+1 -> 2026 | G14: =F14+1 -> 2027 | H14: =G14+1 -> 2028 | I14: =H14+1 -> 2029 | J14: =I14+1 -> 2030 | K14: =J14+1 -> 2031 | ... M14: =L14+1 -> 2033
B15: Operating Cash | C15: =IncState!C17*5% -> 1567.6 | D15: =IncState!D17*5% -> 1742.85 | E15: =IncState!E17*5% -> 1894.75 | F15: =F4*IncState!F17 -> 2115.75 | G15: =G4*IncState!G17 -> 2362.527 | H15: =H4*IncState!H17 -> 2638.0876 | I15: =I4*IncState!I17 -> 2945.7891 | J15: =J4*IncState!J17 -> 3289.3803 | K15: =K4*IncState!K17 -> 3673.0473 | L15: =L4*IncState!L17 -> 4101.4645 | M15: =M4*IncState!M17 -> 4579.8514
B16: Excess cash | C16: =7016-C15 -> 5448.4 | D16: =8472-D15 -> 6729.15 | E16: =8848-E15 -> 6953.25 | F16: =MAX(CashFlow!F23,0) -> 12229.852 | G16: =MAX(CashFlow!G23,0) -> 21459.808 | H16: =MAX(CashFlow!H23,0) -> 29024.345 | I16: =MAX(CashFlow!I23,0) -> 40525.19 | J16: =MAX(CashFlow!J23,0) -> 47518.274 | K16: =MAX(CashFlow!K23,0) -> 62529.151 | L16: =MAX(CashFlow!L23,0) -> 79924.437 | M16: =MAX(CashFlow!M23,0) -> 100242.17
B17: Accounts receivable | C17: =10755 -> 10755 | D17: 11414 | E17: 11945 | F17: =F5*IncState!F17 -> 13338.242 | G17: =G5*IncState!G17 -> 14893.989 | H17: =H5*IncState!H17 -> 16631.195 | I17: =I5*IncState!I17 -> 18571.026 | J17: =J5*IncState!J17 -> 20737.114 | K17: =K5*IncState!K17 -> 23155.852 | L17: =L5*IncState!L17 -> 25856.706 | M17: =M5*IncState!M17 -> 28872.582
B18: Other current assets | C18: =1356+5492+1776 -> 8624 | D18: =5722+1905+1561 -> 9188 | E18: =1971+1779+5184 -> 8934 | F18: =F6*IncState!F17 -> 9976.0446 | G18: =G6*IncState!G17 -> 11139.631 | H18: =H6*IncState!H17 -> 12438.936 | I18: =I6*IncState!I17 -> 13889.79 | J18: =J6*IncState!J17 -> 15509.869 | K18: =K6*IncState!K17 -> 17318.91 | L18: =L6*IncState!L17 -> 19338.954 | M18: =M6*IncState!M17 -> 21594.613
B19: Total current assets | C19: =SUM(C15:C18) -> 26395 | D19: =SUM(D15:D18) -> 29074 | E19: =SUM(E15:E18) -> 29727 | F19: =SUM(F15:F18) -> 37659.889 | G19: =SUM(G15:G18) -> 49855.955 | H19: =SUM(H15:H18) -> 60732.564 | I19: =SUM(I15:I18) -> 75931.795 | J19: =SUM(J15:J18) -> 87054.637 | ... M19: =SUM(M15:M18) -> 155289.22
B21: Property, plant & equipment, net | C21: =3702+2890 -> 6592 | D21: =3689+2366 -> 6055 | E21: =2157+3236 -> 5393 | F21: =Calcs!F9 -> 4542.8195 | G21: =Calcs!G9 -> 4071.0735 | H21: =Calcs!H9 -> 3867.698 | I21: =Calcs!I9 -> 3859.5797 | J21: =Calcs!J9 -> 3998.7908 | K21: =Calcs!K9 -> 4254.6409 | L21: =Calcs!L9 -> 4608.3176 | M21: =Calcs!M9 -> 5049.2806
B22: Intangible assets | C22: =48568+7125 -> 55693 | D22: =48620+5278 -> 53898 | E22: =51283+4428 -> 55711 | F22: =E22-IncState!F24 -> 54189 | G22: =F22-IncState!G24 -> 53042 | H22: =G22-IncState!H24 -> 52297 | I22: =H22-IncState!I24 -> 51719 | J22: =I22-IncState!J24 -> 51425 | K22: =J22-IncState!K24 -> 51283 | L22: =K22-IncState!L24 -> 51283 | M22: =L22-IncState!M24 -> 51283
B23: Investment in unconsolidated entities | C23: 4672 | D23: 4848 | E23: 4852 | F23: =F8 -> 4852 | G23: =G8 -> 4852 | H23: =H8 -> 4852 | I23: =I8 -> 4852 | J23: =J8 -> 4852 | K23: =K8 -> 4852 | L23: =L8 -> 4852 | M23: =M8 -> 4852
B24: Other assets | C24: =2800+2697 -> 5497 | D24: =3433+2515 -> 5948 | E24: =4770+2475 -> 7245 | F24: =F7*IncState!F17 -> 8090.0429 | G24: =G7*IncState!G17 -> 9033.6499 | H24: =H7*IncState!H17 -> 10087.318 | I24: =I7*IncState!I17 -> 11263.883 | J24: =J7*IncState!J17 -> 12577.681 | K24: =K7*IncState!K17 -> 14044.717 | L24: =L7*IncState!L17 -> 15682.866 | M24: =M7*IncState!M17 -> 17512.085
B25: Total non-current assets | C25: =SUM(C21:C24) -> 72454 | D25: =SUM(D21:D24) -> 70749 | E25: =SUM(E21:E24) -> 73201 | F25: =SUM(F21:F24) -> 71673.862 | G25: =SUM(G21:G24) -> 70998.723 | H25: =SUM(H21:H24) -> 71104.015 | I25: =SUM(I21:I24) -> 71694.463 | J25: =SUM(J21:J24) -> 72853.471 | ... M25: =SUM(M21:M24) -> 78696.366
A27: * | B27: TOTAL ASSETS | C27: =SUM(C25,C19) -> 98849 | D27: =SUM(D25,D19) -> 99823 | E27: =SUM(E25,E19) -> 102928 | F27: =SUM(F25,F19) -> 109333.75 | G27: =SUM(G25,G19) -> 120854.68 | H27: =SUM(H25,H19) -> 131836.58 | I27: =SUM(I25,I19) -> 147626.26 | J27: =SUM(J25,J19) -> 159908.11 | ... M27: =SUM(M25,M19) -> 233985.58
B29: Revolver/Short term debt | C29: 1182 | D29: 999 | E29: 0 | F29: =MIN(CashFlow!F23,0) -> 0 | G29: =MIN(CashFlow!G23,0) -> 0 | H29: =MIN(CashFlow!H23,0) -> 0 | I29: =MIN(CashFlow!I23,0) -> 0 | J29: =MIN(CashFlow!J23,0) -> 0 | K29: =MIN(CashFlow!K23,0) -> 0 | L29: =MIN(CashFlow!L23,0) -> 0 | M29: =MIN(CashFlow!M23,0) -> 0
B30: Accounts payable/Accurals | C30: 6743 | D30: 6111 | E30: 6658 | F30: =F10*IncState!F18 -> 7434.5763 | G30: =G10*IncState!G18 -> 8301.731 | H30: =H10*IncState!H18 -> 9270.029 | I30: =I10*IncState!I18 -> 10351.267 | J30: =J10*IncState!J18 -> 11558.619 | K30: =K10*IncState!K18 -> 12906.794 | L30: =L10*IncState!L18 -> 14412.218 | M30: =M10*IncState!M18 -> 16093.232
B31: Other current liabilities | C31: =17376+590 -> 17966 | D31: =518+19003 -> 19521 | E31: =20743+579 -> 21322 | F31: =F11*IncState!F17 -> 23808.957 | G31: =G11*IncState!G17 -> 26585.988 | H31: =H11*IncState!H17 -> 29686.927 | I31: =I11*IncState!I17 -> 33149.553 | J31: =J11*IncState!J17 -> 37016.053 | K31: =K11*IncState!K17 -> 41333.534 | L31: =L11*IncState!L17 -> 46154.598 | M31: =M11*IncState!M17 -> 51537.982
B32: Total current liabilities | C32: =SUM(C29:C31) -> 25891 | D32: =SUM(D29:D31) -> 26631 | E32: =SUM(E29:E31) -> 27980 | F32: =SUM(F29:F31) -> 31243.533 | G32: =SUM(G29:G31) -> 34887.719 | H32: =SUM(H29:H31) -> 38956.956 | I32: =SUM(I29:I31) -> 43500.82 | J32: =SUM(J29:J31) -> 48574.672 | ... M32: =SUM(M29:M31) -> 67631.214
B34: Long-term debt, including current maturities | C34: 9419 | D34: 8427 | E34: 8433 | F34: =Debt!F26 -> 8433 | G34: =Debt!G26 -> 8433 | H34: =Debt!H26 -> 5933 | I34: =Debt!I26 -> 6000 | J34: =Debt!J26 -> 0 | K34: =Debt!K26 -> 0 | L34: =Debt!L26 -> 0 | M34: =Debt!M26 -> 0
B35: Other long-term liabilities | C35: =2897+2283 -> 5180 | D35: =2644+2475 -> 5119 | E35: =2380+2962 -> 5342 | F35: =F12*IncState!F17 -> 5965.0806 | G35: =G12*IncState!G17 -> 6660.8362 | H35: =H12*IncState!H17 -> 7437.7433 | I35: =I12*IncState!I17 -> 8305.2674 | J35: =J12*IncState!J17 -> 9273.9778 | K35: =K12*IncState!K17 -> 10355.677 | L35: =L12*IncState!L17 -> 11563.543 | M35: =M12*IncState!M17 -> 12912.292
B36: Total non-current liabilities | C36: =SUM(C34:C35) -> 14599 | D36: =SUM(D34:D35) -> 13546 | E36: =SUM(E34:E35) -> 13775 | F36: =SUM(F34:F35) -> 14398.081 | G36: =SUM(G34:G35) -> 15093.836 | H36: =SUM(H34:H35) -> 13370.743 | I36: =SUM(I34:I35) -> 14305.267 | J36: =SUM(J34:J35) -> 9273.9778 | ... M36: =SUM(M34:M35) -> 12912.292
B38: Equity | C38: 58359 | D38: 59646 | E38: 61173 | F38: =Calcs!F17 -> 63692.137 | G38: =Calcs!G17 -> 70873.123 | H38: =Calcs!H17 -> 79508.88 | I38: =Calcs!I17 -> 89820.17 | J38: =Calcs!J17 -> 102059.46 | K38: =Calcs!K17 -> 116515.31 | L38: =Calcs!L17 -> 133517.39 | M38: =Calcs!M17 -> 153442.08
A39: * | B39: TOTAL LIABILITIES & EQUITY | C39: =SUM(C38,C36,C32) -> 98849 | D39: =SUM(D38,D36,D32) -> 99823 | E39: =SUM(E38,E36,E32) -> 102928 | F39: =SUM(F38,F36,F32) -> 109333.75 | G39: =SUM(G38,G36,G32) -> 120854.68 | H39: =SUM(H38,H36,H32) -> 131836.58 | I39: =SUM(I38,I36,I32) -> 147626.26 | J39: =SUM(J38,J36,J32) -> 159908.11 | ... M39: =SUM(M38,M36,M32) -> 233985.58
A41: * | B41: Balance check | C41: =C39-C27 -> 0 | D41: =D39-D27 -> 0 | E41: =E39-E27 -> 0 | F41: =F39-F27 -> 0 | G41: =G39-G27 -> 0 | H41: =H39-H27 -> 0 | I41: =I39-I27 -> 0 | J41: =J39-J27 -> 0 | ... M41: =M39-M27 -> 0

Sheet CashFlow
A1: =CoName -> Salesforce Inc. | C1: Hist. | D1: Hist. | E1: Hist. | F1: Proj. | G1: Proj. | H1: Proj. | I1: Proj. | J1: Proj. | K1: Proj. | L1: Proj. | M1: Proj.
A2: Cash flow statement | C2: 2023 | D2: =C2+1 -> 2024 | E2: =D2+1 -> 2025 | F2: =E2+1 -> 2026 | G2: =F2+1 -> 2027 | H2: =G2+1 -> 2028 | I2: =H2+1 -> 2029 | J2: =I2+1 -> 2030 | K2: =J2+1 -> 2031 | ... M2: =L2+1 -> 2033
B3: Net Income | F3: =IncState!F36 -> 7456.1369 | G3: =IncState!G36 -> 8717.9859 | H3: =IncState!H36 -> 10172.758 | I3: =IncState!I36 -> 11848.289 | J3: =IncState!J36 -> 13776.288 | K3: =IncState!K36 -> 15992.854 | L3: =IncState!L36 -> 18539.073 | M3: =IncState!M36 -> 21461.69
B4: Depreciation | F4: =IncState!F23 -> 1741.2576 | G4: =IncState!G23 -> 1466.7568 | H4: =IncState!H23 -> 1314.4424 | I4: =IncState!I23 -> 1248.7778 | J4: =IncState!J23 -> 1246.1566 | K4: =IncState!K23 -> 1291.1042 | L4: =IncState!L23 -> 1373.7115 | M4: =IncState!M23 -> 1487.9044
B5: Amortization | F5: =IncState!F24 -> 1522 | G5: =IncState!G24 -> 1147 | H5: =IncState!H24 -> 745 | I5: =IncState!I24 -> 578 | J5: =IncState!J24 -> 294 | K5: =IncState!K24 -> 142 | L5: =IncState!L24 -> 0 | M5: =IncState!M24 -> 0
B6: (inc) / dec in OWC | F6: =Calcs!F25 -> 607.247 | G6: =Calcs!G25 -> 678.07512 | H6: =Calcs!H25 -> 757.1645 | I6: =Calcs!I25 -> 845.47871 | J6: =Calcs!J25 -> 944.09373 | K6: =Calcs!K25 -> 1054.211 | L6: =Calcs!L25 -> 1177.1722 | M6: =Calcs!M25 -> 1314.4753
B7: (inc) / dec in LT assets | F7: =BalSheet!E24-BalSheet!F24 -> -845.04288 | G7: =BalSheet!F24-BalSheet!G24 -> -943.60706 | H7: =BalSheet!G24-BalSheet!H24 -> -1053.6676 | I7: =BalSheet!H24-BalSheet!I24 -> -1176.5653 | J7: =BalSheet!I24-BalSheet!J24 -> -1313.7977 | K7: =BalSheet!J24-BalSheet!K24 -> -1467.0365 | L7: =BalSheet!K24-BalSheet!L24 -> -1638.1488 | M7: =BalSheet!L24-BalSheet!M24 -> -1829.2193
B8: inc / (dec) in LT liabilities | F8: =BalSheet!F35-BalSheet!E35 -> 623.08062 | G8: =BalSheet!G35-BalSheet!F35 -> 695.75554 | H8: =BalSheet!H35-BalSheet!G35 -> 776.90713 | I8: =BalSheet!I35-BalSheet!H35 -> 867.52409 | J8: =BalSheet!J35-BalSheet!I35 -> 968.71043 | K8: =BalSheet!K35-BalSheet!J35 -> 1081.699 | L8: =BalSheet!L35-BalSheet!K35 -> 1207.8662 | M8: =BalSheet!M35-BalSheet!L35 -> 1348.7494
B9: Cash Flow From Operations | F9: =SUM(F3:F8) -> 11104.679 | G9: =SUM(G3:G8) -> 11761.966 | H9: =SUM(H3:H8) -> 12712.604 | I9: =SUM(I3:I8) -> 14211.505 | J9: =SUM(J3:J8) -> 15915.451 | K9: =SUM(K3:K8) -> 18094.832 | L9: =SUM(L3:L8) -> 20659.674 | M9: =SUM(M3:M8) -> 23783.6
B11: Capex | F11: =Calcs!F7*-1 -> -891.07719 | G11: =Calcs!G7*-1 -> -995.01072 | H11: =Calcs!H7*-1 -> -1111.0669 | I11: =Calcs!I7*-1 -> -1240.6596 | J11: =Calcs!J7*-1 -> -1385.3677 | K11: =Calcs!K7*-1 -> -1546.9543 | L11: =Calcs!L7*-1 -> -1727.3881 | M11: =Calcs!M7*-1 -> -1928.8673
B12: Cash Flow From Investing | F12: =F11 -> -891.07719 | G12: =G11 -> -995.01072 | H12: =H11 -> -1111.0669 | I12: =I11 -> -1240.6596 | J12: =J11 -> -1385.3677 | K12: =K11 -> -1546.9543 | L12: =L11 -> -1727.3881 | M12: =M11 -> -1928.8673
B14: Dividends paid | F14: =IncState!F38*-1 -> -1537 | G14: =IncState!G38*-1 -> -1537 | H14: =IncState!H38*-1 -> -1537 | I14: =IncState!I38*-1 -> -1537 | J14: =IncState!J38*-1 -> -1537 | K14: =IncState!K38*-1 -> -1537 | L14: =IncState!L38*-1 -> -1537 | M14: =IncState!M38*-1 -> -1537
B15: Share issuance / (repurchases) | F15: =Calcs!F11 -> -3400 | G15: =Calcs!G11 -> 0 | H15: =Calcs!H11 -> 0 | I15: =Calcs!I11 -> 0 | J15: =Calcs!J11 -> 0 | K15: =Calcs!K11 -> 0 | L15: =Calcs!L11 -> 0 | M15: =Calcs!M11 -> 0
B16: Debt Issuance / (repayment) | F16: =SUM(Debt!F8:F9) -> 0 | G16: =SUM(Debt!G8:G9) -> 0 | H16: =SUM(Debt!H8:H9) -> -2500 | I16: =SUM(Debt!I8:I9) -> 67 | J16: =SUM(Debt!J8:J9) -> -6000 | K16: =SUM(Debt!K8:K9) -> 0 | L16: =SUM(Debt!L8:L9) -> 0 | M16: =SUM(Debt!M8:M9) -> 0
B17: Cash Flow From Financing | F17: =SUM(F14:F16) -> -4937 | G17: =SUM(G14:G16) -> -1537 | H17: =SUM(H14:H16) -> -4037 | I17: =SUM(I14:I16) -> -1470 | J17: =SUM(J14:J16) -> -7537 | K17: =SUM(K14:K16) -> -1537 | L17: =SUM(L14:L16) -> -1537 | M17: =SUM(M14:M16) -> -1537
B19: Net changes in cash | F19: =SUM(F17,F12,F9) -> 5276.6021 | G19: =SUM(G17,G12,G9) -> 9229.9556 | H19: =SUM(H17,H12,H9) -> 7564.5372 | I19: =SUM(I17,I12,I9) -> 11500.845 | J19: =SUM(J17,J12,J9) -> 6993.0837 | K19: =SUM(K17,K12,K9) -> 15010.877 | L19: =SUM(L17,L12,L9) -> 17395.286 | M19: =SUM(M17,M12,M9) -> 20317.732
B21: Beginning cash | F21: =BalSheet!E16 -> 6953.25 | G21: =BalSheet!F16 -> 12229.852 | H21: =BalSheet!G16 -> 21459.808 | I21: =BalSheet!H16 -> 29024.345 | J21: =BalSheet!I16 -> 40525.19 | K21: =BalSheet!J16 -> 47518.274 | L21: =BalSheet!K16 -> 62529.151 | M21: =BalSheet!L16 -> 79924.437
B22: Changes | F22: =F19 -> 5276.6021 | G22: =G19 -> 9229.9556 | H22: =H19 -> 7564.5372 | I22: =I19 -> 11500.845 | J22: =J19 -> 6993.0837 | K22: =K19 -> 15010.877 | L22: =L19 -> 17395.286 | M22: =M19 -> 20317.732
B23: Ending cash | F23: =SUM(F21:F22) -> 12229.852 | G23: =SUM(G21:G22) -> 21459.808 | H23: =SUM(H21:H22) -> 29024.345 | I23: =SUM(I21:I22) -> 40525.19 | J23: =SUM(J21:J22) -> 47518.274 | K23: =SUM(K21:K22) -> 62529.151 | L23: =SUM(L21:L22) -> 79924.437 | M23: =SUM(M21:M22) -> 100242.17

Sheet Free Cash Flow
A1: =CoName -> Salesforce Inc. | C1: Hist. | D1: Hist. | E1: Hist. | F1: Proj. | G1: Proj. | H1: Proj. | I1: Proj. | J1: Proj. | K1: Proj. | L1: Proj. | M1: Proj.
A2: Free Cash Flows | C2: 2023 | D2: =C2+1 -> 2024 | E2: =D2+1 -> 2025 | F2: =E2+1 -> 2026 | G2: =F2+1 -> 2027 | H2: =G2+1 -> 2028 | I2: =H2+1 -> 2029 | J2: =I2+1 -> 2030 | K2: =J2+1 -> 2031 | ... M2: =L2+1 -> 2033
A3: * | B3: Sales | F3: =IncState!F17 -> 42315 | G3: =IncState!G17 -> 47250.54 | H3: =IncState!H17 -> 52761.753 | I3: =IncState!I17 -> 58915.782 | J3: =IncState!J17 -> 65787.606 | K3: =IncState!K17 -> 73460.946 | L3: =IncState!L17 -> 82029.289 | M3: =IncState!M17 -> 91597.028
B4: EBIT | F4: =IncState!F21 -> 8983.2975 | G4: =IncState!G21 -> 10503.597 | H4: =IncState!H21 -> 12256.334 | I4: =IncState!I21 -> 14275.048 | J4: =IncState!J21 -> 16597.938 | K4: =IncState!K21 -> 19268.499 | L4: =IncState!L21 -> 22336.232 | M4: =IncState!M21 -> 25857.458
B5: Effective Tax Rate | F5: =IncState!F11 -> 0.17 | G5: =IncState!G11 -> 0.17 | H5: =IncState!H11 -> 0.17 | I5: =IncState!I11 -> 0.17 | J5: =IncState!J11 -> 0.17 | K5: =IncState!K11 -> 0.17 | L5: =IncState!L11 -> 0.17 | M5: =IncState!M11 -> 0.17
A7: * | B7: NOPAT | F7: =F4*(1-F5) -> 7456.1369 | G7: =G4*(1-G5) -> 8717.9859 | H7: =H4*(1-H5) -> 10172.758 | I7: =I4*(1-I5) -> 11848.289 | J7: =J4*(1-J5) -> 13776.288 | K7: =K4*(1-K5) -> 15992.854 | L7: =L4*(1-L5) -> 18539.073 | M7: =M4*(1-M5) -> 21461.69
