Workbook
Name Ccy: MAIN!$C$6
Name circ: MAIN!$C$9
Name CoName: MAIN!$C$4
Name g: #REF!
Name IQ_CH: 110000
Name IQ_CQ: 5000
Name IQ_CY: 10000
Name IQ_DAILY: 500000
Name IQ_FH: 100000
Name IQ_FQ: 500
Name IQ_FY: 1000
Name IQ_LTM: 2000
Name IQ_MONTH: 15000
Name IQ_NTM: 6000
Name IQ_WEEK: 50000
Name IQ_YTD: 3000
Name OpCase: [1]DCF!$E$98
Name ScenarioREV: Assumptions!$D$4
Name TTS: #REF!
Name Units: MAIN!$C$7

Sheet MAIN
A1: =CoName -> Intel Corp.
A2: Model Details
B4: Company name | C4: Intel Corp. | E4: Current Stock Price | F4: 35.92 | H4: Operating Case One | I4: Terminal Mult | J4: Perpetuity | K4: Average
B5: Latest BS date | C5: 247.43 | E5: Diluted s/o | F5: 4770 | H5: Implied Price | I5: ='DCF Model'!G18 -> 44.281909 | J5: ='DCF Model'!C18 -> 35.608007 | K5: =AVERAGE(I5:J5) -> 39.944958
B6: Currency | C6: USD | E6: Mkt Cap | F6: =F5*F4 -> 171338.4 | H6: Difference | I6: =I5/$F$4-1 -> 0.23279258 | J6: =J5/$F$4-1 -> -0.0086857796 | K6: =K5/$F$4-1 -> 0.1120534
B7: Units | C7: m | E7: Cash | F7: =11141+19794 -> 30935
B8: Analyst name | C8: Alan Chen | E8: Debt | F8: =2496+11430 -> 13926
B9: Circular switch | C9: 0 | E9: EV | F9: =F6-F7+F8 -> 154329.4

Sheet Quarterly Projections
A1: =CoName -> Intel Corp.
A2: Revenue | C2: Q122 | D2: Q222 | E2: Q322 | F2: Q422 | G2: 2022 | H2: Q123 | I2: Q223 | J2: Q323 | K2: Q423 | L2: =G2+1 -> 2023 | M2: Q124 | N2: Q224 | O2: Q324 | P2: Q424 | Q2: =L2+1 -> 2024 | R2: Q125 | S2: Q225 | T2: Q325 | U2: Q425 | V2: =Q2+1 -> 2025 | W2: =V2+1 -> 2026 | X2: =W2+1 -> 2027 | Y2: =X2+1 -> 2028 | Z2: =Y2+1 -> 2029 | AA2: =Z2+1 -> 2030 | AB2: =AA2+1 -> 2031 | AC2: =AB2+1 -> 2032 | AD2: =AC2+1 -> 2033 | ... AF2: =AE2+1 -> 2035
B3: CCG | C3: 9322 | D3: 7678 | E3: 8128 | F3: 6645 | G3: =SUM(C3:F3) -> 31773 | H3: 5767 | I3: 6780 | J3: 7687 | K3: 8844 | L3: =SUM(H3:K3) -> 29078 | M3: 8273 | N3: 8143 | O3: 8161 | P3: 8017 | Q3: =SUM(M3:P3) -> 32594 | R3: 7629 | S3: 7871 | T3: 8535 | U3: =P3*(1+U9) -> 8337.68 | V3: =SUM(R3:U3) -> 32372.68
B4: DCAI | C4: 6074 | D4: 4695 | E4: 4255 | F4: 4421 | G4: =SUM(C4:F4) -> 19445 | H4: 3718 | I4: 4004 | J4: 3814 | K4: 3985 | L4: =SUM(H4:K4) -> 15521 | M4: 3828 | N4: 3805 | O4: 4141 | P4: =3387+1623 -> 5010 | Q4: =SUM(M4:P4) -> 16784 | R4: 4126 | S4: 3939 | T4: 4117 | U4: =P4*(1+U9) -> 5210.4 | V4: =SUM(R4:U4) -> 17392.4
B5: Intel Foundry | C5: =2139+394+156 -> 2689 | D5: =2211+460+57 -> 2728 | E5: =2133+450+78 -> 2661 | F5: =1926+565+178 -> 2669 | G5: =SUM(C5:F5) -> 10747 | H5: =1489+458+118 -> 2065 | I5: =1363+454+232 -> 2049 | J5: =1450+530+311 -> 2291 | K5: =1471+637+291 -> 2399 | L5: =SUM(H5:K5) -> 8804 | M5: 4356 | N5: 4282 | O5: 4339 | P5: 4502 | Q5: =SUM(M5:P5) -> 17479 | R5: 4667 | S5: 4417 | T5: 4235 | U5: =P5*(1+U9) -> 4682.08 | V5: =SUM(R5:U5) -> 18001.08
B6: Other | C6: 268 | D6: 220 | E6: 294 | F6: 307 | G6: =SUM(C6:F6) -> 1089 | H6: 165 | I6: 115 | J6: 186 | K6: 178 | L6: =SUM(H6:K6) -> 644 | M6: 643 | N6: 881 | O6: 964 | P6: 1042 | Q6: =SUM(M6:P6) -> 3530 | R6: 943 | S6: 1054 | T6: 993 | U6: =P6*(1+U9) -> 1083.68 | V6: =SUM(R6:U6) -> 4073.68
B7: Eliminations | C7: 0 | D7: 0 | E7: 0 | F7: 0 | G7: =SUM(C7:F7) -> 0 | H7: 0 | I7: 0 | J7: 0 | K7: 0 | L7: =SUM(H7:K7) -> 0 | M7: -4376 | N7: -4278 | O7: -4321 | P7: -4311 | Q7: =SUM(M7:P7) -> -17286 | R7: -4698 | S7: -4421 | T7: -4227 | U7: =-U10*SUM(U3:U6) -> -5794.152 | V7: =SUM(R7:U7) -> -19140.152
A8: * | B8: TOTAL REVENUES | C8: =SUM(C3:C7) -> 18353 | D8: =SUM(D3:D7) -> 15321 | E8: =SUM(E3:E7) -> 15338 | F8: =SUM(F3:F7) -> 14042 | G8: =SUM(G3:G7) -> 63054 | H8: =SUM(H3:H7) -> 11715 | I8: =SUM(I3:I7) -> 12948 | J8: =SUM(J3:J7) -> 13978 | ... V8: =SUM(V3:V7) -> 52699.688 | W8: =V8*(1+W9) -> 54017.18 | X8: =W8*(1+X9) -> 59418.898 | Y8: =X8*(1+Y9) -> 68331.733 | Z8: =Y8*(1+Z9) -> 81998.08 | AA8: =Z8*(1+AA9) -> 102497.6 | AB8: =AA8*(1+AB9) -> 128122 | AC8: =AB8*(1+AC9) -> 160152.5 | AD8: =AC8*(1+AD9) -> 200190.62 | ... AF8: =AE8*(1+AF9) -> 312797.85
B9: y/y | H9: =H8/C8-1 -> -0.36168474 | I9: =I8/D8-1 -> -0.15488545 | J9: =J8/E8-1 -> -0.088668666 | K9: =K8/F8-1 -> 0.09713716 | L9: =L8/G8-1 -> -0.14284581 | M9: =M8/H8-1 -> 0.086128895 | N9: =N8/I8-1 -> -0.0088816806 | O9: =O8/J8-1 -> -0.049649449 | ... T9: =T8/O8-1 -> 0.027777778 | U9: 0.04 | V9: =V8/Q8-1 -> -0.0075575225 | W9: 0.025 | X9: 0.1 | Y9: 0.15 | Z9: 0.2 | AA9: 0.25 | AB9: =AA9 -> 0.25 | AC9: =AB9 -> 0.25 | AD9: =AC9 -> 0.25 | AE9: =AD9 -> 0.25 | AF9: =AE9 -> 0.25
B10: Eliminations | M10: =-M7/M8 -> 0.34391701 | N10: =-N7/N8 -> 0.33335931 | O10: =-O7/O8 -> 0.32527853 | P10: =-P7/P8 -> 0.30231417 | Q10: =-Q7/Q8 -> 0.32553059 | R10: =-R7/R8 -> 0.37088498 | S10: =-S7/S8 -> 0.34377916 | T10: =-T7/T8 -> 0.30960229 | U10: 0.3 | V10: =U10 -> 0.3 | W10: =V10 -> 0.3 | X10: =W10 -> 0.3 | Y10: =X10 -> 0.3 | Z10: =Y10 -> 0.3 | AA10: =Z10 -> 0.3 | AB10: =AA10 -> 0.3 | AC10: =AB10 -> 0.3 | ... AF10: =AE10 -> 0.3

Sheet Assumptions
A1: =CoName -> Intel Corp. | C1: Hist. | D1: Hist. | E1: Hist. | F1: Proj. | G1: Proj. | H1: Proj. | I1: Proj. | J1: Proj. | K1: Proj. | L1: Proj. | M1: Proj. | N1: Proj. | O1: Proj.
A2: * | B2: Income Statement | C2: 2022 | D2: =C2+1 -> 2023 | E2: =D2+1 -> 2024 | F2: =E2+1 -> 2025 | G2: =F2+1 -> 2026 | H2: =G2+1 -> 2027 | I2: =H2+1 -> 2028 | J2: =I2+1 -> 2029 | K2: =J2+1 -> 2030 | ... O2: =N2+1 -> 2034
B4: Operating Case | D4: 1
D5: Variance
B6: Street Case | D6: 0 | F6: ='Quarterly Projections'!V9 -> -0.0075575225 | G6: ='Quarterly Projections'!W9 -> 0.025 | H6: ='Quarterly Projections'!X9 -> 0.1 | I6: ='Quarterly Projections'!Y9 -> 0.15 | J6: ='Quarterly Projections'!Z9 -> 0.2 | K6: ='Quarterly Projections'!AA9 -> 0.25 | L6: ='Quarterly Projections'!AB9 -> 0.25 | M6: ='Quarterly Projections'!AC9 -> 0.25 | ... O6: ='Quarterly Projections'!AE9 -> 0.25
B7: Optimistic Case | D7: 0.025 | F7: =F6+$D$7 -> 0.017442478 | G7: =G6+$D$7 -> 0.05 | H7: =H6+$D$7 -> 0.125 | I7: =I6+$D$7 -> 0.175 | J7: =J6+$D$7 -> 0.225 | K7: =K6+$D$7 -> 0.275 | L7: =L6+$D$7 -> 0.275 | M7: =M6+$D$7 -> 0.275 | ... O7: =O6+$D$7 -> 0.275
B8: Pessimistic Case | D8: -0.025 | F8: =F6+$D$8 -> -0.032557522 | G8: =G6+$D$8 -> 0 | H8: =H6+$D$8 -> 0.075 | I8: =I6+$D$8 -> 0.125 | J8: =J6+$D$8 -> 0.175 | K8: =K6+$D$8 -> 0.225 | L8: =L6+$D$8 -> 0.225 | M8: =M6+$D$8 -> 0.225 | ... O8: =O6+$D$8 -> 0.225
B10: Revenue Growth | D10: =IncState!D17/IncState!C17-1 -> -0.13997526 | E10: =IncState!E17/IncState!D17-1 -> -0.020782622 | F10: =CHOOSE(ScenarioREV,F6,F7,F8) -> -0.0075575225 | G10: =CHOOSE(ScenarioREV,G6,G7,G8) -> 0.025 | H10: =CHOOSE(ScenarioREV,H6,H7,H8) -> 0.1 | I10: =CHOOSE(ScenarioREV,I6,I7,I8) -> 0.15 | J10: =CHOOSE(ScenarioREV,J6,J7,J8) -> 0.2 | K10: =CHOOSE(ScenarioREV,K6,K7,K8) -> 0.25 | L10: =CHOOSE(ScenarioREV,L6,L7,L8) -> 0.25 | M10: =CHOOSE(ScenarioREV,M6,M7,M8) -> 0.25 | ... O10: =CHOOSE(ScenarioREV,O6,O7,O8) -> 0.25
B11: COGS % of sales | C11: =IncState!C18/IncState!C17 -> 0.57392077 | D11: =IncState!D18/IncState!D17 -> 0.59963487 | E11: =IncState!E18/IncState!E17 -> 0.67335832 | F11: =E11-0.05 -> 0.62335832 | G11: =F11-0.05 -> 0.57335832 | H11: =G11-0.05 -> 0.52335832 | I11: =H11-0.05 -> 0.47335832 | J11: =I11-0.05 -> 0.42335832 | K11: =J11-0.02 -> 0.40335832 | L11: =K11-0.02 -> 0.38335832 | M11: =L11-0.02 -> 0.36335832 | N11: =M11-0.02 -> 0.34335832 | O11: =N11-0.02 -> 0.32335832
B12: R&D % of sales | C12: =IncState!C19/IncState!C17 -> 0.27798395 | D12: =IncState!D19/IncState!D17 -> 0.2958988 | E12: =IncState!E19/IncState!E17 -> 0.31159489 | F12: =E12-0.02 -> 0.29159489 | G12: =F12-0.02 -> 0.27159489 | H12: =G12-0.02 -> 0.25159489 | I12: =H12-0.02 -> 0.23159489 | J12: =I12-0.02 -> 0.21159489 | K12: =J12-0.02 -> 0.19159489 | L12: =K12 -> 0.19159489 | M12: =L12 -> 0.19159489 | N12: =M12 -> 0.19159489 | O12: =N12 -> 0.19159489
B13: SG&A % of sales | C13: =IncState!C20/IncState!C17 -> 0.11107939 | D13: =IncState!D20/IncState!D17 -> 0.10275135 | E13: =IncState!E20/IncState!E17 -> 0.23496733 | F13: =E13-0.02 -> 0.21496733 | G13: =F13-0.02 -> 0.19496733 | H13: =G13-0.02 -> 0.17496733 | I13: =H13-0.02 -> 0.15496733 | J13: =I13-0.02 -> 0.13496733 | K13: =J13-0.02 -> 0.11496733 | L13: =K13-0.02 -> 0.094967326 | M13: =L13-0.02 -> 0.074967326 | N13: =M13 -> 0.074967326 | O13: =N13 -> 0.074967326
B14: Amortization $ Amt | C14: =IncState!C24 -> 1907 | D14: =IncState!D24 -> 1755 | E14: =IncState!E24 -> 1428 | F14: =E14 -> 1428 | G14: =F14 -> 1428 | H14: =G14 -> 1428 | I14: =H14 -> 1428 | J14: =I14 -> 1428 | K14: =J14 -> 1428 | L14: =K14 -> 1428 | M14: =L14 -> 1428 | ... O14: =N14 -> 1428
B15: Non recurring income / (expense) | C15: =IncState!C27 -> 2 | D15: =IncState!D27 -> -62 | E15: =IncState!E27 -> 6970 | F15: 0 | G15: 0 | H15: 0 | I15: 0 | J15: 0 | K15: 0 | L15: 0 | M15: 0 | N15: 0 | O15: 0
B16: Other Income / (expense) | C16: =IncState!C28 -> 1073 | D16: =IncState!D28 -> 172 | E16: =IncState!E28 -> 15 | F16: 0 | G16: 0 | H16: 0 | I16: 0 | J16: 0 | K16: 0 | L16: 0 | M16: 0 | N16: 0 | O16: 0
B17: Effective tax rate | C17: =IncState!C35/IncState!C33 -> -0.07319224 | D17: =IncState!D35/IncState!D33 -> -1.3833333 | E17: =IncState!E35/IncState!E33 -> -1.7900491 | F17: 0.12 | G17: =F17 -> 0.12 | H17: =G17 -> 0.12 | I17: =H17 -> 0.12 | J17: =I17 -> 0.12 | K17: =J17 -> 0.12 | L17: =K17 -> 0.12 | M17: =L17 -> 0.12 | N17: =M17 -> 0.12 | O17: =N17 -> 0.12
B18: Dividend Payout Rate | C18: =IncState!C37 -> 1.4598345 | D18: =IncState!D37 -> 0.73699284 | E18: =IncState!E37 -> 0.37359813 | F18: =E18 -> 0.37359813 | G18: =F18 -> 0.37359813 | H18: =G18 -> 0.37359813 | I18: =H18 -> 0.37359813 | J18: =I18 -> 0.37359813 | K18: =J18 -> 0.37359813 | L18: =K18 -> 0.37359813 | M18: =L18 -> 0.37359813 | ... O18: =N18 -> 0.37359813
B19: Basic WASO | C19: =IncState!C40 -> 4108 | D19: =IncState!D40 -> 4190 | E19: =IncState!E40 -> 4280 | F19: =E19 -> 4280 | G19: =F19 -> 4280 | H19: =G19 -> 4280 | I19: =H19 -> 4280 | J19: =I19 -> 4280 | K19: =J19 -> 4280 | L19: =K19 -> 4280 | M19: =L19 -> 4280 | ... O19: =N19 -> 4280
B20: Diluted WASO | C20: =IncState!C41 -> 4123 | D20: =IncState!D41 -> 4212 | E20: =IncState!E41 -> 4280 | F20: =E20 -> 4280 | G20: =F20 -> 4280 | H20: =G20 -> 4280 | I20: =H20 -> 4280 | J20: =I20 -> 4280 | K20: =J20 -> 4280 | L20: =K20 -> 4280 | M20: =L20 -> 4280 | ... O20: =N20 -> 4280
A22: * | B22: Debt | C22: =C2 -> 2022 | D22: =D2 -> 2023 | E22: =E2 -> 2024 | F22: =F2 -> 2025 | G22: =G2 -> 2026 | H22: =H2 -> 2027 | I22: =I2 -> 2028 | J22: =J2 -> 2029 | ... O22: =O2 -> 2034
B24: Interest rate on Revolver | E24: 0.05 | F24: =E24 -> 0.05 | G24: =F24 -> 0.05 | H24: =G24 -> 0.05 | I24: =H24 -> 0.05 | J24: =I24 -> 0.05 | K24: =J24 -> 0.05 | L24: =K24 -> 0.05 | M24: =L24 -> 0.05 | ... O24: =N24 -> 0.05
B25: Interest rate on long-term debt | E25: 0.039325 | F25: =E25 -> 0.039325 | G25: =F25 -> 0.039325 | H25: =G25 -> 0.039325 | I25: =H25 -> 0.039325 | J25: =I25 -> 0.039325 | K25: =J25 -> 0.039325 | L25: =K25 -> 0.039325 | M25: =L25 -> 0.039325 | ... O25: =N25 -> 0.039325
B26: Interest rate on cash | E26: =IncState!E30/BalSheet!E18 -> 0.16705837 | F26: =E26 -> 0.16705837 | G26: =F26 -> 0.16705837 | H26: =G26 -> 0.16705837 | I26: =H26 -> 0.16705837 | J26: =I26 -> 0.16705837 | K26: =J26 -> 0.16705837 | L26: =K26 -> 0.16705837 | M26: =L26 -> 0.16705837 | ... O26: =N26 -> 0.16705837
B28: Issuance of long-term debt | F28: 0 | G28: 0 | H28: 0 | I28: 0 | J28: 0 | K28: 0 | L28: 0 | M28: 0 | N28: 0 | O28: 0
B29: Repayment of long-term debt | F29: 0 | G29: 0 | H29: 0 | I29: 0 | J29: 0 | K29: 0 | L29: 0 | M29: 0 | N29: 0 | O29: 0
A31: * | B31: Calcs | C31: =C22 -> 2022 | D31: =D22 -> 2023 | E31: =E22 -> 2024 | F31: =F22 -> 2025 | G31: =G22 -> 2026 | H31: =H22 -> 2027 | I31: =I22 -> 2028 | J31: =J22 -> 2029 | ... O31: =O22 -> 2034
B33: CapEx % of Sales | D33: =25750/IncState!D17 -> 0.47484694 | E33: =23944/IncState!E17 -> 0.4509143 | F33: =E33-0.05 -> 0.4009143 | G33: =F33-0.01 -> 0.3909143 | H33: =G33-0.01 -> 0.3809143 | I33: =H33-0.01 -> 0.3709143 | J33: =I33-0.01 -> 0.3609143 | K33: =J33-0.01 -> 0.3509143 | L33: =K33-0.01 -> 0.3409143 | M33: =L33-0.01 -> 0.3309143 | N33: =M33-0.01 -> 0.3209143 | O33: =N33-0.01 -> 0.3109143
B34: Depreciation % of beginning PP&E | D34: =IncState!D23/BalSheet!C24 -> 0.097044274 | E34: =IncState!E23/BalSheet!D24 -> 0.10296233 | F34: =E34-0.005 -> 0.097962327 | G34: =F34-0.005 -> 0.092962327 | H34: =G34-0.005 -> 0.087962327 | I34: =H34-0.005 -> 0.082962327 | J34: =I34-0.005 -> 0.077962327 | K34: =J34-0.005 -> 0.072962327 | L34: =K34-0.005 -> 0.067962327 | M34: =L34-0.005 -> 0.062962327 | ... O34: =N34-0.005 -> 0.052962327
B35: Share issuance / (repurchases) | F35: 10000 | G35: 10000 | H35: 10000 | I35: 10000 | J35: 10000 | K35: 10000 | L35: 10000 | M35: 10000 | N35: 10000 | O35: 10000
A37: * | B37: Shareholder information | C37: =C31 -> 2022 | D37: =D31 -> 2023 | E37: =E31 -> 2024 | F37: =F31 -> 2025 | G37: =G31 -> 2026 | H37: =H31 -> 2027 | I37: =I31 -> 2028 | J37: =J31 -> 2029 | ... O37: =O31 -> 2034
B39: =B18 -> Dividend Payout Rate | C39: =C18 -> 1.4598345 | D39: =D18 -> 0.73699284 | E39: =E18 -> 0.37359813 | F39: =F18 -> 0.37359813 | G39: =G18 -> 0.37359813 | H39: =H18 -> 0.37359813 | I39: =I18 -> 0.37359813 | ... O39: =O18 -> 0.37359813
B40: Basic WASO | C40: =C19 -> 4108 | D40: =D19 -> 4190 | E40: =E19 -> 4280 | F40: =F19 -> 4280 | G40: =G19 -> 4280 | H40: =H19 -> 4280 | I40: =I19 -> 4280 | J40: =J19 -> 4280 | ... O40: =O19 -> 4280
B41: Diluted WASO | C41: =C20 -> 4123 | D41: =D20 -> 4212 | E41: =E20 -> 4280 | F41: =F20 -> 4280 | G41: =G20 -> 4280 | H41: =H20 -> 4280 | I41: =I20 -> 4280 | J41: =J20 -> 4280 | ... O41: =O20 -> 4280
A43: * | B43: Balance Sheet - Assets | C43: =C37 -> 2022 | D43: =D37 -> 2023 | E43: =E37 -> 2024 | F43: =F37 -> 2025 | G43: =G37 -> 2026 | H43: =H37 -> 2027 | I43: =I37 -> 2028 | J43: =J37 -> 2029 | ... O43: =O37 -> 2034
B45: Operating Cash % of sales | C45: =BalSheet!C17/IncState!C17 -> 0.015 | D45: =BalSheet!D17/IncState!D17 -> 0.015 | E45: =BalSheet!E17/IncState!E17 -> 0.015 | F45: =E45 -> 0.015 | G45: =F45 -> 0.015 | H45: =G45 -> 0.015 | I45: =H45 -> 0.015 | J45: =I45 -> 0.015 | K45: =J45 -> 0.015 | L45: =K45 -> 0.015 | M45: =L45 -> 0.015 | ... O45: =N45 -> 0.015
B46: Accounts receivable % of sales | C46: =BalSheet!C19/IncState!C17 -> 0.065546991 | D46: =BalSheet!D19/IncState!D17 -> 0.062735118 | E46: =BalSheet!E19/IncState!E17 -> 0.065497825 | F46: =E46 -> 0.065497825 | G46: =F46 -> 0.065497825 | H46: =G46 -> 0.065497825 | I46: =H46 -> 0.065497825 | J46: =I46 -> 0.065497825 | K46: =J46 -> 0.065497825 | L46: =K46 -> 0.065497825 | M46: =L46 -> 0.065497825 | ... O46: =N46 -> 0.065497825
B47: Inventories % of COGS | C47: =BalSheet!C20/IncState!C18 -> 0.365425 | D47: =BalSheet!D20/IncState!D18 -> 0.34219024 | E47: =BalSheet!E20/IncState!E18 -> 0.34114554 | F47: =E47 -> 0.34114554 | G47: =F47 -> 0.34114554 | H47: =G47 -> 0.34114554 | I47: =H47 -> 0.34114554 | J47: =I47 -> 0.34114554 | K47: =J47 -> 0.34114554 | L47: =K47 -> 0.34114554 | M47: =L47 -> 0.34114554 | ... O47: =N47 -> 0.34114554
B48: Other current assets % of sales | C48: =BalSheet!C21/IncState!C17 -> 0.3474165 | D48: =BalSheet!D21/IncState!D17 -> 0.39944309 | E48: =BalSheet!E21/IncState!E17 -> 0.44065084 | F48: =E48 -> 0.44065084 | G48: =F48 -> 0.44065084 | H48: =G48 -> 0.44065084 | I48: =H48 -> 0.44065084 | J48: =I48 -> 0.44065084 | K48: =J48 -> 0.44065084 | L48: =K48 -> 0.44065084 | M48: =L48 -> 0.44065084 | ... O48: =N48 -> 0.44065084
B50: Investments in unconsolidated entities | C50: =BalSheet!C26 -> 5912 | D50: =BalSheet!D26 -> 5829 | E50: =BalSheet!E26 -> 5383 | F50: =E50 -> 5383 | G50: =F50 -> 5383 | H50: =G50 -> 5383 | I50: =H50 -> 5383 | J50: =I50 -> 5383 | K50: =J50 -> 5383 | L50: =K50 -> 5383 | M50: =L50 -> 5383 | ... O50: =N50 -> 5383
B51: Other long-term assets % of sales | C51: =BalSheet!C27/IncState!C17 -> 0.17944936 | D51: =BalSheet!D27/IncState!D17 -> 0.25165966 | E51: =BalSheet!E27/IncState!E17 -> 0.14076948 | F51: =E51 -> 0.14076948 | G51: =F51 -> 0.14076948 | H51: =G51 -> 0.14076948 | I51: =H51 -> 0.14076948 | J51: =I51 -> 0.14076948 | K51: =J51 -> 0.14076948 | L51: =K51 -> 0.14076948 | M51: =L51 -> 0.14076948 | ... O51: =N51 -> 0.14076948
A53: * | B53: Balance Sheet - Liabilities | C53: =C43 -> 2022 | D53: =D43 -> 2023 | E53: =E43 -> 2024 | F53: =F43 -> 2025 | G53: =G43 -> 2026 | H53: =H43 -> 2027 | I53: =I43 -> 2028 | J53: =J43 -> 2029 | ... O53: =O43 -> 2034
...

Sheet Calcs
A1: =CoName -> Intel Corp. | C1: Hist. | D1: Hist. | E1: Hist. | F1: Proj. | G1: Proj. | H1: Proj. | I1: Proj. | J1: Proj. | K1: Proj. | L1: Proj. | M1: Proj. | N1: Proj. | O1: Proj.
A2: Net PP&E | C2: 2022 | D2: =C2+1 -> 2023 | E2: =D2+1 -> 2024 | F2: =E2+1 -> 2025 | G2: =F2+1 -> 2026 | H2: =G2+1 -> 2027 | I2: =H2+1 -> 2028 | J2: =I2+1 -> 2029 | K2: =J2+1 -> 2030 | ... O2: =N2+1 -> 2034
B3: Capital expenditure % of sales | F3: =Assumptions!F33 -> 0.4009143 | G3: =Assumptions!G33 -> 0.3909143 | H3: =Assumptions!H33 -> 0.3809143 | I3: =Assumptions!I33 -> 0.3709143 | J3: =Assumptions!J33 -> 0.3609143 | K3: =Assumptions!K33 -> 0.3509143 | L3: =Assumptions!L33 -> 0.3409143 | M3: =Assumptions!M33 -> 0.3309143 | ... O3: =Assumptions!O33 -> 0.3109143
B4: Depreciation % of PP&E | F4: =Assumptions!F34 -> 0.097962327 | G4: =F4 -> 0.097962327 | H4: =G4 -> 0.097962327 | I4: =H4 -> 0.097962327 | J4: =I4 -> 0.097962327 | K4: =J4 -> 0.097962327 | L4: =K4 -> 0.097962327 | M4: =L4 -> 0.097962327 | N4: =M4 -> 0.097962327 | O4: =N4 -> 0.097962327
B6: Beginning PP&E | F6: =E9 -> 107919 | G6: =F9 -> 118475.06 | H6: =G9 -> 127985.06 | I6: =H9 -> 138080.85 | J6: =I9 -> 149899.35 | K6: =J9 -> 164809.14 | L6: =K9 -> 184631.92 | M6: =L9 -> 210223.57 | ... O6: =N9 -> 283102.13
B7: Capex | F7: =F3*IncState!F17 -> 21128.058 | G7: =G3*IncState!G17 -> 21116.088 | H7: =H3*IncState!H17 -> 22633.508 | I7: =I3*IncState!I17 -> 25345.217 | J7: =J3*IncState!J17 -> 29594.279 | K7: =K3*IncState!K17 -> 35967.873 | L7: =L3*IncState!L17 -> 43678.621 | M7: =M3*IncState!M17 -> 52996.751 | ... O7: =O3*IncState!O17 -> 77802.658
B8: Depreciation | F8: =F4*F6 -> 10571.996 | G8: =G4*G6 -> 11606.093 | H8: =H4*H6 -> 12537.714 | I8: =I4*I6 -> 13526.721 | J8: =J4*J6 -> 14684.489 | K8: =K4*K6 -> 16145.086 | L8: =L4*L6 -> 18086.973 | M8: =M4*M6 -> 20593.99 | ... O8: =O4*O6 -> 27733.343
B9: Ending PP&E | E9: =BalSheet!E24 -> 107919 | F9: =F6+F7-F8 -> 118475.06 | G9: =G6+G7-G8 -> 127985.06 | H9: =H6+H7-H8 -> 138080.85 | I9: =I6+I7-I8 -> 149899.35 | J9: =J6+J7-J8 -> 164809.14 | K9: =K6+K7-K8 -> 184631.92 | L9: =L6+L7-L8 -> 210223.57 | M9: =M6+M7-M8 -> 242626.33 | ... O9: =O6+O7-O8 -> 333171.44
A10: Equity | C10: =C2 -> 2022 | D10: =D2 -> 2023 | E10: =E2 -> 2024 | F10: =F2 -> 2025 | G10: =G2 -> 2026 | H10: =H2 -> 2027 | I10: =I2 -> 2028 | J10: =J2 -> 2029 | ... O10: =O2 -> 2034
B11: Share issuance/(repurchases) | F11: =Assumptions!F35 -> 10000 | G11: =Assumptions!G35 -> 10000 | H11: =Assumptions!H35 -> 10000 | I11: =Assumptions!I35 -> 10000 | J11: =Assumptions!J35 -> 10000 | K11: =Assumptions!K35 -> 10000 | L11: =Assumptions!L35 -> 10000 | M11: =Assumptions!M35 -> 10000 | ... O11: =Assumptions!O35 -> 10000
B13: Beginning balance | F13: =E17 -> 105032 | G13: =F17 -> 107407.84 | H13: =G17 -> 113911.21 | I13: =H17 -> 124930.8 | J13: =I17 -> 141755.05 | K13: =J17 -> 166758.2 | L13: =K17 -> 201323.75 | M13: =L17 -> 246940.34 | ... O13: =N17 -> 384618.62
B14: Net income | F14: =IncState!F36 -> -6025.1588 | G14: =IncState!G36 -> -1897.6271 | H14: =IncState!H36 -> 2618.587 | I14: =IncState!I36 -> 8423.2483 | J14: =IncState!J36 -> 16602.146 | K14: =IncState!K36 -> 26164.556 | L14: =IncState!L36 -> 37215.589 | M14: =IncState!M36 -> 52156.854 | ... O14: =IncState!O36 -> 90303.472
B15: Dividends paid | F15: =IncState!F38*-1 -> -1599 | G15: =IncState!G38*-1 -> -1599 | H15: =IncState!H38*-1 -> -1599 | I15: =IncState!I38*-1 -> -1599 | J15: =IncState!J38*-1 -> -1599 | K15: =IncState!K38*-1 -> -1599 | L15: =IncState!L38*-1 -> -1599 | M15: =IncState!M38*-1 -> -1599 | ... O15: =IncState!O38*-1 -> -1599
B16: Share issuance / (repurchase) | F16: =F11 -> 10000 | G16: =G11 -> 10000 | H16: =H11 -> 10000 | I16: =I11 -> 10000 | J16: =J11 -> 10000 | K16: =K11 -> 10000 | L16: =L11 -> 10000 | M16: =M11 -> 10000 | ... O16: =O11 -> 10000
B17: Ending balance | E17: =BalSheet!E41 -> 105032 | F17: =SUM(F13:F16) -> 107407.84 | G17: =SUM(G13:G16) -> 113911.21 | H17: =SUM(H13:H16) -> 124930.8 | I17: =SUM(I13:I16) -> 141755.05 | J17: =SUM(J13:J16) -> 166758.2 | K17: =SUM(K13:K16) -> 201323.75 | L17: =SUM(L13:L16) -> 246940.34 | M17: =SUM(M13:M16) -> 307498.19 | ... O17: =SUM(O13:O16) -> 483323.09
A18: OWC | C18: =C10 -> 2022 | D18: =D10 -> 2023 | E18: =E10 -> 2024 | F18: =F10 -> 2025 | G18: =G10 -> 2026 | H18: =H10 -> 2027 | I18: =I10 -> 2028 | J18: =J10 -> 2029 | ... O18: =O10 -> 2034
B19: Operating Cash | E19: =BalSheet!E17 -> 796.515 | F19: =BalSheet!F17 -> 790.49532 | G19: =BalSheet!G17 -> 810.2577 | H19: =BalSheet!H17 -> 891.28347 | I19: =BalSheet!I17 -> 1024.976 | J19: =BalSheet!J17 -> 1229.9712 | K19: =BalSheet!K17 -> 1537.464 | L19: =BalSheet!L17 -> 1921.83 | ... O19: =BalSheet!O17 -> 3753.5742
B20: =BalSheet!B20 -> Inventories | E20: =BalSheet!E20 -> 12198 | F20: =BalSheet!F20 -> 11206.9 | G20: =BalSheet!G20 -> 10565.687 | H20: =BalSheet!H20 -> 10608.731 | I20: =BalSheet!I20 -> 11034.487 | J20: =BalSheet!J20 -> 11842.72 | K20: =BalSheet!K20 -> 14104.069 | L20: =BalSheet!L20 -> 16755.921 | ... O20: =BalSheet!O20 -> 27604.347
B21: =BalSheet!B19 -> Accounts receivable | E21: =BalSheet!E19 -> 3478 | F21: =BalSheet!F19 -> 3451.7149 | G21: =BalSheet!G19 -> 3538.0078 | H21: =BalSheet!H19 -> 3891.8086 | I21: =BalSheet!I19 -> 4475.5799 | J21: =BalSheet!J19 -> 5370.6959 | K21: =BalSheet!K19 -> 6713.3698 | L21: =BalSheet!L19 -> 8391.7123 | ... O21: =BalSheet!O19 -> 16390.063
B22: Other current assets | E22: =BalSheet!E21 -> 23399 | F22: =BalSheet!F21 -> 23222.162 | G22: =BalSheet!G21 -> 23802.716 | H22: =BalSheet!H21 -> 26182.987 | I22: =BalSheet!I21 -> 30110.435 | J22: =BalSheet!J21 -> 36132.522 | K22: =BalSheet!K21 -> 45165.653 | L22: =BalSheet!L21 -> 56457.066 | ... O22: =BalSheet!O21 -> 110267.71
B23: Accounts payables | E23: =BalSheet!E33 -> 14312 | F23: =BalSheet!F33 -> 13149.136 | G23: =BalSheet!G33 -> 12396.795 | H23: =BalSheet!H33 -> 12447.299 | I23: =BalSheet!I33 -> 12946.842 | J23: =BalSheet!J33 -> 13895.148 | K23: =BalSheet!K33 -> 16548.404 | L23: =BalSheet!L33 -> 19659.841 | ... O23: =BalSheet!O33 -> 32388.377
B24: Other current liabilities | E24: =BalSheet!E34 -> 17625 | F24: =BalSheet!F34 -> 17491.799 | G24: =BalSheet!G34 -> 17929.094 | H24: =BalSheet!H34 -> 19722.003 | I24: =BalSheet!I34 -> 22680.303 | J24: =BalSheet!J34 -> 27216.364 | K24: =BalSheet!K34 -> 34020.455 | L24: =BalSheet!L34 -> 42525.569 | ... O24: =BalSheet!O34 -> 83057.752
A25: * | B25: OWC | E25: =SUM(E19:E22)-SUM(E23:E24) -> 7934.515 | F25: =SUM(F19:F22)-SUM(F23:F24) -> 8030.3378 | G25: =SUM(G19:G22)-SUM(G23:G24) -> 8390.7789 | H25: =SUM(H19:H22)-SUM(H23:H24) -> 9405.5078 | I25: =SUM(I19:I22)-SUM(I23:I24) -> 11018.333 | J25: =SUM(J19:J22)-SUM(J23:J24) -> 13464.398 | K25: =SUM(K19:K22)-SUM(K23:K24) -> 16951.696 | L25: =SUM(L19:L22)-SUM(L23:L24) -> 21341.119 | ... O25: =SUM(O19:O22)-SUM(O23:O24) -> 42569.563
B26: Change in OWC | F26: =E25-F25 -> -95.822761 | G26: =F25-G25 -> -360.44118 | H26: =G25-H25 -> -1014.7289 | I26: =H25-I25 -> -1612.8248 | J26: =I25-J25 -> -2446.0649 | K26: =J25-K25 -> -3487.2986 | L26: =K25-L25 -> -4389.4231 | M26: =L25-M25 -> -5524.6536 | ... O26: =N25-O25 -> -8750.6298

Sheet Debt
A1: =CoName -> Intel Corp. | C1: Hist. | D1: Hist. | E1: Hist. | F1: Proj. | G1: Proj. | H1: Proj. | I1: Proj. | J1: Proj. | K1: Proj. | L1: Proj. | M1: Proj. | N1: Proj. | O1: Proj.
A2: Assumptions | C2: 2022 | D2: =C2+1 -> 2023 | E2: =D2+1 -> 2024 | F2: =E2+1 -> 2025 | G2: =F2+1 -> 2026 | H2: =G2+1 -> 2027 | I2: =H2+1 -> 2028 | J2: =I2+1 -> 2029 | K2: =J2+1 -> 2030 | ... O2: =N2+1 -> 2034
B4: Interest rate on revolver | F4: =Assumptions!F24 -> 0.05 | G4: =Assumptions!G24 -> 0.05 | H4: =Assumptions!H24 -> 0.05 | I4: =Assumptions!I24 -> 0.05 | J4: =Assumptions!J24 -> 0.05 | K4: =Assumptions!K24 -> 0.05 | L4: =Assumptions!L24 -> 0.05 | M4: =Assumptions!M24 -> 0.05 | ... O4: =Assumptions!O24 -> 0.05
B5: Interest rate on long-term debt | F5: =Assumptions!F25 -> 0.039325 | G5: =Assumptions!G25 -> 0.039325 | H5: =Assumptions!H25 -> 0.039325 | I5: =Assumptions!I25 -> 0.039325 | J5: =Assumptions!J25 -> 0.039325 | K5: =Assumptions!K25 -> 0.039325 | L5: =Assumptions!L25 -> 0.039325 | M5: =Assumptions!M25 -> 0.039325 | ... O5: =Assumptions!O25 -> 0.039325
B6: Interest rate on cash | F6: =Assumptions!F26 -> 0.16705837 | G6: =Assumptions!G26 -> 0.16705837 | H6: =Assumptions!H26 -> 0.16705837 | I6: =Assumptions!I26 -> 0.16705837 | J6: =Assumptions!J26 -> 0.16705837 | K6: =Assumptions!K26 -> 0.16705837 | L6: =Assumptions!L26 -> 0.16705837 | M6: =Assumptions!M26 -> 0.16705837 | ... O6: =Assumptions!O26 -> 0.16705837
B8: Issuance of long-term debt | F8: =Assumptions!F28 -> 0 | G8: =Assumptions!G28 -> 0 | H8: =Assumptions!H28 -> 0 | I8: =Assumptions!I28 -> 0 | J8: =Assumptions!J28 -> 0 | K8: =Assumptions!K28 -> 0 | L8: =Assumptions!L28 -> 0 | M8: =Assumptions!M28 -> 0 | ... O8: =Assumptions!O28 -> 0
B9: Repayment of long-term debt | F9: =Assumptions!F29 -> 0 | G9: =Assumptions!G29 -> 0 | H9: =Assumptions!H29 -> 0 | I9: =Assumptions!I29 -> 0 | J9: =Assumptions!J29 -> 0 | K9: =Assumptions!K29 -> 0 | L9: =Assumptions!L29 -> 0 | M9: =Assumptions!M29 -> 0 | ... O9: =Assumptions!O29 -> 0
A11: Revolver | C11: =C2 -> 2022 | D11: =D2 -> 2023 | E11: =E2 -> 2024 | F11: =F2 -> 2025 | G11: =G2 -> 2026 | H11: =H2 -> 2027 | I11: =I2 -> 2028 | J11: =J2 -> 2029 | ... O11: =O2 -> 2034
B12: Balance | E12: =BalSheet!E32 -> 3729 | F12: =E12 -> 3729 | G12: =F12 -> 3729 | H12: =G12 -> 3729 | I12: =H12 -> 3729 | J12: =I12 -> 3729 | K12: =J12 -> 3729 | L12: =K12 -> 3729 | M12: =L12 -> 3729 | ... O12: =N12 -> 3729
B13: Interest rate | F13: =F4 -> 0.05 | G13: =G4 -> 0.05 | H13: =H4 -> 0.05 | I13: =I4 -> 0.05 | J13: =J4 -> 0.05 | K13: =K4 -> 0.05 | L13: =L4 -> 0.05 | M13: =M4 -> 0.05 | ... O13: =O4 -> 0.05
B14: Interest expense | F14: =F12*F13 -> 186.45 | G14: =G12*G13 -> 186.45 | H14: =H12*H13 -> 186.45 | I14: =I12*I13 -> 186.45 | J14: =J12*J13 -> 186.45 | K14: =K12*K13 -> 186.45 | L14: =L12*L13 -> 186.45 | M14: =M12*M13 -> 186.45 | ... O14: =O12*O13 -> 186.45
A16: Long term debt | C16: =C11 -> 2022 | D16: =D11 -> 2023 | E16: =E11 -> 2024 | F16: =F11 -> 2025 | G16: =G11 -> 2026 | H16: =H11 -> 2027 | I16: =I11 -> 2028 | J16: =J11 -> 2029 | ... O16: =O11 -> 2034
B17: Beginning balance | F17: =E20 -> 46282 | G17: =F20 -> 46282 | H17: =G20 -> 46282 | I17: =H20 -> 46282 | J17: =I20 -> 46282 | K17: =J20 -> 46282 | L17: =K20 -> 46282 | M17: =L20 -> 46282 | ... O17: =N20 -> 46282
B18: Issuance | F18: =F8 -> 0 | G18: =G8 -> 0 | H18: =H8 -> 0 | I18: =I8 -> 0 | J18: =J8 -> 0 | K18: =K8 -> 0 | L18: =L8 -> 0 | M18: =M8 -> 0 | ... O18: =O8 -> 0
B19: Repayment | F19: =F9 -> 0 | G19: =G9 -> 0 | H19: =H9 -> 0 | I19: =I9 -> 0 | J19: =J9 -> 0 | K19: =K9 -> 0 | L19: =L9 -> 0 | M19: =M9 -> 0 | ... O19: =O9 -> 0
B20: Ending balance | E20: =BalSheet!E37 -> 46282 | F20: =SUM(F17:F19) -> 46282 | G20: =SUM(G17:G19) -> 46282 | H20: =SUM(H17:H19) -> 46282 | I20: =SUM(I17:I19) -> 46282 | J20: =SUM(J17:J19) -> 46282 | K20: =SUM(K17:K19) -> 46282 | L20: =SUM(L17:L19) -> 46282 | M20: =SUM(M17:M19) -> 46282 | ... O20: =SUM(O17:O19) -> 46282
B21: Interest rate | F21: =F5 -> 0.039325 | G21: =G5 -> 0.039325 | H21: =H5 -> 0.039325 | I21: =I5 -> 0.039325 | J21: =J5 -> 0.039325 | K21: =K5 -> 0.039325 | L21: =L5 -> 0.039325 | M21: =M5 -> 0.039325 | ... O21: =O5 -> 0.039325
B22: Interest expense | F22: =F20*F21 -> 1820.0396 | G22: =G20*G21 -> 1820.0396 | H22: =H20*H21 -> 1820.0396 | I22: =I20*I21 -> 1820.0396 | J22: =J20*J21 -> 1820.0396 | K22: =K20*K21 -> 1820.0396 | L22: =L20*L21 -> 1820.0396 | M22: =M20*M21 -> 1820.0396 | ... O22: =O20*O21 -> 1820.0396
A24: Debt summary | C24: =C16 -> 2022 | D24: =D16 -> 2023 | E24: =E16 -> 2024 | F24: =F16 -> 2025 | G24: =G16 -> 2026 | H24: =H16 -> 2027 | I24: =I16 -> 2028 | J24: =J16 -> 2029 | ... O24: =O16 -> 2034
B25: Revolver | F25: =F12 -> 3729 | G25: =G12 -> 3729 | H25: =H12 -> 3729 | I25: =I12 -> 3729 | J25: =J12 -> 3729 | K25: =K12 -> 3729 | L25: =L12 -> 3729 | M25: =M12 -> 3729 | ... O25: =O12 -> 3729
B26: Total long term debt | F26: =F20 -> 46282 | G26: =G20 -> 46282 | H26: =H20 -> 46282 | I26: =I20 -> 46282 | J26: =J20 -> 46282 | K26: =K20 -> 46282 | L26: =L20 -> 46282 | M26: =M20 -> 46282 | ... O26: =O20 -> 46282
B27: Total debt | F27: =SUM(F25:F26) -> 50011 | G27: =SUM(G25:G26) -> 50011 | H27: =SUM(H25:H26) -> 50011 | I27: =SUM(I25:I26) -> 50011 | J27: =SUM(J25:J26) -> 50011 | K27: =SUM(K25:K26) -> 50011 | L27: =SUM(L25:L26) -> 50011 | M27: =SUM(M25:M26) -> 50011 | ... O27: =SUM(O25:O26) -> 50011
B28: Total interest expense | F28: =SUM(F22,F14) -> 2006.4896 | G28: =SUM(G22,G14) -> 2006.4896 | H28: =SUM(H22,H14) -> 2006.4896 | I28: =SUM(I22,I14) -> 2006.4896 | J28: =SUM(J22,J14) -> 2006.4896 | K28: =SUM(K22,K14) -> 2006.4896 | L28: =SUM(L22,L14) -> 2006.4896 | M28: =SUM(M22,M14) -> 2006.4896 | ... O28: =SUM(O22,O14) -> 2006.4896
A30: Interest income | C30: =C11 -> 2022 | D30: =D11 -> 2023 | E30: =E11 -> 2024 | F30: =F11 -> 2025 | G30: =G11 -> 2026 | H30: =H11 -> 2027 | I30: =I11 -> 2028 | J30: =J11 -> 2029 | ... O30: =O11 -> 2034
B31: Excess Cash | F31: =BalSheet!F18 -> 589.09976
B32: Interest rate | F32: =F6 -> 0.16705837
B33: Interest income | F33: =F31*F32 -> 98.414046

Sheet IncState
A1: =CoName -> Intel Corp. | C1: Hist. | D1: Hist. | E1: Hist. | F1: Proj. | G1: Proj. | H1: Proj. | I1: Proj. | J1: Proj. | K1: Proj. | L1: Proj. | M1: Proj. | N1: Proj. | O1: Proj.
A2: Assumptions | C2: 2022 | D2: =C2+1 -> 2023 | E2: =D2+1 -> 2024 | F2: =E2+1 -> 2025 | G2: =F2+1 -> 2026 | H2: =G2+1 -> 2027 | I2: =H2+1 -> 2028 | J2: =I2+1 -> 2029 | K2: =J2+1 -> 2030 | ... O2: =N2+1 -> 2034
B4: Revenue growth | F4: =Assumptions!F10 -> -0.0075575225 | G4: =Assumptions!G10 -> 0.025 | H4: =Assumptions!H10 -> 0.1 | I4: =Assumptions!I10 -> 0.15 | J4: =Assumptions!J10 -> 0.2 | K4: =Assumptions!K10 -> 0.25 | L4: =Assumptions!L10 -> 0.25 | M4: =Assumptions!M10 -> 0.25 | ... O4: =Assumptions!O10 -> 0.25
B5: Cost of goods sold as % of sales | F5: =Assumptions!F11 -> 0.62335832 | G5: =Assumptions!G11 -> 0.57335832 | H5: =Assumptions!H11 -> 0.52335832 | I5: =Assumptions!I11 -> 0.47335832 | J5: =Assumptions!J11 -> 0.42335832 | K5: =Assumptions!K11 -> 0.40335832 | L5: =Assumptions!L11 -> 0.38335832 | M5: =Assumptions!M11 -> 0.36335832 | ... O5: =Assumptions!O11 -> 0.32335832
B6: R&D % of sales | F6: =Assumptions!F12 -> 0.29159489 | G6: =Assumptions!G12 -> 0.27159489 | H6: =Assumptions!H12 -> 0.25159489 | I6: =Assumptions!I12 -> 0.23159489 | J6: =Assumptions!J12 -> 0.21159489 | K6: =Assumptions!K12 -> 0.19159489 | L6: =Assumptions!L12 -> 0.19159489 | M6: =Assumptions!M12 -> 0.19159489 | ... O6: =Assumptions!O12 -> 0.19159489
B7: SG&A % of sales | F7: =Assumptions!F13 -> 0.21496733 | G7: =Assumptions!G13 -> 0.19496733 | H7: =Assumptions!H13 -> 0.17496733 | I7: =Assumptions!I13 -> 0.15496733 | J7: =Assumptions!J13 -> 0.13496733 | K7: =Assumptions!K13 -> 0.11496733 | L7: =Assumptions!L13 -> 0.094967326 | M7: =Assumptions!M13 -> 0.074967326 | ... O7: =Assumptions!O13 -> 0.074967326
B8: Amortization amount | F8: =Assumptions!F14 -> 1428 | G8: =Assumptions!G14 -> 1428 | H8: =Assumptions!H14 -> 1428 | I8: =Assumptions!I14 -> 1428 | J8: =Assumptions!J14 -> 1428 | K8: =Assumptions!K14 -> 1428 | L8: =Assumptions!L14 -> 1428 | M8: =Assumptions!M14 -> 1428 | ... O8: =Assumptions!O14 -> 1428
B9: Non recurring items, amount | F9: =Assumptions!F15 -> 0 | G9: =Assumptions!G15 -> 0 | H9: =Assumptions!H15 -> 0 | I9: =Assumptions!I15 -> 0 | J9: =Assumptions!J15 -> 0 | K9: =Assumptions!K15 -> 0 | L9: =Assumptions!L15 -> 0 | M9: =Assumptions!M15 -> 0 | ... O9: =Assumptions!O15 -> 0
B10: Other income (expense), amt | F10: =Assumptions!F16 -> 0 | G10: =Assumptions!G16 -> 0 | H10: =Assumptions!H16 -> 0 | I10: =Assumptions!I16 -> 0 | J10: =Assumptions!J16 -> 0 | K10: =Assumptions!K16 -> 0 | L10: =Assumptions!L16 -> 0 | M10: =Assumptions!M16 -> 0 | ... O10: =Assumptions!O16 -> 0
B11: Effective tax rate | F11: =Assumptions!F17 -> 0.12 | G11: =Assumptions!G17 -> 0.12 | H11: =Assumptions!H17 -> 0.12 | I11: =Assumptions!I17 -> 0.12 | J11: =Assumptions!J17 -> 0.12 | K11: =Assumptions!K17 -> 0.12 | L11: =Assumptions!L17 -> 0.12 | M11: =Assumptions!M17 -> 0.12 | ... O11: =Assumptions!O17 -> 0.12
B12: Dividend Payout Rate | F12: =Assumptions!F18 -> 0.37359813 | G12: =Assumptions!G18 -> 0.37359813 | H12: =Assumptions!H18 -> 0.37359813 | I12: =Assumptions!I18 -> 0.37359813 | J12: =Assumptions!J18 -> 0.37359813 | K12: =Assumptions!K18 -> 0.37359813 | L12: =Assumptions!L18 -> 0.37359813 | M12: =Assumptions!M18 -> 0.37359813 | ... O12: =Assumptions!O18 -> 0.37359813
B13: Basic WASO | F13: =Assumptions!F19 -> 4280 | G13: =Assumptions!G19 -> 4280 | H13: =Assumptions!H19 -> 4280 | I13: =Assumptions!I19 -> 4280 | J13: =Assumptions!J19 -> 4280 | K13: =Assumptions!K19 -> 4280 | L13: =Assumptions!L19 -> 4280 | M13: =Assumptions!M19 -> 4280 | ... O13: =Assumptions!O19 -> 4280
B14: Diluted WASO | F14: =Assumptions!F20 -> 4280 | G14: =Assumptions!G20 -> 4280 | H14: =Assumptions!H20 -> 4280 | I14: =Assumptions!I20 -> 4280 | J14: =Assumptions!J20 -> 4280 | K14: =Assumptions!K20 -> 4280 | L14: =Assumptions!L20 -> 4280 | M14: =Assumptions!M20 -> 4280 | ... O14: =Assumptions!O20 -> 4280
A16: Income statement | C16: =C39 -> 44926 | D16: =D39 -> 45291 | E16: =E39 -> 45657 | F16: =F39 -> 46022 | G16: =G2 -> 2026 | H16: =H2 -> 2027 | I16: =I2 -> 2028 | J16: =J2 -> 2029 | K16: =K2 -> 2030 | L16: =L2 -> 2031 | M16: =M2 -> 2032 | N16: =N2 -> 2033 | O16: =O2 -> 2034
B17: Revenue | C17: 63054 | D17: 54228 | E17: 53101 | F17: =E17*(1+F4) -> 52699.688 | G17: =F17*(1+G4) -> 54017.18 | H17: =G17*(1+H4) -> 59418.898 | I17: =H17*(1+I4) -> 68331.733 | J17: =I17*(1+J4) -> 81998.08 | K17: =J17*(1+K4) -> 102497.6 | L17: =K17*(1+L4) -> 128122 | M17: =L17*(1+M4) -> 160152.5 | ... O17: =N17*(1+O4) -> 250238.28
B18: COGS | C18: 36188 | D18: 32517 | E18: 35756 | F18: =F17*F5 -> 32850.789 | G18: =G17*G5 -> 30971.2 | H18: =H17*H5 -> 31097.375 | I18: =I17*I5 -> 32345.394 | J18: =J17*J5 -> 34714.569 | K18: =K17*K5 -> 41343.259 | L18: =L17*L5 -> 49116.634 | M18: =M17*M5 -> 58192.743 | ... O18: =O17*O5 -> 80916.629
B19: R&D | C19: 17528 | D19: 16046 | E19: 16546 | F19: =F17*F6 -> 15366.959 | G19: =G17*G6 -> 14670.79 | H19: =H17*H6 -> 14949.491 | I19: =I17*I6 -> 15825.28 | J19: =J17*J6 -> 17350.374 | K19: =K17*K6 -> 19638.016 | L19: =L17*L6 -> 24547.52 | M19: =M17*M6 -> 30684.4 | ... O19: =O17*O6 -> 47944.375
B20: SG&A | C20: 7004 | D20: =5634-62 -> 5572 | E20: =5507+6970 -> 12477 | F20: =F17*F7 -> 11328.711 | G20: =G17*G7 -> 10531.585 | H20: =H17*H7 -> 10396.366 | I20: =I17*I7 -> 10589.186 | J20: =J17*J7 -> 11067.062 | K20: =K17*K7 -> 11783.875 | L20: =L17*L7 -> 12167.404 | M20: =M17*M7 -> 12006.205 | ... O20: =O17*O7 -> 18759.695
A21: * | B21: EBIT | C21: =C17-SUM(C18:C20) -> 2334 | D21: =D17-SUM(D18:D20) -> 93 | E21: =E17-SUM(E18:E20) -> -11678 | F21: =F17-SUM(F18:F20) -> -6846.7713 | G21: =G17-SUM(G18:G20) -> -2156.3944 | H21: =H17-SUM(H18:H20) -> 2975.667 | I21: =I17-SUM(I18:I20) -> 9571.873 | J21: =J17-SUM(J18:J20) -> 18866.075 | ... O21: =O17-SUM(O18:O20) -> 102617.58
B23: Depreciation | C23: 11128 | D23: 7847 | E23: 9951 | F23: =Calcs!F8 -> 10571.996 | G23: =Calcs!G8 -> 11606.093 | H23: =Calcs!H8 -> 12537.714 | I23: =Calcs!I8 -> 13526.721 | J23: =Calcs!J8 -> 14684.489 | K23: =Calcs!K8 -> 16145.086 | L23: =Calcs!L8 -> 18086.973 | M23: =Calcs!M8 -> 20593.99 | ... O23: =Calcs!O8 -> 27733.343
B24: Amortization | C24: 1907 | D24: 1755 | E24: 1428 | F24: =F8 -> 1428 | G24: =G8 -> 1428 | H24: =H8 -> 1428 | I24: =I8 -> 1428 | J24: =J8 -> 1428 | K24: =K8 -> 1428 | L24: =L8 -> 1428 | M24: =M8 -> 1428 | ... O24: =O8 -> 1428
A25: * | B25: EBITDA | C25: =SUM(C21,C23:C24) -> 15369 | D25: =SUM(D21,D23:D24) -> 9695 | E25: =SUM(E21,E23:E24) -> -299 | F25: =SUM(F21,F23:F24) -> 5153.225 | G25: =SUM(G21,G23:G24) -> 10877.698 | H25: =SUM(H21,H23:H24) -> 16941.381 | I25: =SUM(I21,I23:I24) -> 24526.594 | J25: =SUM(J21,J23:J24) -> 34978.564 | ... O25: =SUM(O21,O23:O24) -> 131778.92
B27: Non-recurring items | C27: 2 | D27: -62 | E27: 6970 | F27: =F9 -> 0 | G27: =G9 -> 0 | H27: =H9 -> 0 | I27: =I9 -> 0 | J27: =J9 -> 0 | K27: =K9 -> 0 | L27: =L9 -> 0 | M27: =M9 -> 0 | ... O27: =O9 -> 0
B28: Other income (expense) | C28: 1073 | D28: 172 | E28: 15 | F28: =F10 -> 0 | G28: =G10 -> 0 | H28: =H10 -> 0 | I28: =I10 -> 0 | J28: =J10 -> 0 | K28: =K10 -> 0 | L28: =L10 -> 0 | M28: =M10 -> 0 | ... O28: =O10 -> 0
B30: Interest income | C30: 589 | D30: 1335 | E30: 1245 | F30: =IF(circ=1,Debt!F33,0) -> 0 | G30: =IF(circ=1,Debt!G33,0) -> 0 | H30: =IF(circ=1,Debt!H33,0) -> 0 | I30: =IF(circ=1,Debt!I33,0) -> 0 | J30: =IF(circ=1,Debt!J33,0) -> 0 | K30: =IF(circ=1,Debt!K33,0) -> 0 | L30: =IF(circ=1,Debt!L33,0) -> 0 | M30: =IF(circ=1,Debt!M33,0) -> 0 | ... O30: =IF(circ=1,Debt!O33,0) -> 0
B31: Interest expense | C31: -596 | D31: -878 | E31: -1034 | F31: =IF(circ=1,Debt!F28,0) -> 0 | G31: =IF(circ=1,Debt!G28,0) -> 0 | H31: =IF(circ=1,Debt!H28,0) -> 0 | I31: =IF(circ=1,Debt!I28,0) -> 0 | J31: =IF(circ=1,Debt!J28,0) -> 0 | K31: =IF(circ=1,Debt!K28,0) -> 0 | L31: =IF(circ=1,Debt!L28,0) -> 0 | M31: =IF(circ=1,Debt!M28,0) -> 0 | ... O31: =IF(circ=1,Debt!O28,0) -> 0
A33: * | B33: Pretax Income | C33: =C21+SUM(C27:C31) -> 3402 | D33: =D21+SUM(D27:D31) -> 660 | E33: =E21+SUM(E27:E31) -> -4482 | F33: =F21+SUM(F27:F31) -> -6846.7713 | G33: =G21+SUM(G27:G31) -> -2156.3944 | H33: =H21+SUM(H27:H31) -> 2975.667 | I33: =I21+SUM(I27:I31) -> 9571.873 | J33: =J21+SUM(J27:J31) -> 18866.075 | ... O33: =O21+SUM(O27:O31) -> 102617.58
B35: Tax expense | C35: -249 | D35: -913 | E35: 8023 | F35: =F33*F11 -> -821.61256 | G35: =G33*G11 -> -258.76733 | H35: =H33*H11 -> 357.08004 | I35: =I33*I11 -> 1148.6248 | J35: =J33*J11 -> 2263.929 | K35: =K33*K11 -> 3567.8939 | L35: =L33*L11 -> 5074.853 | M35: =M33*M11 -> 7112.2983 | ... O35: =O33*O11 -> 12314.11
A36: * | B36: Net income | C36: =C33-C35 -> 3651 | D36: =D33-D35 -> 1573 | E36: =E33-E35 -> -12505 | F36: =F33-F35 -> -6025.1588 | G36: =G33-G35 -> -1897.6271 | H36: =H33-H35 -> 2618.587 | I36: =I33-I35 -> 8423.2483 | J36: =J33-J35 -> 16602.146 | ... O36: =O33-O35 -> 90303.472
B37: Dividend payout rate | C37: =C38/C40 -> 1.4598345 | D37: =D38/D40 -> 0.73699284 | E37: =E38/E40 -> 0.37359813 | F37: =F12 -> 0.37359813 | G37: =G12 -> 0.37359813 | H37: =H12 -> 0.37359813 | I37: =I12 -> 0.37359813 | J37: =J12 -> 0.37359813 | K37: =K12 -> 0.37359813 | L37: =L12 -> 0.37359813 | M37: =M12 -> 0.37359813 | ... O37: =O12 -> 0.37359813
B38: Dividends | C38: 5997 | D38: 3088 | E38: 1599 | F38: =F37*F40 -> 1599 | G38: =G37*G40 -> 1599 | H38: =H37*H40 -> 1599 | I38: =I37*I40 -> 1599 | J38: =J37*J40 -> 1599 | K38: =K37*K40 -> 1599 | L38: =L37*L40 -> 1599 | M38: =M37*M40 -> 1599 | ... O38: =O37*O40 -> 1599
A39: Shareholder information | C39: 44926 | D39: 45291 | E39: 45657 | F39: 46022 | G39: =G16 -> 2026 | H39: =H16 -> 2027 | I39: =I16 -> 2028 | J39: =J16 -> 2029 | K39: =K16 -> 2030 | L39: =L16 -> 2031 | M39: =M16 -> 2032 | N39: =N16 -> 2033 | O39: =O16 -> 2034
B40: Basic WASO | C40: 4108 | D40: 4190 | E40: 4280 | F40: =F13 -> 4280 | G40: =G13 -> 4280 | H40: =H13 -> 4280 | I40: =I13 -> 4280 | J40: =J13 -> 4280 | K40: =K13 -> 4280 | L40: =L13 -> 4280 | M40: =M13 -> 4280 | ... O40: =O13 -> 4280
B41: Diluted WASO | C41: 4123 | D41: 4212 | E41: 4280 | F41: =F14 -> 4280 | G41: =G14 -> 4280 | H41: =H14 -> 4280 | I41: =I14 -> 4280 | J41: =J14 -> 4280 | K41: =K14 -> 4280 | L41: =L14 -> 4280 | M41: =M14 -> 4280 | ... O41: =O14 -> 4280
B42: Basic earnings per share | C42: =C36/C40 -> 0.88875365 | D42: =D36/D40 -> 0.37541766 | E42: =E36/E40 -> -2.921729 | F42: =F36/F40 -> -1.4077474 | G42: =G36/G40 -> -0.44337081 | H42: =H36/H40 -> 0.61181938 | I42: =I36/I40 -> 1.9680487 | J42: =J36/J40 -> 3.879006 | ... O42: =O36/O40 -> 21.098942
A43: * | B43: Diluted earnings per share | C43: =C36/C41 -> 0.88552025 | D43: =D36/D41 -> 0.37345679 | E43: =E36/E41 -> -2.921729 | F43: =F36/F41 -> -1.4077474 | G43: =G36/G41 -> -0.44337081 | H43: =H36/H41 -> 0.61181938 | I43: =I36/I41 -> 1.9680487 | J43: =J36/J41 -> 3.879006 | ... O43: =O36/O41 -> 21.098942

Sheet BalSheet
A1: =CoName -> Intel Corp. | C1: Hist. | D1: Hist. | E1: Hist. | F1: Proj. | G1: Proj. | H1: Proj. | I1: Proj. | J1: Proj. | K1: Proj. | L1: Proj. | M1: Proj. | N1: Proj. | O1: Proj.
A2: Assumptions | C2: 2022 | D2: =C2+1 -> 2023 | E2: =D2+1 -> 2024 | F2: =E2+1 -> 2025 | G2: =F2+1 -> 2026 | H2: =G2+1 -> 2027 | I2: =H2+1 -> 2028 | J2: =I2+1 -> 2029 | K2: =J2+1 -> 2030 | ... O2: =N2+1 -> 2034
B4: Operating Cash % of sales | F4: =Assumptions!F45 -> 0.015 | G4: =F4 -> 0.015 | H4: =G4 -> 0.015 | I4: =H4 -> 0.015 | J4: =I4 -> 0.015 | K4: =J4 -> 0.015 | L4: =K4 -> 0.015 | M4: =L4 -> 0.015 | N4: =M4 -> 0.015 | O4: =N4 -> 0.015
B5: Accounts receivable % of sales | F5: =Assumptions!F46 -> 0.065497825 | G5: =Assumptions!G46 -> 0.065497825 | H5: =Assumptions!H46 -> 0.065497825 | I5: =Assumptions!I46 -> 0.065497825 | J5: =Assumptions!J46 -> 0.065497825 | K5: =Assumptions!K46 -> 0.065497825 | L5: =Assumptions!L46 -> 0.065497825 | M5: =Assumptions!M46 -> 0.065497825 | ... O5: =Assumptions!O46 -> 0.065497825
B6: Inventories % of COGS | F6: =Assumptions!F47 -> 0.34114554 | G6: =Assumptions!G47 -> 0.34114554 | H6: =Assumptions!H47 -> 0.34114554 | I6: =Assumptions!I47 -> 0.34114554 | J6: =Assumptions!J47 -> 0.34114554 | K6: =Assumptions!K47 -> 0.34114554 | L6: =Assumptions!L47 -> 0.34114554 | M6: =Assumptions!M47 -> 0.34114554 | ... O6: =Assumptions!O47 -> 0.34114554
B7: Other current assets % of sales | F7: =Assumptions!F48 -> 0.44065084 | G7: =Assumptions!G48 -> 0.44065084 | H7: =Assumptions!H48 -> 0.44065084 | I7: =Assumptions!I48 -> 0.44065084 | J7: =Assumptions!J48 -> 0.44065084 | K7: =Assumptions!K48 -> 0.44065084 | L7: =Assumptions!L48 -> 0.44065084 | M7: =Assumptions!M48 -> 0.44065084 | ... O7: =Assumptions!O48 -> 0.44065084
B9: Other long-term assets % of sales | F9: =Assumptions!F51 -> 0.14076948 | G9: =Assumptions!G51 -> 0.14076948 | H9: =Assumptions!H51 -> 0.14076948 | I9: =Assumptions!I51 -> 0.14076948 | J9: =Assumptions!J51 -> 0.14076948 | K9: =Assumptions!K51 -> 0.14076948 | L9: =Assumptions!L51 -> 0.14076948 | M9: =Assumptions!M51 -> 0.14076948 | ... O9: =Assumptions!O51 -> 0.14076948
B10: Investment in unconsolidated entities $ balance | F10: =Assumptions!F50 -> 5383 | G10: =Assumptions!G50 -> 5383 | H10: =Assumptions!H50 -> 5383 | I10: =Assumptions!I50 -> 5383 | J10: =Assumptions!J50 -> 5383 | K10: =Assumptions!K50 -> 5383 | L10: =Assumptions!L50 -> 5383 | M10: =Assumptions!M50 -> 5383 | ... O10: =Assumptions!O50 -> 5383
B12: Accounts payable/Accural % of COGS | F12: =Assumptions!F55 -> 0.40026849 | G12: =Assumptions!G55 -> 0.40026849 | H12: =Assumptions!H55 -> 0.40026849 | I12: =Assumptions!I55 -> 0.40026849 | J12: =Assumptions!J55 -> 0.40026849 | K12: =Assumptions!K55 -> 0.40026849 | L12: =Assumptions!L55 -> 0.40026849 | M12: =Assumptions!M55 -> 0.40026849 | ... O12: =Assumptions!O55 -> 0.40026849
B13: Other current liabilities % of sales | F13: =Assumptions!F56 -> 0.33191465 | G13: =Assumptions!G56 -> 0.33191465 | H13: =Assumptions!H56 -> 0.33191465 | I13: =Assumptions!I56 -> 0.33191465 | J13: =Assumptions!J56 -> 0.33191465 | K13: =Assumptions!K56 -> 0.33191465 | L13: =Assumptions!L56 -> 0.33191465 | M13: =Assumptions!M56 -> 0.33191465 | ... O13: =Assumptions!O56 -> 0.33191465
B14: Other long-term liabilities % of sales | F14: =Assumptions!F57 -> 0.17899851 | G14: =Assumptions!G57 -> 0.17899851 | H14: =Assumptions!H57 -> 0.17899851 | I14: =Assumptions!I57 -> 0.17899851 | J14: =Assumptions!J57 -> 0.17899851 | K14: =Assumptions!K57 -> 0.17899851 | L14: =Assumptions!L57 -> 0.17899851 | M14: =Assumptions!M57 -> 0.17899851 | ... O14: =Assumptions!O57 -> 0.17899851
A16: Balance sheet | C16: =C2 -> 2022 | D16: =D2 -> 2023 | E16: =E2 -> 2024 | F16: =F2 -> 2025 | G16: =G2 -> 2026 | H16: =H2 -> 2027 | I16: =I2 -> 2028 | J16: =J2 -> 2029 | ... O16: =O2 -> 2034
B17: Operating Cash | C17: =1.5%*IncState!C17 -> 945.81 | D17: =1.5%*IncState!D17 -> 813.42 | E17: =1.5%*IncState!E17 -> 796.515 | F17: =F4*IncState!F17 -> 790.49532 | G17: =G4*IncState!G17 -> 810.2577 | H17: =H4*IncState!H17 -> 891.28347 | I17: =I4*IncState!I17 -> 1024.976 | J17: =J4*IncState!J17 -> 1229.9712 | K17: =K4*IncState!K17 -> 1537.464 | L17: =L4*IncState!L17 -> 1921.83 | M17: =M4*IncState!M17 -> 2402.2875 | ... O17: =O4*IncState!O17 -> 3753.5742
B18: Excess cash | C18: =11144-C17 -> 10198.19 | D18: =7079-D17 -> 6265.58 | E18: =8249-E17 -> 7452.485 | F18: =MAX(CashFlow!F23,0) -> 589.09976 | G18: =MAX(CashFlow!G23,0) -> 0 | H18: =MAX(CashFlow!H23,0) -> 1543.5668 | I18: =MAX(CashFlow!I23,0) -> 6705.2241 | J18: =MAX(CashFlow!J23,0) -> 16302.966 | K18: =MAX(CashFlow!K23,0) -> 29770.113 | L18: =MAX(CashFlow!L23,0) -> 47813.227 | M18: =MAX(CashFlow!M23,0) -> 73096.161 | ... O18: =MAX(CashFlow!O23,0) -> 148972.05
B19: Accounts receivable | C19: 4133 | D19: 3402 | E19: 3478 | F19: =F5*IncState!F17 -> 3451.7149 | G19: =G5*IncState!G17 -> 3538.0078 | H19: =H5*IncState!H17 -> 3891.8086 | I19: =I5*IncState!I17 -> 4475.5799 | J19: =J5*IncState!J17 -> 5370.6959 | K19: =K5*IncState!K17 -> 6713.3698 | L19: =L5*IncState!L17 -> 8391.7123 | M19: =M5*IncState!M17 -> 10489.64 | ... O19: =O5*IncState!O17 -> 16390.063
B20: Inventories | C20: 13224 | D20: 11127 | E20: 12198 | F20: =F6*IncState!F18 -> 11206.9 | G20: =G6*IncState!G18 -> 10565.687 | H20: =H6*IncState!H18 -> 10608.731 | I20: =I6*IncState!I18 -> 11034.487 | J20: =J6*IncState!J18 -> 11842.72 | K20: =K6*IncState!K18 -> 14104.069 | L20: =L6*IncState!L18 -> 16755.921 | M20: =M6*IncState!M18 -> 19852.195 | ... O20: =O6*IncState!O18 -> 27604.347
B21: Other current assets | C21: =4712+17194 -> 21906 | D21: =3706+17955 -> 21661 | E21: =9586+13813 -> 23399 | F21: =F7*IncState!F17 -> 23222.162 | G21: =G7*IncState!G17 -> 23802.716 | H21: =H7*IncState!H17 -> 26182.987 | I21: =I7*IncState!I17 -> 30110.435 | J21: =J7*IncState!J17 -> 36132.522 | K21: =K7*IncState!K17 -> 45165.653 | L21: =L7*IncState!L17 -> 56457.066 | M21: =M7*IncState!M17 -> 70571.332 | ... O21: =O7*IncState!O17 -> 110267.71
B22: Total current assets | C22: =SUM(C17:C21) -> 50407 | D22: =SUM(D17:D21) -> 43269 | E22: =SUM(E17:E21) -> 47324 | F22: =SUM(F17:F21) -> 39260.372 | G22: =SUM(G17:G21) -> 38716.668 | H22: =SUM(H17:H21) -> 43118.377 | I22: =SUM(I17:I21) -> 53350.702 | J22: =SUM(J17:J21) -> 70878.876 | ... O22: =SUM(O17:O21) -> 306987.74
B24: Property, plant & equipment, net | C24: 80860 | D24: 96647 | E24: 107919 | F24: =Calcs!F9 -> 118475.06 | G24: =Calcs!G9 -> 127985.06 | H24: =Calcs!H9 -> 138080.85 | I24: =Calcs!I9 -> 149899.35 | J24: =Calcs!J9 -> 164809.14 | K24: =Calcs!K9 -> 184631.92 | L24: =Calcs!L9 -> 210223.57 | M24: =Calcs!M9 -> 242626.33 | ... O24: =Calcs!O9 -> 333171.44
B25: Intangible assets | C25: =27591+6018 -> 33609 | D25: =27591+4589 -> 32180 | E25: =24693+3691 -> 28384 | F25: =E25-IncState!F24 -> 26956 | G25: =F25-IncState!G24 -> 25528 | H25: =G25-IncState!H24 -> 24100 | I25: =H25-IncState!I24 -> 22672 | J25: =I25-IncState!J24 -> 21244 | K25: =J25-IncState!K24 -> 19816 | L25: =K25-IncState!L24 -> 18388 | M25: =L25-IncState!M24 -> 16960 | ... O25: =N25-IncState!O24 -> 14104
B26: Investment in unconsolidated entities | C26: 5912 | D26: =5829 -> 5829 | E26: 5383 | F26: =F10 -> 5383 | G26: =G10 -> 5383 | H26: =H10 -> 5383 | I26: =I10 -> 5383 | J26: =J10 -> 5383 | K26: =K10 -> 5383 | L26: =L10 -> 5383 | M26: =M10 -> 5383 | ... O26: =O10 -> 5383
B27: Other assets | C27: =11315 -> 11315 | D27: =13647 -> 13647 | E27: =7475 -> 7475 | F27: =F9*IncState!F17 -> 7418.5075 | G27: =G9*IncState!G17 -> 7603.9702 | H27: =H9*IncState!H17 -> 8364.3672 | I27: =I9*IncState!I17 -> 9619.0223 | J27: =J9*IncState!J17 -> 11542.827 | K27: =K9*IncState!K17 -> 14428.533 | L27: =L9*IncState!L17 -> 18035.667 | M27: =M9*IncState!M17 -> 22544.584 | ... O27: =O9*IncState!O17 -> 35225.912
B28: Total non-current assets | C28: =SUM(C24:C27) -> 131696 | D28: =SUM(D24:D27) -> 148303 | E28: =SUM(E24:E27) -> 149161 | F28: =SUM(F24:F27) -> 158232.57 | G28: =SUM(G24:G27) -> 166500.03 | H28: =SUM(H24:H27) -> 175928.22 | I28: =SUM(I24:I27) -> 187573.37 | J28: =SUM(J24:J27) -> 202978.96 | ... O28: =SUM(O24:O27) -> 387884.35
A30: * | B30: TOTAL ASSETS | C30: =SUM(C28,C22) -> 182103 | D30: =SUM(D28,D22) -> 191572 | E30: =SUM(E28,E22) -> 196485 | F30: =SUM(F28,F22) -> 197492.94 | G30: =SUM(G28,G22) -> 205216.7 | H30: =SUM(H28,H22) -> 219046.59 | I30: =SUM(I28,I22) -> 240924.07 | J30: =SUM(J28,J22) -> 273857.84 | ... O30: =SUM(O28,O22) -> 694872.09
B32: Revolver/Short term debt | C32: 4367 | D32: 2288 | E32: 3729 | F32: =Debt!F12+(MIN(CashFlow!F23,0)*-1) -> 3729 | G32: =-MIN(CashFlow!G23,0)+F32 -> 5028.5972 | H32: =-MIN(CashFlow!H23,0)+G32 -> 5028.5972 | I32: =-MIN(CashFlow!I23,0)+H32 -> 5028.5972 | J32: =-MIN(CashFlow!J23,0)+I32 -> 5028.5972 | K32: =-MIN(CashFlow!K23,0)+J32 -> 5028.5972 | L32: =-MIN(CashFlow!L23,0)+K32 -> 5028.5972 | M32: =-MIN(CashFlow!M23,0)+L32 -> 5028.5972 | N32: =-MIN(CashFlow!N23,0)+M32 -> 5028.5972 | O32: =-MIN(CashFlow!O23,0)+N32 -> 5028.5972
B33: Accounts payables | C33: =9595+2251 -> 11846 | D33: =8578+1107 -> 9685 | E33: =12556+1756 -> 14312 | F33: =F12*IncState!F18 -> 13149.136 | G33: =G12*IncState!G18 -> 12396.795 | H33: =H12*IncState!H18 -> 12447.299 | I33: =I12*IncState!I18 -> 12946.842 | J33: =J12*IncState!J18 -> 13895.148 | K33: =K12*IncState!K18 -> 16548.404 | L33: =L12*IncState!L18 -> 19659.841 | M33: =M12*IncState!M18 -> 23292.721 | ... O33: =O12*IncState!O18 -> 32388.377
B34: Other current liabilities | C34: =11858+4084 -> 15942 | D34: =12425+3655 -> 16080 | E34: =14282+3343 -> 17625 | F34: =F13*IncState!F17 -> 17491.799 | G34: =G13*IncState!G17 -> 17929.094 | H34: =H13*IncState!H17 -> 19722.003 | I34: =I13*IncState!I17 -> 22680.303 | J34: =J13*IncState!J17 -> 27216.364 | K34: =K13*IncState!K17 -> 34020.455 | L34: =L13*IncState!L17 -> 42525.569 | M34: =M13*IncState!M17 -> 53156.961 | ... O34: =O13*IncState!O17 -> 83057.752
B35: Total current liabilities | C35: =SUM(C32:C34) -> 32155 | D35: =SUM(D32:D34) -> 28053 | E35: =SUM(E32:E34) -> 35666 | F35: =SUM(F32:F34) -> 34369.934 | G35: =SUM(G32:G34) -> 35354.486 | H35: =SUM(H32:H34) -> 37197.899 | I35: =SUM(I32:I34) -> 40655.743 | J35: =SUM(J32:J34) -> 46140.109 | ... O35: =SUM(O32:O34) -> 120474.73
B37: Long-term debt, including current maturities | C37: 37684 | D37: 46978 | E37: 46282 | F37: =Debt!F26 -> 46282 | G37: =Debt!G26 -> 46282 | H37: =Debt!H26 -> 46282 | I37: =Debt!I26 -> 46282 | J37: =Debt!J26 -> 46282 | K37: =Debt!K26 -> 46282 | L37: =Debt!L26 -> 46282 | M37: =Debt!M26 -> 46282 | ... O37: =Debt!O26 -> 46282
B38: Other long-term liabilities | C38: 8978 | D38: 6576 | E38: 9505 | F38: =BalSheet!F14*IncState!F17 -> 9433.1657 | G38: =BalSheet!G14*IncState!G17 -> 9668.9949 | H38: =BalSheet!H14*IncState!H17 -> 10635.894 | I38: =BalSheet!I14*IncState!I17 -> 12231.279 | J38: =BalSheet!J14*IncState!J17 -> 14677.534 | K38: =BalSheet!K14*IncState!K17 -> 18346.918 | L38: =BalSheet!L14*IncState!L17 -> 22933.647 | M38: =BalSheet!M14*IncState!M17 -> 28667.059 | ... O38: =BalSheet!O14*IncState!O17 -> 44792.28
B39: Total non-current liabilities | C39: =SUM(C37:C38) -> 46662 | D39: =SUM(D37:D38) -> 53554 | E39: =SUM(E37:E38) -> 55787 | F39: =SUM(F37:F38) -> 55715.166 | G39: =SUM(G37:G38) -> 55950.995 | H39: =SUM(H37:H38) -> 56917.894 | I39: =SUM(I37:I38) -> 58513.279 | J39: =SUM(J37:J38) -> 60959.534 | ... O39: =SUM(O37:O38) -> 91074.28
B41: Equity | C41: 103286 | D41: 109965 | E41: =105032 -> 105032 | F41: =Calcs!F17 -> 107407.84 | G41: =Calcs!G17 -> 113911.21 | H41: =Calcs!H17 -> 124930.8 | I41: =Calcs!I17 -> 141755.05 | J41: =Calcs!J17 -> 166758.2 | K41: =Calcs!K17 -> 201323.75 | L41: =Calcs!L17 -> 246940.34 | M41: =Calcs!M17 -> 307498.19 | ... O41: =Calcs!O17 -> 483323.09
A42: * | B42: TOTAL LIABILITIES & EQUITY | C42: =SUM(C41,C39,C35) -> 182103 | D42: =SUM(D41,D39,D35) -> 191572 | E42: =SUM(E41,E39,E35) -> 196485 | F42: =SUM(F41,F39,F35) -> 197492.94 | G42: =SUM(G41,G39,G35) -> 205216.7 | H42: =SUM(H41,H39,H35) -> 219046.59 | I42: =SUM(I41,I39,I35) -> 240924.07 | J42: =SUM(J41,J39,J35) -> 273857.84 | ... O42: =SUM(O41,O39,O35) -> 694872.09
A44: * | B44: Balance check | C44: =C42-C30 -> 0 | D44: =D42-D30 -> 0 | E44: =E42-E30 -> 0 | F44: =F42-F30 -> 0 | G44: =G42-G30 -> 0 | H44: =H42-H30 -> 0 | I44: =I42-I30 -> 0 | J44: =J42-J30 -> 0 | ... O44: =O42-O30 -> 0

Sheet CashFlow
A1: =CoName -> Intel Corp. | C1: Hist. | D1: Hist. | E1: Hist. | F1: Proj. | G1: Proj. | H1: Proj. | I1: Proj. | J1: Proj. | K1: Proj. | L1: Proj. | M1: Proj. | N1: Proj. | O1: Proj.
A2: Cash flow statement | C2: 2022 | D2: =C2+1 -> 2023 | E2: =D2+1 -> 2024 | F2: =E2+1 -> 2025 | G2: =F2+1 -> 2026 | H2: =G2+1 -> 2027 | I2: =H2+1 -> 2028 | J2: =I2+1 -> 2029 | K2: =J2+1 -> 2030 | ... O2: =N2+1 -> 2034
B3: Net Income | F3: =IncState!F36 -> -6025.1588 | G3: =IncState!G36 -> -1897.6271 | H3: =IncState!H36 -> 2618.587 | I3: =IncState!I36 -> 8423.2483 | J3: =IncState!J36 -> 16602.146 | K3: =IncState!K36 -> 26164.556 | L3: =IncState!L36 -> 37215.589 | M3: =IncState!M36 -> 52156.854 | ... O3: =IncState!O36 -> 90303.472
B4: Depreciation | F4: =IncState!F23 -> 10571.996 | G4: =IncState!G23 -> 11606.093 | H4: =IncState!H23 -> 12537.714 | I4: =IncState!I23 -> 13526.721 | J4: =IncState!J23 -> 14684.489 | K4: =IncState!K23 -> 16145.086 | L4: =IncState!L23 -> 18086.973 | M4: =IncState!M23 -> 20593.99 | ... O4: =IncState!O23 -> 27733.343
B5: Amortization | F5: =IncState!F24 -> 1428 | G5: =IncState!G24 -> 1428 | H5: =IncState!H24 -> 1428 | I5: =IncState!I24 -> 1428 | J5: =IncState!J24 -> 1428 | K5: =IncState!K24 -> 1428 | L5: =IncState!L24 -> 1428 | M5: =IncState!M24 -> 1428 | ... O5: =IncState!O24 -> 1428
B6: (inc) / dec in OWC | F6: =Calcs!F26 -> -95.822761 | G6: =Calcs!G26 -> -360.44118 | H6: =Calcs!H26 -> -1014.7289 | I6: =Calcs!I26 -> -1612.8248 | J6: =Calcs!J26 -> -2446.0649 | K6: =Calcs!K26 -> -3487.2986 | L6: =Calcs!L26 -> -4389.4231 | M6: =Calcs!M26 -> -5524.6536 | ... O6: =Calcs!O26 -> -8750.6298
B7: (inc) / dec in LT Assets | F7: =BalSheet!E27-BalSheet!F27 -> 56.49248 | G7: =BalSheet!F27-BalSheet!G27 -> -185.46269 | H7: =BalSheet!G27-BalSheet!H27 -> -760.39702 | I7: =BalSheet!H27-BalSheet!I27 -> -1254.6551 | J7: =BalSheet!I27-BalSheet!J27 -> -1923.8045 | K7: =BalSheet!J27-BalSheet!K27 -> -2885.7067 | L7: =BalSheet!K27-BalSheet!L27 -> -3607.1334 | M7: =BalSheet!L27-BalSheet!M27 -> -4508.9167 | ... O7: =BalSheet!N27-BalSheet!O27 -> -7045.1824
B8: inc / (dec) in LT liabilities | F8: =BalSheet!F38-BalSheet!E38 -> -71.834251 | G8: =BalSheet!G38-BalSheet!F38 -> 235.82914 | H8: =BalSheet!H38-BalSheet!G38 -> 966.89949 | I8: =BalSheet!I38-BalSheet!H38 -> 1595.3842 | J8: =BalSheet!J38-BalSheet!I38 -> 2446.2557 | K8: =BalSheet!K38-BalSheet!J38 -> 3669.3836 | L8: =BalSheet!L38-BalSheet!K38 -> 4586.7295 | M8: =BalSheet!M38-BalSheet!L38 -> 5733.4118 | ... O8: =BalSheet!O38-BalSheet!N38 -> 8958.456
B9: Cash Flow From Operations | F9: =SUM(F3:F8) -> 5863.673 | G9: =SUM(G3:G8) -> 10826.391 | H9: =SUM(H3:H8) -> 15776.075 | I9: =SUM(I3:I8) -> 22105.874 | J9: =SUM(J3:J8) -> 30791.021 | K9: =SUM(K3:K8) -> 41034.02 | L9: =SUM(L3:L8) -> 53320.735 | M9: =SUM(M3:M8) -> 69878.686 | ... O9: =SUM(O3:O8) -> 112627.46
B11: Capex | F11: =Calcs!F7 -> 21128.058 | G11: =Calcs!G7 -> 21116.088 | H11: =Calcs!H7 -> 22633.508 | I11: =Calcs!I7 -> 25345.217 | J11: =Calcs!J7 -> 29594.279 | K11: =Calcs!K7 -> 35967.873 | L11: =Calcs!L7 -> 43678.621 | M11: =Calcs!M7 -> 52996.751 | ... O11: =Calcs!O7 -> 77802.658
B12: Cash Flow From Investing | F12: =-F11 -> -21128.058 | G12: =-G11 -> -21116.088 | H12: =-H11 -> -22633.508 | I12: =-I11 -> -25345.217 | J12: =-J11 -> -29594.279 | K12: =-K11 -> -35967.873 | L12: =-L11 -> -43678.621 | M12: =-M11 -> -52996.751 | ... O12: =-O11 -> -77802.658
B14: Dividends Paid | F14: =Calcs!F15 -> -1599 | G14: =Calcs!G15 -> -1599 | H14: =Calcs!H15 -> -1599 | I14: =Calcs!I15 -> -1599 | J14: =Calcs!J15 -> -1599 | K14: =Calcs!K15 -> -1599 | L14: =Calcs!L15 -> -1599 | M14: =Calcs!M15 -> -1599 | ... O14: =Calcs!O15 -> -1599
B15: Share issuance / (repurchases) | F15: =Calcs!F11 -> 10000 | G15: =Calcs!G11 -> 10000 | H15: =Calcs!H11 -> 10000 | I15: =Calcs!I11 -> 10000 | J15: =Calcs!J11 -> 10000 | K15: =Calcs!K11 -> 10000 | L15: =Calcs!L11 -> 10000 | M15: =Calcs!M11 -> 10000 | ... O15: =Calcs!O11 -> 10000
B16: Debt issuance / (repayments) | F16: =SUM(Debt!F8:F9) -> 0 | G16: =SUM(Debt!G8:G9) -> 0 | H16: =SUM(Debt!H8:H9) -> 0 | I16: =SUM(Debt!I8:I9) -> 0 | J16: =SUM(Debt!J8:J9) -> 0 | K16: =SUM(Debt!K8:K9) -> 0 | L16: =SUM(Debt!L8:L9) -> 0 | M16: =SUM(Debt!M8:M9) -> 0 | ... O16: =SUM(Debt!O8:O9) -> 0
B17: Cash Flow From Financing | F17: =SUM(F14:F16) -> 8401 | G17: =SUM(G14:G16) -> 8401 | H17: =SUM(H14:H16) -> 8401 | I17: =SUM(I14:I16) -> 8401 | J17: =SUM(J14:J16) -> 8401 | K17: =SUM(K14:K16) -> 8401 | L17: =SUM(L14:L16) -> 8401 | M17: =SUM(M14:M16) -> 8401 | ... O17: =SUM(O14:O16) -> 8401
B19: Net Changes in Cash | F19: =SUM(F17,F12,F9) -> -6863.3852 | G19: =SUM(G17,G12,G9) -> -1888.697 | H19: =SUM(H17,H12,H9) -> 1543.5668 | I19: =SUM(I17,I12,I9) -> 5161.6573 | J19: =SUM(J17,J12,J9) -> 9597.7417 | K19: =SUM(K17,K12,K9) -> 13467.147 | L19: =SUM(L17,L12,L9) -> 18043.113 | M19: =SUM(M17,M12,M9) -> 25282.934 | ... O19: =SUM(O17,O12,O9) -> 43225.8
B21: Beginning Balance | F21: =BalSheet!E18 -> 7452.485 | G21: =BalSheet!F18 -> 589.09976 | H21: =BalSheet!G18 -> 0 | I21: =BalSheet!H18 -> 1543.5668 | J21: =BalSheet!I18 -> 6705.2241 | K21: =BalSheet!J18 -> 16302.966 | L21: =BalSheet!K18 -> 29770.113 | M21: =BalSheet!L18 -> 47813.227 | ... O21: =BalSheet!N18 -> 105746.25
B22: =B19 -> Net Changes in Cash | F22: =F19 -> -6863.3852 | G22: =G19 -> -1888.697 | H22: =H19 -> 1543.5668 | I22: =I19 -> 5161.6573 | J22: =J19 -> 9597.7417 | K22: =K19 -> 13467.147 | L22: =L19 -> 18043.113 | M22: =M19 -> 25282.934 | ... O22: =O19 -> 43225.8
B23: Ending Balance | F23: =SUM(F21:F22) -> 589.09976 | G23: =SUM(G21:G22) -> -1299.5972 | H23: =SUM(H21:H22) -> 1543.5668 | I23: =SUM(I21:I22) -> 6705.2241 | J23: =SUM(J21:J22) -> 16302.966 | K23: =SUM(K21:K22) -> 29770.113 | L23: =SUM(L21:L22) -> 47813.227 | M23: =SUM(M21:M22) -> 73096.161 | ... O23: =SUM(O21:O22) -> 148972.05

Sheet Free Cash Flow
A1: =CoName -> Intel Corp. | C1: Hist. | D1: Hist. | E1: Hist. | F1: Proj. | G1: Proj. | H1: Proj. | I1: Proj. | J1: Proj. | K1: Proj. | L1: Proj. | M1: Proj. | N1: Proj. | O1: Proj.
A2: Free Cash Flows | C2: 2022 | D2: =C2+1 -> 2023 | E2: =D2+1 -> 2024 | F2: =E2+1 -> 2025 | G2: =F2+1 -> 2026 | H2: =G2+1 -> 2027 | I2: =H2+1 -> 2028 | J2: =I2+1 -> 2029 | K2: =J2+1 -> 2030 | ... O2: =N2+1 -> 2034
A3: * | B3: Sales | F3: =IncState!F17 -> 52699.688 | G3: =IncState!G17 -> 54017.18 | H3: =IncState!H17 -> 59418.898 | I3: =IncState!I17 -> 68331.733 | J3: =IncState!J17 -> 81998.08 | K3: =IncState!K17 -> 102497.6 | L3: =IncState!L17 -> 128122 | M3: =IncState!M17 -> 160152.5 | ... O3: =IncState!O17 -> 250238.28
B4: EBIT | F4: =IncState!F21 -> -6846.7713 | G4: =IncState!G21 -> -2156.3944 | H4: =IncState!H21 -> 2975.667 | I4: =IncState!I21 -> 9571.873 | J4: =IncState!J21 -> 18866.075 | K4: =IncState!K21 -> 29732.449 | L4: =IncState!L21 -> 42290.442 | M4: =IncState!M21 -> 59269.152 | ... O4: =IncState!O21 -> 102617.58
B5: Effective Tax Rate | F5: =Assumptions!F17 -> 0.12 | G5: =Assumptions!G17 -> 0.12 | H5: =Assumptions!H17 -> 0.12 | I5: =Assumptions!I17 -> 0.12 | J5: =Assumptions!J17 -> 0.12 | K5: =Assumptions!K17 -> 0.12 | L5: =Assumptions!L17 -> 0.12 | M5: =Assumptions!M17 -> 0.12 | ... O5: =Assumptions!O17 -> 0.12
