Workbook
Name Ccy: MAIN!$C$6
Name circ: MAIN!$C$9
Name CoName: MAIN!$C$4
Name g: #REF!
Name IQ_CH: 110000
Name IQ_CQ: 5000
Name IQ_CY: 10000
Name IQ_DAILY: 500000
Name IQ_FH: 100000
Name IQ_FQ: 500
Name IQ_FY: 1000
Name IQ_LTM: 2000
Name IQ_MONTH: 15000
Name IQ_NTM: 6000
Name IQ_WEEK: 50000
Name IQ_YTD: 3000
Name OpCase: [1]DCF!$E$98
Name ScenarioREV: Assumptions!$D$4
Name TTS: #REF!
Name Units: MAIN!$C$7

Sheet MAIN
A1: =CoName -> Meta Platforms Inc.
A2: Model Details
B4: Company name | C4: Meta Platforms Inc. | E4: Current Stock Price | F4: 663 | H4: Operating Case One | I4: Terminal Mult | J4: Perpetuity | K4: Average
B5: Latest BS date | C5: 247.43 | E5: Diluted s/o | F5: =2168+343 -> 2511 | H5: Implied Price | I5: ='DCF Model'!G18 -> 1037.2867 | J5: ='DCF Model'!C18 -> 574.14783 | K5: =AVERAGE(I5:J5) -> 805.71729
B6: Currency | C6: USD | E6: Mkt Cap | F6: =F5*F4 -> 1664793 | H6: Difference | I6: =I5/$F$4-1 -> 0.56453507 | J6: =J5/$F$4-1 -> -0.13401534 | K6: =K5/$F$4-1 -> 0.21525986
B7: Units | C7: m | E7: Cash | F7: =43889+33926 -> 77815
B8: Analyst name | C8: Alan Chen | E8: Debt | F8: 28826
B9: Circular switch | C9: 0 | E9: EV | F9: =F6-F7+F8 -> 1615804

Sheet Quarterly Projections
A1: =CoName -> Meta Platforms Inc.
A2: Quarterly Data | C2: Q122 | D2: Q222 | E2: Q322 | F2: Q422 | G2: 2022 | H2: Q123 | I2: Q223 | J2: Q323 | K2: Q423 | L2: 2023 | M2: Q124 | N2: Q224 | O2: Q324 | P2: Q424 | Q2: 2024 | R2: Q125 | S2: Q225 | T2: Q325 | U2: Q425E | V2: 2025 | W2: Q126E | X2: Q226E | Y2: Q326E | Z2: Q426E | AA2: 2026 | AB2: Q127E | AC2: Q227E | AD2: Q327E | AE2: Q427E | AF2: 2027 | AG2: 2028 | AH2: =AG2+1 -> 2029
A3: Revenue | C3: 27908 | D3: 28822 | E3: 27714 | F3: 31165 | G3: =SUM(C3:F3) -> 115609 | H3: 28645 | I3: 31999 | J3: 34146 | K3: 40111 | L3: =SUM(H3:K3) -> 134901 | M3: 36455 | N3: 39071 | O3: 40589 | P3: 48385 | Q3: =SUM(M3:P3) -> 164500 | R3: 42314 | S3: 47516 | T3: 51242 | U3: =P3*(1+U5) -> 58062 | V3: =SUM(R3:U3) -> 199134 | W3: =R3*(1+W5) -> 50776.8 | X3: =S3*(1+X5) -> 57019.2 | Y3: =T3*(1+Y5) -> 61490.4 | Z3: =U3*(1+Z5) -> 69674.4 | AA3: =SUM(W3:Z3) -> 238960.8 | AB3: =W3*(1+AB5) -> 60932.16 | AC3: =X3*(1+AC5) -> 68137.944 | AD3: =Y3*(1+AD5) -> 73173.576 | AE3: =Z3*(1+AE5) -> 82564.164 | AF3: =SUM(AB3:AE3) -> 284807.84 | AG3: =SUM(AB3:AE3)*(1+AG5) -> 334649.22 | AH3: =AG3*(1+AH5) -> 391539.58
B4: Q/Q | C4: n/a | D4: =D3/C3-1 -> 0.032750466 | E4: =E3/D3-1 -> -0.038442856 | F4: =F3/E3-1 -> 0.1245219 | H4: =H3/F3-1 -> -0.080859939 | I4: =I3/H3-1 -> 0.1170885 | J4: =J3/I3-1 -> 0.067095847 | K4: =K3/J3-1 -> 0.17469103 | M4: =M3/K3-1 -> -0.091147067 | N4: =N3/M3-1 -> 0.071759704 | O4: =O3/N3-1 -> 0.038852346 | P4: =P3/O3-1 -> 0.19207174 | R4: =R3/P3-1 -> -0.12547277 | S4: =S3/R3-1 -> 0.12293803 | T4: =T3/S3-1 -> 0.078415692
B5: Y/Y | C5: n/a | D5: n/a | E5: n/a | F5: n/a | H5: =H3/C3-1 -> 0.026408198 | I5: =I3/D3-1 -> 0.1102283 | J5: =J3/E3-1 -> 0.23208487 | K5: =K3/F3-1 -> 0.28705278 | L5: =L3/G3-1 -> 0.16687282 | M5: =M3/H3-1 -> 0.27264793 | N5: =N3/I3-1 -> 0.22100691 | O5: =O3/J3-1 -> 0.18868974 | ... T5: =T3/O3-1 -> 0.26246027 | U5: 0.2 | V5: =V3/Q3-1 -> 0.21054103 | W5: 0.2 | X5: =W5 -> 0.2 | Y5: =X5 -> 0.2 | Z5: =Y5 -> 0.2 | AA5: =AA3/V3-1 -> 0.2 | AB5: =Z5 -> 0.2 | AC5: =AB5-0.005 -> 0.195 | AD5: =AC5-0.005 -> 0.19 | AE5: =AD5-0.005 -> 0.185 | AF5: =AE5-0.005 -> 0.18 | AG5: =AF5-0.005 -> 0.175 | AH5: =AG5-0.005 -> 0.17
B6: COGS | C6: 6005 | D6: 5192 | E6: 5716 | F6: 8336 | G6: =SUM(C6:F6) -> 25249 | H6: 6108 | I6: 5945 | J6: 6120 | K6: 7695 | L6: =SUM(H6:K6) -> 25868 | M6: 6640 | N6: 7308 | O6: 7375 | P6: 8839 | Q6: =SUM(M6:P6) -> 30162 | R6: 7572 | S6: 8491 | T6: 9206 | U6: =U3*(1-U11) -> 10431.263 | V6: =SUM(R6:U6) -> 35700.263 | W6: 9206
A7: Gross Profit | C7: =C3-C6 -> 21903 | D7: =D3-D6 -> 23630 | E7: =E3-E6 -> 21998 | F7: =F3-F6 -> 22829 | G7: =SUM(C7:F7) -> 90360 | H7: =H3-H6 -> 22537 | I7: =I3-I6 -> 26054 | J7: =J3-J6 -> 28026 | K7: =K3-K6 -> 32416 | L7: =SUM(H7:K7) -> 109033 | M7: =M3-M6 -> 29815 | N7: =N3-N6 -> 31763 | O7: =O3-O6 -> 33214 | P7: =P3-P6 -> 39546 | Q7: =SUM(M7:P7) -> 134338 | R7: =R3-R6 -> 34742 | S7: =S3-S6 -> 39025 | T7: =T3-T6 -> 42036 | U7: =U3-U6 -> 47630.737 | V7: =SUM(R7:U7) -> 163433.74 | W7: =W3-W6 -> 41570.8 | X7: =X3-X6 -> 57019.2 | Y7: =Y3-Y6 -> 61490.4 | Z7: =Z3-Z6 -> 69674.4 | AA7: =SUM(W7:Z7) -> 229754.8 | AB7: =AB3-AB6 -> 60932.16 | AC7: =AC3-AC6 -> 68137.944 | AD7: =AD3-AD6 -> 73173.576 | AE7: =AE3-AE6 -> 82564.164 | AF7: =SUM(AB7:AE7) -> 284807.84 | AG7: =AG3-AG6 -> 334649.22 | AH7: =AH3-AH6 -> 391539.58
B8: R&D | C8: 7707 | D8: 8690 | E8: 9170 | F8: 9771 | G8: =SUM(C8:F8) -> 35338 | H8: 9381 | I8: 9344 | J8: 9241 | K8: 10517 | L8: =SUM(H8:K8) -> 38483 | M8: 9978 | N8: 10537 | O8: 11177 | P8: 12180 | Q8: =SUM(M8:P8) -> 43872 | R8: 12150 | S8: 12942 | T8: 15144 | U8: =U7*U12 -> 14076.732 | V8: =SUM(R8:U8) -> 54312.732 | W8: =W7*W12 -> 9828.628 | X8: =X7*X12 -> 13481.109 | Y8: =Y7*Y12 -> 14538.24 | Z8: =Z7*Z12 -> 16473.192 | AA8: =SUM(W8:Z8) -> 54321.169 | AB8: =AB7*AB12 -> 14406.255 | AC8: =AC7*AC12 -> 16109.926 | AD8: =AD7*AD12 -> 17300.506 | AE8: =AE7*AE12 -> 19520.732 | AF8: =SUM(AB8:AE8) -> 67337.418 | AG8: =AG7*AG12 -> 79121.467 | AH8: =AH7*AH12 -> 92572.116
B9: SG&A | C9: =3312+2360 -> 5672 | D9: =3595+2987 -> 6582 | E9: =3780+3384 -> 7164 | F9: =4574+3085 -> 7659 | G9: =SUM(C9:F9) -> 27077 | H9: =3044+2885 -> 5929 | I9: =3154+4164 -> 7318 | J9: =2877+2070 -> 4947 | K9: =3226+2289 -> 5515 | L9: =SUM(H9:K9) -> 23709 | M9: =2564+3455 -> 6019 | N9: =2721+3658 -> 6379 | O9: =2822+1865 -> 4687 | P9: =3240+761 -> 4001 | Q9: =SUM(M9:P9) -> 21086 | R9: =2757+2280 -> 5037 | S9: =2979+2663 -> 5642 | T9: =3512+2845 -> 6357 | U9: =U7*U13 -> 5908.9925 | V9: =SUM(R9:U9) -> 22944.993 | W9: =W7*W13 -> 5157.2065 | X9: =X7*X13 -> 7073.7101 | Y9: =Y7*Y13 -> 7628.4 | Z9: =Z7*Z13 -> 8643.6939 | AA9: =SUM(W9:Z9) -> 28503.01 | AB9: =AB7*AB13 -> 7559.1456 | AC9: =AC7*AC13 -> 8453.0836 | AD9: =AD7*AD13 -> 9077.796 | AE9: =AE7*AE13 -> 10242.777 | AF9: =SUM(AB9:AE9) -> 35332.802 | AG9: =AG7*AG13 -> 41516.043 | AH9: =AH7*AH13 -> 48573.77
A10: Operating Income | C10: =C7-SUM(C8:C9) -> 8524 | D10: =D7-SUM(D8:D9) -> 8358 | E10: =E7-SUM(E8:E9) -> 5664 | F10: =F7-SUM(F8:F9) -> 5399 | G10: =SUM(C10:F10) -> 27945 | H10: =H7-SUM(H8:H9) -> 7227 | I10: =I7-SUM(I8:I9) -> 9392 | J10: =J7-SUM(J8:J9) -> 13838 | K10: =K7-SUM(K8:K9) -> 16384 | L10: =SUM(H10:K10) -> 46841 | M10: =M7-SUM(M8:M9) -> 13818 | N10: =N7-SUM(N8:N9) -> 14847 | O10: =O7-SUM(O8:O9) -> 17350 | P10: =P7-SUM(P8:P9) -> 23365 | Q10: =SUM(M10:P10) -> 69380 | R10: =R7-SUM(R8:R9) -> 17555 | S10: =S7-SUM(S8:S9) -> 20441 | T10: =T7-SUM(T8:T9) -> 20535 | U10: =U7-SUM(U8:U9) -> 27645.013 | V10: =SUM(R10:U10) -> 86176.013 | W10: =W7-SUM(W8:W9) -> 26584.965 | X10: =X7-SUM(X8:X9) -> 36464.38 | Y10: =Y7-SUM(Y8:Y9) -> 39323.76 | Z10: =Z7-SUM(Z8:Z9) -> 44557.514 | AA10: =SUM(W10:Z10) -> 146930.62 | AB10: =AB7-SUM(AB8:AB9) -> 38966.76 | AC10: =AC7-SUM(AC8:AC9) -> 43574.935 | AD10: =AD7-SUM(AD8:AD9) -> 46795.274 | AE10: =AE7-SUM(AE8:AE9) -> 52800.655 | AF10: =SUM(AB10:AE10) -> 182137.62 | AG10: =AG7-SUM(AG8:AG9) -> 214011.71 | AH10: =AH7-SUM(AH8:AH9) -> 250393.7
B11: Gross Margin | C11: =C7/C3 -> 0.78482872 | D11: =D7/D3 -> 0.81985983 | E11: =E7/E3 -> 0.79375045 | F11: =F7/F3 -> 0.73252046 | H11: =H7/H3 -> 0.78676907 | I11: =I7/I3 -> 0.81421294 | J11: =J7/J3 -> 0.82076964 | K11: =K7/K3 -> 0.80815736 | M11: =M7/M3 -> 0.81785763 | N11: =N7/N3 -> 0.8129559 | O11: =O7/O3 -> 0.81830052 | P11: =P7/P3 -> 0.81731942 | R11: =R7/R3 -> 0.82105213 | S11: =S7/S3 -> 0.8213023 | T11: =T7/T3 -> 0.82034269 | U11: =T11 -> 0.82034269 | V11: =U11 -> 0.82034269 | W11: =U11 -> 0.82034269 | X11: =W11 -> 0.82034269 | Y11: =X11 -> 0.82034269 | Z11: =Y11 -> 0.82034269 | AA11: =Z11 -> 0.82034269 | AB11: =Z11 -> 0.82034269 | AC11: =AB11 -> 0.82034269 | AD11: =AC11 -> 0.82034269 | AE11: =AD11 -> 0.82034269 | AF11: =AE11 -> 0.82034269 | AG11: =AE11 -> 0.82034269 | AH11: =AG11 -> 0.82034269
B12: R&D Margin | C12: =C8/C3 -> 0.27615737 | D12: =D8/D3 -> 0.30150579 | E12: =E8/E3 -> 0.3308797 | F12: =F8/F3 -> 0.31352479 | H12: =H8/H3 -> 0.32749171 | I12: =I8/I3 -> 0.29200913 | J12: =J8/J3 -> 0.27063199 | K12: =K8/K3 -> 0.2621974 | M12: =M8/M3 -> 0.27370731 | N12: =N8/N3 -> 0.26968852 | O12: =O8/O3 -> 0.27537017 | P12: =P8/P3 -> 0.25173091 | R12: =R8/R3 -> 0.28713901 | S12: =S8/S3 -> 0.27237141 | T12: =T8/T3 -> 0.29553882 | U12: =T12 -> 0.29553882 | V12: =U12 -> 0.29553882 | W12: =V12*0.8 -> 0.23643105 | X12: =W12 -> 0.23643105 | Y12: =X12 -> 0.23643105 | Z12: =Y12 -> 0.23643105 | AA12: =Z12 -> 0.23643105 | AB12: =Z12 -> 0.23643105 | AC12: =AB12 -> 0.23643105 | AD12: =AC12 -> 0.23643105 | AE12: =AD12 -> 0.23643105 | AF12: =AE12 -> 0.23643105 | AG12: =AE12 -> 0.23643105 | AH12: =AG12 -> 0.23643105
B13: SG&A Margin | C13: =C9/C3 -> 0.20323921 | D13: =D9/D3 -> 0.22836722 | E13: =E9/E3 -> 0.25849751 | F13: =F9/F3 -> 0.24575646 | H13: =H9/H3 -> 0.20698202 | I13: =I9/I3 -> 0.22869465 | J13: =J9/J3 -> 0.14487788 | K13: =K9/K3 -> 0.13749346 | M13: =M9/M3 -> 0.16510767 | N13: =N9/N3 -> 0.16326687 | O13: =O9/O3 -> 0.11547464 | P13: =P9/P3 -> 0.082690917 | R13: =R9/R3 -> 0.11903862 | S13: =S9/S3 -> 0.11873895 | T13: =T9/T3 -> 0.12405839 | U13: =T13 -> 0.12405839 | V13: =U13 -> 0.12405839 | W13: =U13 -> 0.12405839 | X13: =W13 -> 0.12405839 | Y13: =X13 -> 0.12405839 | Z13: =Y13 -> 0.12405839 | AA13: =Z13 -> 0.12405839 | AB13: =Z13 -> 0.12405839 | AC13: =AB13 -> 0.12405839 | AD13: =AC13 -> 0.12405839 | AE13: =AD13 -> 0.12405839 | AF13: =AE13 -> 0.12405839 | AG13: =AE13 -> 0.12405839 | AH13: =AG13 -> 0.12405839
B14: EBIT Margin | C14: =C10/C3 -> 0.30543213 | D14: =D10/D3 -> 0.28998682 | E14: =E10/E3 -> 0.20437324 | F14: =F10/F3 -> 0.17323921 | H14: =H10/H3 -> 0.25229534 | I14: =I10/I3 -> 0.29350917 | J14: =J10/J3 -> 0.40525977 | K14: =K10/K3 -> 0.40846651 | M14: =M10/M3 -> 0.37904266 | N14: =N10/N3 -> 0.38000051 | O14: =O10/O3 -> 0.42745571 | P14: =P10/P3 -> 0.48289759 | R14: =R10/R3 -> 0.41487451 | S14: =S10/S3 -> 0.43019194 | T14: =T10/T3 -> 0.40074548

Sheet Assumptions
A1: =CoName -> Meta Platforms Inc. | C1: Hist. | D1: Hist. | E1: Hist. | F1: Proj. | G1: Proj. | H1: Proj. | I1: Proj. | J1: Proj.
A2: * | B2: Income Statement | C2: 2022 | D2: =C2+1 -> 2023 | E2: =D2+1 -> 2024 | F2: =E2+1 -> 2025 | G2: =F2+1 -> 2026 | H2: =G2+1 -> 2027 | I2: =H2+1 -> 2028 | J2: =I2+1 -> 2029
B4: Operating Case | D4: 1
D5: Variance
B6: Street Case | D6: 0 | F6: ='Quarterly Projections'!V5 -> 0.21054103 | G6: ='Quarterly Projections'!AA5 -> 0.2 | H6: ='Quarterly Projections'!AG5 -> 0.175 | I6: ='Quarterly Projections'!AG5 -> 0.175 | J6: ='Quarterly Projections'!AH5 -> 0.17
B7: Optimistic Case | D7: 0.025 | F7: =F6+$D$7 -> 0.23554103 | G7: =G6+$D$7 -> 0.225 | H7: =H6+$D$7 -> 0.2 | I7: =I6+$D$7 -> 0.2 | J7: =J6+$D$7 -> 0.195
B8: Pessimistic Case | D8: -0.025 | F8: =F6+$D$8 -> 0.18554103 | G8: =G6+$D$8 -> 0.175 | H8: =H6+$D$8 -> 0.15 | I8: =I6+$D$8 -> 0.15 | J8: =J6+$D$8 -> 0.145
B10: Revenue Growth | D10: =IncState!D17/IncState!C17-1 -> 0.15687468 | E10: =IncState!E17/IncState!D17-1 -> 0.21941113 | F10: =CHOOSE(ScenarioREV,F6,F7,F8) -> 0.21054103 | G10: =CHOOSE(ScenarioREV,G6,G7,G8) -> 0.2 | H10: =CHOOSE(ScenarioREV,H6,H7,H8) -> 0.175 | I10: =CHOOSE(ScenarioREV,I6,I7,I8) -> 0.175 | J10: =CHOOSE(ScenarioREV,J6,J7,J8) -> 0.17
B11: COGS % of sales | C11: =IncState!C18/IncState!C17 -> 0.21652703 | D11: =IncState!D18/IncState!D17 -> 0.19242858 | E11: =IncState!E18/IncState!E17 -> 0.18334843 | F11: =1-'Quarterly Projections'!V11 -> 0.17965731 | G11: =1-'Quarterly Projections'!W11 -> 0.17965731 | H11: =1-'Quarterly Projections'!X11 -> 0.17965731 | I11: =1-'Quarterly Projections'!Y11 -> 0.17965731 | J11: =1-'Quarterly Projections'!Z11 -> 0.17965731
B12: R&D % of sales | C12: =IncState!C19/IncState!C17 -> 0.30304693 | D12: =IncState!D19/IncState!D17 -> 0.28526634 | E12: =IncState!E19/IncState!E17 -> 0.26670355 | F12: ='Quarterly Projections'!V12 -> 0.29553882 | G12: ='Quarterly Projections'!AA12 -> 0.23643105 | H12: ='Quarterly Projections'!AF12 -> 0.23643105 | I12: ='Quarterly Projections'!AG12 -> 0.23643105 | J12: ='Quarterly Projections'!AH12 -> 0.23643105
B13: SG&A % of sales | C13: =IncState!C20/IncState!C17 -> 0.23221192 | D13: =IncState!D20/IncState!D17 -> 0.1757498 | E13: =IncState!E20/IncState!E17 -> 0.12818767 | F13: =E13 -> 0.12818767 | G13: =F13 -> 0.12818767 | H13: =G13 -> 0.12818767 | I13: =H13 -> 0.12818767 | J13: =I13 -> 0.12818767
B14: Amortization $ Amt | C14: =IncState!C24 -> 0 | D14: =IncState!D24 -> 0 | E14: =IncState!E24 -> 0 | F14: =E14 -> 0 | G14: =F14 -> 0 | H14: =G14 -> 0 | I14: =H14 -> 0 | J14: =I14 -> 0
B15: Non recurring income / (expense) | C15: =IncState!C27 -> -81 | D15: =IncState!D27 -> -366 | E15: =IncState!E27 -> -690 | F15: 0 | G15: 0 | H15: 0 | I15: 0 | J15: 0
B16: Other Income / (expense) | C16: =IncState!C28 -> -320 | D16: =IncState!D28 -> -150 | E16: =IncState!E28 -> 171 | F16: 0 | G16: 0 | H16: 0 | I16: 0 | J16: 0
B17: Effective tax rate | C17: =IncState!C35/IncState!C33 -> 0.19862844 | D17: =IncState!D35/IncState!D33 -> 0.17563465 | E17: =IncState!E35/IncState!E33 -> 0.11750138 | F17: 0.135 | G17: =F17 -> 0.135 | H17: =G17 -> 0.135 | I17: =H17 -> 0.135 | J17: =I17 -> 0.135
B18: Dividend Payout Rate | C18: =IncState!C37 -> 0 | D18: =IncState!D37 -> 0 | E18: =IncState!E37 -> 0.081334189 | F18: =E18 -> 0.081334189 | G18: =F18 -> 0.081334189 | H18: =G18 -> 0.081334189 | I18: =H18 -> 0.081334189 | J18: =I18 -> 0.081334189
B19: Basic WASO | C19: =IncState!C40 -> 2687 | D19: =IncState!D40 -> 2574 | E19: =IncState!E40 -> 2534 | F19: =E19 -> 2534 | G19: =F19 -> 2534 | H19: =G19 -> 2534 | I19: =H19 -> 2534 | J19: =I19 -> 2534
B20: Diluted WASO | C20: =IncState!C41 -> 2702 | D20: =IncState!D41 -> 2629 | E20: =IncState!E41 -> 2614 | F20: =E20 -> 2614 | G20: =F20 -> 2614 | H20: =G20 -> 2614 | I20: =H20 -> 2614 | J20: =I20 -> 2614
A22: * | B22: Debt | C22: =C2 -> 2022 | D22: =D2 -> 2023 | E22: =E2 -> 2024 | F22: =F2 -> 2025 | G22: =G2 -> 2026 | H22: =H2 -> 2027 | I22: =I2 -> 2028 | J22: =J2 -> 2029
B24: Interest rate on Revolver | E24: =E25 -> 0.0485 | F24: =E24 -> 0.0485 | G24: =F24 -> 0.0485 | H24: =G24 -> 0.0485 | I24: =H24 -> 0.0485 | J24: =I24 -> 0.0485
B25: Interest rate on long-term debt | E25: 0.0485 | F25: =E25 -> 0.0485 | G25: =F25 -> 0.0485 | H25: =G25 -> 0.0485 | I25: =H25 -> 0.0485 | J25: =I25 -> 0.0485
B26: Interest rate on cash | E26: =IncState!E30/BalSheet!E16 -> 0.060765566 | F26: =E26 -> 0.060765566 | G26: =F26 -> 0.060765566 | H26: =G26 -> 0.060765566 | I26: =H26 -> 0.060765566 | J26: =I26 -> 0.060765566
B28: Issuance of long-term debt | E28: 0 | F28: 0 | G28: 0 | H28: 0 | I28: 0 | J28: 0
B29: Repayment of long-term debt | E29: 0 | F29: 0 | G29: 0 | H29: 0 | I29: 0 | J29: 0
A31: * | B31: Calcs | C31: =C22 -> 2022 | D31: =D22 -> 2023 | E31: =E22 -> 2024 | F31: =F22 -> 2025 | G31: =G22 -> 2026 | H31: =H22 -> 2027 | I31: =I22 -> 2028 | J31: =J22 -> 2029
B33: CapEx % of Sales | C33: =31186/IncState!C17 -> 0.26744076 | D33: =27045/IncState!D17 -> 0.20047887 | E33: =37256/IncState!E17 -> 0.22647887 | F33: =72000/IncState!F17 -> 0.36156338 | G33: =F33-0.04 -> 0.32156338 | H33: =G33-0.04 -> 0.28156338 | I33: =H33-0.04 -> 0.24156338 | J33: =I33-0.04 -> 0.20156338
B34: Depreciation % of beginning PP&E | D34: =IncState!D23/BalSheet!C21 -> 0.12124828 | E34: =IncState!E23/BalSheet!D21 -> 0.14104349 | F34: =E34 -> 0.14104349 | G34: =F34 -> 0.14104349 | H34: =G34 -> 0.14104349 | I34: =H34 -> 0.14104349 | J34: =I34 -> 0.14104349
B35: Share issuance / (repurchases) | C35: -27956 | D35: -19774 | E35: -30125 | F35: =-51280/5 -> -10256 | G35: =-51280/5 -> -10256 | H35: =-51280/5 -> -10256 | I35: =-51280/5 -> -10256 | J35: =-51280/5 -> -10256
A37: * | B37: Shareholder information | C37: =C31 -> 2022 | D37: =D31 -> 2023 | E37: =E31 -> 2024 | F37: =F31 -> 2025 | G37: =G31 -> 2026 | H37: =H31 -> 2027 | I37: =I31 -> 2028 | J37: =J31 -> 2029
B39: =B18 -> Dividend Payout Rate | C39: =C18 -> 0 | D39: =D18 -> 0 | E39: =E18 -> 0.081334189 | F39: =F18 -> 0.081334189 | G39: =G18 -> 0.081334189 | H39: =H18 -> 0.081334189 | I39: =I18 -> 0.081334189 | J39: =J18 -> 0.081334189
B40: Basic WASO | C40: =C19 -> 2687 | D40: =D19 -> 2574 | E40: =E19 -> 2534 | F40: =F19 -> 2534 | G40: =G19 -> 2534 | H40: =H19 -> 2534 | I40: =I19 -> 2534 | J40: =J19 -> 2534
B41: Diluted WASO | C41: =C20 -> 2702 | D41: =D20 -> 2629 | E41: =E20 -> 2614 | F41: =F20 -> 2614 | G41: =G20 -> 2614 | H41: =H20 -> 2614 | I41: =I20 -> 2614 | J41: =J20 -> 2614
A43: * | B43: Balance Sheet - Assets | C43: =C37 -> 2022 | D43: =D37 -> 2023 | E43: =E37 -> 2024 | F43: =F37 -> 2025 | G43: =G37 -> 2026 | H43: =H37 -> 2027 | I43: =I37 -> 2028 | J43: =J37 -> 2029
B45: Operating Cash % of sales | C45: =BalSheet!C15/IncState!C17 -> 0.015 | D45: =BalSheet!D15/IncState!D17 -> 0.015 | E45: =BalSheet!E15/IncState!E17 -> 0.015 | F45: =E45 -> 0.015 | G45: =F45 -> 0.015 | H45: =G45 -> 0.015 | I45: =H45 -> 0.015 | J45: =I45 -> 0.015
B46: Accounts receivable % of sales | C46: =BalSheet!C17/IncState!C17 -> 0.11547994 | D46: =BalSheet!D17/IncState!D17 -> 0.11985738 | E46: =BalSheet!E17/IncState!E17 -> 0.10330636 | F46: =E46 -> 0.10330636 | G46: =F46 -> 0.10330636 | H46: =G46 -> 0.10330636 | I46: =H46 -> 0.10330636 | J46: =I46 -> 0.10330636
B47: Other current assets % of sales | C47: =BalSheet!C18/IncState!C17 -> 0.26929311 | D47: =BalSheet!D18/IncState!D17 -> 0.20262116 | E47: =BalSheet!E18/IncState!E17 -> 0.23806542 | F47: =E47 -> 0.23806542 | G47: =F47 -> 0.23806542 | H47: =G47 -> 0.23806542 | I47: =H47 -> 0.23806542 | J47: =I47 -> 0.23806542
B49: Investments in unconsolidated entities | C49: =BalSheet!C23 -> 6201 | D49: =BalSheet!D23 -> 6141 | E49: =BalSheet!E23 -> 6070 | F49: =E49 -> 6070 | G49: =F49 -> 6070 | H49: =G49 -> 6070 | I49: =H49 -> 6070 | J49: =I49 -> 6070
B50: Other long-term assets % of sales | C50: =BalSheet!C24/IncState!C17 -> 0.056453619 | D50: =BalSheet!D24/IncState!D17 -> 0.056203763 | E50: =BalSheet!E24/IncState!E17 -> 0.079130218 | F50: =E50 -> 0.079130218 | G50: =F50 -> 0.079130218 | H50: =G50 -> 0.079130218 | I50: =H50 -> 0.079130218 | J50: =I50 -> 0.079130218
A52: * | B52: Balance Sheet - Liabilities | C52: =C43 -> 2022 | D52: =D43 -> 2023 | E52: =E43 -> 2024 | F52: =F43 -> 2025 | G52: =G43 -> 2026 | H52: =H43 -> 2027 | I52: =I43 -> 2028 | J52: =J43 -> 2029
B54: Accounts payable % of COGS | C54: =BalSheet!C30/IncState!C18 -> 0.19763159 | D54: =BalSheet!D30/IncState!D18 -> 0.18679456 | E54: =BalSheet!E30/IncState!E18 -> 0.25486555 | F54: =E54 -> 0.25486555 | G54: =F54 -> 0.25486555 | H54: =G54 -> 0.25486555 | I54: =H54 -> 0.25486555 | J54: =I54 -> 0.25486555
...

Sheet Calcs
A1: =CoName -> Meta Platforms Inc. | C1: Hist. | D1: Hist. | E1: Hist. | F1: Proj. | G1: Proj. | H1: Proj. | I1: Proj. | J1: Proj.
A2: Net PP&E | C2: 2022 | D2: =C2+1 -> 2023 | E2: =D2+1 -> 2024 | F2: =E2+1 -> 2025 | G2: =F2+1 -> 2026 | H2: =G2+1 -> 2027 | I2: =H2+1 -> 2028 | J2: =I2+1 -> 2029
B3: Capital expenditure % of sales | F3: =Assumptions!F33 -> 0.36156338 | G3: =Assumptions!G33 -> 0.32156338 | H3: =Assumptions!H33 -> 0.28156338 | I3: =Assumptions!I33 -> 0.24156338 | J3: =Assumptions!J33 -> 0.20156338
B4: Depreciation % of PP&E | F4: =Assumptions!F34 -> 0.14104349 | G4: =F4 -> 0.14104349 | H4: =G4 -> 0.14104349 | I4: =H4 -> 0.14104349 | J4: =I4 -> 0.14104349
B6: Beginning PP&E | F6: =E9 -> 136268 | G6: =F9 -> 189048.29 | H6: =G9 -> 239225.76 | I6: =H9 -> 284542.08 | J6: =I9 -> 324105.2
B7: Capex | F7: =F3*IncState!F17 -> 72000 | G7: =G3*IncState!G17 -> 76841.51 | H7: =H3*IncState!H17 -> 79057.548 | I7: =I3*IncState!I17 -> 79695.929 | J7: =J3*IncState!J17 -> 77804.109
B8: Depreciation | F8: =F6*F4 -> 19219.715 | G8: =G6*G4 -> 26664.03 | H8: =H6*H4 -> 33741.237 | I8: =I6*I4 -> 40132.808 | J8: =J6*J4 -> 45712.929
B9: Ending PP&E | E9: =BalSheet!E21 -> 136268 | F9: =F6+F7-F8 -> 189048.29 | G9: =G6+G7-G8 -> 239225.76 | H9: =H6+H7-H8 -> 284542.08 | I9: =I6+I7-I8 -> 324105.2 | J9: =J6+J7-J8 -> 356196.38
A10: Equity | C10: =C2 -> 2022 | D10: =D2 -> 2023 | E10: =E2 -> 2024 | F10: =F2 -> 2025 | G10: =G2 -> 2026 | H10: =H2 -> 2027 | I10: =I2 -> 2028 | J10: =J2 -> 2029
B11: Share issuance/(repurchases) | F11: =Assumptions!F35 -> -10256 | G11: =Assumptions!G35 -> -10256 | H11: =Assumptions!H35 -> -10256 | I11: =Assumptions!I35 -> -10256 | J11: =Assumptions!J35 -> -10256
B13: Beginning balance | F13: =E17 -> 182637 | G13: =F17 -> 235142.33 | H13: =G17 -> 311423.93 | I13: =H17 -> 402849.61 | J13: =I17 -> 512069.58
B14: Net income | F14: =IncState!F36 -> 68317.917 | G14: =IncState!G36 -> 94199.214 | H14: =IncState!H36 -> 110684.08 | I14: =IncState!I36 -> 130053.79 | J14: =IncState!J36 -> 152162.93
B15: Dividends paid | F15: =-IncState!F38 -> -5556.5823 | G15: =-IncState!G38 -> -7661.6166 | H15: =-IncState!H38 -> -9002.3995 | I15: =-IncState!I38 -> -10577.819 | J15: =-IncState!J38 -> -12376.049
B16: Share issuance / (repurchase) | F16: =F11 -> -10256 | G16: =G11 -> -10256 | H16: =H11 -> -10256 | I16: =I11 -> -10256 | J16: =J11 -> -10256
B17: Ending balance | E17: =BalSheet!E38 -> 182637 | F17: =SUM(F13:F16) -> 235142.33 | G17: =SUM(G13:G16) -> 311423.93 | H17: =SUM(H13:H16) -> 402849.61 | I17: =SUM(I13:I16) -> 512069.58 | J17: =SUM(J13:J16) -> 641600.46
A18: OWC | C18: =C10 -> 2022 | D18: =D10 -> 2023 | E18: =E10 -> 2024 | F18: =F10 -> 2025 | G18: =G10 -> 2026 | H18: =H10 -> 2027 | I18: =I10 -> 2028 | J18: =J10 -> 2029
B19: Operating Cash | E19: =BalSheet!E15 -> 2467.515 | F19: =BalSheet!F15 -> 2987.0282 | G19: =BalSheet!G15 -> 3584.4338 | H19: =BalSheet!H15 -> 4211.7097 | I19: =BalSheet!I15 -> 4948.7589 | J19: =BalSheet!J15 -> 5790.0479
B20: =BalSheet!B17 -> Accounts receivable | E20: =BalSheet!E17 -> 16994 | F20: =BalSheet!F17 -> 20571.934 | G20: =BalSheet!G17 -> 24686.321 | H20: =BalSheet!H17 -> 29006.427 | I20: =BalSheet!I17 -> 34082.552 | J20: =BalSheet!J17 -> 39876.586
B21: Other current assets | E21: =BalSheet!E18 -> 39162 | F21: =BalSheet!F18 -> 47407.208 | G21: =BalSheet!G18 -> 56888.65 | H21: =BalSheet!H18 -> 66844.163 | I21: =BalSheet!I18 -> 78541.892 | J21: =BalSheet!J18 -> 91894.013
B22: Accounts payables | E22: =BalSheet!E30 -> 7687 | F22: =BalSheet!F30 -> 9118.0947 | G22: =BalSheet!G30 -> 10941.714 | H22: =BalSheet!H30 -> 12856.514 | I22: =BalSheet!I30 -> 15106.403 | J22: =BalSheet!J30 -> 17674.492
B23: Other current liabilities | E23: =BalSheet!E31 -> 25909 | F23: =BalSheet!F31 -> 31363.908 | G23: =BalSheet!G31 -> 37636.689 | H23: =BalSheet!H31 -> 44223.11 | I23: =BalSheet!I31 -> 51962.154 | J23: =BalSheet!J31 -> 60795.72
A24: * | B24: OWC | E24: =SUM(E19:E21)-SUM(E22:E23) -> 25027.515 | F24: =SUM(F19:F21)-SUM(F22:F23) -> 30484.168 | G24: =SUM(G19:G21)-SUM(G22:G23) -> 36581.002 | H24: =SUM(H19:H21)-SUM(H22:H23) -> 42982.677 | I24: =SUM(I19:I21)-SUM(I22:I23) -> 50504.645 | J24: =SUM(J19:J21)-SUM(J22:J23) -> 59090.435
B25: Change in OWC | F25: =E24-F24 -> -5456.6531 | G25: =F24-G24 -> -6096.8336 | H25: =G24-H24 -> -6401.6753 | I25: =H24-I24 -> -7521.9685 | J25: =I24-J24 -> -8585.7897

Sheet Debt
A1: =CoName -> Meta Platforms Inc. | C1: Hist. | D1: Hist. | E1: Hist. | F1: Proj. | G1: Proj. | H1: Proj. | I1: Proj. | J1: Proj.
A2: Assumptions | C2: 2022 | D2: 2023 | E2: 2024 | F2: =E2+1 -> 2025 | G2: =F2+1 -> 2026 | H2: =G2+1 -> 2027 | I2: =H2+1 -> 2028 | J2: =I2+1 -> 2029
F3: 1
B4: Interest rate on revolver | F4: =Assumptions!F24 -> 0.0485 | G4: =Assumptions!G24 -> 0.0485 | H4: =Assumptions!H24 -> 0.0485 | I4: =Assumptions!I24 -> 0.0485 | J4: =Assumptions!J24 -> 0.0485
B5: Interest rate on long-term debt | F5: =Assumptions!F25 -> 0.0485 | G5: =Assumptions!G25 -> 0.0485 | H5: =Assumptions!H25 -> 0.0485 | I5: =Assumptions!I25 -> 0.0485 | J5: =Assumptions!J25 -> 0.0485
B6: Interest rate on cash | F6: =Assumptions!F26 -> 0.060765566 | G6: =Assumptions!G26 -> 0.060765566 | H6: =Assumptions!H26 -> 0.060765566 | I6: =Assumptions!I26 -> 0.060765566 | J6: =Assumptions!J26 -> 0.060765566
B8: Issuance of long-term debt | F8: =Assumptions!F28 -> 0 | G8: =Assumptions!G28 -> 0 | H8: =Assumptions!H28 -> 0 | I8: =Assumptions!I28 -> 0 | J8: =Assumptions!J28 -> 0
B9: Repayment of long-term debt | F9: =Assumptions!F29 -> 0 | G9: =Assumptions!G29 -> 0 | H9: =Assumptions!H29 -> 0 | I9: =Assumptions!I29 -> 0 | J9: =Assumptions!J29 -> 0
A11: Revolver | C11: =C2 -> 2022 | D11: =D2 -> 2023 | E11: =E2 -> 2024 | F11: =F2 -> 2025 | G11: =G2 -> 2026 | H11: =H2 -> 2027 | I11: =I2 -> 2028 | J11: =J2 -> 2029
B12: Balance | F12: NO REVOLVER | G12: NO REVOLVER | H12: NO REVOLVER | I12: NO REVOLVER | J12: NO REVOLVER
B13: Interest rate
B14: Interest expense
A16: Long term debt | C16: =C11 -> 2022 | D16: =D11 -> 2023 | E16: =E11 -> 2024 | F16: =F11 -> 2025 | G16: =G11 -> 2026 | H16: =H11 -> 2027 | I16: =I11 -> 2028 | J16: =J11 -> 2029
B17: Beginning balance | F17: =E20 -> 28826 | G17: =F20 -> 28826 | H17: =G20 -> 28826 | I17: =H20 -> 28826 | J17: =I20 -> 28826
B18: Issuance | F18: =F8 -> 0 | G18: =G8 -> 0 | H18: =H8 -> 0 | I18: =I8 -> 0 | J18: =J8 -> 0
B19: Repayment | F19: =F9 -> 0 | G19: =G9 -> 0 | H19: =H9 -> 0 | I19: =I9 -> 0 | J19: =J9 -> 0
B20: Ending balance | E20: =BalSheet!E34 -> 28826 | F20: =SUM(F17:F19) -> 28826 | G20: =SUM(G17:G19) -> 28826 | H20: =SUM(H17:H19) -> 28826 | I20: =SUM(I17:I19) -> 28826 | J20: =SUM(J17:J19) -> 28826
B21: Interest rate | F21: =F5 -> 0.0485 | G21: =G5 -> 0.0485 | H21: =H5 -> 0.0485 | I21: =I5 -> 0.0485 | J21: =J5 -> 0.0485
B22: Interest expense | F22: =F20*F21 -> 1398.061 | G22: =G20*G21 -> 1398.061 | H22: =H20*H21 -> 1398.061 | I22: =I20*I21 -> 1398.061 | J22: =J20*J21 -> 1398.061
A24: Debt summary | C24: =C16 -> 2022 | D24: =D16 -> 2023 | E24: =E16 -> 2024 | F24: =F16 -> 2025 | G24: =G16 -> 2026 | H24: =H16 -> 2027 | I24: =I16 -> 2028 | J24: =J16 -> 2029
B25: Revolver | F25: =F12 -> NO REVOLVER | G25: =G12 -> NO REVOLVER | H25: =H12 -> NO REVOLVER | I25: =I12 -> NO REVOLVER | J25: =J12 -> NO REVOLVER
B26: Total long term debt | F26: =F20 -> 28826 | G26: =G20 -> 28826 | H26: =H20 -> 28826 | I26: =I20 -> 28826 | J26: =J20 -> 28826
B27: Total debt | F27: =SUM(F25:F26) -> 28826 | G27: =SUM(G25:G26) -> 28826 | H27: =SUM(H25:H26) -> 28826 | I27: =SUM(I25:I26) -> 28826 | J27: =SUM(J25:J26) -> 28826
B28: Total interest expense | F28: =F22 -> 1398.061 | G28: =G22 -> 1398.061 | H28: =H22 -> 1398.061 | I28: =I22 -> 1398.061 | J28: =J22 -> 1398.061
A30: Interest income | C30: =C11 -> 2022 | D30: =D11 -> 2023 | E30: =E11 -> 2024 | F30: =F11 -> 2025 | G30: =G11 -> 2026 | H30: =H11 -> 2027 | I30: =I11 -> 2028 | J30: =J11 -> 2029
B31: Excess Cash | F31: =SUM(BalSheet!F15:F16) -> 42462.016 | G31: =SUM(BalSheet!G15:G16) -> 67419.327 | H31: =SUM(BalSheet!H15:H16) -> 112324.55 | I31: =SUM(BalSheet!I15:I16) -> 180566.52 | J31: =SUM(BalSheet!J15:J16) -> 276391.25
B32: Interest rate | F32: =F6 -> 0.060765566 | G32: =G6 -> 0.060765566 | H32: =H6 -> 0.060765566 | I32: =I6 -> 0.060765566 | J32: =J6 -> 0.060765566
B33: Interest income | F33: =F31*F32 -> 2580.2285 | G33: =G31*G32 -> 4096.7736 | H33: =H31*H32 -> 6825.4647 | I33: =I31*I32 -> 10972.227 | J33: =J31*J32 -> 16795.071

Sheet IncState
A1: =CoName -> Meta Platforms Inc. | C1: Hist. | D1: Hist. | E1: Hist. | F1: Proj. | G1: Proj. | H1: Proj. | I1: Proj. | J1: Proj.
A2: Assumptions | C2: 2022 | D2: =C2+1 -> 2023 | E2: =D2+1 -> 2024 | F2: =E2+1 -> 2025 | G2: =F2+1 -> 2026 | H2: =G2+1 -> 2027 | I2: =H2+1 -> 2028 | J2: =I2+1 -> 2029
B4: Revenue growth | F4: =Assumptions!F10 -> 0.21054103 | G4: =Assumptions!G10 -> 0.2 | H4: =Assumptions!H10 -> 0.175 | I4: =Assumptions!I10 -> 0.175 | J4: =Assumptions!J10 -> 0.17
B5: Cost of goods sold as % of sales | F5: =Assumptions!F11 -> 0.17965731 | G5: =Assumptions!G11 -> 0.17965731 | H5: =Assumptions!H11 -> 0.17965731 | I5: =Assumptions!I11 -> 0.17965731 | J5: =Assumptions!J11 -> 0.17965731
B6: R&D % of sales | F6: =Assumptions!F12 -> 0.29553882 | G6: =Assumptions!G12 -> 0.23643105 | H6: =Assumptions!H12 -> 0.23643105 | I6: =Assumptions!I12 -> 0.23643105 | J6: =Assumptions!J12 -> 0.23643105
B7: SG&A % of sales | F7: =Assumptions!F13 -> 0.12818767 | G7: =Assumptions!G13 -> 0.12818767 | H7: =Assumptions!H13 -> 0.12818767 | I7: =Assumptions!I13 -> 0.12818767 | J7: =Assumptions!J13 -> 0.12818767
B8: Amortization amount | F8: =Assumptions!F14 -> 0 | G8: =Assumptions!G14 -> 0 | H8: =Assumptions!H14 -> 0 | I8: =Assumptions!I14 -> 0 | J8: =Assumptions!J14 -> 0
B9: Non recurring items, amount | F9: =Assumptions!F15 -> 0 | G9: =Assumptions!G15 -> 0 | H9: =Assumptions!H15 -> 0 | I9: =Assumptions!I15 -> 0 | J9: =Assumptions!J15 -> 0
B10: Other income (expense), amt | F10: =Assumptions!F16 -> 0 | G10: =Assumptions!G16 -> 0 | H10: =Assumptions!H16 -> 0 | I10: =Assumptions!I16 -> 0 | J10: =Assumptions!J16 -> 0
B11: Effective tax rate | F11: =Assumptions!F17 -> 0.135 | G11: =Assumptions!G17 -> 0.135 | H11: =Assumptions!H17 -> 0.135 | I11: =Assumptions!I17 -> 0.135 | J11: =Assumptions!J17 -> 0.135
B12: Dividend Payout Rate | F12: =Assumptions!F18 -> 0.081334189 | G12: =Assumptions!G18 -> 0.081334189 | H12: =Assumptions!H18 -> 0.081334189 | I12: =Assumptions!I18 -> 0.081334189 | J12: =Assumptions!J18 -> 0.081334189
B13: Basic WASO | F13: =Assumptions!F19 -> 2534 | G13: =Assumptions!G19 -> 2534 | H13: =Assumptions!H19 -> 2534 | I13: =Assumptions!I19 -> 2534 | J13: =Assumptions!J19 -> 2534
B14: Diluted WASO | F14: =Assumptions!F20 -> 2614 | G14: =Assumptions!G20 -> 2614 | H14: =Assumptions!H20 -> 2614 | I14: =Assumptions!I20 -> 2614 | J14: =Assumptions!J20 -> 2614
A16: Income statement | C16: =C39 -> 44926 | D16: =D39 -> 45291 | E16: =E39 -> 45657 | F16: =F39 -> 46022 | G16: =G39 -> 46022 | H16: =H39 -> 46022 | I16: =I39 -> 46022 | J16: =J39 -> 46022
B17: Revenue | C17: 116609 | D17: 134902 | E17: 164501 | F17: =E17*(1+F4) -> 199135.21 | G17: =F17*(1+G4) -> 238962.25 | H17: =G17*(1+H4) -> 280780.65 | I17: =H17*(1+I4) -> 329917.26 | J17: =I17*(1+J4) -> 386003.19
B18: COGS | C18: 25249 | D18: 25959 | E18: 30161 | F18: =F17*F5 -> 35776.097 | G18: =G17*G5 -> 42931.316 | H18: =H17*H5 -> 50444.296 | I18: =I17*I5 -> 59272.048 | J18: =J17*J5 -> 69348.296
B19: R&D | C19: 35338 | D19: 38483 | E19: 43873 | F19: =F17*F6 -> 58852.184 | G19: =G17*G6 -> 56498.097 | H19: =H17*H6 -> 66385.264 | I19: =I17*I6 -> 78002.685 | J19: =J17*J6 -> 91263.142
B20: SG&A | C20: =15262+11816 -> 27078 | D20: =12301+11408 -> 23709 | E20: =11347+9740 -> 21087 | F20: =F17*F7 -> 25526.679 | G20: =G17*G7 -> 30632.015 | H20: =H17*H7 -> 35992.617 | I20: =I17*I7 -> 42291.325 | J20: =J17*J7 -> 49480.85
A21: * | B21: EBIT | C21: =C17-SUM(C18:C20) -> 28944 | D21: =D17-SUM(D18:D20) -> 46751 | E21: =E17-SUM(E18:E20) -> 69380 | F21: =F17-SUM(F18:F20) -> 78980.251 | G21: =G17-SUM(G18:G20) -> 108900.83 | H21: =H17-SUM(H18:H20) -> 127958.47 | I21: =I17-SUM(I18:I20) -> 150351.2 | J21: =J17-SUM(J18:J20) -> 175910.91
B23: Depreciation | C23: 8686 | D23: 11178 | E23: 15498 | F23: =Calcs!F8 -> 19219.715 | G23: =Calcs!G8 -> 26664.03 | H23: =Calcs!H8 -> 33741.237 | I23: =Calcs!I8 -> 40132.808 | J23: =Calcs!J8 -> 45712.929
B24: Amortization | F24: =F8 -> 0 | G24: =G8 -> 0 | H24: =H8 -> 0 | I24: =I8 -> 0 | J24: =J8 -> 0
A25: * | B25: EBITDA | C25: =SUM(C21,C23:C24) -> 37630 | D25: =SUM(D21,D23:D24) -> 57929 | E25: =SUM(E21,E23:E24) -> 84878 | F25: =SUM(F21,F23:F24) -> 98199.965 | G25: =SUM(G21,G23:G24) -> 135564.86 | H25: =SUM(H21,H23:H24) -> 161699.71 | I25: =SUM(I21,I23:I24) -> 190484.01 | J25: =SUM(J21,J23:J24) -> 221623.83
B27: Non-recurring items | C27: -81 | D27: -366 | E27: -690 | F27: =F9 -> 0 | G27: =G9 -> 0 | H27: =H9 -> 0 | I27: =I9 -> 0 | J27: =J9 -> 0
B28: Other income (expense) | C28: -320 | D28: -150 | E28: 171 | F28: =F10 -> 0 | G28: =G10 -> 0 | H28: =H10 -> 0 | I28: =I10 -> 0 | J28: =J10 -> 0
B30: Interest income | C30: 461 | D30: 1639 | E30: 2517 | F30: =IF(circ=1,Debt!F33,0) -> 0 | G30: =IF(circ=1,Debt!G33,0) -> 0 | H30: =IF(circ=1,Debt!H33,0) -> 0 | I30: =IF(circ=1,Debt!I33,0) -> 0 | J30: =IF(circ=1,Debt!J33,0) -> 0
B31: Interest expense | C31: -715 | D31: -446 | E31: -715 | F31: =IF(circ=1,-Debt!F28,0) -> 0 | G31: =IF(circ=1,-Debt!G28,0) -> 0 | H31: =IF(circ=1,-Debt!H28,0) -> 0 | I31: =IF(circ=1,-Debt!I28,0) -> 0 | J31: =IF(circ=1,-Debt!J28,0) -> 0
A33: * | B33: Pretax Income | C33: =C21+SUM(C27:C31) -> 28289 | D33: =D21+SUM(D27:D31) -> 47428 | E33: =E21+SUM(E27:E31) -> 70663 | F33: =F21+SUM(F27:F31) -> 78980.251 | G33: =G21+SUM(G27:G31) -> 108900.83 | H33: =H21+SUM(H27:H31) -> 127958.47 | I33: =I21+SUM(I27:I31) -> 150351.2 | J33: =J21+SUM(J27:J31) -> 175910.91
B35: Tax expense | C35: 5619 | D35: 8330 | E35: 8303 | F35: =F33*F11 -> 10662.334 | G35: =G33*G11 -> 14701.611 | H35: =H33*H11 -> 17274.393 | I35: =I33*I11 -> 20297.412 | J35: =J33*J11 -> 23747.972
A36: * | B36: Net income | C36: =C33-C35 -> 22670 | D36: =D33-D35 -> 39098 | E36: =E33-E35 -> 62360 | F36: =F33-F35 -> 68317.917 | G36: =G33-G35 -> 94199.214 | H36: =H33-H35 -> 110684.08 | I36: =I33-I35 -> 130053.79 | J36: =J33-J35 -> 152162.93
B37: Dividend payout rate | C37: =C38/C36 -> 0 | D37: =D38/D36 -> 0 | E37: =E38/E36 -> 0.081334189 | F37: =F12 -> 0.081334189 | G37: =G12 -> 0.081334189 | H37: =H12 -> 0.081334189 | I37: =I12 -> 0.081334189 | J37: =J12 -> 0.081334189
B38: Dividends | C38: 0 | D38: 0 | E38: 5072 | F38: =F36*F37 -> 5556.5823 | G38: =G36*G37 -> 7661.6166 | H38: =H36*H37 -> 9002.3995 | I38: =I36*I37 -> 10577.819 | J38: =J36*J37 -> 12376.049
A39: Shareholder information | C39: 44926 | D39: 45291 | E39: 45657 | F39: 46022 | G39: 46022 | H39: 46022 | I39: 46022 | J39: 46022
B40: Basic WASO | C40: 2687 | D40: 2574 | E40: 2534 | F40: =F13 -> 2534 | G40: =G13 -> 2534 | H40: =H13 -> 2534 | I40: =I13 -> 2534 | J40: =J13 -> 2534
B41: Diluted WASO | C41: 2702 | D41: 2629 | E41: 2614 | F41: =F14 -> 2614 | G41: =G14 -> 2614 | H41: =H14 -> 2614 | I41: =I14 -> 2614 | J41: =J14 -> 2614
B42: Basic earnings per share | C42: =C36/C40 -> 8.4369185 | D42: =D36/D40 -> 15.189588 | E42: =E36/E40 -> 24.609313 | F42: =F36/F40 -> 26.960504 | G42: =G36/G40 -> 37.174117 | H42: =H36/H40 -> 43.679588 | I42: =I36/I40 -> 51.323516 | J42: =J36/J40 -> 60.048514
A43: * | B43: Diluted earnings per share | C43: =C36/C41 -> 8.3900814 | D43: =D36/D41 -> 14.871814 | E43: =E36/E41 -> 23.856159 | F43: =F36/F41 -> 26.135393 | G43: =G36/G41 -> 36.036425 | H43: =H36/H41 -> 42.342799 | I43: =I36/I41 -> 49.752789 | J43: =J36/J41 -> 58.210763

Sheet BalSheet
A1: =CoName -> Meta Platforms Inc. | C1: Hist. | D1: Hist. | E1: Hist. | F1: Proj. | G1: Proj. | H1: Proj. | I1: Proj. | J1: Proj.
A2: Assumptions | C2: 2022 | D2: =C2+1 -> 2023 | E2: =D2+1 -> 2024 | F2: =E2+1 -> 2025 | G2: =F2+1 -> 2026 | H2: =G2+1 -> 2027 | I2: =H2+1 -> 2028 | J2: =I2+1 -> 2029
B4: Operating Cash % of sales | F4: =Assumptions!F45 -> 0.015 | G4: =F4 -> 0.015 | H4: =G4 -> 0.015 | I4: =H4 -> 0.015 | J4: =I4 -> 0.015
B5: Accounts receivable % of sales | F5: =Assumptions!F46 -> 0.10330636 | G5: =Assumptions!G46 -> 0.10330636 | H5: =Assumptions!H46 -> 0.10330636 | I5: =Assumptions!I46 -> 0.10330636 | J5: =Assumptions!J46 -> 0.10330636
B6: Other current assets % of sales | F6: =Assumptions!F47 -> 0.23806542 | G6: =Assumptions!G47 -> 0.23806542 | H6: =Assumptions!H47 -> 0.23806542 | I6: =Assumptions!I47 -> 0.23806542 | J6: =Assumptions!J47 -> 0.23806542
B7: Other long-term assets % of sales | F7: =Assumptions!F50 -> 0.079130218 | G7: =Assumptions!G50 -> 0.079130218 | H7: =Assumptions!H50 -> 0.079130218 | I7: =Assumptions!I50 -> 0.079130218 | J7: =Assumptions!J50 -> 0.079130218
B8: Investment in unconsolidated entities $ balance | F8: =Assumptions!F49 -> 6070 | G8: =Assumptions!G49 -> 6070 | H8: =Assumptions!H49 -> 6070 | I8: =Assumptions!I49 -> 6070 | J8: =Assumptions!J49 -> 6070
B10: Accounts payable/Accural % of COGS | F10: =Assumptions!F54 -> 0.25486555 | G10: =Assumptions!G54 -> 0.25486555 | H10: =Assumptions!H54 -> 0.25486555 | I10: =Assumptions!I54 -> 0.25486555 | J10: =Assumptions!J54 -> 0.25486555
B11: Other current liabilities % of sales | F11: =Assumptions!F55 -> 0.15750056 | G11: =Assumptions!G55 -> 0.15750056 | H11: =Assumptions!H55 -> 0.15750056 | I11: =Assumptions!I55 -> 0.15750056 | J11: =Assumptions!J55 -> 0.15750056
B12: Other long-term liabilities % of sales | F12: =Assumptions!F56 -> 0.18841831 | G12: =Assumptions!G56 -> 0.18841831 | H12: =Assumptions!H56 -> 0.18841831 | I12: =Assumptions!I56 -> 0.18841831 | J12: =Assumptions!J56 -> 0.18841831
A14: Balance sheet | C14: =C2 -> 2022 | D14: =D2 -> 2023 | E14: =E2 -> 2024 | F14: =F2 -> 2025 | G14: =G2 -> 2026 | H14: =H2 -> 2027 | I14: =I2 -> 2028 | J14: =J2 -> 2029
B15: Operating Cash | C15: =1.5%*IncState!C17 -> 1749.135 | D15: =1.5%*IncState!D17 -> 2023.53 | E15: =1.5%*IncState!E17 -> 2467.515 | F15: =F4*IncState!F17 -> 2987.0282 | G15: =G4*IncState!G17 -> 3584.4338 | H15: =H4*IncState!H17 -> 4211.7097 | I15: =I4*IncState!I17 -> 4948.7589 | J15: =J4*IncState!J17 -> 5790.0479
B16: Excess cash | C16: =14681-C15 -> 12931.865 | D16: =41862-D15 -> 39838.47 | E16: =43889-E15 -> 41421.485 | F16: =MAX(CashFlow!F23,0) -> 39474.988 | G16: =MAX(CashFlow!G23,0) -> 63834.893 | H16: =MAX(CashFlow!H23,0) -> 108112.84 | I16: =MAX(CashFlow!I23,0) -> 175617.76 | J16: =MAX(CashFlow!J23,0) -> 270601.2
B17: Accounts receivable | C17: 13466 | D17: 16169 | E17: 16994 | F17: =F5*IncState!F17 -> 20571.934 | G17: =G5*IncState!G17 -> 24686.321 | H17: =H5*IncState!H17 -> 29006.427 | I17: =I5*IncState!I17 -> 34082.552 | J17: =J5*IncState!J17 -> 39876.586
B18: Other current assets | C18: =5345+26057 -> 31402 | D18: =3793+23541 -> 27334 | E18: =5236+33926 -> 39162 | F18: =F6*IncState!F17 -> 47407.208 | G18: =G6*IncState!G17 -> 56888.65 | H18: =H6*IncState!H17 -> 66844.163 | I18: =I6*IncState!I17 -> 78541.892 | J18: =J6*IncState!J17 -> 91894.013
B19: Total current assets | C19: =SUM(C15:C18) -> 59549 | D19: =SUM(D15:D18) -> 85365 | E19: =SUM(E15:E18) -> 100045 | F19: =SUM(F15:F18) -> 110441.16 | G19: =SUM(G15:G18) -> 148994.3 | H19: =SUM(H15:H18) -> 208175.14 | I19: =SUM(I15:I18) -> 293190.97 | J19: =SUM(J15:J18) -> 408161.85
B21: Property, plant & equipment, net | C21: =79518+12673 -> 92191 | D21: =96587+13294 -> 109881 | E21: =121346+14922 -> 136268 | F21: =Calcs!F9 -> 189048.29 | G21: =Calcs!G9 -> 239225.76 | H21: =Calcs!H9 -> 284542.08 | I21: =Calcs!I9 -> 324105.2 | J21: =Calcs!J9 -> 356196.38
B22: Intangible assets | C22: =897+20306 -> 21203 | D22: 20654 | E22: =20654 -> 20654 | F22: =E22-IncState!F24 -> 20654 | G22: =F22-IncState!G24 -> 20654 | H22: =G22-IncState!H24 -> 20654 | I22: =H22-IncState!I24 -> 20654 | J22: =I22-IncState!J24 -> 20654
B23: Investment in unconsolidated entities | C23: 6201 | D23: 6141 | E23: 6070 | F23: =F8 -> 6070 | G23: =G8 -> 6070 | H23: =H8 -> 6070 | I23: =I8 -> 6070 | J23: =J8 -> 6070
B24: Other assets | C24: =6583 -> 6583 | D24: 7582 | E24: 13017 | F24: =F7*IncState!F17 -> 15757.613 | G24: =G7*IncState!G17 -> 18909.135 | H24: =H7*IncState!H17 -> 22218.234 | I24: =I7*IncState!I17 -> 26106.425 | J24: =J7*IncState!J17 -> 30544.517
B25: Total non-current assets | C25: =SUM(C21:C24) -> 126178 | D25: =SUM(D21:D24) -> 144258 | E25: =SUM(E21:E24) -> 176009 | F25: =SUM(F21:F24) -> 231529.9 | G25: =SUM(G21:G24) -> 284858.9 | H25: =SUM(H21:H24) -> 333484.31 | I25: =SUM(I21:I24) -> 376935.62 | J25: =SUM(J21:J24) -> 413464.89
A27: * | B27: TOTAL ASSETS | C27: =SUM(C25,C19) -> 185727 | D27: =SUM(D25,D19) -> 229623 | E27: =SUM(E25,E19) -> 276054 | F27: =SUM(F25,F19) -> 341971.06 | G27: =SUM(G25,G19) -> 433853.2 | H27: =SUM(H25,H19) -> 541659.45 | I27: =SUM(I25,I19) -> 670126.59 | J27: =SUM(J25,J19) -> 821626.74
B29: Revolver/Short term debt | C29: 0 | D29: 0 | E29: 0 | F29: =MIN(CashFlow!F23,0) -> 0 | G29: =MIN(CashFlow!G23,0) -> 0 | H29: =MIN(CashFlow!H23,0) -> 0 | I29: =MIN(CashFlow!I23,0) -> 0 | J29: =MIN(CashFlow!J23,0) -> 0
B30: Accounts payable/Accurals | C30: 4990 | D30: 4849 | E30: 7687 | F30: =F10*IncState!F18 -> 9118.0947 | G30: =G10*IncState!G18 -> 10941.714 | H30: =H10*IncState!H18 -> 12856.514 | I30: =I10*IncState!I18 -> 15106.403 | J30: =J10*IncState!J18 -> 17674.492
B31: Other current liabilities | C31: =1117+1367+19552 -> 22036 | D31: =1623+25488 -> 27111 | E31: =1942+23967 -> 25909 | F31: =F11*IncState!F17 -> 31363.908 | G31: =G11*IncState!G17 -> 37636.689 | H31: =H11*IncState!H17 -> 44223.11 | I31: =I11*IncState!I17 -> 51962.154 | J31: =J11*IncState!J17 -> 60795.72
B32: Total current liabilities | C32: =SUM(C29:C31) -> 27026 | D32: =SUM(D29:D31) -> 31960 | E32: =SUM(E29:E31) -> 33596 | F32: =SUM(F29:F31) -> 40482.002 | G32: =SUM(G29:G31) -> 48578.403 | H32: =SUM(H29:H31) -> 57079.623 | I32: =SUM(I29:I31) -> 67068.557 | J32: =SUM(J29:J31) -> 78470.212
B34: Long-term debt, including current maturities | C34: 9923 | D34: 18385 | E34: 28826 | F34: =Debt!F20 -> 28826 | G34: =Debt!G20 -> 28826 | H34: =Debt!H20 -> 28826 | I34: =Debt!I20 -> 28826 | J34: =Debt!J20 -> 28826
B35: Other long-term liabilities | C35: =15301+7764 -> 23065 | D35: =17226+7514+1370 -> 26110 | E35: =2716+9987+18292 -> 30995 | F35: =F12*IncState!F17 -> 37520.719 | G35: =G12*IncState!G17 -> 45024.863 | H35: =H12*IncState!H17 -> 52904.214 | I35: =I12*IncState!I17 -> 62162.452 | J35: =J12*IncState!J17 -> 72730.069
B36: Total non-current liabilities | C36: =SUM(C34:C35) -> 32988 | D36: =SUM(D34:D35) -> 44495 | E36: =SUM(E34:E35) -> 59821 | F36: =SUM(F34:F35) -> 66346.719 | G36: =SUM(G34:G35) -> 73850.863 | H36: =SUM(H34:H35) -> 81730.214 | I36: =SUM(I34:I35) -> 90988.452 | J36: =SUM(J34:J35) -> 101556.07
B38: Equity | C38: 125713 | D38: 153168 | E38: 182637 | F38: =Calcs!F17 -> 235142.33 | G38: =Calcs!G17 -> 311423.93 | H38: =Calcs!H17 -> 402849.61 | I38: =Calcs!I17 -> 512069.58 | J38: =Calcs!J17 -> 641600.46
A39: * | B39: TOTAL LIABILITIES & EQUITY | C39: =SUM(C38,C36,C32) -> 185727 | D39: =SUM(D38,D36,D32) -> 229623 | E39: =SUM(E38,E36,E32) -> 276054 | F39: =SUM(F38,F36,F32) -> 341971.06 | G39: =SUM(G38,G36,G32) -> 433853.2 | H39: =SUM(H38,H36,H32) -> 541659.45 | I39: =SUM(I38,I36,I32) -> 670126.59 | J39: =SUM(J38,J36,J32) -> 821626.74
A41: * | B41: Balance check | C41: =C39-C27 -> 0 | D41: =D39-D27 -> 0 | E41: =E39-E27 -> 0 | F41: =F39-F27 -> 0 | G41: =G39-G27 -> 0 | H41: =H39-H27 -> 0 | I41: =I39-I27 -> 0 | J41: =J39-J27 -> 0

Sheet CashFlow
A1: =CoName -> Meta Platforms Inc. | C1: Hist. | D1: Hist. | E1: Hist. | F1: Proj. | G1: Proj. | H1: Proj. | I1: Proj. | J1: Proj.
A2: Cash flow statement | C2: 2022 | D2: =C2+1 -> 2023 | E2: =D2+1 -> 2024 | F2: =E2+1 -> 2025 | G2: =F2+1 -> 2026 | H2: =G2+1 -> 2027 | I2: =H2+1 -> 2028 | J2: =I2+1 -> 2029
B3: Net Income | F3: =IncState!F36 -> 68317.917 | G3: =IncState!G36 -> 94199.214 | H3: =IncState!H36 -> 110684.08 | I3: =IncState!I36 -> 130053.79 | J3: =IncState!J36 -> 152162.93
B4: Depreciation | F4: =IncState!F23 -> 19219.715 | G4: =IncState!G23 -> 26664.03 | H4: =IncState!H23 -> 33741.237 | I4: =IncState!I23 -> 40132.808 | J4: =IncState!J23 -> 45712.929
B5: Amortzation | F5: =IncState!F24 -> 0 | G5: =IncState!G24 -> 0 | H5: =IncState!H24 -> 0 | I5: =IncState!I24 -> 0 | J5: =IncState!J24 -> 0
B6: (inc) / dec in OWC | F6: =Calcs!F25 -> -5456.6531 | G6: =Calcs!G25 -> -6096.8336 | H6: =Calcs!H25 -> -6401.6753 | I6: =Calcs!I25 -> -7521.9685 | J6: =Calcs!J25 -> -8585.7897
B7: (inc) / dec in LT assets | F7: =BalSheet!E24-BalSheet!F24 -> -2740.6126 | G7: =BalSheet!F24-BalSheet!G24 -> -3151.5225 | H7: =BalSheet!G24-BalSheet!H24 -> -3309.0987 | I7: =BalSheet!H24-BalSheet!I24 -> -3888.1909 | J7: =BalSheet!I24-BalSheet!J24 -> -4438.0922
B8: inc / (dec) in LT liabilities | F8: =BalSheet!F35-BalSheet!E35 -> 6525.7193 | G8: =BalSheet!G35-BalSheet!F35 -> 7504.1439 | H8: =BalSheet!H35-BalSheet!G35 -> 7879.3511 | I8: =BalSheet!I35-BalSheet!H35 -> 9258.2375 | J8: =BalSheet!J35-BalSheet!I35 -> 10567.617
B9: CFFO | F9: =SUM(F3:F8) -> 85866.085 | G9: =SUM(G3:G8) -> 119119.03 | H9: =SUM(H3:H8) -> 142593.89 | I9: =SUM(I3:I8) -> 168034.68 | J9: =SUM(J3:J8) -> 195419.6
B11: Capex | F11: =-Calcs!F7 -> -72000 | G11: =-Calcs!G7 -> -76841.51 | H11: =-Calcs!H7 -> -79057.548 | I11: =-Calcs!I7 -> -79695.929 | J11: =-Calcs!J7 -> -77804.109
B12: CFFI | F12: =F11 -> -72000 | G12: =G11 -> -76841.51 | H12: =H11 -> -79057.548 | I12: =I11 -> -79695.929 | J12: =J11 -> -77804.109
B14: Dividends Paid | F14: =Calcs!F15 -> -5556.5823 | G14: =Calcs!G15 -> -7661.6166 | H14: =Calcs!H15 -> -9002.3995 | I14: =Calcs!I15 -> -10577.819 | J14: =Calcs!J15 -> -12376.049
B15: Share issuance / (repurchases) | F15: =Calcs!F16 -> -10256 | G15: =Calcs!G16 -> -10256 | H15: =Calcs!H16 -> -10256 | I15: =Calcs!I16 -> -10256 | J15: =Calcs!J16 -> -10256
B16: Debt issuance / (repayments) | F16: =SUM(Debt!F8:F9) -> 0 | G16: =SUM(Debt!G8:G9) -> 0 | H16: =SUM(Debt!H8:H9) -> 0 | I16: =SUM(Debt!I8:I9) -> 0 | J16: =SUM(Debt!J8:J9) -> 0
B17: CFFF | F17: =SUM(F14:F16) -> -15812.582 | G17: =SUM(G14:G16) -> -17917.617 | H17: =SUM(H14:H16) -> -19258.4 | I17: =SUM(I14:I16) -> -20833.819 | J17: =SUM(J14:J16) -> -22632.049
B19: Net changes in Cash | F19: =SUM(F17,F12,F9) -> -1946.4972 | G19: =SUM(G17,G12,G9) -> 24359.905 | H19: =SUM(H17,H12,H9) -> 44277.943 | I19: =SUM(I17,I12,I9) -> 67504.927 | J19: =SUM(J17,J12,J9) -> 94983.44
B21: Beginning cash | F21: =BalSheet!E16 -> 41421.485 | G21: =BalSheet!F16 -> 39474.988 | H21: =BalSheet!G16 -> 63834.893 | I21: =BalSheet!H16 -> 108112.84 | J21: =BalSheet!I16 -> 175617.76
B22: =B19 -> Net changes in Cash | F22: =F19 -> -1946.4972 | G22: =G19 -> 24359.905 | H22: =H19 -> 44277.943 | I22: =I19 -> 67504.927 | J22: =J19 -> 94983.44
B23: Ending Cash | F23: =SUM(F21:F22) -> 39474.988 | G23: =SUM(G21:G22) -> 63834.893 | H23: =SUM(H21:H22) -> 108112.84 | I23: =SUM(I21:I22) -> 175617.76 | J23: =SUM(J21:J22) -> 270601.2

Sheet Free Cash Flow
A1: =CoName -> Meta Platforms Inc. | C1: Hist. | D1: Hist. | E1: Hist. | F1: Proj. | G1: Proj. | H1: Proj. | I1: Proj. | J1: Proj.
A2: Free Cash Flows | C2: 2022 | D2: =C2+1 -> 2023 | E2: =D2+1 -> 2024 | F2: =E2+1 -> 2025 | G2: =F2+1 -> 2026 | H2: =G2+1 -> 2027 | I2: =H2+1 -> 2028 | J2: =I2+1 -> 2029
A3: * | B3: Sales | F3: =IncState!F17 -> 199135.21 | G3: =IncState!G17 -> 238962.25 | H3: =IncState!H17 -> 280780.65 | I3: =IncState!I17 -> 329917.26 | J3: =IncState!J17 -> 386003.19
B4: EBIT | F4: =IncState!F21 -> 78980.251 | G4: =IncState!G21 -> 108900.83 | H4: =IncState!H21 -> 127958.47 | I4: =IncState!I21 -> 150351.2 | J4: =IncState!J21 -> 175910.91
B5: Effective Tax Rate | F5: =Assumptions!F17 -> 0.135 | G5: =Assumptions!G17 -> 0.135 | H5: =Assumptions!H17 -> 0.135 | I5: =Assumptions!I17 -> 0.135 | J5: =Assumptions!J17 -> 0.135
A7: * | B7: NOPAT | F7: =F4*(1-F5) -> 68317.917 | G7: =G4*(1-G5) -> 94199.214 | H7: =H4*(1-H5) -> 110684.08 | I7: =I4*(1-I5) -> 130053.79 | J7: =J4*(1-J5) -> 152162.93
B8: Depreciation | F8: =CashFlow!F4 -> 19219.715 | G8: =CashFlow!G4 -> 26664.03 | H8: =CashFlow!H4 -> 33741.237 | I8: =CashFlow!I4 -> 40132.808 | J8: =CashFlow!J4 -> 45712.929
B9: Amortization | F9: =CashFlow!F5 -> 0 | G9: =CashFlow!G5 -> 0 | H9: =CashFlow!H5 -> 0 | I9: =CashFlow!I5 -> 0 | J9: =CashFlow!J5 -> 0
B10: (inc) / dec in OWC | F10: =CashFlow!F6 -> -5456.6531 | G10: =CashFlow!G6 -> -6096.8336 | H10: =CashFlow!H6 -> -6401.6753 | I10: =CashFlow!I6 -> -7521.9685 | J10: =CashFlow!J6 -> -8585.7897
B11: (inc) / dec in other long-term assets | F11: =CashFlow!F7 -> -2740.6126 | G11: =CashFlow!G7 -> -3151.5225 | H11: =CashFlow!H7 -> -3309.0987 | I11: =CashFlow!I7 -> -3888.1909 | J11: =CashFlow!J7 -> -4438.0922
B12: inc / (dec) other long-term liabilities | F12: =CashFlow!F8 -> 6525.7193 | G12: =CashFlow!G8 -> 7504.1439 | H12: =CashFlow!H8 -> 7879.3511 | I12: =CashFlow!I8 -> 9258.2375 | J12: =CashFlow!J8 -> 10567.617
B13: (Capex) | F13: =CashFlow!F11 -> -72000 | G13: =CashFlow!G11 -> -76841.51 | H13: =CashFlow!H11 -> -79057.548 | I13: =CashFlow!I11 -> -79695.929 | J13: =CashFlow!J11 -> -77804.109
A15: * | B15: Free Cash Flow | F15: =SUM(F7:F13) -> 13866.085 | G15: =SUM(G7:G13) -> 42277.522 | H15: =SUM(H7:H13) -> 63536.342 | I15: =SUM(I7:I13) -> 88338.747 | J15: =SUM(J7:J13) -> 117615.49

Sheet WACC
A1: =CoName -> Meta Platforms Inc.
A3: * | B3: WACC | G3: Comp | H3: Levered beta | I3: Gross debt | J3: Market cap | K3: Debt/Mcap | L3: MTR | M3: Unlevered beta
B4: Tax Rate | E4: =Assumptions!F17 -> 0.135 | G4: GOOG | H4: 1.08 | I4: 21607 | J4: 3600000 | K4: =I4/J4 -> 0.0060019444 | L4: =E4 -> 0.135 | M4: =H4/((1+K4*(1-L4))) -> 1.0744219
B5: Risk free rate | E5: 0.0414 | G5: MSFT | H5: 1.07 | I5: =7832+35376 -> 43208 | J5: 3580000 | K5: =I5/J5 -> 0.012069274 | L5: =L4 -> 0.135 | M5: =H5/((1+K5*(1-L5))) -> 1.0589447
B6: Market risk Premium | E6: 0.05 | G6: AMZN | H6: 1.37 | I6: 50742 | J6: 2460000 | K6: =I6/J6 -> 0.020626829 | L6: =L5 -> 0.135 | M6: =H6/((1+K6*(1-L6))) -> 1.3459847
B7: Beta | E7: =M11*0.66 -> 0.69886806 | G7: SNAP | H7: 0.85 | I7: =47+3490 -> 3537 | J7: 13580 | K7: =I7/J7 -> 0.26045655 | L7: =L6 -> 0.135 | M7: =H7/((1+K7*(1-L7))) -> 0.69371054
B8: Cost of Equity | E8: =E5+E6*E7 -> 0.076343403
B9: % Equity | E9: =1-E10 -> 0.98268493 | G9: Industry beta (average) | M9: =AVERAGE(M4:M7) -> 1.0432655
B10: % Debt | E10: =MAIN!F8/MAIN!F6 -> 0.017315066
B11: Cost of debt | E11: =Assumptions!F25 -> 0.0485 | G11: Re-levered beta | M11: =M9*(1+E10*(1-E4)) -> 1.058891
B12: Post tax cost of debt | E12: =E11*(1-E4) -> 0.0419525
A13: * | B13: WACC | E13: =WACC!E8*WACC!E9+WACC!E12*WACC!E10 -> 0.075747922
B14: Long Term growth rate | E14: 0.025

Sheet DCF Model
A1: =CoName -> Meta Platforms Inc. | D1: Proj. | E1: Proj. | F1: Proj. | G1: Proj. | H1: Proj.
A2: Discount Model Year count | D2: 1 | E2: =D2+1 -> 2 | F2: =E2+1 -> 3 | G2: =F2+1 -> 4 | H2: =G2+1 -> 5
B3: Discount Factor | D3: =1/(1+$K$3)^D2 -> 0.92958581 | E3: =1/(1+$K$3)^E2 -> 0.86412977 | F3: =1/(1+$K$3)^F2 -> 0.80328277 | G3: =1/(1+$K$3)^G2 -> 0.74672026 | H3: =1/(1+$K$3)^H2 -> 0.69414056 | I3: WACC | K3: =WACC!E13 -> 0.075747922
B4: PV FCF | D4: =D3*'Free Cash Flow'!F15 -> 12889.716 | E4: =E3*'Free Cash Flow'!G15 -> 36533.265 | F4: =F3*'Free Cash Flow'!H15 -> 51037.649 | G4: =G3*'Free Cash Flow'!I15 -> 65964.332 | H4: =H3*'Free Cash Flow'!J15 -> 81641.681 | I4: Long Term growth rate | K4: =WACC!E14 -> 0.025
H5: =(H4*(1+K4))/(K3-K4) -> 1648988.2
A6: Value Calculation | E6: Multiples Calculation
B7: Total PV of FCFs | C7: =SUM(D4:H4) -> 248066.64 | E7: Total PV of FCFs | G7: =C7 -> 248066.64
B8: PV of TV | C8: =H5*H3 -> 1144629.6 | E8: Multiple TV | G8: =G10*H3*IncState!J25 -> 2307571.4
B9: EV | C9: =SUM(C7:C8) -> 1392696.2 | E9: EV | G9: =SUM(G7:G8) -> 2555638
E10: Implied EBITDA multiple | G10: 15
B12: Cash & Cash Equiv | C12: =MAIN!F7 -> 77815 | E12: Cash & Cash Equiv | G12: =C12 -> 77815
B13: Debt & Claims | C13: =MAIN!F8 -> 28826 | E13: Debt & Claims | G13: =C13 -> 28826
B14: NCI | C14: 0 | E14: NCI | G14: 0
B15: Equity Value | C15: =C9+C12-SUM(C13:C14) -> 1441685.2 | E15: Equity Value | G15: =G9+G12-SUM(G13:G14) -> 2604627
B17: Diluted S/O | C17: =MAIN!F5 -> 2511 | E17: Diluted S/O | G17: =C17 -> 2511
A18: * | B18: Implied Share Price | C18: =C15/C17 -> 574.14783 | E18: Implied Share Price | G18: =G15/G17 -> 1037.2867
A20: Sensitivity analysis
C22: Discount rate variance | E22: 0.005 | J22: Discount rate variance | L22: 0.005
C23: Implied growth rate variance | E23: 0.0025 | J23: TV multiple variance | L23: 2
E27: LTGR | J27: Exit Mult
C28: =C18 -> 574.14783 | D28: =E28-E23 -> 0.0225 | E28: 0.025 | F28: =E28+E23 -> 0.0275 | H28: =G18 -> 1037.2867 | I28: =J28-L23 -> 13 | J28: 15 | K28: =J28+L23 -> 17
C29: =C30+$E$22 -> 0.085747922 | D29: 447.624 | E29: 462.15913 | F29: 477.94196 | H29: =C29 -> 0.085747922 | I29: 875.45219 | J29: 992.4438 | K29: 1109.4354
C30: =C31+$E$22 -> 0.080747922 | D30: 494.86544 | E30: 512.79332 | F30: 532.40464 | H30: =C30 -> 0.080747922 | I30: 894.8346 | J30: 1014.5576 | K30: 1134.2807
C31: 0.075747922 | D31: 551.68615 | E31: 574.14783 | F31: 598.93724 | H31: =C31 -> 0.075747922 | I31: 914.75541 | J31: 1037.2867 | K31: 1159.8181
C32: =C31-$E$22 -> 0.070747922 | D32: 621.11493 | E32: 649.7912 | F32: 681.78281 | H32: =C32 -> 0.070747922 | I32: 935.23226 | J32: 1060.6513 | K32: 1186.0704
C33: =C32-$E$22 -> 0.065747922 | D33: 707.58506 | E33: 745.04755 | F33: 787.40736 | H33: =C33 -> 0.065747922 | I33: 956.28344 | J33: 1084.6723 | K33: 1213.0611
