Workbook
Name Ccy: MAIN!$C$6
Name circ: MAIN!$C$9
Name CoName: MAIN!$C$4
Name g: Presentation!$R$17
Name IQ_CH: 110000
Name IQ_CQ: 5000
Name IQ_CY: 10000
Name IQ_DAILY: 500000
Name IQ_FH: 100000
Name IQ_FQ: 500
Name IQ_FY: 1000
Name IQ_LTM: 2000
Name IQ_MONTH: 15000
Name IQ_NTM: 6000
Name IQ_WEEK: 50000
Name IQ_YTD: 3000
Name OpCase: [1]DCF!$E$98
Name ScenarioREV: Assumptions!$D$4
Name TTS: #REF!
Name Units: MAIN!$C$7

Sheet MAIN
A1: =CoName -> Microsoft Corp.
A2: Model Details
B4: Company name | C4: Microsoft Corp. | E4: Current Stock Price | F4: 516.109 | H4: Sensitivity Ranges | I4: Terminal Mult | J4: Perpetuity | K4: Average
B5: Latest BS date | C5: 247.43 | E5: Diluted s/o | F5: 7432.3777 | H5: High Price | I5: ='DCF Model'!T13 -> 633.68712 | J5: ='DCF Model'!O13 -> 523.07692 | K5: =AVERAGE(I5:J5) -> 578.38202
B6: Currency | C6: USD | E6: Mkt Cap | F6: =F5*F4 -> 3835917 | I6: =I5/$F$4-1 -> 0.22781645 | J6: =J5/$F$4-1 -> 0.013500869 | K6: =K5/$F$4-1 -> 0.12065866
B7: Units | C7: m | E7: Cash | F7: =28849+73163 -> 102012
B8: Analyst name | C8: Alan Chen | E8: Debt | F8: =35376+7832 -> 43208 | H8: Low Price | I8: ='DCF Model'!R9 -> 440.16511 | J8: ='DCF Model'!M9 -> 302.68454 | K8: =AVERAGE(I8:J8) -> 371.42483
B9: Circular switch | C9: 0 | E9: EV | F9: =F6-F7+F8 -> 3777113 | I9: =I8/$F$4-1 -> -0.14714699 | J9: =J8/$F$4-1 -> -0.41352594 | K9: =K8/$F$4-1 -> -0.28033647
B11: Valuations | C11: Terminal Mult | D11: Perpetuity | E11: =K4 -> Average
B12: Implied Price | C12: ='DCF Model'!S16 -> 541.4973 | D12: ='DCF Model'!N16 -> 391.5388 | E12: =AVERAGE(C12:D12) -> 466.51805
B13: Difference | C13: =C12/$F$4-1 -> 0.049191733 | D13: =D12/$F$4-1 -> -0.24136414 | E13: =E12/$F$4-1 -> -0.096086202

Sheet Assumptions
A1: =CoName -> Microsoft Corp. | C1: Hist. | D1: Hist. | E1: Hist. | F1: Proj. | G1: Proj. | H1: Proj. | I1: Proj. | J1: Proj. | K1: Proj. | L1: Proj. | M1: Proj.
A2: * | B2: Income Statement | C2: 2023 | D2: =C2+1 -> 2024 | E2: =D2+1 -> 2025 | F2: =E2+1 -> 2026 | G2: =F2+1 -> 2027 | H2: =G2+1 -> 2028 | I2: =H2+1 -> 2029 | J2: =I2+1 -> 2030 | K2: =J2+1 -> 2031 | ... M2: =L2+1 -> 2033
B4: Operating Case | D4: 1
D5: Variance
B6: Street Case | D6: 0 | F6: =Revenue!G23 -> 0.15539675 | G6: =Revenue!H23 -> 0.16921147 | H6: =Revenue!I23 -> 0.16595178 | I6: =Revenue!J23 -> 0.16036321 | J6: =Revenue!K23 -> 0.15280023 | K6: =Revenue!L23 -> 0.14368981 | L6: =Revenue!M23 -> 0.13350164 | M6: =Revenue!N23 -> 0.12272998
B7: Optimistic Case | D7: 0.03 | F7: =F6+$D$7 -> 0.18539675 | G7: =G6+$D$7 -> 0.19921147 | H7: =H6+$D$7 -> 0.19595178 | I7: =I6+$D$7 -> 0.19036321 | J7: =J6+$D$7 -> 0.18280023 | K7: =K6+$D$7 -> 0.17368981 | L7: =L6+$D$7 -> 0.16350164 | M7: =M6+$D$7 -> 0.15272998
B8: Pessimistic Case | D8: -0.03 | F8: =F6+$D$8 -> 0.12539675 | G8: =G6+$D$8 -> 0.13921147 | H8: =H6+$D$8 -> 0.13595178 | I8: =I6+$D$8 -> 0.13036321 | J8: =J6+$D$8 -> 0.12280023 | K8: =K6+$D$8 -> 0.11368981 | L8: =L6+$D$8 -> 0.10350164 | M8: =M6+$D$8 -> 0.092729978
B10: Revenue Growth | C10: =Revenue!D23 -> 0.068820296 | D10: =Revenue!E23 -> 0.15669962 | E10: =Revenue!F23 -> 0.14932156 | F10: =CHOOSE(ScenarioREV,F6,F7,F8) -> 0.15539675 | G10: =CHOOSE(ScenarioREV,G6,G7,G8) -> 0.16921147 | H10: =CHOOSE(ScenarioREV,H6,H7,H8) -> 0.16595178 | I10: =CHOOSE(ScenarioREV,I6,I7,I8) -> 0.16036321 | J10: =CHOOSE(ScenarioREV,J6,J7,J8) -> 0.15280023 | K10: =CHOOSE(ScenarioREV,K6,K7,K8) -> 0.14368981 | L10: =CHOOSE(ScenarioREV,L6,L7,L8) -> 0.13350164 | M10: =CHOOSE(ScenarioREV,M6,M7,M8) -> 0.12272998
B11: COGS % of sales | C11: =IncState!C18/IncState!C17 -> 0.31079914 | D11: =IncState!D18/IncState!D17 -> 0.30235556 | E11: =IncState!E18/IncState!E17 -> 0.31176258 | F11: =E11 -> 0.31176258 | G11: =F11 -> 0.31176258 | H11: =G11 -> 0.31176258 | I11: =H11 -> 0.31176258 | J11: =I11 -> 0.31176258 | K11: =J11 -> 0.31176258 | L11: =K11 -> 0.31176258 | M11: =L11 -> 0.31176258
B12: R&D % of sales | C12: =IncState!C19/IncState!C17 -> 0.12832975 | D12: =IncState!D19/IncState!D17 -> 0.12038903 | E12: =IncState!E19/IncState!E17 -> 0.11531854 | F12: =E12 -> 0.11531854 | G12: =F12 -> 0.11531854 | H12: =G12 -> 0.11531854 | I12: =H12 -> 0.11531854 | J12: =I12 -> 0.11531854 | K12: =J12 -> 0.11531854 | L12: =K12 -> 0.11531854 | M12: =L12 -> 0.11531854
B13: SG&A % of sales | C13: =IncState!C20/IncState!C17 -> 0.1431423 | D13: =IncState!D20/IncState!D17 -> 0.13081241 | E13: =IncState!E20/IncState!E17 -> 0.11669932 | F13: =E13 -> 0.11669932 | G13: =F13 -> 0.11669932 | H13: =G13 -> 0.11669932 | I13: =H13 -> 0.11669932 | J13: =I13 -> 0.11669932 | K13: =J13 -> 0.11669932 | L13: =K13 -> 0.11669932 | M13: =L13 -> 0.11669932
B14: Amortization $ Amt | C14: 0 | D14: 0 | E14: 0 | F14: =E14 -> 0 | G14: =F14 -> 0 | H14: =G14 -> 0 | I14: =H14 -> 0 | J14: =I14 -> 0 | K14: =J14 -> 0 | L14: =K14 -> 0 | M14: =L14 -> 0
B15: Non recurring income / (expense) | C15: 0 | D15: 0 | E15: 0 | F15: 0 | G15: 0 | H15: 0 | I15: 0 | J15: 0 | K15: 0 | L15: 0 | M15: 0
B16: Other Income / (expense) | C16: 0 | D16: 0 | E16: 0 | F16: 0 | G16: 0 | H16: 0 | I16: 0 | J16: 0 | K16: 0 | L16: 0 | M16: 0
B17: Effective tax rate | C17: =IncState!C35/IncState!C33 -> 0.18978625 | D17: =IncState!D35/IncState!D33 -> 0.18147829 | E17: =IncState!E35/IncState!E33 -> 0.17629644 | F17: =E17 -> 0.17629644 | G17: =F17 -> 0.17629644 | H17: =G17 -> 0.17629644 | I17: =H17 -> 0.17629644 | J17: =I17 -> 0.17629644 | K17: =J17 -> 0.17629644 | L17: =K17 -> 0.17629644 | M17: =L17 -> 0.17629644
B18: Dividend per share (annual) | C18: =IncState!C38 -> 2.6591459 | D18: =IncState!D38 -> 2.9297537 | E18: =IncState!E38 -> 3.2398762 | F18: 3.32 | G18: =F18 -> 3.32 | H18: =G18 -> 3.32 | I18: =H18 -> 3.32 | J18: =I18 -> 3.32 | K18: =J18 -> 3.32 | L18: =K18 -> 3.32 | M18: =L18 -> 3.32
B19: Basic WASO | C19: =IncState!C41 -> 7446 | D19: =IncState!D41 -> 7431 | E19: =IncState!E41 -> 7433 | F19: =E19 -> 7433 | G19: =F19 -> 7433 | H19: =G19 -> 7433 | I19: =H19 -> 7433 | J19: =I19 -> 7433 | K19: =J19 -> 7433 | L19: =K19 -> 7433 | M19: =L19 -> 7433
B20: Diluted WASO | C20: =IncState!C42 -> 7472 | D20: =IncState!D42 -> 7469 | E20: =IncState!E42 -> 7465 | F20: =E20 -> 7465 | G20: =F20 -> 7465 | H20: =G20 -> 7465 | I20: =H20 -> 7465 | J20: =I20 -> 7465 | K20: =J20 -> 7465 | L20: =K20 -> 7465 | M20: =L20 -> 7465
A22: * | B22: Debt | C22: =C2 -> 2023 | D22: =D2 -> 2024 | E22: =E2 -> 2025 | F22: =F2 -> 2026 | G22: =G2 -> 2027 | H22: =H2 -> 2028 | I22: =I2 -> 2029 | J22: =J2 -> 2030 | ... M22: =M2 -> 2033
B24: Interest rate on Revolver | E24: 0.0346 | F24: =E24 -> 0.0346 | G24: =F24 -> 0.0346 | H24: =G24 -> 0.0346 | I24: =H24 -> 0.0346 | J24: =I24 -> 0.0346 | K24: =J24 -> 0.0346 | L24: =K24 -> 0.0346 | M24: =L24 -> 0.0346
B25: Interest rate on long-term debt | E25: 0.0346 | F25: =E25 -> 0.0346 | G25: =F25 -> 0.0346 | H25: =G25 -> 0.0346 | I25: =H25 -> 0.0346 | J25: =I25 -> 0.0346 | K25: =J25 -> 0.0346 | L25: =K25 -> 0.0346 | M25: =L25 -> 0.0346
B26: Interest rate on cash | E26: 0.04 | F26: =E26 -> 0.04 | G26: =F26 -> 0.04 | H26: =G26 -> 0.04 | I26: =H26 -> 0.04 | J26: =I26 -> 0.04 | K26: =J26 -> 0.04 | L26: =K26 -> 0.04 | M26: =L26 -> 0.04
B28: Issuance of long-term debt | F28: 0 | G28: 0 | H28: 0 | I28: 0 | J28: 0 | K28: 0 | L28: 0 | M28: 0
B29: Repayment of long-term debt | F29: =BalSheet!E32 -> 0 | G29: =F29 -> 0 | H29: =G29 -> 0 | I29: =H29 -> 0 | J29: =I29 -> 0 | K29: =J29 -> 0 | L29: =K29 -> 0 | M29: =L29 -> 0
A31: * | B31: Calcs | C31: 2023 | D31: 2024 | E31: 2025 | F31: 2026 | G31: 2027 | H31: 2028 | I31: 2029 | J31: 2030 | K31: 2031 | L31: 2032 | M31: 2033
B33: CapEx % of Sales | C33: =28107/IncState!C17 -> 0.13263337 | D33: =44477/IncState!D17 -> 0.18144842 | E33: =64551/IncState!E17 -> 0.22912851 | F33: 0.24 | G33: =F33-0.015 -> 0.225 | H33: =G33-0.015 -> 0.21 | I33: =H33-0.015 -> 0.195 | J33: =I33-0.015 -> 0.18 | K33: =J33-0.015 -> 0.165 | L33: =K33-0.015 -> 0.15 | M33: =L33-0.015 -> 0.135
B34: Depreciation % of beginning PP&E | D34: =IncState!D23/BalSheet!C24 -> 0.20263304 | E34: =IncState!E23/BalSheet!D24 -> 0.22098064 | F34: =E34 -> 0.22098064 | G34: =F34 -> 0.22098064 | H34: =G34 -> 0.22098064 | I34: =H34 -> 0.22098064 | J34: =I34 -> 0.22098064 | K34: =J34 -> 0.22098064 | L34: =K34 -> 0.22098064 | M34: =L34 -> 0.22098064
B35: Share issuance / (repurchases) | F35: -16000 | G35: -16000 | H35: -16000 | I35: =-60000-SUM(F35:H35) -> -12000 | J35: 0 | K35: 0 | L35: 0 | M35: 0
A37: * | B37: Shareholder information | C37: 2023 | D37: 2024 | E37: 2025 | F37: 2026 | G37: 2027 | H37: 2028 | I37: 2029 | J37: 2030 | K37: 2031 | L37: 2032 | M37: 2033
B39: Diviend Per Share | F39: =E39 -> 0 | G39: =F39 -> 0 | H39: =G39 -> 0 | I39: =H39 -> 0 | J39: =I39 -> 0 | K39: =J39 -> 0 | L39: =K39 -> 0 | M39: =L39 -> 0
B40: Basic WASO | C40: =C19 -> 7446 | D40: =D19 -> 7431 | E40: =E19 -> 7433 | F40: =F19 -> 7433 | G40: =G19 -> 7433 | H40: =H19 -> 7433 | I40: =I19 -> 7433 | J40: =J19 -> 7433 | ... M40: =M19 -> 7433
B41: Diluted WASO | C41: =C20 -> 7472 | D41: =D20 -> 7469 | E41: =E20 -> 7465 | F41: =F20 -> 7465 | G41: =G20 -> 7465 | H41: =H20 -> 7465 | I41: =I20 -> 7465 | J41: =J20 -> 7465 | ... M41: =M20 -> 7465
A43: * | B43: Balance Sheet - Assets | C43: 2023 | D43: 2024 | E43: 2025 | F43: 2026 | G43: 2027 | H43: 2028 | I43: 2029 | J43: 2030 | K43: 2031 | L43: 2032 | M43: 2033
B45: Operating Cash % of sales | C45: =BalSheet!C17/IncState!C17 -> 0.25 | D45: =BalSheet!D17/IncState!D17 -> 0.25 | E45: =BalSheet!E17/IncState!E17 -> 0.25 | F45: =E45 -> 0.25 | G45: =F45 -> 0.25 | H45: =G45 -> 0.25 | I45: =H45 -> 0.25 | J45: =I45 -> 0.25 | K45: =J45 -> 0.25 | L45: =K45 -> 0.25 | M45: =L45 -> 0.25
B46: Accounts receivable % of sales | C46: =BalSheet!C19/IncState!C17 -> 0.2297525 | D46: =BalSheet!D19/IncState!D17 -> 0.23222722 | E46: =BalSheet!E19/IncState!E17 -> 0.24813292 | F46: =E46 -> 0.24813292 | G46: =F46 -> 0.24813292 | H46: =G46 -> 0.24813292 | I46: =H46 -> 0.24813292 | J46: =I46 -> 0.24813292 | K46: =J46 -> 0.24813292 | L46: =K46 -> 0.24813292 | M46: =L46 -> 0.24813292
B47: Inventories % of COGS | C47: =BalSheet!C20/IncState!C18 -> 0.037957579 | D47: =BalSheet!D20/IncState!D18 -> 0.016811938 | E47: =BalSheet!E20/IncState!E18 -> 0.010679601 | F47: =E47 -> 0.010679601 | G47: =F47 -> 0.010679601 | H47: =G47 -> 0.010679601 | I47: =H47 -> 0.010679601 | J47: =I47 -> 0.010679601 | K47: =J47 -> 0.010679601 | L47: =K47 -> 0.010679601 | M47: =L47 -> 0.010679601
B48: Other current assets % of sales | C48: =BalSheet!C21/IncState!C17 -> 0.10290447 | D48: =BalSheet!D21/IncState!D17 -> 0.1061553 | E48: =BalSheet!E21/IncState!E17 -> 0.091305675 | F48: =E48 -> 0.091305675 | G48: =F48 -> 0.091305675 | H48: =G48 -> 0.091305675 | I48: =H48 -> 0.091305675 | J48: =I48 -> 0.091305675 | K48: =J48 -> 0.091305675 | L48: =K48 -> 0.091305675 | M48: =L48 -> 0.091305675
B50: Investments in unconsolidated entities | C50: =BalSheet!C26 -> 9879 | D50: =BalSheet!D26 -> 14600 | E50: =BalSheet!E26 -> 15405 | F50: =E50 -> 15405 | G50: =F50 -> 15405 | H50: =G50 -> 15405 | I50: =H50 -> 15405 | J50: =I50 -> 15405 | K50: =J50 -> 15405 | L50: =K50 -> 15405 | M50: =L50 -> 15405
B51: Other long-term assets % of sales | C51: =BalSheet!C27/IncState!C17 -> 0.14440224 | D51: =BalSheet!D27/IncState!D17 -> 0.14874226 | E51: =BalSheet!E27/IncState!E17 -> 0.14398844 | F51: =E51 -> 0.14398844 | G51: =F51 -> 0.14398844 | H51: =G51 -> 0.14398844 | I51: =H51 -> 0.14398844 | J51: =I51 -> 0.14398844 | K51: =J51 -> 0.14398844 | L51: =K51 -> 0.14398844 | M51: =L51 -> 0.14398844
A53: * | B53: Balance Sheet - Liabilities | C53: 2023 | D53: 2024 | E53: 2025 | F53: 2026 | G53: 2027 | H53: 2028 | I53: 2029 | J53: 2030 | K53: 2031 | L53: 2032 | M53: 2033
...

Sheet Revenue
A1: =CoName -> Microsoft Corp.
A2: * | B2: Revenues (Individual Businesses) | C2: 2022 | D2: 2023 | E2: 2024 | F2: 2025 | G2: 2026E | H2: 2027E | I2: 2028E | J2: 2029E | K2: 2030E | L2: 2031E | M2: 2032E | N2: 2033E
B3: Server products and cloud services | C3: 67350 | D3: 65007 | E3: 79828 | F3: 98435 | G3: =F3*(1+G4) -> 123043.75 | H3: =G3*(1+H4) -> 156265.56 | I3: =H3*(1+I4) -> 194550.63 | J3: =I3*(1+J4) -> 237351.76 | K3: =J3*(1+K4) -> 283635.36 | L3: =K3*(1+L4) -> 331853.37 | M3: =L3*(1+M4) -> 379972.11 | N3: =M3*(1+N4) -> 425568.76
B4: y/y | D4: =D3/C3-1 -> -0.034788419 | E4: =E3/D3-1 -> 0.22799083 | F4: =F3/E3-1 -> 0.23308864 | G4: 0.25 | H4: 0.27 | I4: =H4-0.025 -> 0.245 | J4: =I4-0.025 -> 0.22 | K4: =J4-0.025 -> 0.195 | L4: =K4-0.025 -> 0.17 | M4: =L4-0.025 -> 0.145 | N4: =M4-0.025 -> 0.12
B5: Microsoft 365 Commerical products and cloud services | C5: 44970 | D5: 66949 | E5: 76969 | F5: 87767 | G5: =F5*(1+G6) -> 100079.85 | H5: =G5*(1+H6) -> 114120.08 | I5: =H5*(1+I6) -> 130130.02 | J5: =I5*(1+J6) -> 148385.99 | K5: =J5*(1+K6) -> 169203.09 | L5: =K5*(1+L6) -> 192940.64 | M5: =L5*(1+M6) -> 220008.33 | N5: =M5*(1+N6) -> 250873.35
B6: y/y | D6: =D5/C5-1 -> 0.48874805 | E6: =E5/D5-1 -> 0.14966616 | F6: =F5/E5-1 -> 0.14029025 | G6: =F6 -> 0.14029025 | H6: =G6 -> 0.14029025 | I6: =H6 -> 0.14029025 | J6: =I6 -> 0.14029025 | K6: =J6 -> 0.14029025 | L6: =K6 -> 0.14029025 | M6: =L6 -> 0.14029025 | N6: =M6 -> 0.14029025
B7: Gaming | C7: 24732 | D7: 15466 | E7: 21503 | F7: 23455 | G7: =F7*(1+G8) -> 24287.354 | H7: =G7*(1+H8) -> 25149.246 | I7: =H7*(1+I8) -> 26041.724 | J7: =I7*(1+J8) -> 26965.874 | K7: =J7*(1+K8) -> 27922.819 | L7: =K7*(1+L8) -> 28913.724 | M7: =L7*(1+M8) -> 29939.793 | N7: =M7*(1+N8) -> 31002.275
B8: y/y | D8: =D7/C7-1 -> -0.37465632 | E8: =E7/D7-1 -> 0.3903401 | F8: =F7/E7-1 -> 0.090778031 | G8: =AVERAGE(D8:F8) -> 0.035487272 | H8: =G8 -> 0.035487272 | I8: =H8 -> 0.035487272 | J8: =I8 -> 0.035487272 | K8: =J8 -> 0.035487272 | L8: =K8 -> 0.035487272 | M8: =L8 -> 0.035487272 | N8: =M8 -> 0.035487272
B9: LinkedIn | C9: 16230 | D9: 14989 | E9: 16372 | F9: 17812 | G9: =F9*(1+G10) -> 19378.655 | H9: =G9*(1+H10) -> 21083.106 | I9: =H9*(1+I10) -> 22937.471 | J9: =I9*(1+J10) -> 24954.938 | K9: =J9*(1+K10) -> 27149.85 | L9: =K9*(1+L10) -> 29537.817 | M9: =L9*(1+M10) -> 32135.817 | N9: =M9*(1+N10) -> 34962.324
B10: y/y | D10: =D9/C9-1 -> -0.076463339 | E10: =E9/D9-1 -> 0.092267663 | F10: =F9/E9-1 -> 0.087955045 | G10: =F10 -> 0.087955045 | H10: =G10 -> 0.087955045 | I10: =H10 -> 0.087955045 | J10: =I10 -> 0.087955045 | K10: =J10 -> 0.087955045 | L10: =K10 -> 0.087955045 | M10: =L10 -> 0.087955045 | N10: =M10 -> 0.087955045
B11: Windows and Devices | C11: 13631 | D11: 17147 | E11: 17026 | F11: 17314 | G11: =F11*(1+G12) -> 17606.872 | H11: =G11*(1+H12) -> 17904.697 | I11: =H11*(1+I12) -> 18207.561 | J11: =I11*(1+J12) -> 18515.547 | K11: =J11*(1+K12) -> 18828.743 | L11: =K11*(1+L12) -> 19147.237 | M11: =L11*(1+M12) -> 19471.119 | N11: =M11*(1+N12) -> 19800.479
B12: y/y | D12: =D11/C11-1 -> 0.25794146 | E12: =E11/D11-1 -> -0.007056628 | F12: =F11/E11-1 -> 0.016915306 | G12: =F12 -> 0.016915306 | H12: =G12 -> 0.016915306 | I12: =H12 -> 0.016915306 | J12: =I12 -> 0.016915306 | K12: =J12 -> 0.016915306 | L12: =K12 -> 0.016915306 | M12: =L12 -> 0.016915306 | N12: =M12 -> 0.016915306
B13: Search and news advertising | C13: 11526 | D13: 12125 | E13: 12306 | F13: 13878 | G13: =F13*(1+G14) -> 15650.811 | H13: =G13*(1+H14) -> 17650.086 | I13: =H13*(1+I14) -> 19904.753 | J13: =I13*(1+J14) -> 22447.438 | K13: =J13*(1+K14) -> 25314.931 | L13: =K13*(1+L14) -> 28548.725 | M13: =L13*(1+M14) -> 32195.612 | N13: =M13*(1+N14) -> 36308.362
B14: y/y | D14: =D13/C13-1 -> 0.05196946 | E14: =E13/D13-1 -> 0.014927835 | F14: =F13/E13-1 -> 0.12774256 | G14: =F14 -> 0.12774256 | H14: =G14 -> 0.12774256 | I14: =H14 -> 0.12774256 | J14: =I14 -> 0.12774256 | K14: =J14 -> 0.12774256 | L14: =K14 -> 0.12774256 | M14: =L14 -> 0.12774256 | N14: =M14 -> 0.12774256
B15: Dynamic products and cloud services | C15: 7605 | D15: 5796 | E15: 6831 | F15: 7827 | G15: =F15*(1+G16) -> 8052.698 | H15: =G15*(1+H16) -> 8284.9043 | I15: =H15*(1+I16) -> 8523.8064 | J15: =I15*(1+J16) -> 8769.5974 | K15: =J15*(1+K16) -> 9022.476 | L15: =K15*(1+L16) -> 9282.6466 | M15: =L15*(1+M16) -> 9550.3194 | N15: =M15*(1+N16) -> 9825.7108
B16: y/y | D16: =D15/C15-1 -> -0.23786982 | E16: =E15/D15-1 -> 0.17857143 | F16: =F15/E15-1 -> 0.14580588 | G16: =AVERAGE(D16:F16) -> 0.02883583 | H16: =G16 -> 0.02883583 | I16: =H16 -> 0.02883583 | J16: =I16 -> 0.02883583 | K16: =J16 -> 0.02883583 | L16: =K16 -> 0.02883583 | M16: =L16 -> 0.02883583 | N16: =M16 -> 0.02883583
B17: Enterprise and partner services | C17: 4687 | D17: 7900 | E17: 7594 | F17: 7760 | G17: =F17*(1+G18) -> 8148 | H17: =G17*(1+H18) -> 8555.4 | I17: =H17*(1+I18) -> 8983.17 | J17: =I17*(1+J18) -> 9432.3285 | K17: =J17*(1+K18) -> 9903.9449 | L17: =K17*(1+L18) -> 10399.142 | M17: =L17*(1+M18) -> 10919.099 | N17: =M17*(1+N18) -> 11465.054
B18: y/y | D18: =D17/C17-1 -> 0.68551312 | E18: =E17/D17-1 -> -0.038734177 | F18: =F17/E17-1 -> 0.021859363 | G18: 0.05 | H18: =G18 -> 0.05 | I18: =H18 -> 0.05 | J18: =I18 -> 0.05 | K18: =J18 -> 0.05 | L18: =K18 -> 0.05 | M18: =L18 -> 0.05 | N18: =M18 -> 0.05
B19: Microsoft 365 Consumer products and cloud servcies | C19: 7306 | D19: 6417 | E19: 6648 | F19: 7404 | G19: =F19*(1+G20) -> 9255 | H19: =G19*(1+H20) -> 11568.75 | I19: =H19*(1+I20) -> 14460.938 | J19: =I19*(1+J20) -> 18076.172 | K19: =J19*(1+K20) -> 22595.215 | L19: =K19*(1+L20) -> 28244.019 | M19: =L19*(1+M20) -> 35305.023 | N19: =M19*(1+N20) -> 44131.279
B20: y/y | D20: =D19/C19-1 -> -0.12168081 | E20: =E19/D19-1 -> 0.03599813 | F20: =F19/E19-1 -> 0.11371841 | G20: 0.25 | H20: =G20 -> 0.25 | I20: =H20 -> 0.25 | J20: =I20 -> 0.25 | K20: =J20 -> 0.25 | L20: =K20 -> 0.25 | M20: =L20 -> 0.25 | N20: =M20 -> 0.25
B21: Other | C21: 233 | D21: 119 | E21: 45 | F21: 72
A22: * | B22: TOTAL REVENUES | C22: =SUM(C21,C19,C17,C15,C13,C3,C5,C7,C11,C9) -> 198270 | D22: =SUM(D21,D19,D17,D15,D13,D3,D5,D7,D11,D9) -> 211915 | E22: =SUM(E21,E19,E17,E15,E13,E3,E5,E7,E11,E9) -> 245122 | F22: =SUM(F21,F19,F17,F15,F13,F3,F5,F7,F11,F9) -> 281724 | G22: =SUM(G21,G19,G17,G15,G13,G3,G5,G7,G11,G9) -> 325502.99 | H22: =SUM(H21,H19,H17,H15,H13,H3,H5,H7,H11,H9) -> 380581.83 | I22: =SUM(I21,I19,I17,I15,I13,I3,I5,I7,I11,I9) -> 443740.06 | J22: =SUM(J21,J19,J17,J15,J13,J3,J5,J7,J11,J9) -> 514899.64 | ... N22: =SUM(N21,N19,N17,N15,N13,N3,N5,N7,N11,N9) -> 863937.59
B23: y/y | D23: =D22/C22-1 -> 0.068820296 | E23: =E22/D22-1 -> 0.15669962 | F23: =F22/E22-1 -> 0.14932156 | G23: =G22/F22-1 -> 0.15539675 | H23: =H22/G22-1 -> 0.16921147 | I23: =I22/H22-1 -> 0.16595178 | J23: =J22/I22-1 -> 0.16036321 | K23: =K22/J22-1 -> 0.15280023 | ... N23: =N22/M22-1 -> 0.12272998
A25: * | B25: Revenues (Sectors) | C25: 2022 | D25: 2023 | E25: 2024 | F25: 2025 | G25: 2026E | H25: 2027E | I25: 2028E | J25: 2029E | K25: 2030E | L25: 2031E | M25: 2032E | N25: 2033E
B26: Productivity and Business Processes | C26: 63364 | D26: 94151 | E26: 106820 | F26: 120810 | G26: =F26*(1+G27) -> 136632.24 | H26: =G26*(1+H27) -> 154526.69 | I26: =H26*(1+I27) -> 171674.21 | J26: =I26*(1+J27) -> 187291.06 | K26: =J26*(1+K27) -> 200582.73 | L26: =K26*(1+L27) -> 210806.03 | M26: =L26*(1+M27) -> 217334.27 | N26: =M26*(1+N27) -> 219717.99
B27: y/y | D27: =D26/C26-1 -> 0.48587526 | E27: =E26/D26-1 -> 0.13456044 | F27: =F26/E26-1 -> 0.13096798 | G27: =F27 -> 0.13096798 | H27: =G27 -> 0.13096798 | I27: =H27-0.02 -> 0.11096798 | J27: =I27-0.02 -> 0.090967984 | K27: =J27-0.02 -> 0.070967984 | L27: =K27-0.02 -> 0.050967984 | M27: =L27-0.02 -> 0.030967984 | N27: =M27-0.02 -> 0.010967984
B28: Intelligent Cloud | C28: 74965 | D28: 72944 | E28: 87464 | F28: 106265 | G28: =F28*(1+G29) -> 129107.41 | H28: =G28*(1+H29) -> 156859.95 | I28: =H28*(1+I29) -> 187440.9 | J28: =I28*(1+J29) -> 220234.99 | K28: =J28*(1+K29) -> 254361.95 | L28: =K28*(1+L29) -> 288689.88 | M28: =L28*(1+M29) -> 321876.81 | N28: =M28*(1+N29) -> 352441.26
B29: y/y | D29: =D28/C28-1 -> -0.026959248 | E29: =E28/D28-1 -> 0.19905681 | F29: =F28/E28-1 -> 0.21495701 | G29: =F29 -> 0.21495701 | H29: =G29 -> 0.21495701 | I29: =H29-0.02 -> 0.19495701 | J29: =I29-0.02 -> 0.17495701 | K29: =J29-0.02 -> 0.15495701 | L29: =K29-0.02 -> 0.13495701 | M29: =L29-0.02 -> 0.11495701 | N29: =M29-0.02 -> 0.094957011
B30: More Personal Computing | C30: 59941 | D30: 44820 | E30: 50838 | F30: 54649 | G30: =F30+14000 -> 68649 | H30: =G30*(1+H31) -> 73795.177 | I30: =H30*(1+I31) -> 79327.13 | J30: =I30*(1+J31) -> 85273.778 | K30: =J30*(1+K31) -> 91666.208 | L30: =K30*(1+L31) -> 98537.838 | M30: =L30*(1+M31) -> 105924.59 | N30: =M30*(1+N31) -> 113865.08
B31: y/y | D31: =D30/C30-1 -> -0.25226473 | E31: =E30/D30-1 -> 0.13427041 | F31: =F30/E30-1 -> 0.07496361 | G31: =F31 -> 0.07496361 | H31: =G31 -> 0.07496361 | I31: =H31 -> 0.07496361 | J31: =I31 -> 0.07496361 | K31: =J31 -> 0.07496361 | L31: =K31 -> 0.07496361 | M31: =L31 -> 0.07496361 | N31: =M31 -> 0.07496361
A32: * | B32: TOTAL REVENUES | C32: =SUM(C30,C28,C26) -> 198270 | D32: =SUM(D30,D28,D26) -> 211915 | E32: =SUM(E30,E28,E26) -> 245122 | F32: =SUM(F30,F28,F26) -> 281724 | G32: =SUM(G30,G28,G26) -> 334388.65 | H32: =SUM(H30,H28,H26) -> 385181.82 | I32: =SUM(I30,I28,I26) -> 438442.23 | J32: =SUM(J30,J28,J26) -> 492799.84 | ... N32: =SUM(N30,N28,N26) -> 686024.33
B33: y/y | D33: =D32/C32-1 -> 0.068820296 | E33: =E32/D32-1 -> 0.15669962 | F33: =F32/E32-1 -> 0.14932156 | G33: =G32/F32-1 -> 0.18693703 | H33: =H32/G32-1 -> 0.1518986 | I33: =I32/H32-1 -> 0.13827344 | J33: =J32/I32-1 -> 0.12397894 | K33: =K32/J32-1 -> 0.10919455 | ... N33: =N32/M32-1 -> 0.063379952
A34: * | B34: EBIT Margins (Sectors) | C34: 2022 | D34: 2023 | E34: 2024 | F34: 2025 | G34: 2026E | H34: 2027E | I34: 2028E | J34: 2029E | K34: 2030E | L34: 2031E | M34: 2032E | N34: 2033E
B35: Productivity and Business Processes | C35: =29690/C26 -> 0.46856259 | D35: =34189/D26 -> 0.36312944 | E35: =40540/E26 -> 0.37951694 | F35: =69773/F26 -> 0.57754325 | G35: =F35 -> 0.57754325 | H35: =G35 -> 0.57754325 | I35: =H35 -> 0.57754325 | J35: =I35 -> 0.57754325 | K35: =J35 -> 0.57754325 | L35: =K35 -> 0.57754325 | M35: =L35 -> 0.57754325 | N35: =M35 -> 0.57754325
B36: Intelligent Cloud | C36: =33203/C28 -> 0.44291336 | D36: =37884/D28 -> 0.51935732 | E36: =49584/E28 -> 0.56690753 | F36: =44589/F28 -> 0.41960194 | G36: =F36 -> 0.41960194 | H36: =G36 -> 0.41960194 | I36: =H36 -> 0.41960194 | J36: =I36 -> 0.41960194 | K36: =J36 -> 0.41960194 | L36: =K36 -> 0.41960194 | M36: =L36 -> 0.41960194 | N36: =M36 -> 0.41960194
B37: More Personal Computing | C37: =20490/C30 -> 0.34183614 | D37: =16450/D30 -> 0.36702365 | E37: =19309/E30 -> 0.37981431 | F37: =14166/F30 -> 0.25921792 | G37: =F37 -> 0.25921792 | H37: =G37 -> 0.25921792 | I37: =H37 -> 0.25921792 | J37: =I37 -> 0.25921792 | K37: =J37 -> 0.25921792 | L37: =K37 -> 0.25921792 | M37: =L37 -> 0.25921792 | N37: =M37 -> 0.25921792
B38: TOTAL EBIT MARGIN | C38: =83383/C32 -> 0.42055278 | D38: =88523/D32 -> 0.41772881 | E38: =109433/E32 -> 0.446443 | F38: =128528/F32 -> 0.45621956 | G38: =F38 -> 0.45621956 | H38: =G38 -> 0.45621956 | I38: =H38 -> 0.45621956 | J38: =I38 -> 0.45621956 | K38: =J38 -> 0.45621956 | L38: =K38 -> 0.45621956 | M38: =L38 -> 0.45621956 | N38: =M38 -> 0.45621956
A39: * | B39: TOTAL EBIT | C39: =C32*C38 -> 83383 | D39: =D32*D38 -> 88523 | E39: =E32*E38 -> 109433 | F39: =F32*F38 -> 128528 | G39: =G32*G38 -> 152554.64 | H39: =H32*H38 -> 175727.48 | I39: =I32*I38 -> 200025.92 | J39: =J32*J38 -> 224824.93 | ... N39: =N32*N38 -> 312977.72
B40: y/y | D40: =D39/C39-1 -> 0.061643261 | E40: =E39/D39-1 -> 0.2362098 | F40: =F39/E39-1 -> 0.17449033 | G40: =G39/F39-1 -> 0.18693703 | H40: =H39/G39-1 -> 0.1518986 | I40: =I39/H39-1 -> 0.13827344 | J40: =J39/I39-1 -> 0.12397894 | K40: =K39/J39-1 -> 0.10919455 | ... N40: =N39/M39-1 -> 0.063379952

Sheet Calcs
A1: =CoName -> Microsoft Corp. | C1: Hist. | D1: Hist. | E1: Hist. | F1: Proj. | G1: Proj. | H1: Proj. | I1: Proj. | J1: Proj. | K1: Proj. | L1: Proj. | M1: Proj.
A2: Net PP&E | C2: 2023 | D2: =C2+1 -> 2024 | E2: =D2+1 -> 2025 | F2: =E2+1 -> 2026 | G2: =F2+1 -> 2027 | H2: =G2+1 -> 2028 | I2: =H2+1 -> 2029 | J2: =I2+1 -> 2030 | K2: =J2+1 -> 2031 | ... M2: =L2+1 -> 2033
B3: Capital expenditure % of sales | F3: =Assumptions!F33 -> 0.24 | G3: =Assumptions!G33 -> 0.225 | H3: =Assumptions!H33 -> 0.21 | I3: =Assumptions!I33 -> 0.195 | J3: =Assumptions!J33 -> 0.18 | K3: =Assumptions!K33 -> 0.165 | L3: =Assumptions!L33 -> 0.15 | M3: =Assumptions!M33 -> 0.135
B4: Depreciation % of PP&E | F4: =Assumptions!F34 -> 0.22098064 | G4: =F4 -> 0.22098064 | H4: =G4 -> 0.22098064 | I4: =H4 -> 0.22098064 | J4: =I4 -> 0.22098064 | K4: =J4 -> 0.22098064 | L4: =K4 -> 0.22098064 | M4: =L4 -> 0.22098064
B6: Beginning PP&E | F6: =E9 -> 229789 | G6: =F9 -> 257130.8 | H6: =G9 -> 285940.78 | I6: =H9 -> 315938.82 | J6: =I9 -> 346527.89 | K6: =J9 -> 376795.69 | L6: =K9 -> 405544.24 | M6: =L9 -> 431351.4
B7: Capex | F7: =F3*IncState!F17 -> 78120.719 | G7: =G3*IncState!G17 -> 85630.912 | H7: =H3*IncState!H17 -> 93185.414 | I7: =I3*IncState!I17 -> 100405.43 | J7: =J3*IncState!J17 -> 106843.76 | K7: =K3*IncState!K17 -> 112013.11 | L7: =L3*IncState!L17 -> 115424.58 | M7: =M3*IncState!M17 -> 116631.58
B8: Depreciation | F8: =F4*F6 -> 50778.92 | G8: =G4*G6 -> 56820.929 | H8: =H4*H6 -> 63187.377 | I8: =I4*I6 -> 69816.363 | J8: =J4*J6 -> 76575.954 | K8: =K4*K6 -> 83264.553 | L8: =L4*L6 -> 89617.427 | M8: =M4*M6 -> 95320.309
B9: Ending PP&E | E9: =BalSheet!E24 -> 229789 | F9: =F6+F7-F8 -> 257130.8 | G9: =G6+G7-G8 -> 285940.78 | H9: =H6+H7-H8 -> 315938.82 | I9: =I6+I7-I8 -> 346527.89 | J9: =J6+J7-J8 -> 376795.69 | K9: =K6+K7-K8 -> 405544.24 | L9: =L6+L7-L8 -> 431351.4 | M9: =M6+M7-M8 -> 452662.67
A10: Equity | C10: =C2 -> 2023 | D10: =D2 -> 2024 | E10: =E2 -> 2025 | F10: =F2 -> 2026 | G10: =G2 -> 2027 | H10: =H2 -> 2028 | I10: =I2 -> 2029 | J10: =J2 -> 2030 | ... M10: =M2 -> 2033
B11: Share issuance/(repurchases) | F11: =Assumptions!F35 -> -16000 | G11: =Assumptions!G35 -> -16000 | H11: =Assumptions!H35 -> -16000 | I11: =Assumptions!I35 -> -12000 | J11: =Assumptions!J35 -> 0 | K11: =Assumptions!K35 -> 0 | L11: =Assumptions!L35 -> 0 | M11: =Assumptions!M35 -> 0
B13: Beginning balance | F13: =E17 -> 343479 | G13: =F17 -> 425122.11 | H13: =G17 -> 527463.27 | I13: =H17 -> 653538.65 | J13: =I17 -> 810355.06 | K13: =J17 -> 1008737.4 | L13: =K17 -> 1239171.2 | M13: =L17 -> 1503662.7
B14: Net income | F14: =IncState!F36 -> 122320.67 | G14: =IncState!G36 -> 143018.72 | H14: =IncState!H36 -> 166752.94 | I14: =IncState!I36 -> 193493.97 | J14: =IncState!J36 -> 223059.9 | K14: =IncState!K36 -> 255111.33 | L14: =IncState!L36 -> 289169.11 | M14: =IncState!M36 -> 324658.83
B15: Dividends paid | F15: =IncState!F39 -> 24677.56 | G15: =IncState!G39 -> 24677.56 | H15: =IncState!H39 -> 24677.56 | I15: =IncState!I39 -> 24677.56 | J15: =IncState!J39 -> 24677.56 | K15: =IncState!K39 -> 24677.56 | L15: =IncState!L39 -> 24677.56 | M15: =IncState!M39 -> 24677.56
B16: Share issuance / (repurchase) | F16: =F11 -> -16000 | G16: =G11 -> -16000 | H16: =H11 -> -16000 | I16: =I11 -> -12000 | J16: =J11 -> 0 | K16: =K11 -> 0 | L16: =L11 -> 0 | M16: =M11 -> 0
B17: Ending balance | E17: =BalSheet!E41 -> 343479 | F17: =F13+F14-F15+F16 -> 425122.11 | G17: =G13+G14-G15+G16 -> 527463.27 | H17: =H13+H14-H15+H16 -> 653538.65 | I17: =I13+I14-I15+I16 -> 810355.06 | J17: =J13+J14-J15+J16 -> 1008737.4 | K17: =K13+K14-K15+K16 -> 1239171.2 | L17: =L13+L14-L15+L16 -> 1503662.7 | M17: =M13+M14-M15+M16 -> 1803644
A18: OWC | C18: =C10 -> 2023 | D18: =D10 -> 2024 | E18: =E10 -> 2025 | F18: =F10 -> 2026 | G18: =G10 -> 2027 | H18: =H10 -> 2028 | I18: =I10 -> 2029 | J18: =J10 -> 2030 | ... M18: =M10 -> 2033
B19: Operating Cash | E19: =BalSheet!E17 -> 70431 | F19: =BalSheet!F17 -> 81375.749 | G19: =BalSheet!G17 -> 95145.458 | H19: =BalSheet!H17 -> 110935.02 | I19: =BalSheet!I17 -> 128724.91 | J19: =BalSheet!J17 -> 148394.11 | K19: =BalSheet!K17 -> 169716.83 | L19: =BalSheet!L17 -> 192374.3 | M19: =BalSheet!M17 -> 215984.4
B20: =BalSheet!B20 -> Inventories | E20: =BalSheet!E20 -> 938 | F20: =BalSheet!F20 -> 1083.7622 | G20: =BalSheet!G20 -> 1267.1471 | H20: =BalSheet!H20 -> 1477.4325 | I20: =BalSheet!I20 -> 1714.3583 | J20: =BalSheet!J20 -> 1976.3126 | K20: =BalSheet!K20 -> 2260.2886 | L20: =BalSheet!L20 -> 2562.0408 | M20: =BalSheet!M20 -> 2876.48
B21: =BalSheet!B19 -> Accounts receivable | E21: =BalSheet!E19 -> 69905 | F21: =BalSheet!F19 -> 80768.01 | G21: =BalSheet!G19 -> 94434.883 | H21: =BalSheet!H19 -> 110106.52 | I21: =BalSheet!I19 -> 127763.55 | J21: =BalSheet!J19 -> 147285.86 | K21: =BalSheet!K19 -> 168449.33 | L21: =BalSheet!L19 -> 190937.59 | M21: =BalSheet!M19 -> 214371.36
B22: Other current assets | E22: =BalSheet!E21 -> 25723 | F22: =BalSheet!F21 -> 29720.271 | G22: =BalSheet!G21 -> 34749.281 | H22: =BalSheet!H21 -> 40515.986 | I22: =BalSheet!I21 -> 47013.26 | J22: =BalSheet!J21 -> 54196.897 | K22: =BalSheet!K21 -> 61984.439 | L22: =BalSheet!L21 -> 70259.463 | M22: =BalSheet!M21 -> 78882.405
B23: Accounts payables | E23: =BalSheet!E33 -> 27724 | F23: =BalSheet!F33 -> 32032.22 | G23: =BalSheet!G33 -> 37452.438 | H23: =BalSheet!H33 -> 43667.737 | I23: =BalSheet!I33 -> 50670.435 | J23: =BalSheet!J33 -> 58412.89 | K23: =BalSheet!K33 -> 66806.227 | L23: =BalSheet!L33 -> 75724.968 | M23: =BalSheet!M33 -> 85018.691
B24: Other current liabilities | E24: =BalSheet!E34 -> 113494 | F24: =BalSheet!F34 -> 131130.6 | G24: =BalSheet!G34 -> 153319.4 | H24: =BalSheet!H34 -> 178763.03 | I24: =BalSheet!I34 -> 207430.04 | J24: =BalSheet!J34 -> 239125.4 | K24: =BalSheet!K34 -> 273485.28 | L24: =BalSheet!L34 -> 309996.01 | M24: =BalSheet!M34 -> 348041.82
A25: * | B25: OWC | E25: =SUM(E19:E22)-SUM(E23:E24) -> 25779 | F25: =SUM(F19:F22)-SUM(F23:F24) -> 29784.973 | G25: =SUM(G19:G22)-SUM(G23:G24) -> 34824.932 | H25: =SUM(H19:H22)-SUM(H23:H24) -> 40604.191 | I25: =SUM(I19:I22)-SUM(I23:I24) -> 47115.609 | J25: =SUM(J19:J22)-SUM(J23:J24) -> 54314.886 | K25: =SUM(K19:K22)-SUM(K23:K24) -> 62119.381 | L25: =SUM(L19:L22)-SUM(L23:L24) -> 70412.42 | M25: =SUM(M19:M22)-SUM(M23:M24) -> 79054.135
B26: Change in OWC | F26: =E25-F25 -> -4005.9728 | G26: =F25-G25 -> -5039.9589 | H26: =G25-H25 -> -5779.2593 | I26: =H25-I25 -> -6511.4183 | J26: =I25-J25 -> -7199.2761 | K26: =J25-K25 -> -7804.4956 | L26: =K25-L25 -> -8293.0393 | M26: =L25-M25 -> -8641.7148

Sheet Debt
A1: =CoName -> Microsoft Corp. | C1: Hist. | D1: Hist. | E1: Hist. | F1: Proj. | G1: Proj. | H1: Proj. | I1: Proj. | J1: Proj. | K1: Proj. | L1: Proj. | M1: Proj.
A2: Assumptions | C2: 2023 | D2: =C2+1 -> 2024 | E2: =D2+1 -> 2025 | F2: =E2+1 -> 2026 | G2: =F2+1 -> 2027 | H2: =G2+1 -> 2028 | I2: =H2+1 -> 2029 | J2: =I2+1 -> 2030 | K2: =J2+1 -> 2031 | ... M2: =L2+1 -> 2033
B4: Interest rate on revolver | F4: =Assumptions!F24 -> 0.0346 | G4: =Assumptions!G24 -> 0.0346 | H4: =Assumptions!H24 -> 0.0346 | I4: =Assumptions!I24 -> 0.0346 | J4: =Assumptions!J24 -> 0.0346 | K4: =Assumptions!K24 -> 0.0346 | L4: =Assumptions!L24 -> 0.0346 | M4: =Assumptions!M24 -> 0.0346
B5: Interest rate on long-term debt | F5: =Assumptions!F25 -> 0.0346 | G5: =Assumptions!G25 -> 0.0346 | H5: =Assumptions!H25 -> 0.0346 | I5: =Assumptions!I25 -> 0.0346 | J5: =Assumptions!J25 -> 0.0346 | K5: =Assumptions!K25 -> 0.0346 | L5: =Assumptions!L25 -> 0.0346 | M5: =Assumptions!M25 -> 0.0346
B6: Interest rate on cash | F6: =Assumptions!F26 -> 0.04 | G6: =Assumptions!G26 -> 0.04 | H6: =Assumptions!H26 -> 0.04 | I6: =Assumptions!I26 -> 0.04 | J6: =Assumptions!J26 -> 0.04 | K6: =Assumptions!K26 -> 0.04 | L6: =Assumptions!L26 -> 0.04 | M6: =Assumptions!M26 -> 0.04
B8: Issuance of long-term debt | F8: =Assumptions!F28 -> 0 | G8: =Assumptions!G28 -> 0 | H8: =Assumptions!H28 -> 0 | I8: =Assumptions!I28 -> 0 | J8: =Assumptions!J28 -> 0 | K8: =Assumptions!K28 -> 0 | L8: =Assumptions!L28 -> 0 | M8: =Assumptions!M28 -> 0
B9: Repayment of long-term debt | F9: =Assumptions!F29 -> 0 | G9: =Assumptions!G29 -> 0 | H9: =Assumptions!H29 -> 0 | I9: =Assumptions!I29 -> 0 | J9: =Assumptions!J29 -> 0 | K9: =Assumptions!K29 -> 0 | L9: =Assumptions!L29 -> 0 | M9: =Assumptions!M29 -> 0
A11: Revolver | C11: =C2 -> 2023 | D11: =D2 -> 2024 | E11: =E2 -> 2025 | F11: =F2 -> 2026 | G11: =G2 -> 2027 | H11: =H2 -> 2028 | I11: =I2 -> 2029 | J11: =J2 -> 2030 | ... M11: =M2 -> 2033
B12: Balance | F12: NO REVOLVER
B13: Interest rate
B14: Interest expense
A16: Long term debt | C16: 2023 | D16: 2024 | E16: 2025 | F16: 2026 | G16: 2027 | H16: 2028 | I16: 2029 | J16: 2030 | K16: 2031 | L16: 2032 | M16: 2033
B17: Beginning balance | F17: =E20 -> 40152 | G17: =F20 -> 40152 | H17: =G20 -> 40152 | I17: =H20 -> 40152 | J17: =I20 -> 40152 | K17: =J20 -> 40152 | L17: =K20 -> 40152 | M17: =L20 -> 40152
B18: Issuance | F18: =F8 -> 0 | G18: =G8 -> 0 | H18: =H8 -> 0 | I18: =I8 -> 0 | J18: =J8 -> 0 | K18: =K8 -> 0 | L18: =L8 -> 0 | M18: =M8 -> 0
B19: Repayment | F19: =F9 -> 0 | G19: =G9 -> 0 | H19: =H9 -> 0 | I19: =I9 -> 0 | J19: =J9 -> 0 | K19: =K9 -> 0 | L19: =L9 -> 0 | M19: =M9 -> 0
B20: Ending balance | E20: =BalSheet!E37 -> 40152 | F20: =F17+F18-F19 -> 40152 | G20: =G17+G18-G19 -> 40152 | H20: =H17+H18-H19 -> 40152 | I20: =I17+I18-I19 -> 40152 | J20: =J17+J18-J19 -> 40152 | K20: =K17+K18-K19 -> 40152 | L20: =L17+L18-L19 -> 40152 | M20: =M17+M18-M19 -> 40152
B21: Interest rate | F21: =F5 -> 0.0346 | G21: =G5 -> 0.0346 | H21: =H5 -> 0.0346 | I21: =I5 -> 0.0346 | J21: =J5 -> 0.0346 | K21: =K5 -> 0.0346 | L21: =L5 -> 0.0346 | M21: =M5 -> 0.0346
B22: Interest expense | F22: =F20*F21 -> 1389.2592 | G22: =G20*G21 -> 1389.2592 | H22: =H20*H21 -> 1389.2592 | I22: =I20*I21 -> 1389.2592 | J22: =J20*J21 -> 1389.2592 | K22: =K20*K21 -> 1389.2592 | L22: =L20*L21 -> 1389.2592 | M22: =M20*M21 -> 1389.2592
A24: Debt summary | C24: 2023 | D24: 2024 | E24: 2025 | F24: 2026 | G24: 2027 | H24: 2028 | I24: 2029 | J24: 2030 | K24: 2031 | L24: 2032 | M24: 2033
B25: Revolver | F25: NO REVOLVER | G25: NO REVOLVER | H25: NO REVOLVER | I25: NO REVOLVER | J25: NO REVOLVER | K25: NO REVOLVER | L25: NO REVOLVER | M25: NO REVOLVER
B26: Total long term debt | F26: =F20 -> 40152 | G26: =G20 -> 40152 | H26: =H20 -> 40152 | I26: =I20 -> 40152 | J26: =J20 -> 40152 | K26: =K20 -> 40152 | L26: =L20 -> 40152 | M26: =M20 -> 40152
B27: Total debt | F27: =SUM(F26) -> 40152 | G27: =SUM(G26) -> 40152 | H27: =SUM(H26) -> 40152 | I27: =SUM(I26) -> 40152 | J27: =SUM(J26) -> 40152 | K27: =SUM(K26) -> 40152 | L27: =SUM(L26) -> 40152 | M27: =SUM(M26) -> 40152
B28: Total interest expense | F28: =F22 -> 1389.2592 | G28: =G22 -> 1389.2592 | H28: =H22 -> 1389.2592 | I28: =I22 -> 1389.2592 | J28: =J22 -> 1389.2592 | K28: =K22 -> 1389.2592 | L28: =L22 -> 1389.2592 | M28: =M22 -> 1389.2592
A30: Interest income | C30: 2023 | D30: 2024 | E30: 2025 | F30: 2026 | G30: 2027 | H30: 2028 | I30: 2029 | J30: 2030 | K30: 2031 | L30: 2032 | M30: 2033
B31: Excess Cash | F31: =BalSheet!F18 -> 82756.891 | G31: =BalSheet!G18 -> 161725.1 | H31: =BalSheet!H18 -> 264037.02 | I31: =BalSheet!I18 -> 397288.79 | J31: =BalSheet!J18 -> 573169.79 | K31: =BalSheet!K18 -> 783274.38 | L31: =BalSheet!L18 -> 1030905.2 | M31: =BalSheet!M18 -> 1318897.7
B32: Interest rate | F32: =F6 -> 0.04 | G32: =G6 -> 0.04 | H32: =H6 -> 0.04 | I32: =I6 -> 0.04 | J32: =J6 -> 0.04 | K32: =K6 -> 0.04 | L32: =L6 -> 0.04 | M32: =M6 -> 0.04
B33: Interest income | F33: =F31*F32 -> 3310.2756 | G33: =G31*G32 -> 6469.0041 | H33: =H31*H32 -> 10561.481 | I33: =I31*I32 -> 15891.551 | J33: =J31*J32 -> 22926.792 | K33: =K31*K32 -> 31330.975 | L33: =L31*L32 -> 41236.207 | M33: =M31*M32 -> 52755.909

Sheet IncState
A1: =CoName -> Microsoft Corp. | C1: Hist. | D1: Hist. | E1: Hist. | F1: Proj. | G1: Proj. | H1: Proj. | I1: Proj. | J1: Proj. | K1: Proj. | L1: Proj. | M1: Proj.
A2: Assumptions | C2: 2023 | D2: =C2+1 -> 2024 | E2: =D2+1 -> 2025 | F2: =E2+1 -> 2026 | G2: =F2+1 -> 2027 | H2: =G2+1 -> 2028 | I2: =H2+1 -> 2029 | J2: =I2+1 -> 2030 | K2: =J2+1 -> 2031 | ... M2: =L2+1 -> 2033
B4: Revenue growth | F4: =Assumptions!F10 -> 0.15539675 | G4: =Assumptions!G10 -> 0.16921147 | H4: =Assumptions!H10 -> 0.16595178 | I4: =Assumptions!I10 -> 0.16036321 | J4: =Assumptions!J10 -> 0.15280023 | K4: =Assumptions!K10 -> 0.14368981 | L4: =Assumptions!L10 -> 0.13350164 | M4: =Assumptions!M10 -> 0.12272998
B5: Cost of goods sold as % of sales | F5: =Assumptions!F11 -> 0.31176258 | G5: =Assumptions!G11 -> 0.31176258 | H5: =Assumptions!H11 -> 0.31176258 | I5: =Assumptions!I11 -> 0.31176258 | J5: =Assumptions!J11 -> 0.31176258 | K5: =Assumptions!K11 -> 0.31176258 | L5: =Assumptions!L11 -> 0.31176258 | M5: =Assumptions!M11 -> 0.31176258
B6: R&D % of sales | F6: =Assumptions!F12 -> 0.11531854 | G6: =Assumptions!G12 -> 0.11531854 | H6: =Assumptions!H12 -> 0.11531854 | I6: =Assumptions!I12 -> 0.11531854 | J6: =Assumptions!J12 -> 0.11531854 | K6: =Assumptions!K12 -> 0.11531854 | L6: =Assumptions!L12 -> 0.11531854 | M6: =Assumptions!M12 -> 0.11531854
B7: SG&A % of sales | F7: =Assumptions!F13 -> 0.11669932 | G7: =Assumptions!G13 -> 0.11669932 | H7: =Assumptions!H13 -> 0.11669932 | I7: =Assumptions!I13 -> 0.11669932 | J7: =Assumptions!J13 -> 0.11669932 | K7: =Assumptions!K13 -> 0.11669932 | L7: =Assumptions!L13 -> 0.11669932 | M7: =Assumptions!M13 -> 0.11669932
B8: Amortization amount | F8: =Assumptions!F14 -> 0 | G8: =Assumptions!G14 -> 0 | H8: =Assumptions!H14 -> 0 | I8: =Assumptions!I14 -> 0 | J8: =Assumptions!J14 -> 0 | K8: =Assumptions!K14 -> 0 | L8: =Assumptions!L14 -> 0 | M8: =Assumptions!M14 -> 0
B9: Non recurring items, amount | F9: =Assumptions!F15 -> 0 | G9: =Assumptions!G15 -> 0 | H9: =Assumptions!H15 -> 0 | I9: =Assumptions!I15 -> 0 | J9: =Assumptions!J15 -> 0 | K9: =Assumptions!K15 -> 0 | L9: =Assumptions!L15 -> 0 | M9: =Assumptions!M15 -> 0
B10: Other income (expense), amt | F10: =Assumptions!F16 -> 0 | G10: =Assumptions!G16 -> 0 | H10: =Assumptions!H16 -> 0 | I10: =Assumptions!I16 -> 0 | J10: =Assumptions!J16 -> 0 | K10: =Assumptions!K16 -> 0 | L10: =Assumptions!L16 -> 0 | M10: =Assumptions!M16 -> 0
B11: Effective tax rate | F11: =Assumptions!F17 -> 0.17629644 | G11: =Assumptions!G17 -> 0.17629644 | H11: =Assumptions!H17 -> 0.17629644 | I11: =Assumptions!I17 -> 0.17629644 | J11: =Assumptions!J17 -> 0.17629644 | K11: =Assumptions!K17 -> 0.17629644 | L11: =Assumptions!L17 -> 0.17629644 | M11: =Assumptions!M17 -> 0.17629644
B12: Dividend Per Share | F12: =Assumptions!F18 -> 3.32 | G12: =Assumptions!G18 -> 3.32 | H12: =Assumptions!H18 -> 3.32 | I12: =Assumptions!I18 -> 3.32 | J12: =Assumptions!J18 -> 3.32 | K12: =Assumptions!K18 -> 3.32 | L12: =Assumptions!L18 -> 3.32 | M12: =Assumptions!M18 -> 3.32
B13: Basic WASO | F13: =Assumptions!F19 -> 7433 | G13: =Assumptions!G19 -> 7433 | H13: =Assumptions!H19 -> 7433 | I13: =Assumptions!I19 -> 7433 | J13: =Assumptions!J19 -> 7433 | K13: =Assumptions!K19 -> 7433 | L13: =Assumptions!L19 -> 7433 | M13: =Assumptions!M19 -> 7433
B14: Diluted WASO | F14: =Assumptions!F20 -> 7465 | G14: =Assumptions!G20 -> 7465 | H14: =Assumptions!H20 -> 7465 | I14: =Assumptions!I20 -> 7465 | J14: =Assumptions!J20 -> 7465 | K14: =Assumptions!K20 -> 7465 | L14: =Assumptions!L20 -> 7465 | M14: =Assumptions!M20 -> 7465
A16: Income statement | C16: =C2 -> 2023 | D16: =D2 -> 2024 | E16: =E2 -> 2025 | F16: =F2 -> 2026 | G16: =G2 -> 2027 | H16: =H2 -> 2028 | I16: =I2 -> 2029 | J16: =J2 -> 2030 | ... M16: =M2 -> 2033
B17: Revenue | C17: 211915 | D17: 245122 | E17: 281724 | F17: =E17*(1+F4) -> 325502.99 | G17: =F17*(1+G4) -> 380581.83 | H17: =G17*(1+H4) -> 443740.06 | I17: =H17*(1+I4) -> 514899.64 | J17: =I17*(1+J4) -> 593576.43 | K17: =J17*(1+K4) -> 678867.32 | L17: =K17*(1+L4) -> 769497.22 | M17: =L17*(1+M4) -> 863937.59
B18: COGS | C18: 65863 | D18: 74114 | E18: 87831 | F18: =F17*F5 -> 101479.65 | G18: =G17*G5 -> 118651.17 | H18: =H17*H5 -> 138341.55 | I18: =I17*I5 -> 160526.44 | J18: =J17*J5 -> 185054.92 | K18: =K17*K5 -> 211645.42 | L18: =L17*L5 -> 239900.43 | M18: =M17*M5 -> 269343.41
B19: R&D | C19: 27195 | D19: 29510 | E19: 32488 | F19: =F17*F6 -> 37536.53 | G19: =G17*G6 -> 43888.141 | H19: =H17*H6 -> 51171.456 | I19: =I17*I6 -> 59377.475 | J19: =J17*J6 -> 68450.367 | K19: =K17*K6 -> 78285.987 | L19: =L17*L6 -> 88737.295 | M19: =M17*M6 -> 99628.021
B20: SG&A | C20: =22759+7575 -> 30334 | D20: =24456+7609 -> 32065 | E20: =25654+7223 -> 32877 | F20: =F17*F7 -> 37985.979 | G20: =G17*G7 -> 44413.642 | H20: =H17*H7 -> 51784.165 | I20: =I17*I7 -> 60088.44 | J20: =J17*J7 -> 69269.967 | K20: =K17*K7 -> 79223.356 | L20: =L17*L7 -> 89799.804 | M20: =M17*M7 -> 100820.93
A21: * | B21: EBIT | C21: =C17-SUM(C18:C20) -> 88523 | D21: =D17-SUM(D18:D20) -> 109433 | E21: =E17-SUM(E18:E20) -> 128528 | F21: =F17-SUM(F18:F20) -> 148500.83 | G21: =G17-SUM(G18:G20) -> 173628.88 | H21: =H17-SUM(H18:H20) -> 202442.9 | I21: =I17-SUM(I18:I20) -> 234907.29 | J21: =J17-SUM(J18:J20) -> 270801.18 | ... M21: =M17-SUM(M18:M20) -> 394145.23
B23: Depreciation | C23: 13861 | D23: 22287 | E23: 34153 | F23: =Calcs!F8 -> 50778.92 | G23: =Calcs!G8 -> 56820.929 | H23: =Calcs!H8 -> 63187.377 | I23: =Calcs!I8 -> 69816.363 | J23: =Calcs!J8 -> 76575.954 | K23: =Calcs!K8 -> 83264.553 | L23: =Calcs!L8 -> 89617.427 | M23: =Calcs!M8 -> 95320.309
B24: Amortization | C24: 0 | D24: 0 | E24: 0 | F24: =F8 -> 0 | G24: =G8 -> 0 | H24: =H8 -> 0 | I24: =I8 -> 0 | J24: =J8 -> 0 | K24: =K8 -> 0 | L24: =L8 -> 0 | M24: =M8 -> 0
A25: * | B25: EBITDA | C25: =C21+C23 -> 102384 | D25: =D21+D23 -> 131720 | E25: =E21+E23 -> 162681 | F25: =F21+F23 -> 199279.75 | G25: =G21+G23 -> 230449.81 | H25: =H21+H23 -> 265630.28 | I25: =I21+I23 -> 304723.65 | J25: =J21+J23 -> 347377.13 | ... M25: =M21+M23 -> 489465.54
B27: Non-recurring items | C27: 0 | D27: 0 | E27: 0 | F27: =F9 -> 0 | G27: =G9 -> 0 | H27: =H9 -> 0 | I27: =I9 -> 0 | J27: =J9 -> 0 | K27: =K9 -> 0 | L27: =L9 -> 0 | M27: =M9 -> 0
B28: Other income (expense) | C28: 788 | D28: -1646 | E28: -4901 | F28: =F10 -> 0 | G28: =G10 -> 0 | H28: =H10 -> 0 | I28: =I10 -> 0 | J28: =J10 -> 0 | K28: =K10 -> 0 | L28: =L10 -> 0 | M28: =M10 -> 0
B30: Interest income | C30: 0 | D30: 0 | E30: 0
B31: Interest expense | C31: 0 | D31: 0 | E31: 0
A33: * | B33: Pretax Income | C33: =C21+SUM(C28:C31) -> 89311 | D33: =D21+SUM(D28:D31) -> 107787 | E33: =E21+SUM(E27:E31) -> 123627 | F33: =F21+SUM(F27:F31) -> 148500.83 | G33: =G21+SUM(G27:G31) -> 173628.88 | H33: =H21+SUM(H27:H31) -> 202442.9 | I33: =I21+SUM(I27:I31) -> 234907.29 | J33: =J21+SUM(J27:J31) -> 270801.18 | K33: =K21+SUM(K27:K31) -> 309712.55 | L33: =L21+SUM(L27:L31) -> 351059.68 | M33: =M21+SUM(M27:M31) -> 394145.23
B35: Tax expense | C35: 16950 | D35: 19561 | E35: 21795 | F35: =F33*F11 -> 26180.168 | G35: =G33*G11 -> 30610.153 | H35: =H33*H11 -> 35689.962 | I35: =I33*I11 -> 41413.319 | J35: =J33*J11 -> 47741.284 | K35: =K33*K11 -> 54601.22 | L35: =L33*L11 -> 61890.572 | M35: =M33*M11 -> 69486.401
A36: * | B36: Net income | C36: =C33-C35 -> 72361 | D36: =D33-D35 -> 88226 | E36: =E33-E35 -> 101832 | F36: =F33-F35 -> 122320.67 | G36: =G33-G35 -> 143018.72 | H36: =H33-H35 -> 166752.94 | I36: =I33-I35 -> 193493.97 | J36: =J33-J35 -> 223059.9 | ... M36: =M33-M35 -> 324658.83
B38: Dividend Per Share | C38: =C39/C41 -> 2.6591459 | D38: =D39/D41 -> 2.9297537 | E38: =E39/E41 -> 3.2398762 | F38: =F12 -> 3.32 | G38: =G12 -> 3.32 | H38: =H12 -> 3.32 | I38: =I12 -> 3.32 | J38: =J12 -> 3.32 | K38: =K12 -> 3.32 | L38: =L12 -> 3.32 | M38: =M12 -> 3.32
B39: Dividends | C39: 19800 | D39: 21771 | E39: 24082 | F39: =F38*F41 -> 24677.56 | G39: =G38*G41 -> 24677.56 | H39: =H38*H41 -> 24677.56 | I39: =I38*I41 -> 24677.56 | J39: =J38*J41 -> 24677.56 | K39: =K38*K41 -> 24677.56 | L39: =L38*L41 -> 24677.56 | M39: =M38*M41 -> 24677.56
A40: Shareholder information | C40: 2023 | D40: 2024 | E40: 2025 | F40: 2026 | G40: 2026 | H40: 2026 | I40: 2026 | J40: 2026 | K40: 2026 | L40: 2026 | M40: 2026
B41: Basic WASO | C41: 7446 | D41: 7431 | E41: 7433 | F41: =F13 -> 7433 | G41: =G13 -> 7433 | H41: =H13 -> 7433 | I41: =I13 -> 7433 | J41: =J13 -> 7433 | K41: =K13 -> 7433 | L41: =L13 -> 7433 | M41: =M13 -> 7433
B42: Diluted WASO | C42: 7472 | D42: 7469 | E42: 7465 | F42: =F14 -> 7465 | G42: =G14 -> 7465 | H42: =H14 -> 7465 | I42: =I14 -> 7465 | J42: =J14 -> 7465 | K42: =K14 -> 7465 | L42: =L14 -> 7465 | M42: =M14 -> 7465
B43: Basic earnings per share | C43: =C36/C41 -> 9.7181037 | D43: =D36/D41 -> 11.872695 | E43: =E36/E41 -> 13.699987 | F43: =F36/F41 -> 16.456433 | G43: =G36/G41 -> 19.24105 | H43: =H36/H41 -> 22.434136 | I43: =I36/I41 -> 26.031746 | J43: =J36/J41 -> 30.009403 | ... M43: =M36/M41 -> 43.678034
A44: * | B44: Diluted earnings per share | C44: =C36/C42 -> 9.684288 | D44: =D36/D42 -> 11.812291 | E44: =E36/E42 -> 13.641259 | F44: =F36/F42 -> 16.38589 | G44: =G36/G42 -> 19.15857 | H44: =H36/H42 -> 22.337969 | I44: =I36/I42 -> 25.920157 | J44: =J36/J42 -> 29.880763 | ... M44: =M36/M42 -> 43.490801

Sheet BalSheet
A1: =CoName -> Microsoft Corp. | C1: Hist. | D1: Hist. | E1: Hist. | F1: Proj. | G1: Proj. | H1: Proj. | I1: Proj. | J1: Proj. | K1: Proj. | L1: Proj. | M1: Proj.
A2: Assumptions | C2: 2023 | D2: =C2+1 -> 2024 | E2: =D2+1 -> 2025 | F2: =E2+1 -> 2026 | G2: =F2+1 -> 2027 | H2: =G2+1 -> 2028 | I2: =H2+1 -> 2029 | J2: =I2+1 -> 2030 | K2: =J2+1 -> 2031 | ... M2: =L2+1 -> 2033
B4: Operating Cash % of sales | F4: =Assumptions!F45 -> 0.25 | G4: =F4 -> 0.25 | H4: =G4 -> 0.25 | I4: =H4 -> 0.25 | J4: =I4 -> 0.25 | K4: =J4 -> 0.25 | L4: =K4 -> 0.25 | M4: =L4 -> 0.25
B5: Accounts receivable % of sales | F5: =Assumptions!F46 -> 0.24813292 | G5: =Assumptions!G46 -> 0.24813292 | H5: =Assumptions!H46 -> 0.24813292 | I5: =Assumptions!I46 -> 0.24813292 | J5: =Assumptions!J46 -> 0.24813292 | K5: =Assumptions!K46 -> 0.24813292 | L5: =Assumptions!L46 -> 0.24813292 | M5: =Assumptions!M46 -> 0.24813292
B6: Inventories % of COGS | F6: =Assumptions!F47 -> 0.010679601 | G6: =Assumptions!G47 -> 0.010679601 | H6: =Assumptions!H47 -> 0.010679601 | I6: =Assumptions!I47 -> 0.010679601 | J6: =Assumptions!J47 -> 0.010679601 | K6: =Assumptions!K47 -> 0.010679601 | L6: =Assumptions!L47 -> 0.010679601 | M6: =Assumptions!M47 -> 0.010679601
B7: Other current assets % of sales | F7: =Assumptions!F48 -> 0.091305675 | G7: =Assumptions!G48 -> 0.091305675 | H7: =Assumptions!H48 -> 0.091305675 | I7: =Assumptions!I48 -> 0.091305675 | J7: =Assumptions!J48 -> 0.091305675 | K7: =Assumptions!K48 -> 0.091305675 | L7: =Assumptions!L48 -> 0.091305675 | M7: =Assumptions!M48 -> 0.091305675
B9: Other long-term assets % of sales | F9: =Assumptions!F51 -> 0.14398844 | G9: =Assumptions!G51 -> 0.14398844 | H9: =Assumptions!H51 -> 0.14398844 | I9: =Assumptions!I51 -> 0.14398844 | J9: =Assumptions!J51 -> 0.14398844 | K9: =Assumptions!K51 -> 0.14398844 | L9: =Assumptions!L51 -> 0.14398844 | M9: =Assumptions!M51 -> 0.14398844
B10: Investment in unconsolidated entities $ balance | F10: =Assumptions!F50 -> 15405 | G10: =Assumptions!G50 -> 15405 | H10: =Assumptions!H50 -> 15405 | I10: =Assumptions!I50 -> 15405 | J10: =Assumptions!J50 -> 15405 | K10: =Assumptions!K50 -> 15405 | L10: =Assumptions!L50 -> 15405 | M10: =Assumptions!M50 -> 15405
B12: Accounts payable/Accural % of COGS | F12: =Assumptions!F55 -> 0.31565165 | G12: =Assumptions!G55 -> 0.31565165 | H12: =Assumptions!H55 -> 0.31565165 | I12: =Assumptions!I55 -> 0.31565165 | J12: =Assumptions!J55 -> 0.31565165 | K12: =Assumptions!K55 -> 0.31565165 | L12: =Assumptions!L55 -> 0.31565165 | M12: =Assumptions!M55 -> 0.31565165
B13: Other current liabilities % of sales | F13: =Assumptions!F56 -> 0.40285528 | G13: =Assumptions!G56 -> 0.40285528 | H13: =Assumptions!H56 -> 0.40285528 | I13: =Assumptions!I56 -> 0.40285528 | J13: =Assumptions!J56 -> 0.40285528 | K13: =Assumptions!K56 -> 0.40285528 | L13: =Assumptions!L56 -> 0.40285528 | M13: =Assumptions!M56 -> 0.40285528
B14: Other long-term liabilities % of sales | F14: =Assumptions!F57 -> 0.33420653 | G14: =Assumptions!G57 -> 0.33420653 | H14: =Assumptions!H57 -> 0.33420653 | I14: =Assumptions!I57 -> 0.33420653 | J14: =Assumptions!J57 -> 0.33420653 | K14: =Assumptions!K57 -> 0.33420653 | L14: =Assumptions!L57 -> 0.33420653 | M14: =Assumptions!M57 -> 0.33420653
A16: Balance sheet | C16: =C2 -> 2023 | D16: =D2 -> 2024 | E16: =E2 -> 2025 | F16: =F2 -> 2026 | G16: =G2 -> 2027 | H16: =H2 -> 2028 | I16: =I2 -> 2029 | J16: =J2 -> 2030 | ... M16: =M2 -> 2033
B17: Operating Cash | C17: =25%*IncState!C17 -> 52978.75 | D17: =25%*IncState!D17 -> 61280.5 | E17: =25%*IncState!E17 -> 70431 | F17: =F4*IncState!F17 -> 81375.749 | G17: =G4*IncState!G17 -> 95145.458 | H17: =H4*IncState!H17 -> 110935.02 | I17: =I4*IncState!I17 -> 128724.91 | J17: =J4*IncState!J17 -> 148394.11 | K17: =K4*IncState!K17 -> 169716.83 | L17: =L4*IncState!L17 -> 192374.3 | M17: =M4*IncState!M17 -> 215984.4
B18: Excess cash | C18: =111262-C17 -> 58283.25 | D18: =75543-D17 -> 14262.5 | E18: =94565-E17 -> 24134 | F18: =MAX(CashFlow!F23,0) -> 82756.891 | G18: =MAX(CashFlow!G23,0) -> 161725.1 | H18: =MAX(CashFlow!H23,0) -> 264037.02 | I18: =MAX(CashFlow!I23,0) -> 397288.79 | J18: =MAX(CashFlow!J23,0) -> 573169.79 | K18: =MAX(CashFlow!K23,0) -> 783274.38 | L18: =MAX(CashFlow!L23,0) -> 1030905.2 | M18: =MAX(CashFlow!M23,0) -> 1318897.7
B19: Accounts receivable | C19: 48688 | D19: 56924 | E19: 69905 | F19: =F5*IncState!F17 -> 80768.01 | G19: =G5*IncState!G17 -> 94434.883 | H19: =H5*IncState!H17 -> 110106.52 | I19: =I5*IncState!I17 -> 127763.55 | J19: =J5*IncState!J17 -> 147285.86 | K19: =K5*IncState!K17 -> 168449.33 | L19: =L5*IncState!L17 -> 190937.59 | M19: =M5*IncState!M17 -> 214371.36
B20: Inventories | C20: 2500 | D20: 1246 | E20: 938 | F20: =F6*IncState!F18 -> 1083.7622 | G20: =G6*IncState!G18 -> 1267.1471 | H20: =H6*IncState!H18 -> 1477.4325 | I20: =I6*IncState!I18 -> 1714.3583 | J20: =J6*IncState!J18 -> 1976.3126 | K20: =K6*IncState!K18 -> 2260.2886 | L20: =L6*IncState!L18 -> 2562.0408 | M20: =M6*IncState!M18 -> 2876.48
B21: Other current assets | C21: 21807 | D21: 26021 | E21: 25723 | F21: =F7*IncState!F17 -> 29720.271 | G21: =G7*IncState!G17 -> 34749.281 | H21: =H7*IncState!H17 -> 40515.986 | I21: =I7*IncState!I17 -> 47013.26 | J21: =J7*IncState!J17 -> 54196.897 | K21: =K7*IncState!K17 -> 61984.439 | L21: =L7*IncState!L17 -> 70259.463 | M21: =M7*IncState!M17 -> 78882.405
B22: Total current assets | C22: =SUM(C17:C21) -> 184257 | D22: =SUM(D17:D21) -> 159734 | E22: =SUM(E17:E21) -> 191131 | F22: =SUM(F17:F21) -> 275704.68 | G22: =SUM(G17:G21) -> 387321.87 | H22: =SUM(H17:H21) -> 527071.98 | I22: =SUM(I17:I21) -> 702504.87 | J22: =SUM(J17:J21) -> 925022.96 | ... M22: =SUM(M17:M21) -> 1831012.4
B24: Property, plant & equipment, net | C24: =95641+14346 -> 109987 | D24: =135591+18961 -> 154552 | E24: =204966+24823 -> 229789 | F24: =Calcs!F9 -> 257130.8 | G24: =Calcs!G9 -> 285940.78 | H24: =Calcs!H9 -> 315938.82 | I24: =Calcs!I9 -> 346527.89 | J24: =Calcs!J9 -> 376795.69 | K24: =Calcs!K9 -> 405544.24 | L24: =Calcs!L9 -> 431351.4 | M24: =Calcs!M9 -> 452662.67
B25: Intangible assets | C25: =67886+9366 -> 77252 | D25: =27597+119220 -> 146817 | E25: =22604+119509 -> 142113 | F25: =E25-IncState!F8 -> 142113 | G25: =F25-IncState!G8 -> 142113 | H25: =G25-IncState!H8 -> 142113 | I25: =H25-IncState!I8 -> 142113 | J25: =I25-IncState!J8 -> 142113 | K25: =J25-IncState!K8 -> 142113 | L25: =K25-IncState!L8 -> 142113 | M25: =L25-IncState!M8 -> 142113
B26: Investment in unconsolidated entities | C26: 9879 | D26: 14600 | E26: 15405 | F26: =F10 -> 15405 | G26: =G10 -> 15405 | H26: =H10 -> 15405 | I26: =I10 -> 15405 | J26: =J10 -> 15405 | K26: =K10 -> 15405 | L26: =L10 -> 15405 | M26: =M10 -> 15405
B27: Other assets | C27: 30601 | D27: 36460 | E27: 40565 | F27: =F9*IncState!F17 -> 46868.669 | G27: =G9*IncState!G17 -> 54799.385 | H27: =H9*IncState!H17 -> 63893.441 | I27: =I9*IncState!I17 -> 74139.598 | J27: =J9*IncState!J17 -> 85468.146 | K27: =K9*IncState!K17 -> 97749.048 | L27: =L9*IncState!L17 -> 110798.71 | M27: =M9*IncState!M17 -> 124397.03
B28: Total non-current assets | C28: =SUM(C24:C27) -> 227719 | D28: =SUM(D24:D27) -> 352429 | E28: =SUM(E24:E27) -> 427872 | F28: =SUM(F24:F27) -> 461517.47 | G28: =SUM(G24:G27) -> 498258.17 | H28: =SUM(H24:H27) -> 537350.26 | I28: =SUM(I24:I27) -> 578185.48 | J28: =SUM(J24:J27) -> 619781.84 | ... M28: =SUM(M24:M27) -> 734577.69
A30: * | B30: TOTAL ASSETS | C30: =SUM(C28,C22) -> 411976 | D30: =SUM(D28,D22) -> 512163 | E30: =SUM(E28,E22) -> 619003 | F30: =SUM(F28,F22) -> 737222.15 | G30: =SUM(G28,G22) -> 885580.04 | H30: =SUM(H28,H22) -> 1064422.2 | I30: =SUM(I28,I22) -> 1280690.4 | J30: =SUM(J28,J22) -> 1544804.8 | ... M30: =SUM(M28,M22) -> 2565590.1
B32: Revolver/Short term debt | C32: 5247 | D32: =6693+2249 -> 8942 | E32: 0 | F32: =MIN(CashFlow!F23,0) -> 0 | G32: =MIN(CashFlow!G23,0) -> 0 | H32: =MIN(CashFlow!H23,0) -> 0 | I32: =MIN(CashFlow!I23,0) -> 0 | J32: =MIN(CashFlow!J23,0) -> 0 | K32: =MIN(CashFlow!K23,0) -> 0 | L32: =MIN(CashFlow!L23,0) -> 0 | M32: =MIN(CashFlow!M23,0) -> 0
B33: Accounts payable/Accurals | C33: 18095 | D33: 21996 | E33: =27724 -> 27724 | F33: =F12*IncState!F18 -> 32032.22 | G33: =G12*IncState!G18 -> 37452.438 | H33: =H12*IncState!H18 -> 43667.737 | I33: =I12*IncState!I18 -> 50670.435 | J33: =J12*IncState!J18 -> 58412.89 | K33: =K12*IncState!K18 -> 66806.227 | L33: =L12*IncState!L18 -> 75724.968 | M33: =M12*IncState!M18 -> 85018.691
B34: Other current liabilities | C34: =104149-SUM(C32:C33) -> 80807 | D34: =125286-SUM(D32:D33) -> 94348 | E34: =141218-SUM(E32:E33) -> 113494 | F34: =F13*IncState!F17 -> 131130.6 | G34: =G13*IncState!G17 -> 153319.4 | H34: =H13*IncState!H17 -> 178763.03 | I34: =I13*IncState!I17 -> 207430.04 | J34: =J13*IncState!J17 -> 239125.4 | K34: =K13*IncState!K17 -> 273485.28 | L34: =L13*IncState!L17 -> 309996.01 | M34: =M13*IncState!M17 -> 348041.82
B35: Total current liabilities | C35: =SUM(C32:C34) -> 104149 | D35: =SUM(D32:D34) -> 125286 | E35: =SUM(E32:E34) -> 141218 | F35: =SUM(F32:F34) -> 163162.82 | G35: =SUM(G32:G34) -> 190771.84 | H35: =SUM(H32:H34) -> 222430.76 | I35: =SUM(I32:I34) -> 258100.47 | J35: =SUM(J32:J34) -> 297538.29 | ... M35: =SUM(M32:M34) -> 433060.51
B37: Long-term debt, including current maturities | C37: 41990 | D37: 42688 | E37: 40152 | F37: =Debt!F20 -> 40152 | G37: =Debt!G20 -> 40152 | H37: =Debt!H20 -> 40152 | I37: =Debt!I20 -> 40152 | J37: =Debt!J20 -> 40152 | K37: =Debt!K20 -> 40152 | L37: =Debt!L20 -> 40152 | M37: =Debt!M20 -> 40152
B38: Other long-term liabilities | C38: =205753-C37-C35 -> 59614 | D38: =243686-D37-D35 -> 75712 | E38: =275524-E37-E35 -> 94154 | F38: =F14*IncState!F17 -> 108785.23 | G38: =G14*IncState!G17 -> 127192.93 | H38: =H14*IncState!H17 -> 148300.83 | I38: =I14*IncState!I17 -> 172082.82 | J38: =J14*IncState!J17 -> 198377.12 | K38: =K14*IncState!K17 -> 226881.89 | L38: =L14*IncState!L17 -> 257170.99 | M38: =M14*IncState!M17 -> 288733.58
B39: Total non-current liabilities | C39: =SUM(C37:C38) -> 101604 | D39: =SUM(D37:D38) -> 118400 | E39: =SUM(E37:E38) -> 134306 | F39: =SUM(F37:F38) -> 148937.23 | G39: =SUM(G37:G38) -> 167344.93 | H39: =SUM(H37:H38) -> 188452.83 | I39: =SUM(I37:I38) -> 212234.82 | J39: =SUM(J37:J38) -> 238529.12 | ... M39: =SUM(M37:M38) -> 328885.58
B41: Equity | C41: 206223 | D41: 268477 | E41: 343479 | F41: =Calcs!F17 -> 425122.11 | G41: =Calcs!G17 -> 527463.27 | H41: =Calcs!H17 -> 653538.65 | I41: =Calcs!I17 -> 810355.06 | J41: =Calcs!J17 -> 1008737.4 | K41: =Calcs!K17 -> 1239171.2 | L41: =Calcs!L17 -> 1503662.7 | M41: =Calcs!M17 -> 1803644
A42: * | B42: TOTAL LIABILITIES & EQUITY | C42: =SUM(C41,C39,C35) -> 411976 | D42: =SUM(D41,D39,D35) -> 512163 | E42: =SUM(E41,E39,E35) -> 619003 | F42: =SUM(F41,F39,F35) -> 737222.15 | G42: =SUM(G41,G39,G35) -> 885580.04 | H42: =SUM(H41,H39,H35) -> 1064422.2 | I42: =SUM(I41,I39,I35) -> 1280690.4 | J42: =SUM(J41,J39,J35) -> 1544804.8 | ... M42: =SUM(M41,M39,M35) -> 2565590.1
A44: * | B44: Balance check | C44: =C42-C30 -> 0 | D44: =D42-D30 -> 0 | E44: =E42-E30 -> 0 | F44: =F42-F30 -> 0 | G44: =G42-G30 -> 0 | H44: =H42-H30 -> 0 | I44: =I42-I30 -> 0 | J44: =J42-J30 -> 0 | ... M44: =M42-M30 -> 0

Sheet CashFlow
A1: =CoName -> Microsoft Corp. | C1: Hist. | D1: Hist. | E1: Hist. | F1: Proj. | G1: Proj. | H1: Proj. | I1: Proj. | J1: Proj. | K1: Proj. | L1: Proj. | M1: Proj.
A2: Cash flow statement | C2: 2023 | D2: 2024 | E2: 2025 | F2: 2026 | G2: 2027 | H2: 2028 | I2: 2029 | J2: 2030 | K2: 2031 | L2: 2032 | M2: 2033
B3: Net Income | F3: =IncState!F36 -> 122320.67 | G3: =IncState!G36 -> 143018.72 | H3: =IncState!H36 -> 166752.94 | I3: =IncState!I36 -> 193493.97 | J3: =IncState!J36 -> 223059.9 | K3: =IncState!K36 -> 255111.33 | L3: =IncState!L36 -> 289169.11 | M3: =IncState!M36 -> 324658.83
B4: Depreciation | F4: =Calcs!F8 -> 50778.92 | G4: =Calcs!G8 -> 56820.929 | H4: =Calcs!H8 -> 63187.377 | I4: =Calcs!I8 -> 69816.363 | J4: =Calcs!J8 -> 76575.954 | K4: =Calcs!K8 -> 83264.553 | L4: =Calcs!L8 -> 89617.427 | M4: =Calcs!M8 -> 95320.309
B5: Amortization | F5: =IncState!F24 -> 0 | G5: =IncState!G24 -> 0 | H5: =IncState!H24 -> 0 | I5: =IncState!I24 -> 0 | J5: =IncState!J24 -> 0 | K5: =IncState!K24 -> 0 | L5: =IncState!L24 -> 0 | M5: =IncState!M24 -> 0
B6: (inc) / Dec in OWC | F6: =Calcs!F26 -> -4005.9728 | G6: =Calcs!G26 -> -5039.9589 | H6: =Calcs!H26 -> -5779.2593 | I6: =Calcs!I26 -> -6511.4183 | J6: =Calcs!J26 -> -7199.2761 | K6: =Calcs!K26 -> -7804.4956 | L6: =Calcs!L26 -> -8293.0393 | M6: =Calcs!M26 -> -8641.7148
B7: (inc) / Dec in LT assets | F7: =BalSheet!E27-BalSheet!F27 -> -6303.6692 | G7: =BalSheet!F27-BalSheet!G27 -> -7930.7162 | H7: =BalSheet!G27-BalSheet!H27 -> -9094.0553 | I7: =BalSheet!H27-BalSheet!I27 -> -10246.157 | J7: =BalSheet!I27-BalSheet!J27 -> -11328.548 | K7: =BalSheet!J27-BalSheet!K27 -> -12280.902 | L7: =BalSheet!K27-BalSheet!L27 -> -13049.658 | M7: =BalSheet!L27-BalSheet!M27 -> -13598.323
B8: inc / (dec) in LT liabilities | F8: =BalSheet!F38-BalSheet!E38 -> 14631.226 | G8: =BalSheet!G38-BalSheet!F38 -> 18407.708 | H8: =BalSheet!H38-BalSheet!G38 -> 21107.893 | I8: =BalSheet!I38-BalSheet!H38 -> 23781.996 | J8: =BalSheet!J38-BalSheet!I38 -> 26294.296 | K8: =BalSheet!K38-BalSheet!J38 -> 28504.771 | L8: =BalSheet!L38-BalSheet!K38 -> 30289.104 | M8: =BalSheet!M38-BalSheet!L38 -> 31562.59
B9: Cash Flow From Operations | F9: =SUM(F3:F8) -> 177421.17 | G9: =SUM(G3:G8) -> 205276.69 | H9: =SUM(H3:H8) -> 236174.89 | I9: =SUM(I3:I8) -> 270334.75 | J9: =SUM(J3:J8) -> 307402.32 | K9: =SUM(K3:K8) -> 346795.26 | L9: =SUM(L3:L8) -> 387732.94 | M9: =SUM(M3:M8) -> 429301.69
B11: Capex | F11: =Calcs!F7 -> 78120.719 | G11: =Calcs!G7 -> 85630.912 | H11: =Calcs!H7 -> 93185.414 | I11: =Calcs!I7 -> 100405.43 | J11: =Calcs!J7 -> 106843.76 | K11: =Calcs!K7 -> 112013.11 | L11: =Calcs!L7 -> 115424.58 | M11: =Calcs!M7 -> 116631.58
B12: Cash Flow From Investing | F12: =-F11 -> -78120.719 | G12: =-G11 -> -85630.912 | H12: =-H11 -> -93185.414 | I12: =-I11 -> -100405.43 | J12: =-J11 -> -106843.76 | K12: =-K11 -> -112013.11 | L12: =-L11 -> -115424.58 | M12: =-M11 -> -116631.58
B14: Dividends Paid | F14: =-IncState!F39 -> -24677.56 | G14: =-IncState!G39 -> -24677.56 | H14: =-IncState!H39 -> -24677.56 | I14: =-IncState!I39 -> -24677.56 | J14: =-IncState!J39 -> -24677.56 | K14: =-IncState!K39 -> -24677.56 | L14: =-IncState!L39 -> -24677.56 | M14: =-IncState!M39 -> -24677.56
B15: Share Issuance / (repayment) | F15: =Calcs!F16 -> -16000 | G15: =Calcs!G16 -> -16000 | H15: =Calcs!H16 -> -16000 | I15: =Calcs!I16 -> -12000 | J15: =Calcs!J16 -> 0 | K15: =Calcs!K16 -> 0 | L15: =Calcs!L16 -> 0 | M15: =Calcs!M16 -> 0
B16: Debt Issuance / (repayment) | F16: =-Debt!F19 -> 0 | G16: =-Debt!G19 -> 0 | H16: =-Debt!H19 -> 0 | I16: =-Debt!I19 -> 0 | J16: =-Debt!J19 -> 0 | K16: =-Debt!K19 -> 0 | L16: =-Debt!L19 -> 0 | M16: =-Debt!M19 -> 0
B17: Cash Flow From Financing | F17: =SUM(F14:F16) -> -40677.56 | G17: =SUM(G14:G16) -> -40677.56 | H17: =SUM(H14:H16) -> -40677.56 | I17: =SUM(I14:I16) -> -36677.56 | J17: =SUM(J14:J16) -> -24677.56 | K17: =SUM(K14:K16) -> -24677.56 | L17: =SUM(L14:L16) -> -24677.56 | M17: =SUM(M14:M16) -> -24677.56
