Workbook
Name Ccy: MAIN!$C$6
Name circ: MAIN!$C$9
Name CoName: MAIN!$C$4
Name g: #REF!
Name IQ_CH: 110000
Name IQ_CQ: 5000
Name IQ_CY: 10000
Name IQ_DAILY: 500000
Name IQ_FH: 100000
Name IQ_FQ: 500
Name IQ_FY: 1000
Name IQ_LTM: 2000
Name IQ_MONTH: 15000
Name IQ_NTM: 6000
Name IQ_WEEK: 50000
Name IQ_YTD: 3000
Name OpCase: [1]DCF!$E$98
Name ScenarioREV: Assumptions!$D$4
Name TTS: #REF!
Name Units: MAIN!$C$7

Sheet MAIN
A1: =CoName -> NVIDIA Corp.
A2: Model Details
B4: Company name | C4: NVIDIA Corp. | E4: Current Stock Price | F4: 192.31 | H4: Operating Case One | I4: Terminal Mult | J4: Perpetuity | K4: Average
B5: Latest BS date | C5: 247.43 | E5: Diluted s/o | F5: 24300 | H5: Implied Price | I5: ='DCF Model'!G18 -> 195.49 | J5: ='DCF Model'!C18 -> 167.18469 | K5: =AVERAGE(I5:J5) -> 181.33735
B6: Currency | C6: USD | E6: Mkt Cap | F6: =F5*F4 -> 4673133 | H6: Difference | I6: =I5/$F$4-1 -> 0.01653581 | J6: =J5/$F$4-1 -> -0.13065005 | K6: =K5/$F$4-1 -> -0.057057118
B7: Units | C7: m | E7: Cash | F7: =11639+45152 -> 56791
B8: Analyst name | C8: Alan Chen | E8: Debt | F8: 8466
B9: Circular switch | C9: 0 | E9: EV | F9: =F6-F7+F8 -> 4624808

Sheet Revenue
A1: =CoName -> NVIDIA Corp.
A2: Revenue segments | C2: Q123 | D2: Q223 | E2: Q323 | F2: Q423 | G2: Q124 | H2: Q224 | I2: Q324 | J2: Q424 | K2: 2024 | L2: Q125 | M2: Q225 | N2: Q325 | O2: Q425 | P2: 2025 | Q2: Q126 | R2: Q226 | S2: Q326 | T2: Q426 | U2: 2026 | V2: Q127 | W2: Q227 | X2: Q327 | Y2: Q427 | Z2: 2027 | AA2: Q128 | AB2: Q228 | AC2: Q328 | AD2: Q428 | AE2: 2028
B3: Data Center | C3: 3750 | D3: 3806 | E3: 3833 | F3: 3616 | G3: 4284 | H3: 10323 | I3: 14514 | J3: 18404 | K3: =SUM(G3:J3) -> 47525 | L3: 22563 | M3: 26272 | N3: 30771 | O3: 35580 | P3: =SUM(L3:O3) -> 115186 | Q3: 39112 | R3: 41096 | S3: =N3*(1+S10) -> 47695.05 | T3: =O3*(1+T10) -> 55149 | U3: =SUM(Q3:T3) -> 183052.05 | V3: =Q3*(1+V10) -> 58355.104 | W3: =R3*(1+W10) -> 59260.432 | X3: =S3*(1+X10) -> 66391.51 | Y3: =T3*(1+Y10) -> 74009.958 | Z3: =SUM(V3:Y3) -> 258017 | AA3: =V3*(1+AA10) -> 75453.149 | AB3: =W3*(1+AB10) -> 75379.27 | AC3: =X3*(1+AC10) -> 81661.557 | AD3: =Y3*(1+AD10) -> 88811.95 | AE3: =SUM(AA3:AD3) -> 321305.93
B4: Gaming | C4: 3620 | D4: 2042 | E4: 1574 | F4: 1831 | G4: 2240 | H4: 2486 | I4: 2856 | J4: 2865 | K4: =SUM(G4:J4) -> 10447 | L4: 2647 | M4: 2880 | N4: 3279 | O4: 2544 | P4: =SUM(L4:O4) -> 11350 | Q4: 3763 | R4: 4287 | S4: =N4*(1+S11) -> 4771.1926 | T4: =O4*(1+T11) -> 3701.7121 | U4: =SUM(Q4:T4) -> 16522.905 | V4: =Q4*(1+V11) -> 5614.396 | W4: =R4*(1+W11) -> 6181.854 | X4: =S4*(1+X11) -> 6641.5001 | Y4: =T4*(1+Y11) -> 4967.6977 | Z4: =SUM(V4:Y4) -> 23405.448 | AA4: =V4*(1+AA11) -> 7259.414 | AB4: =W4*(1+AB11) -> 7863.3183 | AC4: =X4*(1+AC11) -> 8169.0452 | AD4: =Y4*(1+AD11) -> 5961.2372 | AE4: =SUM(AA4:AD4) -> 29253.015
B5: Professional Visualization | C5: 622 | D5: 496 | E5: 200 | F5: 226 | G5: 295 | H5: 379 | I5: 416 | J5: 463 | K5: =SUM(G5:J5) -> 1553 | L5: 427 | M5: 454 | N5: 486 | O5: 511 | P5: =SUM(L5:O5) -> 1878 | Q5: 509 | R5: 601 | S5: =N5*(1+S12) -> 611.34572 | T5: =O5*(1+T12) -> 642.79355 | U5: =SUM(Q5:T5) -> 2364.1393 | V5: =Q5*(1+V12) -> 759.428 | W5: =R5*(1+W12) -> 866.642 | X5: =S5*(1+X12) -> 850.99325 | Y5: =T5*(1+Y12) -> 862.62894 | Z5: =SUM(V5:Y5) -> 3339.6922 | AA5: =V5*(1+AA12) -> 981.9404 | AB5: =W5*(1+AB12) -> 1102.3686 | AC5: =X5*(1+AC12) -> 1046.7217 | AD5: =Y5*(1+AD12) -> 1035.1547 | AE5: =SUM(AA5:AD5) -> 4166.1854
B6: Auto | C6: 138 | D6: 220 | E6: 251 | F6: 294 | G6: 296 | H6: 253 | I6: 261 | J6: 281 | K6: =SUM(G6:J6) -> 1091 | L6: 329 | M6: 346 | N6: 449 | O6: 570 | P6: =SUM(L6:O6) -> 1694 | Q6: 567 | R6: 586 | S6: =N6*(1+S13) -> 767.1268 | T6: =O6*(1+T13) -> 973.85807 | U6: =SUM(Q6:T6) -> 2893.9849 | V6: =Q6*(1+V13) -> 845.964 | W6: =R6*(1+W13) -> 845.012 | X6: =S6*(1+X13) -> 1067.8405 | Y6: =T6*(1+Y13) -> 1306.9175 | Z6: =SUM(V6:Y6) -> 4065.734 | AA6: =V6*(1+AA13) -> 1093.8315 | AB6: =W6*(1+AB13) -> 1074.8553 | AC6: =X6*(1+AC13) -> 1313.4438 | AD6: =Y6*(1+AD13) -> 1568.301 | AE6: =SUM(AA6:AD6) -> 5050.4316
B7: OEM & Other | C7: 158 | D7: 140 | E7: 73 | F7: 84 | G7: 77 | H7: 66 | I7: 73 | J7: 90 | K7: =SUM(G7:J7) -> 306 | L7: 78 | M7: 88 | N7: 97 | O7: 126 | P7: =SUM(L7:O7) -> 389 | Q7: 111 | R7: 173 | S7: =N7*(1+S14) -> 164.36582 | T7: =O7*(1+T14) -> 213.50612 | U7: =SUM(Q7:T7) -> 661.87194 | V7: =Q7*(1+V14) -> 165.612 | W7: =R7*(1+W14) -> 249.466 | X7: =S7*(1+X14) -> 228.79722 | Y7: =T7*(1+Y14) -> 286.52521 | Z7: =SUM(V7:Y7) -> 930.40044 | AA7: =V7*(1+AA14) -> 214.13632 | AB7: =W7*(1+AB14) -> 317.32075 | AC7: =X7*(1+AC14) -> 281.42059 | AD7: =Y7*(1+AD14) -> 343.83025 | AE7: =SUM(AA7:AD7) -> 1156.7079
A8: * | B8: TOTAL REVENUES | C8: =SUM(C3:C7) -> 8288 | D8: =SUM(D3:D7) -> 6704 | E8: =SUM(E3:E7) -> 5931 | F8: =SUM(F3:F7) -> 6051 | G8: =SUM(G3:G7) -> 7192 | H8: =SUM(H3:H7) -> 13507 | I8: =SUM(I3:I7) -> 18120 | J8: =SUM(J3:J7) -> 22103 | K8: =SUM(G8:J8) -> 60922 | L8: =SUM(L3:L7) -> 26044 | M8: =SUM(M3:M7) -> 30040 | N8: =SUM(N3:N7) -> 35082 | O8: =SUM(O3:O7) -> 39331 | P8: =SUM(L8:O8) -> 130497 | Q8: =SUM(Q3:Q7) -> 44062 | R8: =SUM(R3:R7) -> 46743 | S8: =SUM(S3:S7) -> 54009.081 | T8: =SUM(T3:T7) -> 60680.87 | U8: =SUM(Q8:T8) -> 205494.95 | V8: =SUM(V3:V7) -> 65740.504 | W8: =SUM(W3:W7) -> 67403.406 | X8: =SUM(X3:X7) -> 75180.641 | Y8: =SUM(Y3:Y7) -> 81433.727 | Z8: =SUM(V8:Y8) -> 289758.28 | AA8: =SUM(AA3:AA7) -> 85002.472 | AB8: =SUM(AB3:AB7) -> 85737.132 | AC8: =SUM(AC3:AC7) -> 92472.188 | AD8: =SUM(AD3:AD7) -> 97720.473 | AE8: =SUM(AA8:AD8) -> 360932.26
A9: % | B9: Revenues y/y | G9: =G8/C8-1 -> -0.13223938 | H9: =H8/D8-1 -> 1.0147673 | I9: =I8/E8-1 -> 2.055134 | J9: =J8/F8-1 -> 2.6527847 | K9: =K8/(SUM(C8:F8)-1) -> 2.258629 | L9: =L8/G8-1 -> 2.6212458 | M9: =M8/H8-1 -> 1.224032 | N9: =N8/I8-1 -> 0.93609272 | O9: =O8/J8-1 -> 0.7794417 | P9: =P8/K8-1 -> 1.1420341 | Q9: =Q8/L8-1 -> 0.69182921 | R9: =R8/M8-1 -> 0.5560253 | S9: =S8/N8-1 -> 0.53950975 | ... AE9: =AE8/Z8-1 -> 0.24563228
A10: % | B10: Data Center | G10: =G3/C3-1 -> 0.1424 | H10: =H3/D3-1 -> 1.7122964 | I10: =I3/E3-1 -> 2.7865901 | J10: =J3/F3-1 -> 4.0896018 | K10: =K3/SUM(C3:F3)-1 -> 2.1672776 | L10: =L3/G3-1 -> 4.2668067 | M10: =M3/H3-1 -> 1.5449966 | N10: =N3/I3-1 -> 1.1200909 | O10: =O3/J3-1 -> 0.93327537 | P10: =P3/K3-1 -> 1.4236928 | Q10: =Q3/L3-1 -> 0.73345743 | R10: =R3/M3-1 -> 0.56425091 | S10: 0.55 | T10: =S10 -> 0.55 | U10: =U3/P3-1 -> 0.58918662 | V10: 0.492 | W10: =V10-0.05 -> 0.442 | X10: =W10-0.05 -> 0.392 | Y10: =X10-0.05 -> 0.342 | Z10: =Z3/U3-1 -> 0.40952807 | AA10: 0.293 | AB10: 0.272 | AC10: 0.23 | AD10: 0.2 | AE10: =AE3/Z3-1 -> 0.24528973
A11: % | B11: Gaming | G11: =G4/C4-1 -> -0.38121547 | H11: =H4/D4-1 -> 0.21743389 | I11: =I4/E4-1 -> 0.81448539 | J11: =J4/F4-1 -> 0.56471873 | K11: =K4/SUM(C4:F4)-1 -> 0.15220029 | L11: =L4/G4-1 -> 0.18169643 | M11: =M4/H4-1 -> 0.15848753 | N11: =N4/I4-1 -> 0.14810924 | O11: =O4/J4-1 -> -0.11204188 | P11: =P4/K4-1 -> 0.086436298 | Q11: =Q4/L4-1 -> 0.42160937 | R11: =R4/M4-1 -> 0.48854167 | S11: =AVERAGE(Q11:R11) -> 0.45507552 | T11: =S11 -> 0.45507552 | U11: =U4/P4-1 -> 0.45576253 | V11: =V10 -> 0.492 | W11: =V11-0.05 -> 0.442 | X11: =W11-0.05 -> 0.392 | Y11: =X11-0.05 -> 0.342 | Z11: =Z4/U4-1 -> 0.41654559 | AA11: =AA10 -> 0.293 | AB11: =AB10 -> 0.272 | AC11: =AC10 -> 0.23 | AD11: =AD10 -> 0.2 | AE11: =AE4/Z4-1 -> 0.24983786
A12: % | B12: Professional Visualization | G12: =G5/C5-1 -> -0.52572347 | H12: =H5/D5-1 -> -0.2358871 | I12: =I5/E5-1 -> 1.08 | J12: =J5/F5-1 -> 1.0486726 | K12: =K5/SUM(C5:F5)-1 -> 0.0058290155 | L12: =L5/G5-1 -> 0.44745763 | M12: =M5/H5-1 -> 0.19788918 | N12: =N5/I5-1 -> 0.16826923 | O12: =O5/J5-1 -> 0.10367171 | P12: =P5/K5-1 -> 0.20927238 | Q12: =Q5/L5-1 -> 0.19203747 | R12: =R5/M5-1 -> 0.32378855 | S12: =AVERAGE(Q12:R12) -> 0.25791301 | T12: =S12 -> 0.25791301 | U12: =U5/P5-1 -> 0.2588601 | V12: =V11 -> 0.492 | W12: =V12-0.05 -> 0.442 | X12: =W12-0.05 -> 0.392 | Y12: =X12-0.05 -> 0.342 | Z12: =Z5/U5-1 -> 0.41264613 | AA12: =AA11 -> 0.293 | AB12: =AB11 -> 0.272 | AC12: =AC11 -> 0.23 | AD12: =AD11 -> 0.2 | AE12: =AE5/Z5-1 -> 0.24747588
A13: % | B13: Auto | G13: =G6/C6-1 -> 1.1449275 | H13: =H6/D6-1 -> 0.15 | I13: =I6/E6-1 -> 0.039840637 | J13: =J6/F6-1 -> -0.044217687 | K13: =K6/SUM(C6:F6)-1 -> 0.20819491 | L13: =L6/G6-1 -> 0.11148649 | M13: =M6/H6-1 -> 0.36758893 | N13: =N6/I6-1 -> 0.72030651 | O13: =O6/J6-1 -> 1.0284698 | P13: =P6/K6-1 -> 0.55270394 | Q13: =Q6/L6-1 -> 0.72340426 | R13: =R6/M6-1 -> 0.69364162 | S13: =AVERAGE(Q13:R13) -> 0.70852294 | T13: =S13 -> 0.70852294 | U13: =U6/P6-1 -> 0.7083736 | V13: =V12 -> 0.492 | W13: =V13-0.05 -> 0.442 | X13: =W13-0.05 -> 0.392 | Y13: =X13-0.05 -> 0.342 | Z13: =Z6/U6-1 -> 0.40489125 | AA13: =AA12 -> 0.293 | AB13: =AB12 -> 0.272 | AC13: =AC12 -> 0.23 | AD13: =AD12 -> 0.2 | AE13: =AE6/Z6-1 -> 0.24219428
A14: % | B14: OEM & Other | G14: =G7/C7-1 -> -0.51265823 | H14: =H7/D7-1 -> -0.52857143 | I14: =I7/E7-1 -> 0 | J14: =J7/F7-1 -> 0.071428571 | K14: =K7/SUM(C7:F7)-1 -> -0.32747253 | L14: =L7/G7-1 -> 0.012987013 | M14: =M7/H7-1 -> 0.33333333 | N14: =N7/I7-1 -> 0.32876712 | O14: =O7/J7-1 -> 0.4 | P14: =P7/K7-1 -> 0.27124183 | Q14: =Q7/L7-1 -> 0.42307692 | R14: =R7/M7-1 -> 0.96590909 | S14: =AVERAGE(Q14:R14) -> 0.69449301 | T14: =S14 -> 0.69449301 | U14: =U7/P7-1 -> 0.70147028 | V14: =V13 -> 0.492 | W14: =V14-0.05 -> 0.442 | X14: =W14-0.05 -> 0.392 | Y14: =X14-0.05 -> 0.342 | Z14: =Z7/U7-1 -> 0.40571065 | AA14: =AA13 -> 0.293 | AB14: =AB13 -> 0.272 | AC14: =AC13 -> 0.23 | AD14: =AD13 -> 0.2 | AE14: =AE7/Z7-1 -> 0.24323664

Sheet Assumptions
A1: =CoName -> NVIDIA Corp. | C1: Hist. | D1: Hist. | E1: Hist. | F1: Proj. | G1: Proj. | H1: Proj. | I1: Proj. | J1: Proj. | K1: Proj. | L1: Proj. | M1: Proj. | N1: Proj. | O1: Proj.
A2: * | B2: Income Statement | C2: 2023 | D2: =C2+1 -> 2024 | E2: =D2+1 -> 2025 | F2: =E2+1 -> 2026 | G2: =F2+1 -> 2027 | H2: =G2+1 -> 2028 | I2: =H2+1 -> 2029 | J2: =I2+1 -> 2030 | K2: =J2+1 -> 2031 | ... O2: =N2+1 -> 2035
B4: Operating Case | D4: 1
D5: Variance
B6: Street Case | D6: 0 | F6: =Revenue!U9 -> 0.57471015 | G6: =Revenue!Z9 -> 0.4100506 | H6: =Revenue!AE9 -> 0.24563228 | I6: =H6-0.025 -> 0.22063228 | J6: =I6 -> 0.22063228 | K6: =J6 -> 0.22063228 | L6: =K6 -> 0.22063228 | M6: =L6 -> 0.22063228 | N6: =M6 -> 0.22063228 | O6: =N6 -> 0.22063228
B7: Optimistic Case | D7: 0.025 | F7: =F6+$D$7 -> 0.59971015 | G7: =G6+$D$7 -> 0.4350506 | H7: =H6+$D$7 -> 0.27063228 | I7: =I6+$D$7 -> 0.24563228 | J7: =J6+$D$7 -> 0.24563228 | K7: =K6+$D$7 -> 0.24563228 | L7: =L6+$D$7 -> 0.24563228 | M7: =M6+$D$7 -> 0.24563228 | ... O7: =O6+$D$7 -> 0.24563228
B8: Pessimistic Case | D8: -0.05 | F8: =F6+$D$8 -> 0.52471015 | G8: =G6+$D$8 -> 0.3600506 | H8: =H6+$D$8 -> 0.19563228 | I8: =I6+$D$8 -> 0.17063228 | J8: =J6+$D$8 -> 0.17063228 | K8: =K6+$D$8 -> 0.17063228 | L8: =L6+$D$8 -> 0.17063228 | M8: =M6+$D$8 -> 0.17063228 | ... O8: =O6+$D$8 -> 0.17063228
B10: Revenue Growth | F10: =CHOOSE(ScenarioREV,F6,F7,F8) -> 0.57471015 | G10: =CHOOSE(ScenarioREV,G6,G7,G8) -> 0.4100506 | H10: =CHOOSE(ScenarioREV,H6,H7,H8) -> 0.24563228 | I10: =CHOOSE(ScenarioREV,I6,I7,I8) -> 0.22063228 | J10: =CHOOSE(ScenarioREV,J6,J7,J8) -> 0.22063228 | K10: =CHOOSE(ScenarioREV,K6,K7,K8) -> 0.22063228 | L10: =CHOOSE(ScenarioREV,L6,L7,L8) -> 0.22063228 | M10: =CHOOSE(ScenarioREV,M6,M7,M8) -> 0.22063228 | ... O10: =CHOOSE(ScenarioREV,O6,O7,O8) -> 0.22063228
B11: COGS % of sales | C11: =IncState!C18/IncState!C17 -> 0.43071106 | D11: =IncState!D18/IncState!D17 -> 0.27282427 | E11: =IncState!E18/IncState!E17 -> 0.25011303 | F11: =E11 -> 0.25011303 | G11: =F11 -> 0.25011303 | H11: =G11 -> 0.25011303 | I11: =H11 -> 0.25011303 | J11: =I11 -> 0.25011303 | K11: =J11 -> 0.25011303 | L11: =K11 -> 0.25011303 | M11: =L11 -> 0.25011303 | ... O11: =N11 -> 0.25011303
B12: R&D % of sales | C12: =IncState!C19/IncState!C17 -> 0.27207681 | D12: =IncState!D19/IncState!D17 -> 0.14239519 | E12: =IncState!E19/IncState!E17 -> 0.098960129 | F12: =E12 -> 0.098960129 | G12: =F12 -> 0.098960129 | H12: =G12 -> 0.098960129 | I12: =H12 -> 0.098960129 | J12: =I12 -> 0.098960129 | K12: =J12 -> 0.098960129 | L12: =K12 -> 0.098960129 | M12: =L12 -> 0.098960129 | ... O12: =N12 -> 0.098960129
B13: SG&A % of sales | C13: =IncState!C20/IncState!C17 -> 0.090457478 | D13: =IncState!D20/IncState!D17 -> 0.043563901 | E13: =IncState!E20/IncState!E17 -> 0.026751573 | F13: =E13 -> 0.026751573 | G13: =F13 -> 0.026751573 | H13: =G13 -> 0.026751573 | I13: =H13 -> 0.026751573 | J13: =I13 -> 0.026751573 | K13: =J13 -> 0.026751573 | L13: =K13 -> 0.026751573 | M13: =L13 -> 0.026751573 | ... O13: =N13 -> 0.026751573
B14: Amortization $ Amt | C14: 0 | D14: 0 | E14: 0 | F14: =E14 -> 0 | G14: =F14 -> 0 | H14: =G14 -> 0 | I14: =H14 -> 0 | J14: =I14 -> 0 | K14: =J14 -> 0 | L14: =K14 -> 0 | M14: =L14 -> 0 | ... O14: =N14 -> 0
B15: Non recurring income / (expense) | C15: 0 | D15: 0 | E15: 0 | F15: 0 | G15: 0 | H15: 0 | I15: 0 | J15: 0 | K15: 0 | L15: 0 | M15: 0 | N15: 0 | O15: 0
B16: Other Income / (expense) | C16: 0 | D16: 0 | E16: 0 | F16: 0 | G16: 0 | H16: 0 | I16: 0 | J16: 0 | K16: 0 | L16: 0 | M16: 0 | N16: 0 | O16: 0
B17: Effective tax rate | C17: =IncState!C35/IncState!C33 -> -0.044726142 | D17: =IncState!D35/IncState!D33 -> 0.11999527 | E17: =IncState!E35/IncState!E33 -> 0.13264942 | F17: 0.165 | G17: =F17 -> 0.165 | H17: =G17 -> 0.165 | I17: =H17 -> 0.165 | J17: =I17 -> 0.165 | K17: =J17 -> 0.165 | L17: =K17 -> 0.165 | M17: =L17 -> 0.165 | N17: =M17 -> 0.165 | O17: =N17 -> 0.165
B18: Dividend Payout Rate | C18: 0.016 | D18: 0.016 | E18: 0.016 | F18: =E18+0.005 -> 0.021 | G18: =F18+0.005 -> 0.026 | H18: =G18+0.005 -> 0.031 | I18: =H18+0.005 -> 0.036 | J18: =I18+0.005 -> 0.041 | K18: =J18+0.005 -> 0.046 | L18: =K18+0.005 -> 0.051 | M18: =L18+0.005 -> 0.056 | ... O18: =N18+0.005 -> 0.066
B19: Basic WASO | C19: =IncState!C40 -> 24870 | D19: =IncState!D40 -> 24690 | E19: =IncState!E40 -> 24555 | F19: =E19 -> 24555 | G19: =F19 -> 24555 | H19: =G19 -> 24555 | I19: =H19 -> 24555 | J19: =I19 -> 24555 | K19: =J19 -> 24555 | L19: =K19 -> 24555 | M19: =L19 -> 24555 | ... O19: =N19 -> 24555
B20: Diluted WASO | C20: =IncState!C41 -> 25070 | D20: =IncState!D41 -> 24940 | E20: =IncState!E41 -> 24804 | F20: =E20 -> 24804 | G20: =F20 -> 24804 | H20: =G20 -> 24804 | I20: =H20 -> 24804 | J20: =I20 -> 24804 | K20: =J20 -> 24804 | L20: =K20 -> 24804 | M20: =L20 -> 24804 | ... O20: =N20 -> 24804
A22: * | B22: Debt | C22: 2023 | D22: =C22+1 -> 2024 | E22: =D22+1 -> 2025 | F22: =E22+1 -> 2026 | G22: =F22+1 -> 2027 | H22: =G22+1 -> 2028 | I22: =H22+1 -> 2029 | J22: =I22+1 -> 2030 | K22: =J22+1 -> 2031 | ... O22: =N22+1 -> 2035
B24: Interest rate on Revolver | F24: =E24 -> 0 | G24: =F24 -> 0 | H24: =G24 -> 0 | I24: =H24 -> 0 | J24: =I24 -> 0 | K24: =J24 -> 0 | L24: =K24 -> 0 | M24: =L24 -> 0 | ... O24: =N24 -> 0
B25: Interest rate on long-term debt | E25: 0.029 | F25: =E25 -> 0.029 | G25: =F25 -> 0.029 | H25: =G25 -> 0.029 | I25: =H25 -> 0.029 | J25: =I25 -> 0.029 | K25: =J25 -> 0.029 | L25: =K25 -> 0.029 | M25: =L25 -> 0.029 | ... O25: =N25 -> 0.029
B26: Interest rate on cash | C26: =IncState!C30/BalSheet!C16 -> 0.089465519 | D26: =IncState!D30/BalSheet!D16 -> 0.13603155 | E26: =IncState!E30/BalSheet!E16 -> 0.26931884 | F26: 0.05 | G26: =F26 -> 0.05 | H26: =G26 -> 0.05 | I26: =H26 -> 0.05 | J26: =I26 -> 0.05 | K26: =J26 -> 0.05 | L26: =K26 -> 0.05 | M26: =L26 -> 0.05 | N26: =M26 -> 0.05 | O26: =N26 -> 0.05
B28: Issuance of long-term debt | F28: 0 | G28: 0 | H28: 0 | I28: 0 | J28: 0 | K28: 0 | L28: 0 | M28: 0 | N28: 0 | O28: 0
B29: Repayment of long-term debt | F29: 0 | G29: 0 | H29: 0 | I29: 0 | J29: 0 | K29: 0 | L29: 0 | M29: 0 | N29: 0 | O29: 0
A31: * | B31: Calcs | C31: 2023 | D31: =C31+1 -> 2024 | E31: =D31+1 -> 2025 | F31: =E31+1 -> 2026 | G31: =F31+1 -> 2027 | H31: =G31+1 -> 2028 | I31: =H31+1 -> 2029 | J31: =I31+1 -> 2030 | K31: =J31+1 -> 2031 | ... O31: =N31+1 -> 2035
B33: CapEx % of Sales | C33: =1833/IncState!C17 -> 0.067954326 | D33: =1069/IncState!D17 -> 0.017547027 | E33: =3236/IncState!E17 -> 0.024797505 | F33: =AVERAGE(C33:E33) -> 0.036766286 | G33: =F33 -> 0.036766286 | H33: =G33 -> 0.036766286 | I33: =H33 -> 0.036766286 | J33: =I33 -> 0.036766286 | K33: =J33 -> 0.036766286 | L33: =K33 -> 0.036766286 | M33: =L33 -> 0.036766286 | N33: =M33 -> 0.036766286 | O33: =N33 -> 0.036766286
B34: Depreciation % of beginning PP&E | D34: =IncState!D23/BalSheet!C22 -> 0.31124871 | E34: =IncState!E23/BalSheet!D22 -> 0.29353612 | F34: =E34 -> 0.29353612 | G34: =F34 -> 0.29353612 | H34: =G34 -> 0.29353612 | I34: =H34 -> 0.29353612 | J34: =I34 -> 0.29353612 | K34: =J34 -> 0.29353612 | L34: =K34 -> 0.29353612 | M34: =L34 -> 0.29353612 | ... O34: =N34 -> 0.29353612
B35: Share issuance / (repurchases) | C35: 0 | D35: 0 | E35: 0 | F35: 0 | G35: 0 | H35: 0 | I35: 0 | J35: 0 | K35: 0 | L35: 0 | M35: 0 | N35: 0 | O35: 0
A37: * | B37: Shareholder information | C37: 2023 | D37: =C37+1 -> 2024 | E37: =D37+1 -> 2025 | F37: =E37+1 -> 2026 | G37: =F37+1 -> 2027 | H37: =G37+1 -> 2028 | I37: =H37+1 -> 2029 | J37: =I37+1 -> 2030 | K37: =J37+1 -> 2031 | ... O37: =N37+1 -> 2035
B39: Dividend payout ratio | C39: 0.016 | D39: 0.016 | E39: 0.016 | F39: =E39 -> 0.016 | G39: =F39 -> 0.016 | H39: =G39 -> 0.016 | I39: =H39 -> 0.016 | J39: =I39 -> 0.016 | K39: =J39 -> 0.016 | L39: =K39 -> 0.016 | M39: =L39 -> 0.016 | ... O39: =N39 -> 0.016
B40: Basic WASO | C40: 24870 | D40: 24690 | E40: 24555 | F40: =F19 -> 24555 | G40: =G19 -> 24555 | H40: =H19 -> 24555 | I40: =I19 -> 24555 | J40: =J19 -> 24555 | K40: =K19 -> 24555 | L40: =L19 -> 24555 | M40: =M19 -> 24555 | ... O40: =O19 -> 24555
B41: Diluted WASO | C41: 25070 | D41: 24940 | E41: 24804 | F41: =F20 -> 24804 | G41: =G20 -> 24804 | H41: =H20 -> 24804 | I41: =I20 -> 24804 | J41: =J20 -> 24804 | K41: =K20 -> 24804 | L41: =L20 -> 24804 | M41: =M20 -> 24804 | ... O41: =O20 -> 24804
A43: * | B43: Balance Sheet - Assets | C43: 2023 | D43: =C43+1 -> 2024 | E43: =D43+1 -> 2025 | F43: =E43+1 -> 2026 | G43: =F43+1 -> 2027 | H43: =G43+1 -> 2028 | I43: =H43+1 -> 2029 | J43: =I43+1 -> 2030 | K43: =J43+1 -> 2031 | ... O43: =N43+1 -> 2035
B45: Operating Cash % of sales | C45: =BalSheet!C15/IncState!C17 -> 0.015 | D45: =BalSheet!D15/IncState!D17 -> 0.015 | E45: =BalSheet!E15/IncState!E17 -> 0.015 | F45: =E45 -> 0.015 | G45: =F45 -> 0.015 | H45: =G45 -> 0.015 | I45: =H45 -> 0.015 | J45: =I45 -> 0.015 | K45: =J45 -> 0.015 | L45: =K45 -> 0.015 | M45: =L45 -> 0.015 | ... O45: =N45 -> 0.015
B46: Accounts receivable % of sales | C46: =BalSheet!C17/IncState!C17 -> 0.14187736 | D46: =BalSheet!D17/IncState!D17 -> 0.1641279 | E46: =BalSheet!E17/IncState!E17 -> 0.17674736 | F46: =E46 -> 0.17674736 | G46: =F46 -> 0.17674736 | H46: =G46 -> 0.17674736 | I46: =H46 -> 0.17674736 | J46: =I46 -> 0.17674736 | K46: =J46 -> 0.17674736 | L46: =K46 -> 0.17674736 | M46: =L46 -> 0.17674736 | ... O46: =N46 -> 0.17674736
B47: Inventories % of COGS | C47: =BalSheet!C18/IncState!C18 -> 0.44405233 | D47: =BalSheet!D18/IncState!D18 -> 0.31779075 | E47: =BalSheet!E18/IncState!E18 -> 0.30883299 | F47: =E47 -> 0.30883299 | G47: =F47 -> 0.30883299 | H47: =G47 -> 0.30883299 | I47: =H47 -> 0.30883299 | J47: =I47 -> 0.30883299 | K47: =J47 -> 0.30883299 | L47: =K47 -> 0.30883299 | M47: =L47 -> 0.30883299 | ... O47: =N47 -> 0.30883299
B48: Other current assets % of sales | C48: =BalSheet!C19/IncState!C17 -> 0.39660414 | D48: =BalSheet!D19/IncState!D17 -> 0.35757198 | E48: =BalSheet!E19/IncState!E17 -> 0.29419833 | F48: =E48 -> 0.29419833 | G48: =F48 -> 0.29419833 | H48: =G48 -> 0.29419833 | I48: =H48 -> 0.29419833 | J48: =I48 -> 0.29419833 | K48: =J48 -> 0.29419833 | L48: =K48 -> 0.29419833 | M48: =L48 -> 0.29419833 | ... O48: =N48 -> 0.29419833
B49: Other long-term assets % of sales | C49: =BalSheet!C24/IncState!C17 -> 0.26751687 | D49: =BalSheet!D24/IncState!D17 -> 0.1736811 | E49: =BalSheet!E24/IncState!E17 -> 0.13336705 | F49: =E49 -> 0.13336705 | G49: =F49 -> 0.13336705 | H49: =G49 -> 0.13336705 | I49: =H49 -> 0.13336705 | J49: =I49 -> 0.13336705 | K49: =J49 -> 0.13336705 | L49: =K49 -> 0.13336705 | M49: =L49 -> 0.13336705 | ... O49: =N49 -> 0.13336705
A51: * | B51: Balance Sheet - Liabilities | C51: 2023 | D51: =C51+1 -> 2024 | E51: =D51+1 -> 2025 | F51: =E51+1 -> 2026 | G51: =F51+1 -> 2027 | H51: =G51+1 -> 2028 | I51: =H51+1 -> 2029 | J51: =I51+1 -> 2030 | K51: =J51+1 -> 2031 | ... O51: =N51+1 -> 2035
B53: Accounts payable % of COGS | C53: =BalSheet!C30/IncState!C18 -> 0.10268549 | D53: =BalSheet!D30/IncState!D18 -> 0.16238493 | E53: =BalSheet!E30/IncState!E18 -> 0.193327 | F53: =E53 -> 0.193327 | G53: =F53 -> 0.193327 | H53: =G53 -> 0.193327 | I53: =H53 -> 0.193327 | J53: =I53 -> 0.193327 | K53: =J53 -> 0.193327 | L53: =K53 -> 0.193327 | M53: =L53 -> 0.193327 | ... O53: =N53 -> 0.193327
...

Sheet Calcs
A1: =CoName -> NVIDIA Corp. | C1: Hist. | D1: Hist. | E1: Hist. | F1: Proj. | G1: Proj. | H1: Proj. | I1: Proj. | J1: Proj. | K1: Proj. | L1: Proj. | M1: Proj. | N1: Proj. | O1: Proj.
A2: Net PP&E | C2: 2023 | D2: =C2+1 -> 2024 | E2: =D2+1 -> 2025 | F2: =E2+1 -> 2026 | G2: =F2+1 -> 2027 | H2: =G2+1 -> 2028 | I2: =H2+1 -> 2029 | J2: =I2+1 -> 2030 | K2: =J2+1 -> 2031 | ... O2: =N2+1 -> 2035
B3: Capital expenditure % of sales | F3: =Assumptions!F33 -> 0.036766286 | G3: =Assumptions!G33 -> 0.036766286 | H3: =Assumptions!H33 -> 0.036766286 | I3: =Assumptions!I33 -> 0.036766286 | J3: =Assumptions!J33 -> 0.036766286 | K3: =Assumptions!K33 -> 0.036766286 | L3: =Assumptions!L33 -> 0.036766286 | M3: =Assumptions!M33 -> 0.036766286 | ... O3: =Assumptions!O33 -> 0.036766286
B4: Depreciation % of PP&E | F4: =Assumptions!F34 -> 0.29353612 | G4: =F4 -> 0.29353612 | H4: =G4 -> 0.29353612 | I4: =H4 -> 0.29353612 | J4: =I4 -> 0.29353612 | K4: =J4 -> 0.29353612 | L4: =K4 -> 0.29353612 | M4: =L4 -> 0.29353612 | N4: =M4 -> 0.29353612 | O4: =N4 -> 0.29353612
B6: Beginning PP&E | F6: =E9 -> 8076 | G6: =F9 -> 13260.688 | H6: =G9 -> 20021.533 | I6: =H9 -> 27414.629 | J6: =I9 -> 35565.405 | K6: =J9 -> 44897.427 | L6: =K9 -> 55852.45 | M6: =L9 -> 68916.527 | ... O6: =N9 -> 103690.83
B7: Capex | F7: =F3*IncState!F17 -> 7555.2862 | G7: =G3*IncState!G17 -> 10653.336 | H7: =H3*IncState!H17 -> 13270.139 | I7: =I3*IncState!I17 -> 16197.96 | J7: =J3*IncState!J17 -> 19771.753 | K7: =K3*IncState!K17 -> 24134.04 | L7: =L3*IncState!L17 -> 29458.788 | M7: =M3*IncState!M17 -> 35958.348 | ... O7: =O3*IncState!O17 -> 53575.894
B8: Depreciation | F8: =F4*F6 -> 2370.5977 | G8: =G4*G6 -> 3892.4911 | H8: =H4*H6 -> 5877.0432 | I8: =I4*I6 -> 8047.1839 | J8: =J4*J6 -> 10439.731 | K8: =K4*K6 -> 13179.017 | L8: =L4*L6 -> 16394.712 | M8: =M4*M6 -> 20229.49 | ... O8: =O4*O6 -> 30437.003
B9: Ending PP&E | E9: =BalSheet!E22 -> 8076 | F9: =F6+F7-F8 -> 13260.688 | G9: =G6+G7-G8 -> 20021.533 | H9: =H6+H7-H8 -> 27414.629 | I9: =I6+I7-I8 -> 35565.405 | J9: =J6+J7-J8 -> 44897.427 | K9: =K6+K7-K8 -> 55852.45 | L9: =L6+L7-L8 -> 68916.527 | M9: =M6+M7-M8 -> 84645.384 | ... O9: =O6+O7-O8 -> 126829.72
A10: Equity | C10: =C2 -> 2023 | D10: =D2 -> 2024 | E10: =E2 -> 2025 | F10: =F2 -> 2026 | G10: =G2 -> 2027 | H10: =H2 -> 2028 | I10: =I2 -> 2029 | J10: =J2 -> 2030 | ... O10: =O2 -> 2035
B11: Share issuance/(repurchases) | F11: =Assumptions!F35 -> 0 | G11: =Assumptions!G35 -> 0 | H11: =Assumptions!H35 -> 0 | I11: =Assumptions!I35 -> 0 | J11: =Assumptions!J35 -> 0 | K11: =Assumptions!K35 -> 0 | L11: =Assumptions!L35 -> 0 | M11: =Assumptions!M35 -> 0 | ... O11: =Assumptions!O35 -> 0
B13: Beginning balance | F13: =E17 -> 79327 | G13: =F17 -> 185912.51 | H13: =G17 -> 336292.14 | I13: =H17 -> 523643.9 | J13: =I17 -> 752376.68 | K13: =J17 -> 1031647.6 | L13: =K17 -> 1372634 | M13: =L17 -> 1788979.4 | ... O13: =N17 -> 2918036.7
B14: Net income | F14: =IncState!F36 -> 107101.16 | G14: =IncState!G36 -> 151018.06 | H14: =IncState!H36 -> 188112.97 | I14: =IncState!I36 -> 229616.76 | J14: =IncState!J36 -> 280277.63 | K14: =IncState!K36 -> 342115.93 | L14: =IncState!L36 -> 417597.74 | M14: =IncState!M36 -> 509733.29 | ... O14: =IncState!O36 -> 759473.63
B15: Dividends paid | F15: =-IncState!F38 -> -515.655 | G15: =-IncState!G38 -> -638.43 | H15: =-IncState!H38 -> -761.205 | I15: =-IncState!I38 -> -883.98 | J15: =-IncState!J38 -> -1006.755 | K15: =-IncState!K38 -> -1129.53 | L15: =-IncState!L38 -> -1252.305 | M15: =-IncState!M38 -> -1375.08 | ... O15: =-IncState!O38 -> -1620.63
B16: Share issuance / (repurchase) | F16: =F11 -> 0 | G16: =G11 -> 0 | H16: =H11 -> 0 | I16: =I11 -> 0 | J16: =J11 -> 0 | K16: =K11 -> 0 | L16: =L11 -> 0 | M16: =M11 -> 0 | ... O16: =O11 -> 0
B17: Ending balance | E17: =BalSheet!E38 -> 79327 | F17: =SUM(F13:F16) -> 185912.51 | G17: =SUM(G13:G16) -> 336292.14 | H17: =SUM(H13:H16) -> 523643.9 | I17: =SUM(I13:I16) -> 752376.68 | J17: =SUM(J13:J16) -> 1031647.6 | K17: =SUM(K13:K16) -> 1372634 | L17: =SUM(L13:L16) -> 1788979.4 | M17: =SUM(M13:M16) -> 2297337.6 | ... O17: =SUM(O13:O16) -> 3675889.7
A18: OWC | C18: =C10 -> 2023 | D18: =D10 -> 2024 | E18: =E10 -> 2025 | F18: =F10 -> 2026 | G18: =G10 -> 2027 | H18: =H10 -> 2028 | I18: =I10 -> 2029 | J18: =J10 -> 2030 | ... O18: =O10 -> 2035
B19: Operating Cash | E19: =BalSheet!E15 -> 1957.455 | F19: =BalSheet!F15 -> 3082.4243 | G19: =BalSheet!G15 -> 4346.3742 | H19: =BalSheet!H15 -> 5413.984 | I19: =BalSheet!I15 -> 6608.4836 | J19: =BalSheet!J15 -> 8066.5284 | K19: =BalSheet!K15 -> 9846.265 | L19: =BalSheet!L15 -> 12018.669 | ... O19: =BalSheet!O15 -> 21858.025
B20: =BalSheet!B18 -> Inventories | E20: =BalSheet!E18 -> 10080 | F20: =BalSheet!F18 -> 15873.078 | G20: =BalSheet!G18 -> 22381.844 | H20: =BalSheet!H18 -> 27879.547 | I20: =BalSheet!I18 -> 34030.675 | J20: =BalSheet!J18 -> 41538.94 | K20: =BalSheet!K18 -> 50703.772 | L20: =BalSheet!L18 -> 61890.66 | ... O20: =BalSheet!O18 -> 112558.86
B21: =BalSheet!B17 -> Accounts receivable | E21: =BalSheet!E17 -> 23065 | F21: =BalSheet!F17 -> 36320.69 | G21: =BalSheet!G17 -> 51214.01 | H21: =BalSheet!H17 -> 63793.824 | I21: =BalSheet!I17 -> 77868.801 | J21: =BalSheet!J17 -> 95049.173 | K21: =BalSheet!K17 -> 116020.09 | L21: =BalSheet!L17 -> 141617.87 | ... O21: =BalSheet!O17 -> 257556.55
B22: Other current assets | E22: =BalSheet!E19 -> 38392 | F22: =BalSheet!F19 -> 60456.272 | G22: =BalSheet!G19 -> 85246.403 | H22: =BalSheet!H19 -> 106185.67 | I22: =BalSheet!I19 -> 129613.66 | J22: =BalSheet!J19 -> 158210.62 | K22: =BalSheet!K19 -> 193116.98 | L22: =BalSheet!L19 -> 235724.82 | ... O22: =BalSheet!O19 -> 428706.31
B23: Accounts payables | E23: =BalSheet!E30 -> 6310 | F23: =BalSheet!F30 -> 9936.4211 | G23: =BalSheet!G30 -> 14010.856 | H23: =BalSheet!H30 -> 17452.375 | I23: =BalSheet!I30 -> 21302.932 | J23: =BalSheet!J30 -> 26003.047 | K23: =BalSheet!K30 -> 31740.159 | L23: =BalSheet!L30 -> 38743.062 | ... O23: =BalSheet!O30 -> 70460.951
B24: Other current liabilities | E24: =BalSheet!E31 -> 11737 | F24: =BalSheet!F31 -> 18482.373 | G24: =BalSheet!G31 -> 26061.081 | H24: =BalSheet!H31 -> 32462.524 | I24: =BalSheet!I31 -> 39624.805 | J24: =BalSheet!J31 -> 48367.316 | K24: =BalSheet!K31 -> 59038.707 | L24: =BalSheet!L31 -> 72064.552 | ... O24: =BalSheet!O31 -> 131061.83
A25: * | B25: OWC | E25: =SUM(E19:E22)-SUM(E23:E24) -> 55447.455 | F25: =SUM(F19:F22)-SUM(F23:F24) -> 87313.67 | G25: =SUM(G19:G22)-SUM(G23:G24) -> 123116.69 | H25: =SUM(H19:H22)-SUM(H23:H24) -> 153358.13 | I25: =SUM(I19:I22)-SUM(I23:I24) -> 187193.88 | J25: =SUM(J19:J22)-SUM(J23:J24) -> 228494.89 | K25: =SUM(K19:K22)-SUM(K23:K24) -> 278908.24 | L25: =SUM(L19:L22)-SUM(L23:L24) -> 340444.41 | ... O25: =SUM(O19:O22)-SUM(O23:O24) -> 619156.96
B26: Change in OWC | F26: =E25-F25 -> -31866.215 | G26: =F25-G25 -> -35803.023 | H26: =G25-H25 -> -30241.434 | I26: =H25-I25 -> -33835.753 | J26: =I25-J25 -> -41301.013 | K26: =J25-K25 -> -50413.35 | L26: =K25-L25 -> -61536.162 | M26: =L25-M25 -> -75113.026 | ... O26: =N25-O25 -> -111914.14

Sheet Debt
A1: =CoName -> NVIDIA Corp. | C1: Hist. | D1: Hist. | E1: Hist. | F1: Proj. | G1: Proj. | H1: Proj. | I1: Proj. | J1: Proj. | K1: Proj. | L1: Proj. | M1: Proj. | N1: Proj. | O1: Proj.
A2: Assumptions | C2: 2023 | D2: =C2+1 -> 2024 | E2: =D2+1 -> 2025 | F2: =E2+1 -> 2026 | G2: =F2+1 -> 2027 | H2: =G2+1 -> 2028 | I2: =H2+1 -> 2029 | J2: =I2+1 -> 2030 | K2: =J2+1 -> 2031 | ... O2: =N2+1 -> 2035
B4: Interest rate on revolver | F4: =Assumptions!F24 -> 0 | G4: =Assumptions!G24 -> 0 | H4: =Assumptions!H24 -> 0 | I4: =Assumptions!I24 -> 0 | J4: =Assumptions!J24 -> 0 | K4: =Assumptions!K24 -> 0 | L4: =Assumptions!L24 -> 0 | M4: =Assumptions!M24 -> 0 | ... O4: =Assumptions!O24 -> 0
B5: Interest rate on long-term debt | F5: =Assumptions!F25 -> 0.029 | G5: =Assumptions!G25 -> 0.029 | H5: =Assumptions!H25 -> 0.029 | I5: =Assumptions!I25 -> 0.029 | J5: =Assumptions!J25 -> 0.029 | K5: =Assumptions!K25 -> 0.029 | L5: =Assumptions!L25 -> 0.029 | M5: =Assumptions!M25 -> 0.029 | ... O5: =Assumptions!O25 -> 0.029
B6: Interest rate on cash | F6: =Assumptions!F26 -> 0.05 | G6: =Assumptions!G26 -> 0.05 | H6: =Assumptions!H26 -> 0.05 | I6: =Assumptions!I26 -> 0.05 | J6: =Assumptions!J26 -> 0.05 | K6: =Assumptions!K26 -> 0.05 | L6: =Assumptions!L26 -> 0.05 | M6: =Assumptions!M26 -> 0.05 | ... O6: =Assumptions!O26 -> 0.05
B8: Issuance of long-term debt | F8: =Assumptions!F28 -> 0 | G8: =Assumptions!G28 -> 0 | H8: =Assumptions!H28 -> 0 | I8: =Assumptions!I28 -> 0 | J8: =Assumptions!J28 -> 0 | K8: =Assumptions!K28 -> 0 | L8: =Assumptions!L28 -> 0 | M8: =Assumptions!M28 -> 0 | ... O8: =Assumptions!O28 -> 0
B9: Repayment of long-term debt | F9: =Assumptions!F29 -> 0 | G9: =Assumptions!G29 -> 0 | H9: =Assumptions!H29 -> 0 | I9: =Assumptions!I29 -> 0 | J9: =Assumptions!J29 -> 0 | K9: =Assumptions!K29 -> 0 | L9: =Assumptions!L29 -> 0 | M9: =Assumptions!M29 -> 0 | ... O9: =Assumptions!O29 -> 0
A11: Revolver | C11: 2023 | D11: =C11+1 -> 2024 | E11: =D11+1 -> 2025 | F11: =E11+1 -> 2026 | G11: =F11+1 -> 2027 | H11: =G11+1 -> 2028 | I11: =H11+1 -> 2029 | J11: =I11+1 -> 2030 | K11: =J11+1 -> 2031 | ... O11: =N11+1 -> 2035
B12: Balance | F12: NO REVOLVER
B13: Interest rate
B14: Interest expense
A16: Long term debt | C16: 2023 | D16: =C16+1 -> 2024 | E16: =D16+1 -> 2025 | F16: =E16+1 -> 2026 | G16: =F16+1 -> 2027 | H16: =G16+1 -> 2028 | I16: =H16+1 -> 2029 | J16: =I16+1 -> 2030 | K16: =J16+1 -> 2031 | ... O16: =N16+1 -> 2035
B17: Beginning balance | F17: =E20 -> 8463 | G17: =F20 -> 8463 | H17: =G20 -> 8463 | I17: =H20 -> 8463 | J17: =I20 -> 8463 | K17: =J20 -> 8463 | L17: =K20 -> 8463 | M17: =L20 -> 8463 | ... O17: =N20 -> 8463
B18: Issuance | F18: =F8 -> 0 | G18: =G8 -> 0 | H18: =H8 -> 0 | I18: =I8 -> 0 | J18: =J8 -> 0 | K18: =K8 -> 0 | L18: =L8 -> 0 | M18: =M8 -> 0 | ... O18: =O8 -> 0
B19: Repayment | F19: =F9 -> 0 | G19: =G9 -> 0 | H19: =H9 -> 0 | I19: =I9 -> 0 | J19: =J9 -> 0 | K19: =K9 -> 0 | L19: =L9 -> 0 | M19: =M9 -> 0 | ... O19: =O9 -> 0
B20: Ending balance | E20: =BalSheet!E34 -> 8463 | F20: =SUM(F17:F19) -> 8463 | G20: =SUM(G17:G19) -> 8463 | H20: =SUM(H17:H19) -> 8463 | I20: =SUM(I17:I19) -> 8463 | J20: =SUM(J17:J19) -> 8463 | K20: =SUM(K17:K19) -> 8463 | L20: =SUM(L17:L19) -> 8463 | M20: =SUM(M17:M19) -> 8463 | ... O20: =SUM(O17:O19) -> 8463
B21: Interest rate | F21: =F5 -> 0.029 | G21: =G5 -> 0.029 | H21: =H5 -> 0.029 | I21: =I5 -> 0.029 | J21: =J5 -> 0.029 | K21: =K5 -> 0.029 | L21: =L5 -> 0.029 | M21: =M5 -> 0.029 | ... O21: =O5 -> 0.029
B22: Interest expense | F22: =F20*F21 -> 245.427 | G22: =G20*G21 -> 245.427 | H22: =H20*H21 -> 245.427 | I22: =I20*I21 -> 245.427 | J22: =J20*J21 -> 245.427 | K22: =K20*K21 -> 245.427 | L22: =L20*L21 -> 245.427 | M22: =M20*M21 -> 245.427 | ... O22: =O20*O21 -> 245.427
A24: Debt summary | C24: 2023 | D24: =C24+1 -> 2024 | E24: =D24+1 -> 2025 | F24: =E24+1 -> 2026 | G24: =F24+1 -> 2027 | H24: =G24+1 -> 2028 | I24: =H24+1 -> 2029 | J24: =I24+1 -> 2030 | K24: =J24+1 -> 2031 | ... O24: =N24+1 -> 2035
B25: Revolver | F25: =F12 -> NO REVOLVER | G25: =G12 -> 0 | H25: =H12 -> 0 | I25: =I12 -> 0 | J25: =J12 -> 0 | K25: =K12 -> 0 | L25: =L12 -> 0 | M25: =M12 -> 0 | ... O25: =O12 -> 0
B26: Total long term debt | F26: =F20 -> 8463 | G26: =G20 -> 8463 | H26: =H20 -> 8463 | I26: =I20 -> 8463 | J26: =J20 -> 8463 | K26: =K20 -> 8463 | L26: =L20 -> 8463 | M26: =M20 -> 8463 | ... O26: =O20 -> 8463
B27: Total debt | F27: =SUM(F25:F26) -> 8463 | G27: =SUM(G25:G26) -> 8463 | H27: =SUM(H25:H26) -> 8463 | I27: =SUM(I25:I26) -> 8463 | J27: =SUM(J25:J26) -> 8463 | K27: =SUM(K25:K26) -> 8463 | L27: =SUM(L25:L26) -> 8463 | M27: =SUM(M25:M26) -> 8463 | ... O27: =SUM(O25:O26) -> 8463
B28: Total interest expense | F28: =F22 -> 245.427 | G28: =G22 -> 245.427 | H28: =H22 -> 245.427 | I28: =I22 -> 245.427 | J28: =J22 -> 245.427 | K28: =K22 -> 245.427 | L28: =L22 -> 245.427 | M28: =M22 -> 245.427 | ... O28: =O22 -> 245.427
A30: Interest income | C30: 2023 | D30: =C30+1 -> 2024 | E30: =D30+1 -> 2025 | F30: =E30+1 -> 2026 | G30: =F30+1 -> 2027 | H30: =G30+1 -> 2028 | I30: =H30+1 -> 2029 | J30: =I30+1 -> 2030 | K30: =J30+1 -> 2031 | ... O30: =N30+1 -> 2035
B31: Excess Cash | E31: =BalSheet!E16 -> 6631.545 | F31: =BalSheet!F16 -> 69476.523 | G31: =BalSheet!G16 -> 169776.21 | H31: =BalSheet!H16 -> 313144.91 | I31: =BalSheet!I16 -> 492788.07 | J31: =BalSheet!J16 -> 712755.66 | K31: =BalSheet!K16 -> 981790.48 | L31: =BalSheet!L16 -> 1310617.5 | ... O31: =BalSheet!O16 -> 2802392.3
B32: Interest rate | E32: =Assumptions!E26 -> 0.26931884 | F32: =F6 -> 0.05 | G32: =G6 -> 0.05 | H32: =H6 -> 0.05 | I32: =I6 -> 0.05 | J32: =J6 -> 0.05 | K32: =K6 -> 0.05 | L32: =L6 -> 0.05 | M32: =M6 -> 0.05 | ... O32: =O6 -> 0.05
B33: Interest income | E33: =E31*E32 -> 1786 | F33: =F31*F32 -> 3473.8262 | G33: =G31*G32 -> 8488.8105 | H33: =H31*H32 -> 15657.245 | I33: =I31*I32 -> 24639.404 | J33: =J31*J32 -> 35637.783 | K33: =K31*K32 -> 49089.524 | L33: =L31*L32 -> 65530.875 | ... O33: =O31*O32 -> 140119.62

Sheet IncState
A1: =CoName -> NVIDIA Corp. | C1: Hist. | D1: Hist. | E1: Hist. | F1: Proj. | G1: Proj. | H1: Proj. | I1: Proj. | J1: Proj. | K1: Proj. | L1: Proj. | M1: Proj. | N1: Proj. | O1: Proj.
A2: Assumptions | C2: 2023 | D2: =C2+1 -> 2024 | E2: =D2+1 -> 2025 | F2: =E2+1 -> 2026 | G2: =F2+1 -> 2027 | H2: =G2+1 -> 2028 | I2: =H2+1 -> 2029 | J2: =I2+1 -> 2030 | K2: =J2+1 -> 2031 | ... O2: =N2+1 -> 2035
B4: Revenue growth | F4: =Assumptions!F10 -> 0.57471015 | G4: =Assumptions!G10 -> 0.4100506 | H4: =Assumptions!H10 -> 0.24563228 | I4: =Assumptions!I10 -> 0.22063228 | J4: =Assumptions!J10 -> 0.22063228 | K4: =Assumptions!K10 -> 0.22063228 | L4: =Assumptions!L10 -> 0.22063228 | M4: =Assumptions!M10 -> 0.22063228 | ... O4: =Assumptions!O10 -> 0.22063228
B5: Cost of goods sold as % of sales | F5: =Assumptions!F11 -> 0.25011303 | G5: =Assumptions!G11 -> 0.25011303 | H5: =Assumptions!H11 -> 0.25011303 | I5: =Assumptions!I11 -> 0.25011303 | J5: =Assumptions!J11 -> 0.25011303 | K5: =Assumptions!K11 -> 0.25011303 | L5: =Assumptions!L11 -> 0.25011303 | M5: =Assumptions!M11 -> 0.25011303 | ... O5: =Assumptions!O11 -> 0.25011303
B6: R&D % of sales | F6: =Assumptions!F12 -> 0.098960129 | G6: =Assumptions!G12 -> 0.098960129 | H6: =Assumptions!H12 -> 0.098960129 | I6: =Assumptions!I12 -> 0.098960129 | J6: =Assumptions!J12 -> 0.098960129 | K6: =Assumptions!K12 -> 0.098960129 | L6: =Assumptions!L12 -> 0.098960129 | M6: =Assumptions!M12 -> 0.098960129 | ... O6: =Assumptions!O12 -> 0.098960129
B7: SG&A % of sales | F7: =Assumptions!F13 -> 0.026751573 | G7: =Assumptions!G13 -> 0.026751573 | H7: =Assumptions!H13 -> 0.026751573 | I7: =Assumptions!I13 -> 0.026751573 | J7: =Assumptions!J13 -> 0.026751573 | K7: =Assumptions!K13 -> 0.026751573 | L7: =Assumptions!L13 -> 0.026751573 | M7: =Assumptions!M13 -> 0.026751573 | ... O7: =Assumptions!O13 -> 0.026751573
B8: Amortization amount | F8: =Assumptions!F14 -> 0 | G8: =Assumptions!G14 -> 0 | H8: =Assumptions!H14 -> 0 | I8: =Assumptions!I14 -> 0 | J8: =Assumptions!J14 -> 0 | K8: =Assumptions!K14 -> 0 | L8: =Assumptions!L14 -> 0 | M8: =Assumptions!M14 -> 0 | ... O8: =Assumptions!O14 -> 0
B9: Non recurring items, amount | F9: =Assumptions!F15 -> 0 | G9: =Assumptions!G15 -> 0 | H9: =Assumptions!H15 -> 0 | I9: =Assumptions!I15 -> 0 | J9: =Assumptions!J15 -> 0 | K9: =Assumptions!K15 -> 0 | L9: =Assumptions!L15 -> 0 | M9: =Assumptions!M15 -> 0 | ... O9: =Assumptions!O15 -> 0
B10: Other income (expense), amt | F10: =Assumptions!F16 -> 0 | G10: =Assumptions!G16 -> 0 | H10: =Assumptions!H16 -> 0 | I10: =Assumptions!I16 -> 0 | J10: =Assumptions!J16 -> 0 | K10: =Assumptions!K16 -> 0 | L10: =Assumptions!L16 -> 0 | M10: =Assumptions!M16 -> 0 | ... O10: =Assumptions!O16 -> 0
B11: Effective tax rate | F11: =Assumptions!F17 -> 0.165 | G11: =Assumptions!G17 -> 0.165 | H11: =Assumptions!H17 -> 0.165 | I11: =Assumptions!I17 -> 0.165 | J11: =Assumptions!J17 -> 0.165 | K11: =Assumptions!K17 -> 0.165 | L11: =Assumptions!L17 -> 0.165 | M11: =Assumptions!M17 -> 0.165 | ... O11: =Assumptions!O17 -> 0.165
B12: Dividend Payout Rate | F12: =Assumptions!F18 -> 0.021 | G12: =Assumptions!G18 -> 0.026 | H12: =Assumptions!H18 -> 0.031 | I12: =Assumptions!I18 -> 0.036 | J12: =Assumptions!J18 -> 0.041 | K12: =Assumptions!K18 -> 0.046 | L12: =Assumptions!L18 -> 0.051 | M12: =Assumptions!M18 -> 0.056 | ... O12: =Assumptions!O18 -> 0.066
B13: Basic WASO | F13: =Assumptions!F19 -> 24555 | G13: =Assumptions!G19 -> 24555 | H13: =Assumptions!H19 -> 24555 | I13: =Assumptions!I19 -> 24555 | J13: =Assumptions!J19 -> 24555 | K13: =Assumptions!K19 -> 24555 | L13: =Assumptions!L19 -> 24555 | M13: =Assumptions!M19 -> 24555 | ... O13: =Assumptions!O19 -> 24555
B14: Diluted WASO | F14: =Assumptions!F20 -> 24804 | G14: =Assumptions!G20 -> 24804 | H14: =Assumptions!H20 -> 24804 | I14: =Assumptions!I20 -> 24804 | J14: =Assumptions!J20 -> 24804 | K14: =Assumptions!K20 -> 24804 | L14: =Assumptions!L20 -> 24804 | M14: =Assumptions!M20 -> 24804 | ... O14: =Assumptions!O20 -> 24804
A16: Income statement | C16: 2023 | D16: =C16+1 -> 2024 | E16: =D16+1 -> 2025 | F16: =E16+1 -> 2026 | G16: =F16+1 -> 2027 | H16: =G16+1 -> 2028 | I16: =H16+1 -> 2029 | J16: =I16+1 -> 2030 | K16: =J16+1 -> 2031 | ... O16: =N16+1 -> 2035
B17: Revenue | C17: 26974 | D17: =Revenue!K8 -> 60922 | E17: =Revenue!P8 -> 130497 | F17: =E17*(1+F4) -> 205494.95 | G17: =F17*(1+G4) -> 289758.28 | H17: =G17*(1+H4) -> 360932.26 | I17: =H17*(1+I4) -> 440565.57 | J17: =I17*(1+J4) -> 537768.56 | K17: =J17*(1+K4) -> 656417.67 | L17: =K17*(1+L4) -> 801244.59 | M17: =L17*(1+M4) -> 978025.02 | ... O17: =N17*(1+O4) -> 1457201.7
B18: COGS | C18: 11618 | D18: 16621 | E18: 32639 | F18: =F17*F5 -> 51396.965 | G18: =G17*G5 -> 72472.321 | H18: =H17*H5 -> 90273.862 | I18: =I17*I5 -> 110191.19 | J18: =J17*J5 -> 134502.92 | K18: =K17*K5 -> 164178.61 | L18: =L17*L5 -> 200401.71 | M18: =M17*M5 -> 244616.8 | ... O18: =O17*O5 -> 364465.13
B19: R&D | C19: 7339 | D19: 8675 | E19: 12914 | F19: =F17*F6 -> 20335.807 | G19: =G17*G6 -> 28674.517 | H19: =H17*H6 -> 35717.904 | I19: =I17*I6 -> 43598.426 | J19: =J17*J6 -> 53217.646 | K19: =K17*K6 -> 64959.177 | L19: =L17*L6 -> 79291.269 | M19: =M17*M6 -> 96785.482 | ... O19: =O17*O6 -> 144204.87
B20: SG&A | C20: 2440 | D20: 2654 | E20: 3491 | F20: =F17*F7 -> 5497.3131 | G20: =G17*G7 -> 7751.4897 | H20: =H17*H7 -> 9655.5058 | I20: =I17*I7 -> 11785.822 | J20: =J17*J7 -> 14386.155 | K20: =K17*K7 -> 17560.205 | L20: =L17*L7 -> 21434.553 | M20: =M17*M7 -> 26163.707 | ... O20: =O17*O7 -> 38982.437
A21: * | B21: EBIT | C21: =C17-SUM(C18:C20) -> 5577 | D21: =D17-SUM(D18:D20) -> 32972 | E21: =E17-SUM(E18:E20) -> 81453 | F21: =F17-SUM(F18:F20) -> 128264.87 | G21: =G17-SUM(G18:G20) -> 180859.95 | H21: =H17-SUM(H18:H20) -> 225284.99 | I21: =I17-SUM(I18:I20) -> 274990.14 | J21: =J17-SUM(J18:J20) -> 335661.84 | ... O21: =O17-SUM(O18:O20) -> 909549.26
B23: Depreciation | C23: 1864 | D23: 1508 | E23: 1544 | F23: =Calcs!F8 -> 2370.5977 | G23: =Calcs!G8 -> 3892.4911 | H23: =Calcs!H8 -> 5877.0432 | I23: =Calcs!I8 -> 8047.1839 | J23: =Calcs!J8 -> 10439.731 | K23: =Calcs!K8 -> 13179.017 | L23: =Calcs!L8 -> 16394.712 | M23: =Calcs!M8 -> 20229.49 | ... O23: =Calcs!O8 -> 30437.003
B24: Amortization | C24: 0 | D24: 0 | E24: 0 | F24: =F8 -> 0 | G24: =G8 -> 0 | H24: =H8 -> 0 | I24: =I8 -> 0 | J24: =J8 -> 0 | K24: =K8 -> 0 | L24: =L8 -> 0 | M24: =M8 -> 0 | ... O24: =O8 -> 0
A25: * | B25: EBITDA | C25: =C21+C23 -> 7441 | D25: =D21+D23 -> 34480 | E25: =E21+E23 -> 82997 | F25: =F21+F23 -> 130635.46 | G25: =G21+G23 -> 184752.44 | H25: =H21+H23 -> 231162.04 | I25: =I21+I23 -> 283037.32 | J25: =J21+J23 -> 346101.57 | ... O25: =O21+O23 -> 939986.26
B27: Non-recurring items | C27: -1353 | F27: =F9 -> 0 | G27: =G9 -> 0 | H27: =H9 -> 0 | I27: =I9 -> 0 | J27: =J9 -> 0 | K27: =K9 -> 0 | L27: =L9 -> 0 | M27: =M9 -> 0 | ... O27: =O9 -> 0
B28: Other income (expense) | C28: -48 | D28: 237 | E28: 1034 | F28: =F10 -> 0 | G28: =G10 -> 0 | H28: =H10 -> 0 | I28: =I10 -> 0 | J28: =J10 -> 0 | K28: =K10 -> 0 | L28: =L10 -> 0 | M28: =M10 -> 0 | ... O28: =O10 -> 0
B30: Interest income | C30: 267 | D30: 866 | E30: 1786 | F30: =IF(circ=1,Debt!F33,0) -> 0 | G30: =IF(circ=1,Debt!G33,0) -> 0 | H30: =IF(circ=1,Debt!H33,0) -> 0 | I30: =IF(circ=1,Debt!I33,0) -> 0 | J30: =IF(circ=1,Debt!J33,0) -> 0 | K30: =IF(circ=1,Debt!K33,0) -> 0 | L30: =IF(circ=1,Debt!L33,0) -> 0 | M30: =IF(circ=1,Debt!M33,0) -> 0 | ... O30: =IF(circ=1,Debt!O33,0) -> 0
B31: Interest expense | C31: -262 | D31: -257 | E31: -247 | F31: =IF(circ=1,-Debt!F28,0) -> 0 | G31: =IF(circ=1,-Debt!G28,0) -> 0 | H31: =IF(circ=1,-Debt!H28,0) -> 0 | I31: =IF(circ=1,-Debt!I28,0) -> 0 | J31: =IF(circ=1,-Debt!J28,0) -> 0 | K31: =IF(circ=1,-Debt!K28,0) -> 0 | L31: =IF(circ=1,-Debt!L28,0) -> 0 | M31: =IF(circ=1,-Debt!M28,0) -> 0 | ... O31: =IF(circ=1,-Debt!O28,0) -> 0
A33: * | B33: Pretax Income | C33: =C21+SUM(C30:C31,C27:C28) -> 4181 | D33: =D21+SUM(D28:D31) -> 33818 | E33: =E21+SUM(E27:E31) -> 84026 | F33: =F21+SUM(F27:F31) -> 128264.87 | G33: =G21+SUM(G27:G31) -> 180859.95 | H33: =H21+SUM(H27:H31) -> 225284.99 | I33: =I21+SUM(I27:I31) -> 274990.14 | J33: =J21+SUM(J27:J31) -> 335661.84 | K33: =K21+SUM(K27:K31) -> 409719.67 | L33: =L21+SUM(L27:L31) -> 500117.06 | ... O33: =O21+SUM(O27:O31) -> 909549.26
B35: Tax expense | C35: -187 | D35: 4058 | E35: 11146 | F35: =F33*F11 -> 21163.703 | G35: =G33*G11 -> 29841.892 | H35: =H33*H11 -> 37172.024 | I35: =I33*I11 -> 45373.372 | J35: =J33*J11 -> 55384.203 | K35: =K33*K11 -> 67603.746 | L35: =L33*L11 -> 82519.315 | M35: =M33*M11 -> 100725.74 | ... O35: =O33*O11 -> 150075.63
A36: * | B36: Net income | C36: =C33-C35 -> 4368 | D36: =D33-D35 -> 29760 | E36: =E33-E35 -> 72880 | F36: =F33-F35 -> 107101.16 | G36: =G33-G35 -> 151018.06 | H36: =H33-H35 -> 188112.97 | I36: =I33-I35 -> 229616.76 | J36: =J33-J35 -> 280277.63 | ... O36: =O33-O35 -> 759473.63
B37: Dividend payout rate | C37: 0.016 | D37: 0.016 | E37: 0.016 | F37: =F12 -> 0.021 | G37: =G12 -> 0.026 | H37: =H12 -> 0.031 | I37: =I12 -> 0.036 | J37: =J12 -> 0.041 | K37: =K12 -> 0.046 | L37: =L12 -> 0.051 | M37: =M12 -> 0.056 | ... O37: =O12 -> 0.066
B38: Dividends | C38: =C37*C40 -> 397.92 | D38: =D37*D40 -> 395.04 | E38: =E37*E40 -> 392.88 | F38: =F37*F40 -> 515.655 | G38: =G37*G40 -> 638.43 | H38: =H37*H40 -> 761.205 | I38: =I37*I40 -> 883.98 | J38: =J37*J40 -> 1006.755 | ... O38: =O37*O40 -> 1620.63
A39: Shareholder information | C39: 2023 | D39: =C39+1 -> 2024 | E39: =D39+1 -> 2025 | F39: =E39+1 -> 2026 | G39: =F39+1 -> 2027 | H39: =G39+1 -> 2028 | I39: =H39+1 -> 2029 | J39: =I39+1 -> 2030 | K39: =J39+1 -> 2031 | ... O39: =N39+1 -> 2035
B40: Basic WASO | C40: 24870 | D40: 24690 | E40: 24555 | F40: =F13 -> 24555 | G40: =G13 -> 24555 | H40: =H13 -> 24555 | I40: =I13 -> 24555 | J40: =J13 -> 24555 | K40: =K13 -> 24555 | L40: =L13 -> 24555 | M40: =M13 -> 24555 | ... O40: =O13 -> 24555
B41: Diluted WASO | C41: 25070 | D41: 24940 | E41: 24804 | F41: =F14 -> 24804 | G41: =G14 -> 24804 | H41: =H14 -> 24804 | I41: =I14 -> 24804 | J41: =J14 -> 24804 | K41: =K14 -> 24804 | L41: =L14 -> 24804 | M41: =M14 -> 24804 | ... O41: =O14 -> 24804
B42: Basic earnings per share | C42: =C36/C40 -> 0.17563329 | D42: =D36/D40 -> 1.2053463 | E42: =E36/E40 -> 2.968031 | F42: =F36/F40 -> 4.3616845 | G42: =G36/G40 -> 6.1501958 | H42: =H36/H40 -> 7.6608825 | I42: =I36/I40 -> 9.3511205 | J42: =J36/J40 -> 11.41428 | ... O42: =O36/O40 -> 30.92949
A43: * | B43: Diluted earnings per share | C43: =C36/C41 -> 0.17423215 | D43: =D36/D41 -> 1.1932638 | E43: =E36/E41 -> 2.9382358 | F43: =F36/F41 -> 4.3178989 | G43: =G36/G41 -> 6.0884559 | H43: =H36/H41 -> 7.5839772 | I43: =I36/I41 -> 9.2572473 | J43: =J36/J41 -> 11.299695 | ... O43: =O36/O41 -> 30.618998

Sheet BalSheet
A1: =CoName -> NVIDIA Corp. | C1: Hist. | D1: Hist. | E1: Hist. | F1: Proj. | G1: Proj. | H1: Proj. | I1: Proj. | J1: Proj. | K1: Proj. | L1: Proj. | M1: Proj. | N1: Proj. | O1: Proj.
A2: Assumptions | C2: 2023 | D2: =C2+1 -> 2024 | E2: =D2+1 -> 2025 | F2: =E2+1 -> 2026 | G2: =F2+1 -> 2027 | H2: =G2+1 -> 2028 | I2: =H2+1 -> 2029 | J2: =I2+1 -> 2030 | K2: =J2+1 -> 2031 | ... O2: =N2+1 -> 2035
B4: Operating Cash % of sales | F4: =Assumptions!F45 -> 0.015 | G4: =F4 -> 0.015 | H4: =G4 -> 0.015 | I4: =H4 -> 0.015 | J4: =I4 -> 0.015 | K4: =J4 -> 0.015 | L4: =K4 -> 0.015 | M4: =L4 -> 0.015 | N4: =M4 -> 0.015 | O4: =N4 -> 0.015
B5: Accounts receivable % of sales | F5: =Assumptions!F46 -> 0.17674736 | G5: =Assumptions!G46 -> 0.17674736 | H5: =Assumptions!H46 -> 0.17674736 | I5: =Assumptions!I46 -> 0.17674736 | J5: =Assumptions!J46 -> 0.17674736 | K5: =Assumptions!K46 -> 0.17674736 | L5: =Assumptions!L46 -> 0.17674736 | M5: =Assumptions!M46 -> 0.17674736 | ... O5: =Assumptions!O46 -> 0.17674736
B6: Inventories % of COGS | F6: =Assumptions!F47 -> 0.30883299 | G6: =Assumptions!G47 -> 0.30883299 | H6: =Assumptions!H47 -> 0.30883299 | I6: =Assumptions!I47 -> 0.30883299 | J6: =Assumptions!J47 -> 0.30883299 | K6: =Assumptions!K47 -> 0.30883299 | L6: =Assumptions!L47 -> 0.30883299 | M6: =Assumptions!M47 -> 0.30883299 | ... O6: =Assumptions!O47 -> 0.30883299
B7: Other current assets % of sales | F7: =Assumptions!F48 -> 0.29419833 | G7: =Assumptions!G48 -> 0.29419833 | H7: =Assumptions!H48 -> 0.29419833 | I7: =Assumptions!I48 -> 0.29419833 | J7: =Assumptions!J48 -> 0.29419833 | K7: =Assumptions!K48 -> 0.29419833 | L7: =Assumptions!L48 -> 0.29419833 | M7: =Assumptions!M48 -> 0.29419833 | ... O7: =Assumptions!O48 -> 0.29419833
B8: Other long-term assets % of sales | F8: =Assumptions!F49 -> 0.13336705 | G8: =Assumptions!G49 -> 0.13336705 | H8: =Assumptions!H49 -> 0.13336705 | I8: =Assumptions!I49 -> 0.13336705 | J8: =Assumptions!J49 -> 0.13336705 | K8: =Assumptions!K49 -> 0.13336705 | L8: =Assumptions!L49 -> 0.13336705 | M8: =Assumptions!M49 -> 0.13336705 | ... O8: =Assumptions!O49 -> 0.13336705
B10: Accounts payable/Accural % of COGS | F10: =Assumptions!F53 -> 0.193327 | G10: =Assumptions!G53 -> 0.193327 | H10: =Assumptions!H53 -> 0.193327 | I10: =Assumptions!I53 -> 0.193327 | J10: =Assumptions!J53 -> 0.193327 | K10: =Assumptions!K53 -> 0.193327 | L10: =Assumptions!L53 -> 0.193327 | M10: =Assumptions!M53 -> 0.193327 | ... O10: =Assumptions!O53 -> 0.193327
B11: Other current liabilities % of sales | F11: =Assumptions!F54 -> 0.089940765 | G11: =Assumptions!G54 -> 0.089940765 | H11: =Assumptions!H54 -> 0.089940765 | I11: =Assumptions!I54 -> 0.089940765 | J11: =Assumptions!J54 -> 0.089940765 | K11: =Assumptions!K54 -> 0.089940765 | L11: =Assumptions!L54 -> 0.089940765 | M11: =Assumptions!M54 -> 0.089940765 | ... O11: =Assumptions!O54 -> 0.089940765
B12: Other long-term liabilities % of sales | F12: =Assumptions!F55 -> 0.044169598 | G12: =Assumptions!G55 -> 0.044169598 | H12: =Assumptions!H55 -> 0.044169598 | I12: =Assumptions!I55 -> 0.044169598 | J12: =Assumptions!J55 -> 0.044169598 | K12: =Assumptions!K55 -> 0.044169598 | L12: =Assumptions!L55 -> 0.044169598 | M12: =Assumptions!M55 -> 0.044169598 | ... O12: =Assumptions!O55 -> 0.044169598
A14: Balance sheet | C14: 2023 | D14: =C14+1 -> 2024 | E14: =D14+1 -> 2025 | F14: =E14+1 -> 2026 | G14: =F14+1 -> 2027 | H14: =G14+1 -> 2028 | I14: =H14+1 -> 2029 | J14: =I14+1 -> 2030 | K14: =J14+1 -> 2031 | ... O14: =N14+1 -> 2035
B15: Operating Cash | C15: =1.5%*IncState!C17 -> 404.61 | D15: =1.5%*IncState!D17 -> 913.83 | E15: =1.5%*IncState!E17 -> 1957.455 | F15: =F4*IncState!F17 -> 3082.4243 | G15: =G4*IncState!G17 -> 4346.3742 | H15: =H4*IncState!H17 -> 5413.984 | I15: =I4*IncState!I17 -> 6608.4836 | J15: =J4*IncState!J17 -> 8066.5284 | K15: =K4*IncState!K17 -> 9846.265 | L15: =L4*IncState!L17 -> 12018.669 | M15: =M4*IncState!M17 -> 14670.375 | ... O15: =O4*IncState!O17 -> 21858.025
B16: Excess cash | C16: =3389-C15 -> 2984.39 | D16: =7280-D15 -> 6366.17 | E16: =8589-E15 -> 6631.545 | F16: =MAX(CashFlow!F23,0) -> 69476.523 | G16: =MAX(CashFlow!G23,0) -> 169776.21 | H16: =MAX(CashFlow!H23,0) -> 313144.91 | I16: =MAX(CashFlow!I23,0) -> 492788.07 | J16: =MAX(CashFlow!J23,0) -> 712755.66 | K16: =MAX(CashFlow!K23,0) -> 981790.48 | L16: =MAX(CashFlow!L23,0) -> 1310617.5 | M16: =MAX(CashFlow!M23,0) -> 1712365.5 | ... O16: =MAX(CashFlow!O23,0) -> 2802392.3
B17: Accounts receivable | C17: 3827 | D17: 9999 | E17: 23065 | F17: =F5*IncState!F17 -> 36320.69 | G17: =G5*IncState!G17 -> 51214.01 | H17: =H5*IncState!H17 -> 63793.824 | I17: =I5*IncState!I17 -> 77868.801 | J17: =J5*IncState!J17 -> 95049.173 | K17: =K5*IncState!K17 -> 116020.09 | L17: =L5*IncState!L17 -> 141617.87 | M17: =M5*IncState!M17 -> 172863.34 | ... O17: =O5*IncState!O17 -> 257556.55
B18: Inventories | C18: 5159 | D18: 5282 | E18: 10080 | F18: =F6*IncState!F18 -> 15873.078 | G18: =G6*IncState!G18 -> 22381.844 | H18: =H6*IncState!H18 -> 27879.547 | I18: =I6*IncState!I18 -> 34030.675 | J18: =J6*IncState!J18 -> 41538.94 | K18: =K6*IncState!K18 -> 50703.772 | L18: =L6*IncState!L18 -> 61890.66 | M18: =M6*IncState!M18 -> 75545.738 | ... O18: =O6*IncState!O18 -> 112558.86
B19: Other current assets | C19: =791+9907 -> 10698 | D19: =3080+18704 -> 21784 | E19: =3771+34621 -> 38392 | F19: =F7*IncState!F17 -> 60456.272 | G19: =G7*IncState!G17 -> 85246.403 | H19: =H7*IncState!H17 -> 106185.67 | I19: =I7*IncState!I17 -> 129613.66 | J19: =J7*IncState!J17 -> 158210.62 | K19: =K7*IncState!K17 -> 193116.98 | L19: =L7*IncState!L17 -> 235724.82 | M19: =M7*IncState!M17 -> 287733.33 | ... O19: =O7*IncState!O17 -> 428706.31
B20: Total current assets | C20: =SUM(C15:C19) -> 23073 | D20: =SUM(D15:D19) -> 44345 | E20: =SUM(E15:E19) -> 80126 | F20: =SUM(F15:F19) -> 185208.99 | G20: =SUM(G15:G19) -> 332964.84 | H20: =SUM(H15:H19) -> 516417.93 | I20: =SUM(I15:I19) -> 740909.69 | J20: =SUM(J15:J19) -> 1015620.9 | ... O20: =SUM(O15:O19) -> 3623072
B22: Property, plant & equipment, net | C22: =3807+1038 -> 4845 | D22: =3914+1346 -> 5260 | E22: =6283+1793 -> 8076 | F22: =Calcs!F9 -> 13260.688 | G22: =Calcs!G9 -> 20021.533 | H22: =Calcs!H9 -> 27414.629 | I22: =Calcs!I9 -> 35565.405 | J22: =Calcs!J9 -> 44897.427 | K22: =Calcs!K9 -> 55852.45 | L22: =Calcs!L9 -> 68916.527 | M22: =Calcs!M9 -> 84645.384 | ... O22: =Calcs!O9 -> 126829.72
B23: Intangible assets | C23: =4372+1676 -> 6048 | D23: =4430+1112 -> 5542 | E23: =5188+807 -> 5995 | F23: =E23-IncState!F24 -> 5995 | G23: =F23-IncState!G24 -> 5995 | H23: =G23-IncState!H24 -> 5995 | I23: =H23-IncState!I24 -> 5995 | J23: =I23-IncState!J24 -> 5995 | K23: =J23-IncState!K24 -> 5995 | L23: =K23-IncState!L24 -> 5995 | M23: =L23-IncState!M24 -> 5995 | ... O23: =N23-IncState!O24 -> 5995
B24: Other assets | C24: =3396+3820 -> 7216 | D24: =6081+4500 -> 10581 | E24: =6425+10979 -> 17404 | F24: =F8*IncState!F17 -> 27406.256 | G24: =G8*IncState!G17 -> 38644.207 | H24: =H8*IncState!H17 -> 48136.472 | I24: =I8*IncState!I17 -> 58756.931 | J24: =J8*IncState!J17 -> 71720.607 | K24: =K8*IncState!K17 -> 87544.488 | L24: =L8*IncState!L17 -> 106859.63 | M24: =M8*IncState!M17 -> 130436.31 | ... O24: =O8*IncState!O17 -> 194342.69
B25: Total non-current assets | C25: =SUM(C22:C24) -> 18109 | D25: =SUM(D22:D24) -> 21383 | E25: =SUM(E22:E24) -> 31475 | F25: =SUM(F22:F24) -> 46661.944 | G25: =SUM(G22:G24) -> 64660.74 | H25: =SUM(H22:H24) -> 81546.101 | I25: =SUM(I22:I24) -> 100317.34 | J25: =SUM(J22:J24) -> 122613.03 | ... O25: =SUM(O22:O24) -> 327167.41
A27: * | B27: TOTAL ASSETS | C27: =SUM(C25,C20) -> 41182 | D27: =SUM(D25,D20) -> 65728 | E27: =SUM(E25,E20) -> 111601 | F27: =SUM(F25,F20) -> 231870.93 | G27: =SUM(G25,G20) -> 397625.58 | H27: =SUM(H25,H20) -> 597964.03 | I27: =SUM(I25,I20) -> 841227.03 | J27: =SUM(J25,J20) -> 1138233.9 | ... O27: =SUM(O25,O20) -> 3950239.5
B29: Revolver/Short term debt | C29: 1250 | D29: 1250 | E29: 0 | F29: =MIN(CashFlow!F23,0) -> 0 | G29: =MIN(CashFlow!G23,0) -> 0 | H29: =MIN(CashFlow!H23,0) -> 0 | I29: =MIN(CashFlow!I23,0) -> 0 | J29: =MIN(CashFlow!J23,0) -> 0 | K29: =MIN(CashFlow!K23,0) -> 0 | L29: =MIN(CashFlow!L23,0) -> 0 | M29: =MIN(CashFlow!M23,0) -> 0 | ... O29: =MIN(CashFlow!O23,0) -> 0
B30: Accounts payable/Accurals | C30: 1193 | D30: 2699 | E30: 6310 | F30: =F10*IncState!F18 -> 9936.4211 | G30: =G10*IncState!G18 -> 14010.856 | H30: =H10*IncState!H18 -> 17452.375 | I30: =I10*IncState!I18 -> 21302.932 | J30: =J10*IncState!J18 -> 26003.047 | K30: =K10*IncState!K18 -> 31740.159 | L30: =L10*IncState!L18 -> 38743.062 | M30: =M10*IncState!M18 -> 47291.032 | ... O30: =O10*IncState!O18 -> 70460.951
B31: Other current liabilities | C31: 4120 | D31: 6682 | E31: 11737 | F31: =F11*IncState!F17 -> 18482.373 | G31: =G11*IncState!G17 -> 26061.081 | H31: =H11*IncState!H17 -> 32462.524 | I31: =I11*IncState!I17 -> 39624.805 | J31: =J11*IncState!J17 -> 48367.316 | K31: =K11*IncState!K17 -> 59038.707 | L31: =L11*IncState!L17 -> 72064.552 | M31: =M11*IncState!M17 -> 87964.318 | ... O31: =O11*IncState!O17 -> 131061.83
B32: Total current liabilities | C32: =SUM(C29:C31) -> 6563 | D32: =SUM(D29:D31) -> 10631 | E32: =SUM(E29:E31) -> 18047 | F32: =SUM(F29:F31) -> 28418.794 | G32: =SUM(G29:G31) -> 40071.938 | H32: =SUM(H29:H31) -> 49914.899 | I32: =SUM(I29:I31) -> 60927.737 | J32: =SUM(J29:J31) -> 74370.363 | ... O32: =SUM(O29:O31) -> 201522.79
B34: Long-term debt, including current maturities | C34: 9703 | D34: 8459 | E34: 8463 | F34: =Debt!F20 -> 8463 | G34: =Debt!G20 -> 8463 | H34: =Debt!H20 -> 8463 | I34: =Debt!I20 -> 8463 | J34: =Debt!J20 -> 8463 | K34: =Debt!K20 -> 8463 | L34: =Debt!L20 -> 8463 | M34: =Debt!M20 -> 8463 | ... O34: =Debt!O20 -> 8463
B35: Other long-term liabilities | C35: =902+1913 -> 2815 | D35: 3660 | E35: =1519+4245 -> 5764 | F35: =F12*IncState!F17 -> 9076.6293 | G35: =G12*IncState!G17 -> 12798.507 | H35: =H12*IncState!H17 -> 15942.233 | I35: =I12*IncState!I17 -> 19459.604 | J35: =J12*IncState!J17 -> 23753.021 | K35: =K12*IncState!K17 -> 28993.704 | L35: =L12*IncState!L17 -> 35390.651 | M35: =M12*IncState!M17 -> 43198.972 | ... O35: =O12*IncState!O17 -> 64364.013
B36: Total non-current liabilities | C36: =SUM(C34:C35) -> 12518 | D36: =SUM(D34:D35) -> 12119 | E36: =SUM(E34:E35) -> 14227 | F36: =SUM(F34:F35) -> 17539.629 | G36: =SUM(G34:G35) -> 21261.507 | H36: =SUM(H34:H35) -> 24405.233 | I36: =SUM(I34:I35) -> 27922.604 | J36: =SUM(J34:J35) -> 32216.021 | ... O36: =SUM(O34:O35) -> 72827.013
B38: Equity | C38: 22101 | D38: 42978 | E38: 79327 | F38: =Calcs!F17 -> 185912.51 | G38: =Calcs!G17 -> 336292.14 | H38: =Calcs!H17 -> 523643.9 | I38: =Calcs!I17 -> 752376.68 | J38: =Calcs!J17 -> 1031647.6 | K38: =Calcs!K17 -> 1372634 | L38: =Calcs!L17 -> 1788979.4 | M38: =Calcs!M17 -> 2297337.6 | ... O38: =Calcs!O17 -> 3675889.7
A39: * | B39: TOTAL LIABILITIES & EQUITY | C39: =SUM(C38,C36,C32) -> 41182 | D39: =SUM(D38,D36,D32) -> 65728 | E39: =SUM(E38,E36,E32) -> 111601 | F39: =SUM(F38,F36,F32) -> 231870.93 | G39: =SUM(G38,G36,G32) -> 397625.58 | H39: =SUM(H38,H36,H32) -> 597964.03 | I39: =SUM(I38,I36,I32) -> 841227.03 | J39: =SUM(J38,J36,J32) -> 1138233.9 | ... O39: =SUM(O38,O36,O32) -> 3950239.5
A41: * | B41: Balance check | C41: =C39-C27 -> 0 | D41: =D39-D27 -> 0 | E41: =E39-E27 -> 0 | F41: =F39-F27 -> 0 | G41: =G39-G27 -> 0 | H41: =H39-H27 -> 0 | I41: =I39-I27 -> 0 | J41: =J39-J27 -> 0 | ... O41: =O39-O27 -> 0

Sheet CashFlow
A1: =CoName -> NVIDIA Corp. | C1: Hist. | D1: Hist. | E1: Hist. | F1: Proj. | G1: Proj. | H1: Proj. | I1: Proj. | J1: Proj. | K1: Proj. | L1: Proj. | M1: Proj. | N1: Proj. | O1: Proj.
A2: Cash flow statement | C2: 2023 | D2: =C2+1 -> 2024 | E2: =D2+1 -> 2025 | F2: =E2+1 -> 2026 | G2: =F2+1 -> 2027 | H2: =G2+1 -> 2028 | I2: =H2+1 -> 2029 | J2: =I2+1 -> 2030 | K2: =J2+1 -> 2031 | ... O2: =N2+1 -> 2035
B3: Net Income | F3: =IncState!F36 -> 107101.16 | G3: =IncState!G36 -> 151018.06 | H3: =IncState!H36 -> 188112.97 | I3: =IncState!I36 -> 229616.76 | J3: =IncState!J36 -> 280277.63 | K3: =IncState!K36 -> 342115.93 | L3: =IncState!L36 -> 417597.74 | M3: =IncState!M36 -> 509733.29 | ... O3: =IncState!O36 -> 759473.63
B4: Depreciation | F4: =IncState!F23 -> 2370.5977 | G4: =IncState!G23 -> 3892.4911 | H4: =IncState!H23 -> 5877.0432 | I4: =IncState!I23 -> 8047.1839 | J4: =IncState!J23 -> 10439.731 | K4: =IncState!K23 -> 13179.017 | L4: =IncState!L23 -> 16394.712 | M4: =IncState!M23 -> 20229.49 | ... O4: =IncState!O23 -> 30437.003
B5: Amortization | F5: =IncState!F24 -> 0 | G5: =IncState!G24 -> 0 | H5: =IncState!H24 -> 0 | I5: =IncState!I24 -> 0 | J5: =IncState!J24 -> 0 | K5: =IncState!K24 -> 0 | L5: =IncState!L24 -> 0 | M5: =IncState!M24 -> 0 | ... O5: =IncState!O24 -> 0
B6: (inc) / dec In OWC | F6: =Calcs!F26 -> -31866.215 | G6: =Calcs!G26 -> -35803.023 | H6: =Calcs!H26 -> -30241.434 | I6: =Calcs!I26 -> -33835.753 | J6: =Calcs!J26 -> -41301.013 | K6: =Calcs!K26 -> -50413.35 | L6: =Calcs!L26 -> -61536.162 | M6: =Calcs!M26 -> -75113.026 | ... O6: =Calcs!O26 -> -111914.14
B7: (inc) / dec in LT assets | F7: =BalSheet!E24-BalSheet!F24 -> -10002.256 | G7: =BalSheet!F24-BalSheet!G24 -> -11237.951 | H7: =BalSheet!G24-BalSheet!H24 -> -9492.2647 | I7: =BalSheet!H24-BalSheet!I24 -> -10620.46 | J7: =BalSheet!I24-BalSheet!J24 -> -12963.676 | K7: =BalSheet!J24-BalSheet!K24 -> -15823.881 | L7: =BalSheet!K24-BalSheet!L24 -> -19315.14 | M7: =BalSheet!L24-BalSheet!M24 -> -23576.684 | ... O7: =BalSheet!N24-BalSheet!O24 -> -35127.919
B8: inc / (dec) in LT liabilities | F8: =BalSheet!F35-BalSheet!E35 -> 3312.6293 | G8: =BalSheet!G35-BalSheet!F35 -> 3721.8773 | H8: =BalSheet!H35-BalSheet!G35 -> 3143.7264 | I8: =BalSheet!I35-BalSheet!H35 -> 3517.3712 | J8: =BalSheet!J35-BalSheet!I35 -> 4293.4169 | K8: =BalSheet!K35-BalSheet!J35 -> 5240.6832 | L8: =BalSheet!L35-BalSheet!K35 -> 6396.9471 | M8: =BalSheet!M35-BalSheet!L35 -> 7808.3202 | ... O8: =BalSheet!O35-BalSheet!N35 -> 11633.953
B9: Cash Flow From Operations | F9: =SUM(F3:F8) -> 70915.919 | G9: =SUM(G3:G8) -> 111591.45 | H9: =SUM(H3:H8) -> 157400.04 | I9: =SUM(I3:I8) -> 196725.11 | J9: =SUM(J3:J8) -> 240746.09 | K9: =SUM(K3:K8) -> 294298.4 | L9: =SUM(L3:L8) -> 359538.1 | M9: =SUM(M3:M8) -> 439081.39 | ... O9: =SUM(O3:O8) -> 654502.53
B11: Capex | F11: =Calcs!F7 -> 7555.2862 | G11: =Calcs!G7 -> 10653.336 | H11: =Calcs!H7 -> 13270.139 | I11: =Calcs!I7 -> 16197.96 | J11: =Calcs!J7 -> 19771.753 | K11: =Calcs!K7 -> 24134.04 | L11: =Calcs!L7 -> 29458.788 | M11: =Calcs!M7 -> 35958.348 | ... O11: =Calcs!O7 -> 53575.894
B12: Cash Flow From Investing | F12: =-F11 -> -7555.2862 | G12: =-G11 -> -10653.336 | H12: =-H11 -> -13270.139 | I12: =-I11 -> -16197.96 | J12: =-J11 -> -19771.753 | K12: =-K11 -> -24134.04 | L12: =-L11 -> -29458.788 | M12: =-M11 -> -35958.348 | ... O12: =-O11 -> -53575.894
B14: Dividends Paid | F14: =IncState!F38*-1 -> -515.655 | G14: =IncState!G38*-1 -> -638.43 | H14: =IncState!H38*-1 -> -761.205 | I14: =IncState!I38*-1 -> -883.98 | J14: =IncState!J38*-1 -> -1006.755 | K14: =IncState!K38*-1 -> -1129.53 | L14: =IncState!L38*-1 -> -1252.305 | M14: =IncState!M38*-1 -> -1375.08 | ... O14: =IncState!O38*-1 -> -1620.63
B15: Share issuances | F15: =Calcs!F11 -> 0 | G15: =Calcs!G11 -> 0 | H15: =Calcs!H11 -> 0 | I15: =Calcs!I11 -> 0 | J15: =Calcs!J11 -> 0 | K15: =Calcs!K11 -> 0 | L15: =Calcs!L11 -> 0 | M15: =Calcs!M11 -> 0 | ... O15: =Calcs!O11 -> 0
